Workbook

Sheet Compile Sheet-November-2024
A4: Class | B4: Total Enrolment & Attendance November-24
B5: Boys | C5: Girls | D5: Total | E5: total working Days | F5: Total working days-Boys | G5: Total working days-Girls | H5: Total working days-All | I5: P-Days Boys | J5: P-Days Girls | K5: P-Days All | L5: Percentage-Girls | M5: Percentage-Boys | N5: Percentage-Boys | O5: Total average
A6: ECE (ROSE) | B6: 27 | C6: 27 | D6: =SUM(B6:C6) -> 54 | E6: 24 | F6: =B6*E6 -> 648 | G6: =C6*E6 -> 648 | H6: =SUM(F6:G6) -> 1296 | I6: ='ECE (ROSE)'!AK14 -> 498 | J6: ='ECE (ROSE)'!AL14 -> 390 | K6: =SUM(I6:J6) -> 888 | L6: =J6/G6 -> 0.60185185 | M6: =I6/F6 -> 0.76851852 | N6: =K6/H6 -> 0.68518519 | O6: =AVERAGE(L6:M6) -> 0.68518519
A7: ECE (Daffodils) | B7: 31 | C7: 25 | D7: =SUM(B7:C7) -> 56 | E7: 24 | F7: =B7*E7 -> 744 | G7: =C7*E7 -> 600 | H7: =SUM(F7:G7) -> 1344 | I7: ='ECE (Daffodills)'!AK14 -> 506 | J7: ='ECE (Daffodills)'!AL14 -> 416 | K7: =SUM(I7:J7) -> 922 | L7: =J7/G7 -> 0.69333333 | M7: =I7/F7 -> 0.68010753 | N7: =K7/H7 -> 0.6860119 | O7: =AVERAGE(L7:M7) -> 0.68672043
A8: One | B8: 32 | C8: 24 | D8: =SUM(B8:C8) -> 56 | E8: 24 | F8: =B8*E8 -> 768 | G8: =C8*E8 -> 576 | H8: =SUM(F8:G8) -> 1344 | I8: ='Class-I'!AK14 -> 535 | J8: ='Class-I'!AL14 -> 375 | K8: =SUM(I8:J8) -> 910 | L8: =J8/G8 -> 0.65104167 | M8: =I8/F8 -> 0.69661458 | N8: =K8/H8 -> 0.67708333 | O8: =AVERAGE(L8:M8) -> 0.67382812
A9: Two | B9: 26 | C9: 26 | D9: =SUM(B9:C9) -> 52 | E9: 24 | F9: =B9*E9 -> 624 | G9: =C9*E9 -> 624 | H9: =SUM(F9:G9) -> 1248 | I9: ='Class-II'!AK14 -> 424 | J9: ='Class-II'!AL14 -> 414 | K9: =SUM(I9:J9) -> 838 | L9: =J9/G9 -> 0.66346154 | M9: =I9/F9 -> 0.67948718 | N9: =K9/H9 -> 0.67147436 | O9: =AVERAGE(L9:M9) -> 0.67147436
A10: Three | B10: 28 | C10: 24 | D10: =SUM(B10:C10) -> 52 | E10: 24 | F10: =B10*E10 -> 672 | G10: =C10*E10 -> 576 | H10: =SUM(F10:G10) -> 1248 | I10: ='Class-III'!AK14 -> 444 | J10: ='Class-III'!AL14 -> 413 | K10: =SUM(I10:J10) -> 857 | L10: =J10/G10 -> 0.71701389 | M10: =I10/F10 -> 0.66071429 | N10: =K10/H10 -> 0.68669872 | O10: =AVERAGE(L10:M10) -> 0.68886409
A11: Four | B11: 21 | C11: 32 | D11: =SUM(B11:C11) -> 53 | E11: 24 | F11: =B11*E11 -> 504 | G11: =C11*E11 -> 768 | H11: =SUM(F11:G11) -> 1272 | I11: ='Class-IV'!AK14 -> 311 | J11: ='Class-IV'!AL14 -> 466 | K11: =SUM(I11:J11) -> 777 | L11: =J11/G11 -> 0.60677083 | M11: =I11/F11 -> 0.61706349 | N11: =K11/H11 -> 0.61084906 | O11: =AVERAGE(L11:M11) -> 0.61191716
A12: Five | B12: 23 | C12: 23 | D12: =SUM(B12:C12) -> 46 | E12: 24 | F12: =B12*E12 -> 552 | G12: =C12*E12 -> 552 | H12: =SUM(F12:G12) -> 1104 | I12: ='Class-V'!AK14 -> 417 | J12: ='Class-V'!AL14 -> 371 | K12: =SUM(I12:J12) -> 788 | L12: =J12/G12 -> 0.67210145 | M12: =I12/F12 -> 0.75543478 | N12: =K12/H12 -> 0.71376812 | O12: =AVERAGE(L12:M12) -> 0.71376812
A13: Six | B13: 17 | C13: 28 | D13: =SUM(B13:C13) -> 45 | E13: 24 | F13: =B13*E13 -> 408 | G13: =C13*E13 -> 672 | H13: =SUM(F13:G13) -> 1080 | I13: ='Class-VI'!AK14 -> 283 | J13: ='Class-VI'!AL14 -> 428 | K13: =SUM(I13:J13) -> 711 | L13: =J13/G13 -> 0.63690476 | M13: =I13/F13 -> 0.69362745 | N13: =K13/H13 -> 0.65833333 | O13: =AVERAGE(L13:M13) -> 0.66526611
A14: Seven | B14: 29 | C14: 19 | D14: =SUM(B14:C14) -> 48 | E14: 24 | F14: =B14*E14 -> 696 | G14: =C14*E14 -> 456 | H14: =SUM(F14:G14) -> 1152 | I14: ='Class-VII'!AJ14 -> 453 | J14: ='Class-VII'!AK14 -> 299 | K14: =SUM(I14:J14) -> 752 | L14: =J14/G14 -> 0.65570175 | M14: =I14/F14 -> 0.65086207 | N14: =K14/H14 -> 0.65277778 | O14: =AVERAGE(L14:M14) -> 0.65328191
A15: Eight | B15: 19 | C15: 23 | D15: =SUM(B15:C15) -> 42 | E15: 24 | F15: =B15*E15 -> 456 | G15: =C15*E15 -> 552 | H15: =SUM(F15:G15) -> 1008 | I15: ='Class-VIII'!AK14 -> 288 | J15: ='Class-VIII'!AL14 -> 387 | K15: =SUM(I15:J15) -> 675 | L15: =J15/G15 -> 0.70108696 | M15: =I15/F15 -> 0.63157895 | N15: =K15/H15 -> 0.66964286 | O15: =AVERAGE(L15:M15) -> 0.66633295
A16: Ninth | B16: 16 | C16: 19 | D16: =SUM(B16:C16) -> 35 | E16: 24 | F16: =B16*E16 -> 384 | G16: =C16*E16 -> 456 | H16: =SUM(F16:G16) -> 840 | I16: ='Class-IX'!AK14 -> 271 | J16: ='Class-IX'!AL14 -> 288 | K16: =SUM(I16:J16) -> 559 | L16: =J16/G16 -> 0.63157895 | M16: =I16/F16 -> 0.70572917 | N16: =K16/H16 -> 0.66547619 | O16: =AVERAGE(L16:M16) -> 0.66865406
A17: Total | B17: =SUM(B6:B16) -> 269 | C17: =SUM(C6:C16) -> 270 | D17: =SUM(D6:D16) -> 539 | E17: =SUM(E6:E16) -> 264 | F17: =SUM(F6:F16) -> 6456 | G17: =SUM(G6:G16) -> 6480 | H17: =SUM(H6:H16) -> 12936 | I17: =SUM(I6:I16) -> 4430 | ... K17: =SUM(K6:K16) -> 8677 | L17: =J17/G17 -> 0.65540123 | M17: =I17/F17 -> 0.6861834 | N17: =AVERAGE(N6:N16) -> 0.67066371 | O17: =AVERAGE(O6:O16) -> 0.67139023
A18: % | B18: 1 | C18: 1 | D18: 1 | E18: 1 | F18: 1 | G18: 1 | H18: 1 | I18: =I17/F17 -> 0.6861834 | J18: =J17/G17 -> 0.65540123 | K18: =K17/H17 -> 0.67076376 | L18: 0.54 | M18: 0.56 | N18: 0.55 | O18: =AVERAGE(L17:M17) -> 0.67079231

Sheet ECE (ROSE)
A1: Goverment high school (SJCHS)
A2: Monthly Attendence Month of February-2025
A3: S.No | B3: GR | C3: Student Name | D3: Father Name | E3: Class | F3: =TEXT(F4,"ddd") -> Sat | G3: =TEXT(G4,"ddd") -> Sun | H3: =TEXT(H4,"ddd") -> Mon | I3: =TEXT(I4,"ddd") -> Tue | J3: =TEXT(J4,"ddd") -> Wed | K3: =TEXT(K4,"ddd") -> Thu | L3: =TEXT(L4,"ddd") -> Fri | M3: =TEXT(M4,"ddd") -> Sat | ... AG3: =TEXT(AG4,"ddd") -> Fri | AH3: Present | AI3: Absent | AJ3: Year 2024
F4: 45689 | G4: 45690 | H4: 45691 | I4: 45692 | J4: 45693 | K4: 45694 | L4: 45695 | M4: 45696 | N4: 45697 | O4: 45698 | P4: 45699 | Q4: 45700 | R4: 45701 | S4: 45702 | T4: 45703 | U4: 45704 | V4: 45705 | W4: 45706 | X4: 45707 | Y4: 45708 | Z4: 45709 | AA4: 45710 | AB4: 45711 | AC4: 45712 | AD4: 45713 | AE4: 45714 | AF4: 45715 | AG4: 45716 | AJ4: Total days | AK4: =SUM(AK5:AK8) -> 31
A5: 1 | B5: 112 | C5: Eman | D5: Shahnawaz Khan | E5: ECE | F5: PTM - PTM - PTM - PTM - PTM - PTM - PTM - PTM - PTM | G5: SUNDAY - SUNDAY - SUNDAY - SUNDAY - SUNDAY - SUNDAY | H5: P | I5: P | J5: Kashmir Day - Kashmir Day - Kashmir Day | K5: P | L5: P | M5: P | N5: SUNDAY - SUNDAY - SUNDAY - SUNDAY - SUNDAY - SUNDAY | O5: P | P5: P | Q5: P | R5: P | S5: Shab - E Baraat - Shab - E Baraat - Shab - E Baraat | T5: P | U5: SUNDAY - SUNDAY - SUNDAY - SUNDAY - SUNDAY - SUNDAY | V5: P | W5: P | X5: URS LAL SHEHBAZ QALANDAR - URS LAL SHEHBAZ QALANDAR | Y5: P | Z5: A | AA5: P | AB5: SUNDAY - SUNDAY - SUNDAY - SUNDAY - SUNDAY - SUNDAY | AC5: A | AD5: A | AE5: P | AF5: A | AG5: P | AH5: =COUNTIF(F5:AG5,"P") -> 16 | AI5: =COUNTIF(F5:AG5,"A") -> 4 | AJ5: Working days | AK5: 26
A6: 2 | B6: 135 | C6: Masooma | D6: Faiq Ali | E6: ECE | H6: P | I6: P | K6: P | L6: P | M6: P | O6: P | P6: A | Q6: P | R6: P | T6: A | V6: P | W6: P | Y6: P | Z6: P | AA6: P | AC6: A | AD6: P | AE6: P | AF6: P | AG6: A | AH6: =COUNTIF(F6:AG6,"P") -> 16 | AI6: =COUNTIF(F6:AG6,"A") -> 4 | AJ6: Sunday | AK6: 4
A7: 3 | B7: 137 | C7: Hafsa Batool | D7: Gul Mohammad Chandio | E7: ECE | H7: P | I7: P | K7: P | L7: P | M7: P | O7: P | P7: P | Q7: P | R7: P | T7: A | V7: A | W7: A | Y7: A | Z7: A | AA7: A | AC7: A | AD7: A | AE7: P | AF7: P | AG7: P | AH7: =COUNTIF(F7:AG7,"P") -> 12 | AI7: =COUNTIF(F7:AG7,"A") -> 8 | AJ7: Shab-E-Mairaj | AK7: 1
A8: 4 | B8: 173 | C8: Hoor Fatima | D8: Shahid Ali | E8: ECE | H8: A | I8: P | K8: P | L8: P | M8: P | O8: P | P8: P | Q8: P | R8: P | T8: A | V8: P | W8: P | Y8: P | Z8: A | AA8: A | AC8: P | AD8: P | AE8: P | AF8: P | AG8: P | AH8: =COUNTIF(F8:AG8,"P") -> 16 | AI8: =COUNTIF(F8:AG8,"A") -> 4
A9: 5 | B9: 143 | C9: Kinza | D9: Aijaz Ali | E9: ECE | H9: P | I9: P | K9: P | L9: P | M9: P | O9: P | P9: P | Q9: P | R9: P | T9: P | V9: P | W9: P | Y9: P | Z9: P | AA9: P | AC9: P | AD9: P | AE9: P | AF9: P | AG9: P | AH9: =COUNTIF(F9:AG9,"P") -> 20 | AI9: =COUNTIF(F9:AG9,"A") -> 0
A10: 6 | B10: 146 | C10: Fatima Ansari | D10: Ayaz Ali Ansari | E10: ECE | H10: P | I10: P | K10: P | L10: P | M10: P | O10: P | P10: P | Q10: P | R10: P | T10: P | V10: P | W10: P | Y10: P | Z10: P | AA10: A | AC10: P | AD10: P | AE10: P | AF10: P | AG10: P | AH10: =COUNTIF(F10:AG10,"P") -> 19 | AI10: =COUNTIF(F10:AG10,"A") -> 1
A11: 7 | B11: 148 | C11: Zil-e-Huma | D11: Abdul Qayoom | E11: ECE | H11: P | I11: P | K11: P | L11: A | M11: P | O11: A | P11: P | Q11: A | R11: P | T11: A | V11: P | W11: P | Y11: P | Z11: P | AA11: A | AC11: P | AD11: A | AE11: P | AF11: P | AG11: P | AH11: =COUNTIF(F11:AG11,"P") -> 14 | AI11: =COUNTIF(F11:AG11,"A") -> 6 | AJ11: Present Days Detail
A12: 8 | B12: 150 | C12: Ayat Fatima | D12: Imran Hussain | E12: ECE | H12: P | I12: P | K12: P | L12: P | M12: A | O12: P | P12: P | Q12: P | R12: P | T12: A | V12: A | W12: P | Y12: P | Z12: P | AA12: P | AC12: P | AD12: A | AE12: P | AF12: P | AG12: P | AH12: =COUNTIF(F12:AG12,"P") -> 16 | AI12: =COUNTIF(F12:AG12,"A") -> 4 | AJ12: Detail | AK12: Boys | AL12: Girls | AM12: Total
A13: 9 | B13: 151 | C13: Aqsa | D13: Ahsan Ali | E13: ECE | H13: A | I13: P | K13: P | L13: P | M13: P | O13: P | P13: P | Q13: P | R13: P | T13: P | V13: P | W13: P | Y13: P | Z13: P | AA13: P | AC13: P | AD13: A | AE13: P | AF13: P | AG13: P | AH13: =COUNTIF(F13:AG13,"P") -> 18 | AI13: =COUNTIF(F13:AG13,"A") -> 2 | AJ13: Due Present days | AK13: =29*$AK$5 -> 754 | AL13: =25*$AK$5 -> 650 | AM13: =SUM(AK13:AL13) -> 1404
A14: 10 | B14: 160 | C14: Safa | D14: Dil Murad | E14: ECE | H14: A | I14: A | K14: P | L14: A | M14: P | O14: P | P14: P | Q14: P | R14: P | T14: P | V14: P | W14: P | Y14: P | Z14: P | AA14: P | AC14: P | AD14: P | AE14: P | AF14: P | AG14: P | AH14: =COUNTIF(F14:AG14,"P") -> 17 | AI14: =COUNTIF(F14:AG14,"A") -> 3 | AJ14: Actual present days | AK14: =SUM(AH29:AH57) -> 498 | AL14: =SUM(AH5:AH28) -> 390 | AM14: =AK14+AL14 -> 888
A15: 11 | B15: 161 | C15: Hifza | D15: Zakir Ali | E15: ECE | H15: P | I15: A | K15: P | L15: P | M15: A | O15: P | P15: P | Q15: P | R15: A | T15: A | V15: A | W15: A | Y15: A | Z15: A | AA15: A | AC15: A | AD15: A | AE15: P | AF15: P | AG15: P | AH15: =COUNTIF(F15:AG15,"P") -> 9 | AI15: =COUNTIF(F15:AG15,"A") -> 11 | AJ15: % | AK15: =AK14/AK13 -> 0.66047745 | AL15: =AL14/AL13 -> 0.6 | AM15: =AM14/AM13 -> 0.63247863
A16: 12 | B16: 162 | C16: Zameeran | D16: Babar Ali | E16: ECE | H16: P | I16: P | K16: P | L16: P | M16: P | O16: A | P16: P | Q16: P | R16: P | T16: P | V16: P | W16: A | Y16: P | Z16: P | AA16: P | AC16: P | AD16: P | AE16: P | AF16: P | AG16: P | AH16: =COUNTIF(F16:AG16,"P") -> 18 | AI16: =COUNTIF(F16:AG16,"A") -> 2
A17: 13 | B17: 163 | C17: Parwisha | D17: Sarfaraz Ahmed | E17: ECE | H17: P | I17: P | K17: P | L17: P | M17: P | O17: P | P17: P | Q17: P | R17: P | T17: P | V17: P | W17: P | Y17: P | Z17: P | AA17: P | AC17: P | AD17: P | AE17: P | AF17: P | AG17: P | AH17: =COUNTIF(F17:AG17,"P") -> 20 | AI17: =COUNTIF(F17:AG17,"A") -> 0
A18: 14 | B18: 166 | C18: Aiza | D18: Irshad-Ul-Haq | E18: ECE | H18: P | I18: P | K18: P | L18: P | M18: P | O18: P | P18: P | Q18: P | R18: P | T18: P | V18: P | W18: P | Y18: P | Z18: P | AA18: P | AC18: P | AD18: P | AE18: P | AF18: P | AG18: P | AH18: =COUNTIF(F18:AG18,"P") -> 20 | AI18: =COUNTIF(F18:AG18,"A") -> 0
A19: 15 | B19: 168 | C19: Shazia | D19: Rashid Ali | E19: ECE | H19: P | I19: P | K19: P | L19: P | M19: P | O19: P | P19: P | Q19: A | R19: P | T19: P | V19: P | W19: P | Y19: P | Z19: P | AA19: P | AC19: P | AD19: P | AE19: P | AF19: P | AG19: P | AH19: =COUNTIF(F19:AG19,"P") -> 19 | AI19: =COUNTIF(F19:AG19,"A") -> 1 | AJ19: Absent Days Details
A20: 16 | B20: 170 | C20: Ume Farwa | D20: Meer Ameer-u-Din | E20: ECE | H20: A | I20: P | K20: P | L20: P | M20: A | O20: A | P20: P | Q20: P | R20: P | T20: P | V20: A | W20: P | Y20: A | Z20: P | AA20: A | AC20: P | AD20: P | AE20: P | AF20: P | AG20: P | AH20: =COUNTIF(F20:AG20,"P") -> 14 | AI20: =COUNTIF(F20:AG20,"A") -> 6 | AJ20: Detail | AK20: Boys | AL20: Girls | AM20: Total
A21: 17 | B21: 171 | C21: Ume Rubab | D21: Mohsin Ali | E21: ECE | H21: A | I21: A | K21: P | L21: P | M21: A | O21: P | P21: P | Q21: P | R21: P | T21: P | V21: P | W21: P | Y21: P | Z21: P | AA21: P | AC21: P | AD21: A | AE21: P | AF21: P | AG21: P | AH21: =COUNTIF(F21:AG21,"P") -> 16 | AI21: =COUNTIF(F21:AG21,"A") -> 4 | AJ21: Due Present days | AK21: =29*$AK$5 -> 754 | AL21: =25*$AK$5 -> 650 | AM21: =AK21+AL21 -> 1404
A22: 18 | B22: 172 | C22: Khatija | D22: M. Afzal | E22: ECE | H22: A | I22: P | K22: P | L22: A | M22: P | O22: A | P22: P | Q22: P | R22: P | T22: P | V22: P | W22: P | Y22: P | Z22: A | AA22: P | AC22: P | AD22: A | AE22: P | AF22: P | AG22: P | AH22: =COUNTIF(F22:AG22,"P") -> 15 | AI22: =COUNTIF(F22:AG22,"A") -> 5 | AJ22: Absent days | AK22: =AK21-AK14 -> 256 | AL22: =AL21-AL14 -> 260 | AM22: =AK22+AL22 -> 516
A23: 19 | B23: 180 | C23: Fiza | D23: Ahmed | E23: ECE | H23: P | I23: P | K23: P | L23: P | M23: P | O23: P | P23: P | Q23: P | R23: P | T23: P | V23: P | W23: P | Y23: P | Z23: A | AA23: P | AC23: P | AD23: P | AE23: P | AF23: P | AG23: A | AH23: =COUNTIF(F23:AG23,"P") -> 18 | AI23: =COUNTIF(F23:AG23,"A") -> 2 | AJ23: % | AK23: =AK22/AK21 -> 0.33952255 | AL23: =AL22/AL21 -> 0.4 | AM23: =AM22/AM21 -> 0.36752137
A24: 20 | B24: 181 | C24: Eshaal | D24: M. Fahad | E24: ECE | H24: A | I24: P | K24: P | L24: A | M24: P | O24: A | P24: A | Q24: P | R24: P | T24: A | V24: A | W24: P | Y24: P | Z24: P | AA24: P | AC24: P | AD24: P | AE24: P | AF24: P | AG24: P | AH24: =COUNTIF(F24:AG24,"P") -> 14 | AI24: =COUNTIF(F24:AG24,"A") -> 6
A25: 21 | B25: 195 | C25: Rija Batool | D25: Ghulam Mehdi | E25: ECE | H25: A | I25: P | K25: A | L25: A | M25: A | O25: P | P25: P | Q25: P | R25: P | T25: A | V25: P | W25: A | Y25: P | Z25: P | AA25: P | AC25: P | AD25: A | AE25: P | AF25: P | AG25: P | AH25: =COUNTIF(F25:AG25,"P") -> 13 | AI25: =COUNTIF(F25:AG25,"A") -> 7
A26: 22 | B26: 183 | C26: Musfiral | D26: Faisal | E26: ECE | H26: P | I26: P | K26: P | L26: P | M26: P | O26: P | P26: A | Q26: A | R26: P | T26: A | V26: P | W26: P | Y26: P | Z26: P | AA26: P | AC26: P | AD26: P | AE26: P | AF26: P | AG26: P | AH26: =COUNTIF(F26:AG26,"P") -> 17 | AI26: =COUNTIF(F26:AG26,"A") -> 3
A27: 24 | B27: 170 | C27: Hoorain Noor | D27: Muhammad Akram | E27: ECE | H27: P | I27: P | K27: P | L27: P | M27: P | O27: P | P27: P | Q27: P | R27: P | T27: P | V27: P | W27: P | Y27: P | Z27: P | AA27: P | AC27: P | AD27: P | AE27: P | AF27: A | AG27: P | AH27: =COUNTIF(F27:AG27,"P") -> 19 | AI27: =COUNTIF(F27:AG27,"A") -> 1
A28: 25 | B28: 189 | C28: Zakria | E28: ECE | H28: A | I28: P | K28: A | L28: P | M28: A | O28: P | P28: A | Q28: P | R28: P | T28: A | V28: P | W28: P | Y28: P | Z28: P | AA28: P | AC28: P | AD28: P | AE28: A | AF28: P | AG28: P | AH28: =COUNTIF(F28:AG28,"P") -> 14 | AI28: =COUNTIF(F28:AG28,"A") -> 6
A29: 1 | B29: 99 | C29: Rehan Ali | D29: Abdul Rehman | E29: ECE | H29: A | I29: P | K29: P | L29: P | M29: P | O29: P | P29: P | Q29: P | R29: P | T29: P | V29: P | W29: P | Y29: P | Z29: P | AA29: P | AC29: P | AD29: P | AE29: P | AF29: P | AG29: P | AH29: =COUNTIF(F29:AG29,"P") -> 19 | AI29: =COUNTIF(F29:AG29,"A") -> 1
A30: 2 | B30: 98 | C30: Dilkash | D30: Faraz Hussain | E30: ECE | H30: A | I30: P | K30: P | L30: P | M30: A | O30: P | P30: P | Q30: P | R30: P | T30: A | V30: P | W30: P | Y30: P | Z30: P | AA30: A | AC30: P | AD30: P | AE30: P | AF30: P | AG30: P | AH30: =COUNTIF(F30:AG30,"P") -> 16 | AI30: =COUNTIF(F30:AG30,"A") -> 4
A31: 3 | B31: 136 | C31: Ali | D31: Saddam Hussain | E31: ECE | H31: A | I31: P | K31: P | L31: P | M31: P | O31: P | P31: P | Q31: P | R31: P | T31: P | V31: P | W31: P | Y31: P | Z31: P | AA31: A | AC31: P | AD31: A | AE31: P | AF31: P | AG31: P | AH31: =COUNTIF(F31:AG31,"P") -> 17 | AI31: =COUNTIF(F31:AG31,"A") -> 3
A32: 4 | B32: 139 | C32: Mohammad Aliyan | D32: Shabir Ahmed Bhutto | E32: ECE | H32: A | I32: P | K32: P | L32: P | M32: A | O32: A | P32: P | Q32: P | R32: P | T32: A | V32: P | W32: P | Y32: A | Z32: P | AA32: P | AC32: P | AD32: P | AE32: P | AF32: P | AG32: P | AH32: =COUNTIF(F32:AG32,"P") -> 15 | AI32: =COUNTIF(F32:AG32,"A") -> 5
A33: 5 | B33: 142 | C33: Muhammad Sahil | D33: Irshad Ali | E33: ECE | H33: A | I33: P | K33: P | L33: P | M33: P | O33: P | P33: P | Q33: P | R33: P | T33: P | V33: P | W33: P | Y33: P | Z33: P | AA33: P | AC33: P | AD33: P | AE33: P | AF33: A | AG33: P | AH33: =COUNTIF(F33:AG33,"P") -> 18 | AI33: =COUNTIF(F33:AG33,"A") -> 2
A34: 6 | B34: 144 | C34: Zaryab Sultan | D34: Muhammad Zaman | E34: ECE | H34: P | I34: P | K34: P | L34: P | M34: P | O34: P | P34: P | Q34: P | R34: P | T34: P | V34: P | W34: P | Y34: P | Z34: P | AA34: P | AC34: P | AD34: P | AE34: P | AF34: P | AG34: P | AH34: =COUNTIF(F34:AG34,"P") -> 20 | AI34: =COUNTIF(F34:AG34,"A") -> 0
A35: 7 | B35: 145 | C35: M. Ibrahim | D35: Fayaz Ali Ansari | E35: ECE | H35: P | I35: P | K35: P | L35: P | M35: P | O35: P | P35: P | Q35: P | R35: P | T35: P | V35: A | W35: A | Y35: P | Z35: P | AA35: P | AC35: P | AD35: P | AE35: P | AF35: P | AG35: P | AH35: =COUNTIF(F35:AG35,"P") -> 18 | AI35: =COUNTIF(F35:AG35,"A") -> 2
A36: 8 | B36: 152 | C36: Muhammad Fawad | D36: Waseem Ahmed Channa | E36: ECE | H36: A | I36: P | K36: P | L36: A | M36: A | O36: A | P36: P | Q36: P | R36: P | T36: A | V36: P | W36: P | Y36: A | Z36: A | AA36: P | AC36: A | AD36: A | AE36: A | AF36: P | AG36: P | AH36: =COUNTIF(F36:AG36,"P") -> 10 | AI36: =COUNTIF(F36:AG36,"A") -> 10
A37: 9 | B37: 153 | C37: Muhammad Haris | D37: M. Shareef Niyazi | E37: ECE | H37: P | I37: P | K37: P | L37: P | M37: P | O37: P | P37: P | Q37: P | R37: P | T37: P | V37: P | W37: P | Y37: P | Z37: P | AA37: P | AC37: P | AD37: P | AE37: P | AF37: P | AG37: P | AH37: =COUNTIF(F37:AG37,"P") -> 20 | AI37: =COUNTIF(F37:AG37,"A") -> 0
A38: 10 | B38: 154 | C38: Muhammad Ayan | D38: Abdul Ghaffar | E38: ECE | H38: P | I38: P | K38: P | L38: P | M38: P | O38: P | P38: P | Q38: P | R38: P | T38: P | V38: P | W38: P | Y38: P | Z38: P | AA38: P | AC38: A | AD38: A | AE38: P | AF38: P | AG38: P | AH38: =COUNTIF(F38:AG38,"P") -> 18 | AI38: =COUNTIF(F38:AG38,"A") -> 2
A39: 11 | B39: 155 | C39: Danish | D39: Ayaz Ali | E39: ECE | H39: A | I39: P | K39: P | L39: P | M39: P | O39: P | P39: P | Q39: P | R39: P | T39: P | V39: P | W39: P | Y39: P | Z39: P | AA39: P | AC39: P | AD39: P | AE39: P | AF39: P | AG39: P | AH39: =COUNTIF(F39:AG39,"P") -> 19 | AI39: =COUNTIF(F39:AG39,"A") -> 1
A40: 12 | B40: 156 | C40: Mujahid Ali | D40: Sajjad Ali | E40: ECE | H40: A | I40: P | K40: P | L40: P | M40: P | O40: P | P40: P | Q40: P | R40: P | T40: A | V40: P | W40: P | Y40: P | Z40: P | AA40: A | AC40: P | AD40: P | AE40: P | AF40: P | AG40: P | AH40: =COUNTIF(F40:AG40,"P") -> 17 | AI40: =COUNTIF(F40:AG40,"A") -> 3
...

Sheet ECE (Daffodills)
A1: Goverment high school (SJCHS)
A2: Monthly Attendence Month of February-2025
A3: S.No | B3: GR | C3: Student Name | D3: Father Name | E3: Class | F3: =TEXT(F4,"ddd") -> Sat | G3: =TEXT(G4,"ddd") -> Sun | H3: =TEXT(H4,"ddd") -> Mon | I3: =TEXT(I4,"ddd") -> Tue | J3: =TEXT(J4,"ddd") -> Wed | K3: =TEXT(K4,"ddd") -> Thu | L3: =TEXT(L4,"ddd") -> Fri | M3: =TEXT(M4,"ddd") -> Sat | ... AG3: =TEXT(AG4,"ddd") -> Fri | AH3: Present | AI3: Absent | AJ3: Year 2024
F4: 45689 | G4: 45690 | H4: 45691 | I4: 45692 | J4: 45693 | K4: 45694 | L4: 45695 | M4: 45696 | N4: 45697 | O4: 45698 | P4: 45699 | Q4: 45700 | R4: 45701 | S4: 45702 | T4: 45703 | U4: 45704 | V4: 45705 | W4: 45706 | X4: 45707 | Y4: 45708 | Z4: 45709 | AA4: 45710 | AB4: 45711 | AC4: 45712 | AD4: 45713 | AE4: 45714 | AF4: 45715 | AG4: 45716 | AJ4: Total days | AK4: =SUM(AK5:AK8) -> 31
A5: 1 | B5: 106 | C5: Alishba Batool | D5: Irfan Ali | E5: ECE | F5: PTM - PTM - PTM - PTM - PTM - PTM - PTM - PTM - PTM | G5: SUNDAY - SUNDAY - SUNDAY - SUNDAY - SUNDAY - SUNDAY | H5: P | I5: P | J5: Kashmir Day - Kashmir Day - Kashmir Day | K5: P | L5: P | M5: P | N5: SUNDAY - SUNDAY - SUNDAY - SUNDAY - SUNDAY - SUNDAY | O5: P | P5: P | Q5: P | R5: P | S5: Shab - E Baraat - Shab - E Baraat - Shab - E Baraat | T5: P | U5: SUNDAY - SUNDAY - SUNDAY - SUNDAY - SUNDAY - SUNDAY | V5: P | W5: P | X5: URS LAL SHEHBAZ QALANDAR - URS LAL SHEHBAZ QALANDAR | Y5: P | Z5: P | AA5: P | AB5: SUNDAY - SUNDAY - SUNDAY - SUNDAY - SUNDAY - SUNDAY | AC5: P | AD5: P | AE5: P | AF5: P | AG5: P | AH5: =COUNTIF(F5:AG5,"P") -> 20 | AI5: =COUNTIF(F5:AG5,"A") -> 0 | AJ5: Working days | AK5: 26
A6: 2 | B6: 75 | C6: Amna | D6: Imtiaz Hussain | E6: ECE | H6: P | I6: P | K6: P | L6: P | M6: P | O6: P | P6: P | Q6: P | R6: A | T6: A | V6: P | W6: P | Y6: P | Z6: P | AA6: P | AC6: P | AD6: P | AE6: P | AF6: P | AG6: P | AH6: =COUNTIF(F6:AG6,"P") -> 18 | AI6: =COUNTIF(F6:AG6,"A") -> 2 | AJ6: Sunday | AK6: 4
A7: 3 | B7: 109 | C7: Aniza Memon | D7: M. Qasim | E7: ECE | H7: P | I7: P | K7: P | L7: P | M7: A | O7: P | P7: P | Q7: P | R7: P | T7: A | V7: P | W7: P | Y7: P | Z7: P | AA7: P | AC7: P | AD7: P | AE7: A | AF7: P | AG7: P | AH7: =COUNTIF(F7:AG7,"P") -> 17 | AI7: =COUNTIF(F7:AG7,"A") -> 3 | AJ7: Shab-E-Mairaj | AK7: 1
A8: 4 | B8: 49 | C8: Areeba | D8: Altaf Hussain | E8: ECE | H8: P | I8: P | K8: A | L8: P | M8: P | O8: P | P8: P | Q8: P | R8: P | T8: A | V8: P | W8: P | Y8: P | Z8: P | AA8: P | AC8: P | AD8: P | AE8: P | AF8: P | AG8: P | AH8: =COUNTIF(F8:AG8,"P") -> 18 | AI8: =COUNTIF(F8:AG8,"A") -> 2
A9: 5 | B9: 104 | C9: Batool | D9: Amjad Ali | E9: ECE | H9: P | I9: P | K9: P | L9: P | M9: P | O9: P | P9: P | Q9: P | R9: P | T9: P | V9: A | W9: A | Y9: P | Z9: A | AA9: P | AC9: P | AD9: A | AE9: P | AF9: P | AG9: P | AH9: =COUNTIF(F9:AG9,"P") -> 16 | AI9: =COUNTIF(F9:AG9,"A") -> 4
A10: 6 | B10: 88 | C10: Dua | D10: Khalid Hussain | E10: ECE | H10: P | I10: P | K10: P | L10: P | M10: P | O10: P | P10: P | Q10: P | R10: P | T10: P | V10: P | W10: P | Y10: P | Z10: P | AA10: P | AC10: P | AD10: P | AE10: P | AF10: P | AG10: P | AH10: =COUNTIF(F10:AG10,"P") -> 20 | AI10: =COUNTIF(F10:AG10,"A") -> 0
A11: 7 | B11: 59 | C11: Faiza | D11: Liaqat Ali | E11: ECE | H11: L | I11: L | K11: A | L11: P | M11: P | O11: P | P11: P | Q11: P | R11: P | T11: P | V11: P | W11: P | Y11: P | Z11: P | AA11: P | AC11: P | AD11: P | AE11: P | AF11: P | AG11: P | AH11: =COUNTIF(F11:AG11,"P") -> 17 | AI11: =COUNTIF(F11:AG11,"A") -> 1 | AJ11: Present Days Detail
A12: 8 | B12: 83 | C12: Fatima | D12: Aziz-ur-Rehman | E12: ECE | H12: P | I12: P | K12: P | L12: P | M12: P | O12: P | P12: P | Q12: P | R12: P | T12: P | V12: P | W12: P | Y12: P | Z12: P | AA12: P | AC12: P | AD12: P | AE12: P | AF12: P | AG12: P | AH12: =COUNTIF(F12:AG12,"P") -> 20 | AI12: =COUNTIF(F12:AG12,"A") -> 0 | AJ12: Detail | AK12: Boys | AL12: Girls | AM12: Total
A13: 9 | B13: 89 | C13: Hafsa | D13: Hafeezullah | E13: ECE | H13: P | I13: P | K13: P | L13: P | M13: P | O13: P | P13: P | Q13: P | R13: P | T13: P | V13: P | W13: P | Y13: P | Z13: P | AA13: P | AC13: P | AD13: P | AE13: P | AF13: P | AG13: P | AH13: =COUNTIF(F13:AG13,"P") -> 20 | AI13: =COUNTIF(F13:AG13,"A") -> 0 | AJ13: Due Present days | AK13: =32*$AK$5 -> 832 | AL13: =24*$AK$5 -> 624 | AM13: =SUM(AK13:AL13) -> 1456
A14: 10 | B14: 86 | C14: Insha Arzoo | D14: Meeral | E14: ECE | H14: P | I14: P | K14: P | L14: P | M14: P | O14: P | P14: P | Q14: P | R14: P | T14: P | V14: P | W14: P | Y14: P | Z14: P | AA14: P | AC14: P | AD14: P | AE14: P | AF14: P | AG14: P | AH14: =COUNTIF(F14:AG14,"P") -> 20 | AI14: =COUNTIF(F14:AG14,"A") -> 0 | AJ14: Actual present days | AK14: =SUM(AH29:AH59) -> 506 | AL14: =SUM(AH5:AH28) -> 416 | AM14: =AK14+AL14 -> 922
A15: 11 | B15: 105 | C15: Kauser Fatima | D15: Amir Jamil | E15: ECE | H15: P | I15: P | K15: P | L15: P | M15: P | O15: P | P15: P | Q15: P | R15: P | T15: P | V15: P | W15: P | Y15: P | Z15: P | AA15: P | AC15: P | AD15: P | AE15: P | AF15: P | AG15: P | AH15: =COUNTIF(F15:AG15,"P") -> 20 | AI15: =COUNTIF(F15:AG15,"A") -> 0 | AJ15: % | AK15: =AK14/AK13 -> 0.60817308 | AL15: =AL14/AL13 -> 0.66666667 | AM15: =AM14/AM13 -> 0.63324176
A16: 12 | B16: 84 | C16: Mirha | D16: M. Luqman | E16: ECE | H16: A | I16: A | K16: A | L16: A | M16: A | O16: P | P16: P | Q16: P | R16: P | T16: P | V16: P | W16: P | Y16: P | Z16: P | AA16: A | AC16: P | AD16: P | AE16: P | AF16: P | AG16: P | AH16: =COUNTIF(F16:AG16,"P") -> 14 | AI16: =COUNTIF(F16:AG16,"A") -> 6
A17: 13 | B17: 85 | C17: Misbah Bhutto | D17: M. Azeem | E17: ECE | H17: P | I17: P | K17: P | L17: P | M17: P | O17: P | P17: P | Q17: A | R17: P | T17: P | V17: P | W17: P | Y17: P | Z17: P | AA17: P | AC17: P | AD17: P | AE17: P | AF17: P | AG17: P | AH17: =COUNTIF(F17:AG17,"P") -> 19 | AI17: =COUNTIF(F17:AG17,"A") -> 1
A18: 14 | B18: 102 | C18: Rimsha | D18: Meer Ameer-ud-Din | E18: ECE | H18: P | I18: P | K18: P | L18: P | M18: A | O18: A | P18: P | Q18: P | R18: P | T18: P | V18: A | W18: P | Y18: P | Z18: P | AA18: P | AC18: P | AD18: P | AE18: A | AF18: P | AG18: P | AH18: =COUNTIF(F18:AG18,"P") -> 16 | AI18: =COUNTIF(F18:AG18,"A") -> 4
A19: 15 | B19: 87 | C19: Sidra Batool | D19: Muhammad Khan | E19: ECE | H19: P | I19: P | K19: P | L19: P | M19: P | O19: P | P19: P | Q19: P | R19: P | T19: P | V19: P | W19: P | Y19: P | Z19: P | AA19: P | AC19: P | AD19: P | AE19: P | AF19: P | AG19: P | AH19: =COUNTIF(F19:AG19,"P") -> 20 | AI19: =COUNTIF(F19:AG19,"A") -> 0 | AJ19: Absent Days Details
A20: 16 | B20: 71 | C20: Sidra | D20: Khalid Hussain | E20: ECE | H20: P | I20: P | K20: P | L20: P | M20: P | O20: P | P20: P | Q20: P | R20: P | T20: P | V20: P | W20: P | Y20: P | Z20: A | AA20: P | AC20: P | AD20: P | AE20: P | AF20: P | AG20: P | AH20: =COUNTIF(F20:AG20,"P") -> 19 | AI20: =COUNTIF(F20:AG20,"A") -> 1 | AJ20: Detail | AK20: Boys | AL20: Girls | AM20: Total
A21: 17 | B21: 81 | C21: Taniya Bibi | D21: Wazir Ali | E21: ECE | H21: P | I21: P | K21: P | L21: P | M21: P | O21: P | P21: P | Q21: A | R21: A | T21: A | V21: A | W21: A | Y21: A | Z21: A | AA21: A | AC21: A | AD21: A | AE21: A | AF21: A | AG21: A | AH21: =COUNTIF(F21:AG21,"P") -> 7 | AI21: =COUNTIF(F21:AG21,"A") -> 13 | AJ21: Due Present days | AK21: =32*$AK$5 -> 832 | AL21: =24*$AK$5 -> 624 | AM21: =AK21+AL21 -> 1456
A22: 18 | B22: 82 | C22: Tanzeela | D22: Hizbullah | E22: ECE | H22: P | I22: P | K22: P | L22: P | M22: P | O22: P | P22: P | Q22: A | R22: P | T22: P | V22: A | W22: P | Y22: P | Z22: P | AA22: P | AC22: P | AD22: P | AE22: P | AF22: P | AG22: P | AH22: =COUNTIF(F22:AG22,"P") -> 18 | AI22: =COUNTIF(F22:AG22,"A") -> 2 | AJ22: Absent days | AK22: =AK21-AK14 -> 326 | AL22: =AL21-AL14 -> 208 | AM22: =AK22+AL22 -> 534
A23: 19 | B23: 68 | C23: Tayaba Fatima | D23: Waseem Ahmed | E23: ECE | H23: P | I23: P | K23: P | L23: A | M23: P | O23: P | P23: P | Q23: P | R23: P | T23: A | V23: P | W23: P | Y23: P | Z23: P | AA23: P | AC23: P | AD23: P | AE23: P | AF23: P | AG23: P | AH23: =COUNTIF(F23:AG23,"P") -> 18 | AI23: =COUNTIF(F23:AG23,"A") -> 2 | AJ23: % | AK23: =AK22/AK21 -> 0.39182692 | AL23: =AL22/AL21 -> 0.33333333 | AM23: =AM22/AM21 -> 0.36675824
A24: 20 | B24: 69 | C24: Tooba Noor | D24: M. Shareef | E24: ECE | H24: P | I24: P | K24: P | L24: P | M24: P | O24: P | P24: P | Q24: P | R24: P | T24: P | V24: P | W24: P | Y24: P | Z24: P | AA24: P | AC24: P | AD24: P | AE24: P | AF24: P | AG24: P | AH24: =COUNTIF(F24:AG24,"P") -> 20 | AI24: =COUNTIF(F24:AG24,"A") -> 0
A25: 21 | B25: 70 | C25: Umm-e-Kulsoom | D25: Shah Ali | E25: ECE | H25: P | I25: P | K25: P | L25: P | M25: P | O25: P | P25: P | Q25: P | R25: P | T25: A | V25: P | W25: P | Y25: P | Z25: P | AA25: P | AC25: P | AD25: P | AE25: P | AF25: P | AG25: P | AH25: 14 | AI25: =COUNTIF(F25:AG25,"A") -> 1
A26: 22 | B26: 103 | C26: Zunaira | D26: Amjad Ali | E26: ECE | H26: P | I26: P | K26: P | L26: P | M26: P | O26: P | P26: P | Q26: P | R26: P | T26: P | V26: P | W26: P | Y26: P | Z26: A | AA26: P | AC26: P | AD26: P | AE26: A | AF26: P | AG26: P | AH26: =COUNTIF(F26:AG26,"P") -> 18 | AI26: =COUNTIF(F26:AG26,"A") -> 2
A27: 23 | B27: 149 | C27: Sahib Khatoon | D27: A. Qayoom | E27: ECE | H27: P | I27: P | K27: A | L27: P | M27: A | O27: A | P27: P | Q27: A | R27: P | T27: A | V27: A | W27: P | Y27: P | Z27: P | AA27: A | AC27: P | AD27: A | AE27: P | AF27: P | AG27: P | AH27: =COUNTIF(F27:AG27,"P") -> 12 | AI27: =COUNTIF(F27:AG27,"A") -> 8
A28: 24 | B28: 169 | C28: Parsa Batool | D28: Imran Ali | E28: ECE | H28: A | I28: P | K28: P | L28: P | M28: P | O28: A | P28: P | Q28: P | R28: P | T28: P | V28: A | W28: A | Y28: P | Z28: P | AA28: A | AC28: P | AD28: P | AE28: P | AF28: P | AG28: P | AH28: =COUNTIF(F28:AG28,"P") -> 15 | AI28: =COUNTIF(F28:AG28,"A") -> 5
A29: 1 | B29: 61 | C29: Abrar | D29: Jan Muhammad | E29: ECE | H29: P | I29: P | K29: P | L29: P | M29: P | O29: A | P29: A | Q29: A | R29: A | T29: A | V29: P | W29: P | Y29: P | Z29: P | AA29: P | AC29: P | AD29: P | AE29: A | AF29: P | AG29: P | AH29: =COUNTIF(F29:AG29,"P") -> 14 | AI29: =COUNTIF(F29:AG29,"A") -> 6
A30: 2 | B30: 79 | C30: Azan Shafeeque | D30: M. Shafeeque | E30: ECE | H30: P | I30: P | K30: P | L30: P | M30: P | O30: P | P30: P | Q30: P | R30: P | T30: P | V30: P | W30: P | Y30: P | Z30: P | AA30: P | AC30: P | AD30: P | AE30: P | AF30: P | AG30: P | AH30: =COUNTIF(F30:AG30,"P") -> 20 | AI30: =COUNTIF(F30:AG30,"A") -> 0
A31: 3 | B31: 16 | C31: Azan Fayaz | D31: Fayaz Hussain | E31: ECE | H31: P | I31: P | K31: P | L31: P | M31: P | O31: P | P31: P | Q31: P | R31: P | T31: P | V31: P | W31: P | Y31: P | Z31: P | AA31: P | AC31: P | AD31: P | AE31: P | AF31: P | AG31: P | AH31: =COUNTIF(F31:AG31,"P") -> 20 | AI31: =COUNTIF(F31:AG31,"A") -> 0
A32: 4 | B32: 78 | C32: Adil Ahmed | D32: Faiz Muhammad | E32: ECE | H32: P | I32: P | K32: P | L32: P | M32: P | O32: P | P32: P | Q32: P | R32: P | T32: P | V32: P | W32: P | Y32: P | Z32: A | AA32: P | AC32: P | AD32: P | AE32: P | AF32: P | AG32: P | AH32: =COUNTIF(F32:AG32,"P") -> 19 | AI32: =COUNTIF(F32:AG32,"A") -> 1
A33: 5 | B33: 76 | C33: Ab. Qudoos | D33: Sikandar | E33: ECE | H33: P | I33: P | K33: P | L33: P | M33: P | O33: P | P33: P | Q33: P | R33: P | T33: P | V33: A | W33: P | Y33: P | Z33: P | AA33: P | AC33: P | AD33: P | AE33: P | AF33: P | AG33: P | AH33: =COUNTIF(F33:AG33,"P") -> 19 | AI33: =COUNTIF(F33:AG33,"A") -> 1
A34: 7 | B34: 108 | C34: Arham | D34: Qasim Memon | E34: ECE | H34: P | I34: P | K34: P | L34: P | M34: A | O34: P | P34: P | Q34: P | R34: P | T34: P | V34: P | W34: P | Y34: A | Z34: P | AA34: P | AC34: P | AD34: P | AE34: P | AF34: P | AG34: P | AH34: =COUNTIF(F34:AG34,"P") -> 18 | AI34: =COUNTIF(F34:AG34,"A") -> 2
A35: 8 | B35: 131 | C35: Amar Farooque | D35: M. Farooque | E35: ECE | H35: P | I35: P | K35: P | L35: P | M35: A | O35: P | P35: P | Q35: P | R35: P | T35: P | V35: P | W35: P | Y35: A | Z35: P | AA35: P | AC35: P | AD35: P | AE35: P | AF35: P | AG35: P | AH35: =COUNTIF(F35:AG35,"P") -> 18 | AI35: =COUNTIF(F35:AG35,"A") -> 2
A36: 9 | B36: 101 | C36: Ashfaque | D36: M. Zubair | E36: ECE | H36: P | I36: P | K36: P | L36: P | M36: P | O36: P | P36: P | Q36: P | R36: P | T36: P | V36: P | W36: P | Y36: P | Z36: P | AA36: P | AC36: P | AD36: P | AE36: P | AF36: P | AG36: P | AH36: =COUNTIF(F36:AG36,"P") -> 20 | AI36: =COUNTIF(F36:AG36,"A") -> 0
A37: 10 | B37: 100 | C37: Fahad | D37: M. Maroof | E37: ECE | H37: P | I37: P | K37: P | L37: P | M37: P | O37: P | P37: P | Q37: P | R37: P | T37: P | V37: P | W37: A | Y37: P | Z37: P | AA37: P | AC37: P | AD37: P | AE37: P | AF37: P | AG37: P | AH37: =COUNTIF(F37:AG37,"P") -> 19 | AI37: =COUNTIF(F37:AG37,"A") -> 1
... A59: 32 | B59: 97 | C59: Faheem | D59: M.Ibrahim | E59: ECE | H59: P | I59: P | K59: P | L59: P | M59: A | O59: P | P59: P | Q59: P | R59: P | T59: A | V59: P | W59: P | Y59: P | Z59: P | AA59: P | AC59: P | AD59: P | AE59: P | AF59: P | AG59: P | AH59: =COUNTIF(F59:AG59,"P") -> 18 | AI59: =COUNTIF(F59:AG59,"A") -> 2

Sheet Class-I
A1: Goverment high school (SJCHS)
A2: Monthly Attendence Month of February-2025
A3: S.No | B3: GR | C3: Student Name | D3: Father Name | E3: Class | F3: =TEXT(F4,"ddd") -> Sat | G3: =TEXT(G4,"ddd") -> Sun | H3: =TEXT(H4,"ddd") -> Mon | I3: =TEXT(I4,"ddd") -> Tue | J3: =TEXT(J4,"ddd") -> Wed | K3: =TEXT(K4,"ddd") -> Thu | L3: =TEXT(L4,"ddd") -> Fri | M3: =TEXT(M4,"ddd") -> Sat | ... AG3: =TEXT(AG4,"ddd") -> Fri | AH3: Present | AI3: Absent | AJ3: Year 2024
F4: 45689 | G4: 45690 | H4: 45691 | I4: 45692 | J4: 45693 | K4: 45694 | L4: 45695 | M4: 45696 | N4: 45697 | O4: 45698 | P4: 45699 | Q4: 45700 | R4: 45701 | S4: 45702 | T4: 45703 | U4: 45704 | V4: 45705 | W4: 45706 | X4: 45707 | Y4: 45708 | Z4: 45709 | AA4: 45710 | AB4: 45711 | AC4: 45712 | AD4: 45713 | AE4: 45714 | AF4: 45715 | AG4: 45716 | AJ4: Total days | AK4: =SUM(AK5:AK8) -> 31
A5: 1 | B5: 815 | C5: Anum | D5: M. Arif | E5: One | F5: PTM - PTM - PTM - PTM - PTM - PTM - PTM - PTM - PTM | G5: SUNDAY - SUNDAY - SUNDAY - SUNDAY - SUNDAY - SUNDAY - SUNDAY - SUNDAY - SUNDAY | H5: P | I5: P | J5: Kashmir Day - Kashmir Day - Kashmir Day | K5: P | L5: P | M5: P | N5: SUNDAY - SUNDAY - SUNDAY - SUNDAY - SUNDAY - SUNDAY - SUNDAY - SUNDAY - SUNDAY | O5: P | P5: A | Q5: P | R5: P | S5: Shab - E Baraat - Shab - E Baraat | T5: P | U5: SUNDAY - SUNDAY - SUNDAY - SUNDAY - SUNDAY - SUNDAY - SUNDAY - SUNDAY - SUNDAY | V5: P | W5: P | X5: URS LAL SHEHBAZ QALANDAR - URS LAL SHEHBAZ QALANDAR | Y5: P | Z5: P | AA5: P | AB5: SUNDAY - SUNDAY - SUNDAY - SUNDAY - SUNDAY - SUNDAY - SUNDAY - SUNDAY - SUNDAY | AC5: P | AD5: P | AE5: P | AF5: P | AG5: P | AH5: =COUNTIF(F5:AG5,"P") -> 19 | AI5: =COUNTIF(F5:AG5,"A") -> 1 | AJ5: Working days | AK5: 26
A6: 2 | B6: 819 | C6: Amna | D6: Saeed Ahmed | E6: One | H6: P | I6: A | K6: A | L6: A | M6: A | O6: P | P6: P | Q6: P | R6: P | T6: P | V6: P | W6: A | Y6: A | Z6: A | AA6: L | AC6: L | AD6: L | AE6: L | AF6: P | AG6: P | AH6: =COUNTIF(F6:AG6,"P") -> 9 | AI6: =COUNTIF(F6:AG6,"A") -> 7 | AJ6: Sunday | AK6: 4
A7: 3 | B7: 812 | C7: Adeeba | D7: Qurban Ali | E7: One | H7: P | I7: P | K7: P | L7: P | M7: A | O7: A | P7: A | Q7: P | R7: P | T7: P | V7: P | W7: A | Y7: P | Z7: P | AA7: P | AC7: P | AD7: P | AE7: A | AF7: P | AG7: P | AH7: =COUNTIF(F7:AG7,"P") -> 15 | AI7: =COUNTIF(F7:AG7,"A") -> 5 | AJ7: Shab-E-Mairaj | AK7: 1
A8: 4 | B8: 801 | C8: Emaan Noor | D8: Noor Mohammad | E8: One | H8: P | I8: P | K8: P | L8: P | M8: A | O8: L | P8: P | Q8: P | R8: P | T8: P | V8: P | W8: P | Y8: P | Z8: P | AA8: P | AC8: P | AD8: P | AE8: P | AF8: P | AG8: P | AH8: =COUNTIF(F8:AG8,"P") -> 18 | AI8: =COUNTIF(F8:AG8,"A") -> 1
A9: 5 | B9: 828 | C9: Horain | D9: Saeed Ahmed | E9: One | H9: P | I9: P | K9: A | L9: P | M9: A | O9: P | P9: A | Q9: P | R9: P | T9: P | V9: A | W9: A | Y9: A | Z9: A | AA9: P | AC9: P | AD9: P | AE9: P | AF9: P | AG9: P | AH9: =COUNTIF(F9:AG9,"P") -> 13 | AI9: =COUNTIF(F9:AG9,"A") -> 7
A10: 6 | B10: 829 | C10: Hannah | D10: Luqman Ali | E10: One | H10: A | I10: A | K10: A | L10: A | M10: A | O10: P | P10: P | Q10: P | R10: P | T10: P | V10: P | W10: P | Y10: P | Z10: P | AA10: A | AC10: P | AD10: P | AE10: P | AF10: P | AG10: P | AH10: =COUNTIF(F10:AG10,"P") -> 14 | AI10: =COUNTIF(F10:AG10,"A") -> 6
A11: 7 | B11: 814 | C11: Horiya | D11: Siddique | E11: One | H11: L | I11: P | K11: P | L11: P | M11: P | O11: P | P11: P | Q11: P | R11: P | T11: P | V11: P | W11: P | Y11: P | Z11: P | AA11: L | AC11: P | AD11: P | AE11: P | AF11: P | AG11: P | AH11: =COUNTIF(F11:AG11,"P") -> 18 | AI11: =COUNTIF(F11:AG11,"A") -> 0 | AJ11: Present Days Detail
A12: 8 | B12: 817 | C12: Hareem Fatima | D12: Deedar Ali | E12: One | H12: P | I12: P | K12: P | L12: P | M12: P | O12: P | P12: P | Q12: P | R12: P | T12: P | V12: P | W12: P | Y12: P | Z12: P | AA12: P | AC12: P | AD12: P | AE12: P | AF12: P | AG12: P | AH12: =COUNTIF(F12:AG12,"P") -> 20 | AI12: =COUNTIF(F12:AG12,"A") -> 0 | AJ12: Detail | AK12: Boys | AL12: Girls | AM12: Total
A13: 9 | B13: 807 | C13: Maham Noor | D13: Zaheer Abbas | E13: One | H13: P | I13: P | K13: P | L13: P | M13: P | O13: A | P13: A | Q13: A | R13: A | T13: A | V13: A | W13: A | Y13: P | Z13: P | AA13: P | AC13: P | AD13: P | AE13: P | AF13: P | AG13: P | AH13: =COUNTIF(F13:AG13,"P") -> 13 | AI13: =COUNTIF(F13:AG13,"A") -> 7 | AJ13: Due Present days | AK13: =32*$AK$5 -> 832 | AL13: =24*$AK$5 -> 624 | AM13: =SUM(AK13:AL13) -> 1456
A14: 10 | B14: 827 | C14: Maria | D14: Mehboob Ali | E14: One | H14: P | I14: P | K14: P | L14: P | M14: P | O14: P | P14: P | Q14: P | R14: P | T14: P | V14: P | W14: P | Y14: A | Z14: L | AA14: L | AC14: L | AD14: P | AE14: P | AF14: P | AG14: P | AH14: =COUNTIF(F14:AG14,"P") -> 16 | AI14: =COUNTIF(F14:AG14,"A") -> 1 | AJ14: Actual present days | AK14: =SUM(AH28:AH59) -> 535 | AL14: =SUM(AH5:AH27) -> 375 | AM14: =AK14+AL14 -> 910
A15: 11 | B15: 802 | C15: Mehreen | D15: M. Maroof | E15: One | H15: P | I15: P | K15: P | L15: P | M15: P | O15: P | P15: P | Q15: P | R15: P | T15: P | V15: P | W15: P | Y15: P | Z15: P | AA15: P | AC15: P | AD15: P | AE15: P | AF15: P | AG15: P | AH15: =COUNTIF(F15:AG15,"P") -> 20 | AI15: =COUNTIF(F15:AG15,"A") -> 0 | AJ15: % | AK15: =AK14/AK13 -> 0.64302885 | AL15: =AL14/AL13 -> 0.60096154 | AM15: =AM14/AM13 -> 0.625
A16: 12 | C16: Mahira | D16: Arbab Ali | E16: One | H16: P | I16: P | K16: P | L16: P | M16: P | O16: P | P16: P | Q16: A | R16: P | T16: P | V16: A | W16: A | Y16: P | Z16: P | AA16: P | AC16: P | AD16: P | AE16: P | AF16: P | AG16: P | AH16: =COUNTIF(F16:AG16,"P") -> 17 | AI16: =COUNTIF(F16:AG16,"A") -> 3
A17: 13 | B17: 836 | C17: Meerab | D17: Yasir Ahmed | E17: One | H17: P | I17: P | K17: P | L17: P | M17: P | O17: P | P17: P | Q17: P | R17: P | T17: P | V17: P | W17: P | Y17: P | Z17: P | AA17: P | AC17: P | AD17: P | AE17: P | AF17: P | AG17: P | AH17: =COUNTIF(F17:AG17,"P") -> 20 | AI17: =COUNTIF(F17:AG17,"A") -> 0
A18: 14 | B18: 835 | C18: Qudsia Zehra | D18: Awaheed Ali | E18: One | H18: P | I18: P | K18: A | L18: A | M18: A | O18: P | P18: P | Q18: P | R18: P | T18: A | V18: P | W18: P | Y18: P | Z18: P | AA18: P | AC18: P | AD18: P | AE18: P | AF18: P | AG18: P | AH18: =COUNTIF(F18:AG18,"P") -> 16 | AI18: =COUNTIF(F18:AG18,"A") -> 4
A19: 15 | C19: Paras | D19: Sadam | E19: One | H19: P | I19: P | K19: P | L19: P | M19: A | O19: A | P19: P | Q19: P | R19: P | T19: A | V19: P | W19: P | Y19: P | Z19: P | AA19: A | AC19: P | AD19: A | AE19: A | AF19: P | AG19: P | AH19: =COUNTIF(F19:AG19,"P") -> 14 | AI19: =COUNTIF(F19:AG19,"A") -> 6 | AJ19: Absent Days Details
A20: 16 | B20: 892 | C20: Thamna Batool | D20: Shehzad | E20: One | H20: A | I20: P | K20: P | L20: P | M20: P | O20: P | P20: P | Q20: P | R20: P | T20: P | V20: P | W20: P | Y20: P | Z20: P | AA20: P | AC20: P | AD20: P | AE20: P | AF20: P | AG20: P | AH20: =COUNTIF(F20:AG20,"P") -> 19 | AI20: =COUNTIF(F20:AG20,"A") -> 1 | AJ20: Detail | AK20: Boys | AL20: Girls | AM20: Total
A21: 17 | B21: 838 | C21: Tamana Fatima | D21: Shehzad | E21: One | H21: A | I21: P | K21: P | L21: P | M21: P | O21: P | P21: P | Q21: P | R21: P | T21: P | V21: P | W21: P | Y21: P | Z21: P | AA21: P | AC21: P | AD21: P | AE21: P | AF21: P | AG21: P | AH21: =COUNTIF(F21:AG21,"P") -> 19 | AI21: =COUNTIF(F21:AG21,"A") -> 1 | AJ21: Due Present days | AK21: =32*$AK$5 -> 832 | AL21: =24*$AK$5 -> 624 | AM21: =AK21+AL21 -> 1456
A22: 18 | B22: 808 | C22: Haram | D22: Moien Khan | E22: One | H22: A | I22: P | K22: P | L22: A | M22: L | O22: P | P22: P | Q22: A | R22: A | T22: A | V22: P | W22: P | Y22: P | Z22: P | AA22: P | AC22: P | AD22: P | AE22: P | AF22: P | AG22: P | AH22: =COUNTIF(F22:AG22,"P") -> 14 | AI22: =COUNTIF(F22:AG22,"A") -> 5 | AJ22: Absent days | AK22: =AK21-AK14 -> 297 | AL22: =AL21-AL14 -> 249 | AM22: =AK22+AL22 -> 546
A23: 19 | B23: 800 | C23: Ayesha | D23: A. Latif | E23: One | H23: P | I23: P | K23: P | L23: P | M23: P | O23: P | P23: P | Q23: P | R23: P | T23: P | V23: P | W23: P | Y23: P | Z23: P | AA23: P | AC23: P | AD23: P | AE23: P | AF23: P | AG23: P | AH23: =COUNTIF(F23:AG23,"P") -> 20 | AI23: =COUNTIF(F23:AG23,"A") -> 0 | AJ23: % | AK23: =AK22/AK21 -> 0.35697115 | AL23: =AL22/AL21 -> 0.39903846 | AM23: =AM22/AM21 -> 0.375
A24: 20 | B24: 823 | C24: Zaiba Bakhtawar | D24: Hameed | E24: One | H24: P | I24: P | K24: P | L24: A | M24: P | O24: P | P24: P | Q24: P | R24: P | T24: A | V24: P | W24: A | Y24: P | Z24: A | AA24: P | AC24: A | AD24: P | AE24: A | AF24: P | AG24: P | AH24: =COUNTIF(F24:AG24,"P") -> 14 | AI24: =COUNTIF(F24:AG24,"A") -> 6
A25: 21 | B25: 793 | C25: Zainab | D25: A. Aziz | E25: One | H25: P | I25: P | K25: P | L25: P | M25: P | O25: P | P25: P | Q25: P | R25: P | T25: P | V25: P | W25: P | Y25: P | Z25: P | AA25: P | AC25: P | AD25: P | AE25: P | AF25: P | AG25: P | AH25: =COUNTIF(F25:AG25,"P") -> 20 | AI25: =COUNTIF(F25:AG25,"A") -> 0
A26: 22 | B26: 811 | C26: Zainab | D26: Zulfiqar | E26: One | H26: P | I26: P | K26: P | L26: P | M26: P | O26: P | P26: P | Q26: P | R26: P | T26: P | V26: P | W26: P | Y26: P | Z26: P | AA26: P | AC26: P | AD26: P | AE26: P | AF26: P | AG26: P | AH26: =COUNTIF(F26:AG26,"P") -> 20 | AI26: =COUNTIF(F26:AG26,"A") -> 0
A27: 23 | B27: 822 | C27: Ayat | D27: Mir Muhammad | E27: One | H27: A | I27: P | K27: A | L27: A | M27: A | O27: A | P27: A | Q27: A | R27: A | T27: A | V27: A | W27: P | Y27: A | Z27: P | AA27: P | AC27: P | AD27: A | AE27: P | AF27: A | AG27: P | AH27: =COUNTIF(F27:AG27,"P") -> 7 | AI27: =COUNTIF(F27:AG27,"A") -> 13
A28: 1 | B28: 824 | C28: Arsalan | D28: Zulfiqar | E28: One | H28: P | I28: P | K28: P | L28: P | M28: P | O28: P | P28: P | Q28: P | R28: P | T28: P | V28: P | W28: P | Y28: P | Z28: P | AA28: P | AC28: P | AD28: P | AE28: P | AF28: P | AG28: P | AH28: =COUNTIF(F28:AG28,"P") -> 20 | AI28: =COUNTIF(F28:AG28,"A") -> 0
A29: 2 | B29: 791 | C29: Arsalan | D29: Faheem | E29: One | H29: P | I29: P | K29: P | L29: P | M29: A | O29: P | P29: A | Q29: P | R29: P | T29: A | V29: P | W29: P | Y29: A | Z29: P | AA29: A | AC29: P | AD29: P | AE29: P | AF29: P | AG29: P | AH29: =COUNTIF(F29:AG29,"P") -> 15 | AI29: =COUNTIF(F29:AG29,"A") -> 5
A30: 3 | B30: 809 | C30: Ahmed Nawaz | D30: Ali Nawaz | E30: One | H30: P | I30: P | K30: P | L30: A | M30: P | O30: P | P30: P | Q30: P | R30: P | T30: P | V30: P | W30: A | Y30: P | Z30: P | AA30: A | AC30: P | AD30: P | AE30: P | AF30: P | AG30: P | AH30: =COUNTIF(F30:AG30,"P") -> 17 | AI30: =COUNTIF(F30:AG30,"A") -> 3
A31: 4 | B31: 837 | C31: A. Malik | D31: Sohail | E31: One | H31: P | I31: A | K31: P | L31: P | M31: A | O31: P | P31: P | Q31: A | R31: P | T31: P | V31: A | W31: P | Y31: P | Z31: P | AA31: A | AC31: P | AD31: P | AE31: P | AF31: P | AG31: P | AH31: =COUNTIF(F31:AG31,"P") -> 15 | AI31: =COUNTIF(F31:AG31,"A") -> 5
A32: 5 | B32: 798 | C32: Abdullah | D32: Imtiaz | E32: One | H32: P | I32: P | K32: P | L32: P | M32: P | O32: P | P32: P | Q32: P | R32: A | T32: A | V32: P | W32: P | Y32: P | Z32: P | AA32: P | AC32: P | AD32: P | AE32: P | AF32: P | AG32: P | AH32: =COUNTIF(F32:AG32,"P") -> 18 | AI32: =COUNTIF(F32:AG32,"A") -> 2
A33: 6 | B33: 816 | C33: Aqeel | D33: A. Ghaffar | E33: One | H33: P | I33: P | K33: P | L33: P | M33: P | O33: P | P33: P | Q33: P | R33: P | T33: P | V33: P | W33: P | Y33: P | Z33: P | AA33: P | AC33: P | AD33: A | AE33: P | AF33: P | AG33: P | AH33: =COUNTIF(F33:AG33,"P") -> 19 | AI33: =COUNTIF(F33:AG33,"A") -> 1
A34: 7 | B34: 797 | C34: A. Wasay | D34: Aslam | E34: One | H34: A | I34: A | K34: A | L34: A | M34: A | O34: A | P34: A | Q34: A | R34: A | T34: A | V34: A | W34: A | Y34: A | Z34: A | AA34: A | AC34: A | AD34: A | AE34: A | AF34: A | AG34: A | AH34: =COUNTIF(F34:AG34,"P") -> 0 | AI34: =COUNTIF(F34:AG34,"A") -> 20
A35: 8 | C35: A. Qadir | D35: A. Hammad | E35: One | H35: A | I35: A | K35: A | L35: A | M35: A | O35: A | P35: A | Q35: A | R35: A | T35: P | V35: P | W35: P | Y35: P | Z35: P | AA35: P | AC35: P | AD35: P | AE35: P | AF35: P | AG35: P | AH35: =COUNTIF(F35:AG35,"P") -> 11 | AI35: =COUNTIF(F35:AG35,"A") -> 9
A36: 9 | B36: 795 | C36: Asghar Ali | D36: Akbar Ali | E36: One | H36: P | I36: P | K36: P | L36: P | M36: P | O36: P | P36: P | Q36: P | R36: P | T36: P | V36: P | W36: P | Y36: P | Z36: P | AA36: P | AC36: P | AD36: P | AE36: P | AF36: P | AG36: P | AH36: =COUNTIF(F36:AG36,"P") -> 20 | AI36: =COUNTIF(F36:AG36,"A") -> 0
A37: 10 | B37: 796 | C37: A. Nafay | D37: Irshad ul Haq | E37: One | H37: P | I37: P | K37: P | L37: P | M37: P | O37: P | P37: P | Q37: P | R37: P | T37: P | V37: P | W37: P | Y37: P | Z37: P | AA37: P | AC37: P | AD37: P | AE37: P | AF37: P | AG37: P | AH37: =COUNTIF(F37:AG37,"P") -> 20 | AI37: =COUNTIF(F37:AG37,"A") -> 0
A38: 11 | B38: 821 | C38: Hasaan | D38: Manzoor | E38: One | H38: P | I38: A | K38: P | L38: A | M38: A | O38: A | P38: P | Q38: P | R38: P | T38: A | V38: A | W38: A | Y38: P | Z38: P | AA38: P | AC38: P | AD38: P | AE38: P | AF38: P | AG38: P | AH38: =COUNTIF(F38:AG38,"P") -> 13 | AI38: =COUNTIF(F38:AG38,"A") -> 7
A39: 12 | B39: 776 | C39: Hammad | D39: Rehmatullah | E39: One | H39: P | I39: P | K39: P | L39: P | M39: P | O39: P | P39: P | Q39: P | R39: P | T39: P | V39: P | W39: P | Y39: P | Z39: P | AA39: P | AC39: P | AD39: P | AE39: P | AF39: P | AG39: P | AH39: =COUNTIF(F39:AG39,"P") -> 20 | AI39: =COUNTIF(F39:AG39,"A") -> 0
A40: 13 | B40: 820 | C40: Hammad | D40: Shahid | E40: One | H40: P | I40: P | K40: P | L40: P | M40: P | O40: P | P40: P | Q40: P | R40: A | T40: P | V40: P | W40: A | Y40: P | Z40: P | AA40: P | AC40: P | AD40: P | AE40: P | AF40: P | AG40: P | AH40: =COUNTIF(F40:AG40,"P") -> 18 | AI40: =COUNTIF(F40:AG40,"A") -> 2
...

Sheet Class-II
A1: Goverment High School (SJCHS)
A2: Monthly Attendence Month of February-2025
A3: S.No | B3: GR | C3: Student Name | D3: Father Name | E3: Class | F3: =TEXT(F4,"ddd") -> Sat | G3: =TEXT(G4,"ddd") -> Sun | H3: =TEXT(H4,"ddd") -> Mon | I3: =TEXT(I4,"ddd") -> Tue | J3: =TEXT(J4,"ddd") -> Wed | K3: =TEXT(K4,"ddd") -> Thu | L3: =TEXT(L4,"ddd") -> Fri | M3: =TEXT(M4,"ddd") -> Sat | ... AG3: =TEXT(AG4,"ddd") -> Fri | AH3: Present | AI3: Absent | AJ3: Year 2024
F4: 45689 | G4: 45690 | H4: 45691 | I4: 45692 | J4: 45693 | K4: 45694 | L4: 45695 | M4: 45696 | N4: 45697 | O4: 45698 | P4: 45699 | Q4: 45700 | R4: 45701 | S4: 45702 | T4: 45703 | U4: 45704 | V4: 45705 | W4: 45706 | X4: 45707 | Y4: 45708 | Z4: 45709 | AA4: 45710 | AB4: 45711 | AC4: 45712 | AD4: 45713 | AE4: 45714 | AF4: 45715 | AG4: 45716 | AJ4: Total days | AK4: =SUM(AK5:AK8) -> 31
A5: 1 | B5: 772 | C5: Abiha Zehra | D5: Ab. Mateen | E5: Two | F5: PTM - PTM - PTM - PTM - PTM - PTM - PTM - PTM - PTM | G5: SUNDAY - SUNDAY - SUNDAY - SUNDAY - SUNDAY - SUNDAY | H5: P | I5: P | J5: Kashmir Day - Kashmir Day - Kashmir Day | K5: P | L5: P | M5: P | N5: SUNDAY - SUNDAY - SUNDAY - SUNDAY - SUNDAY - SUNDAY | O5: P | P5: P | Q5: P | R5: A | S5: Shab - E Baraat - Shab - E Baraat | T5: A | U5: SUNDAY - SUNDAY - SUNDAY - SUNDAY - SUNDAY - SUNDAY | V5: A | W5: A | X5: URS LAL SHEHBAZ QALANDAR - URS LAL SHEHBAZ QALANDAR | Y5: A | Z5: P | AA5: P | AB5: SUNDAY - SUNDAY - SUNDAY - SUNDAY - SUNDAY - SUNDAY | AC5: P | AD5: A | AE5: A | AF5: P | AG5: P | AH5: =COUNTIF(F5:AG5,"P") -> 13 | AI5: =COUNTIF(F5:AG5,"A") -> 7 | AJ5: Working days | AK5: 26
A6: 2 | B6: 673 | C6: Aleena Zia | D6: Khuda Baksh | E6: Two | H6: P | I6: P | K6: L | L6: L | M6: L | O6: L | P6: L | Q6: L | R6: L | T6: L | V6: P | W6: P | Y6: P | Z6: P | AA6: P | AC6: P | AD6: P | AE6: P | AF6: P | AG6: P | AH6: =COUNTIF(F6:AG6,"P") -> 12 | AI6: =COUNTIF(F6:AG6,"A") -> 0 | AJ6: Sunday | AK6: 4
A7: 3 | B7: 523 | C7: Anumta Jamali | D7: Zaheer Abbas | E7: Two | H7: P | I7: P | K7: P | L7: P | M7: P | O7: P | P7: P | Q7: P | R7: P | T7: P | V7: P | W7: P | Y7: P | Z7: P | AA7: P | AC7: P | AD7: P | AE7: P | AF7: P | AG7: P | AH7: =COUNTIF(F7:AG7,"P") -> 20 | AI7: =COUNTIF(F7:AG7,"A") -> 0 | AJ7: Shab-E-Mairaj | AK7: 1
A8: 4 | B8: 665 | C8: Ayat | D8: Faiq Ali | E8: Two | H8: P | I8: P | K8: P | L8: P | M8: P | O8: P | P8: P | Q8: P | R8: P | T8: A | V8: P | W8: P | Y8: P | Z8: A | AA8: P | AC8: P | AD8: P | AE8: P | AF8: P | AG8: P | AH8: =COUNTIF(F8:AG8,"P") -> 18 | AI8: =COUNTIF(F8:AG8,"A") -> 2
A9: 5 | B9: 656 | C9: Ayesha | D9: Ali Muhammad | E9: Two | H9: P | I9: P | K9: P | L9: P | M9: P | O9: P | P9: P | Q9: P | R9: P | T9: P | V9: A | W9: P | Y9: P | Z9: P | AA9: P | AC9: P | AD9: P | AE9: A | AF9: P | AG9: P | AH9: =COUNTIF(F9:AG9,"P") -> 18 | AI9: =COUNTIF(F9:AG9,"A") -> 2
A10: 6 | B10: 910 | C10: Ayesha | D10: Zulfiqar | E10: Two | H10: P | I10: P | K10: P | L10: P | M10: P | O10: P | P10: P | Q10: P | R10: P | T10: P | V10: P | W10: P | Y10: P | Z10: L | AA10: P | AC10: P | AD10: P | AE10: P | AF10: P | AG10: P | AH10: =COUNTIF(F10:AG10,"P") -> 19 | AI10: =COUNTIF(F10:AG10,"A") -> 0
A11: 7 | B11: 679 | C11: Dua | D11: Akbar Ali | E11: Two | H11: P | I11: P | K11: P | L11: P | M11: P | O11: P | P11: P | Q11: P | R11: P | T11: P | V11: P | W11: P | Y11: P | Z11: P | AA11: P | AC11: P | AD11: P | AE11: P | AF11: P | AG11: P | AH11: =COUNTIF(F11:AG11,"P") -> 20 | AI11: =COUNTIF(F11:AG11,"A") -> 0 | AJ11: Present Days Detail
A12: 8 | B12: 675 | C12: Fiza | D12: Ahsan ali | E12: Two | H12: P | I12: P | K12: P | L12: P | M12: P | O12: P | P12: P | Q12: P | R12: P | T12: P | V12: P | W12: P | Y12: P | Z12: P | AA12: P | AC12: P | AD12: P | AE12: P | AF12: P | AG12: P | AH12: =COUNTIF(F12:AG12,"P") -> 20 | AI12: =COUNTIF(F12:AG12,"A") -> 0 | AJ12: Detail | AK12: Boys | AL12: Girls | AM12: Total
A13: 9 | B13: 774 | C13: Jannat Fatima | D13: Zulfiqar | E13: Two | H13: P | I13: P | K13: P | L13: P | M13: A | O13: P | P13: P | Q13: P | R13: P | T13: P | V13: P | W13: P | Y13: P | Z13: P | AA13: P | AC13: P | AD13: P | AE13: P | AF13: P | AG13: P | AH13: =COUNTIF(F13:AG13,"P") -> 19 | AI13: =COUNTIF(F13:AG13,"A") -> 1 | AJ13: Due Present days | AK13: =26*$AK$5 -> 676 | AL13: =26*$AK$5 -> 676 | AM13: =SUM(AK13:AL13) -> 1352
A14: 10 | B14: 655 | C14: Kashaf | D14: Abdul Rehman | E14: Two | H14: P | I14: P | K14: P | L14: P | M14: P | O14: P | P14: P | Q14: P | R14: P | T14: P | V14: P | W14: P | Y14: P | Z14: P | AA14: P | AC14: P | AD14: P | AE14: P | AF14: P | AG14: P | AH14: =COUNTIF(F14:AG14,"P") -> 20 | AI14: =COUNTIF(F14:AG14,"A") -> 0 | AJ14: Actual present days | AK14: =SUM(AH28:AH51) -> 424 | AL14: =SUM(AH5:AH27) -> 414 | AM14: =AK14+AL14 -> 838
A15: 11 | B15: 653 | C15: Kashish | D15: M. Noman | E15: Two | H15: P | I15: P | K15: P | L15: P | M15: P | O15: P | P15: P | Q15: P | R15: P | T15: P | V15: P | W15: P | Y15: P | Z15: P | AA15: A | AC15: P | AD15: P | AE15: P | AF15: P | AG15: P | AH15: =COUNTIF(F15:AG15,"P") -> 19 | AI15: =COUNTIF(F15:AG15,"A") -> 1 | AJ15: % | AK15: =AK14/AK13 -> 0.62721893 | AL15: =AL14/AL13 -> 0.61242604 | AM15: =AM14/AM13 -> 0.61982249
A16: 12 | B16: 657 | C16: Masooma | D16: M. Raheem | E16: Two | H16: P | I16: P | K16: P | L16: P | M16: P | O16: P | P16: P | Q16: P | R16: P | T16: P | V16: A | W16: P | Y16: P | Z16: P | AA16: A | AC16: P | AD16: A | AE16: P | AF16: P | AG16: P | AH16: =COUNTIF(F16:AG16,"P") -> 17 | AI16: =COUNTIF(F16:AG16,"A") -> 3
A17: 13 | B17: 672 | C17: Muneeza | D17: Mir Amirudin | E17: Two | H17: P | I17: P | K17: P | L17: P | M17: P | O17: A | P17: A | Q17: A | R17: P | T17: P | V17: P | W17: P | Y17: A | Z17: P | AA17: A | AC17: P | AD17: P | AE17: A | AF17: P | AG17: P | AH17: =COUNTIF(F17:AG17,"P") -> 14 | AI17: =COUNTIF(F17:AG17,"A") -> 6
A18: 14 | B18: 702 | C18: Nayyara | D18: Khalid Hussain | E18: Two | H18: P | I18: P | K18: P | L18: P | M18: P | O18: P | P18: A | Q18: A | R18: A | T18: A | V18: A | W18: P | Y18: A | Z18: A | AA18: A | AC18: P | AD18: P | AE18: P | AF18: P | AG18: P | AH18: =COUNTIF(F18:AG18,"P") -> 12 | AI18: =COUNTIF(F18:AG18,"A") -> 8
A19: 15 | B19: 659 | C19: Rashida | D19: Sajjad Ahmed | E19: Two | H19: P | I19: P | K19: P | L19: P | M19: A | O19: P | P19: P | Q19: P | R19: P | T19: P | V19: P | W19: P | Y19: P | Z19: P | AA19: P | AC19: P | AD19: P | AE19: P | AF19: P | AG19: P | AH19: =COUNTIF(F19:AG19,"P") -> 19 | AI19: =COUNTIF(F19:AG19,"A") -> 1 | AJ19: Absent Days Details
A20: 16 | B20: 661 | C20: Rubab Zahra | D20: Abdul Aziz | E20: Two | H20: P | I20: P | K20: P | L20: P | M20: P | O20: P | P20: P | Q20: P | R20: P | T20: P | V20: P | W20: P | Y20: P | Z20: P | AA20: P | AC20: P | AD20: P | AE20: P | AF20: P | AG20: P | AH20: =COUNTIF(F20:AG20,"P") -> 20 | AI20: =COUNTIF(F20:AG20,"A") -> 0 | AJ20: Detail | AK20: Boys | AL20: Girls | AM20: Total
A21: 17 | B21: 522 | C21: Soha Jamali | D21: Sajid Ali | E21: Two | H21: P | I21: P | K21: P | L21: P | M21: P | O21: P | P21: P | Q21: P | R21: P | T21: A | V21: P | W21: P | Y21: P | Z21: P | AA21: P | AC21: P | AD21: P | AE21: P | AF21: P | AG21: P | AH21: =COUNTIF(F21:AG21,"P") -> 19 | AI21: =COUNTIF(F21:AG21,"A") -> 1 | AJ21: Due Present days | AK21: =26*$AK$5 -> 676 | AL21: =26*$AK$5 -> 676 | AM21: =AK21+AL21 -> 1352
A22: 18 | B22: 654 | C22: Sehar Fatima | D22: Altaf Hussain | E22: Two | H22: P | I22: P | K22: P | L22: P | M22: P | O22: P | P22: P | Q22: P | R22: P | T22: P | V22: P | W22: P | Y22: P | Z22: P | AA22: P | AC22: P | AD22: P | AE22: P | AF22: P | AG22: P | AH22: =COUNTIF(F22:AG22,"P") -> 20 | AI22: =COUNTIF(F22:AG22,"A") -> 0 | AJ22: Absent days | AK22: =AK21-AK14 -> 252 | AL22: =AL21-AL14 -> 262 | AM22: =AK22+AL22 -> 514
A23: 19 | B23: 660 | C23: Saba | D23: Asif | E23: Two | H23: P | I23: P | K23: P | L23: P | M23: P | O23: P | P23: P | Q23: P | R23: P | T23: P | V23: P | W23: P | Y23: P | Z23: P | AA23: P | AC23: P | AD23: P | AE23: P | AF23: P | AG23: P | AH23: =COUNTIF(F23:AG23,"P") -> 20 | AI23: =COUNTIF(F23:AG23,"A") -> 0 | AJ23: % | AK23: =AK22/AK21 -> 0.37278107 | AL23: =AL22/AL21 -> 0.38757396 | AM23: =AM22/AM21 -> 0.38017751
A24: 20 | B24: 841 | C24: Sehrish | D24: Fida Hussain | E24: Two | H24: P | I24: P | K24: P | L24: P | M24: P | O24: P | P24: P | Q24: P | R24: P | T24: A | V24: P | W24: A | Y24: P | Z24: P | AA24: P | AC24: P | AD24: P | AE24: P | AF24: P | AG24: P | AH24: =COUNTIF(F24:AG24,"P") -> 18 | AI24: =COUNTIF(F24:AG24,"A") -> 2
A25: 21 | B25: 676 | C25: Tahreem Fatima | D25: Khalid Hussain | E25: Two | H25: P | I25: A | K25: P | L25: P | M25: P | O25: P | P25: P | Q25: P | R25: P | T25: P | V25: P | W25: P | Y25: P | Z25: P | AA25: P | AC25: P | AD25: P | AE25: P | AF25: P | AG25: P | AH25: =COUNTIF(F25:AG25,"P") -> 19 | AI25: =COUNTIF(F25:AG25,"A") -> 1
A26: 22 | B26: 658 | C26: Taskeen | D26: Amjad Ali | E26: Two | H26: P | I26: P | K26: P | L26: P | M26: P | O26: P | P26: P | Q26: P | R26: P | T26: P | V26: P | W26: P | Y26: P | Z26: A | AA26: P | AC26: P | AD26: A | AE26: P | AF26: P | AG26: P | AH26: =COUNTIF(F26:AG26,"P") -> 18 | AI26: =COUNTIF(F26:AG26,"A") -> 2
A27: 23 | B27: 785 | C27: Zainab | D27: Sikandar | E27: Two | H27: P | I27: P | K27: P | L27: P | M27: P | O27: P | P27: P | Q27: P | R27: P | T27: P | V27: P | W27: P | Y27: P | Z27: P | AA27: P | AC27: P | AD27: P | AE27: P | AF27: P | AG27: P | AH27: =COUNTIF(F27:AG27,"P") -> 20 | AI27: =COUNTIF(F27:AG27,"A") -> 0
A28: 1 | B28: 784 | C28: Abdul Musawir | D28: M. Ismail | E28: Two | H28: P | I28: P | K28: P | L28: P | M28: P | O28: P | P28: P | Q28: P | R28: P | T28: P | V28: P | W28: P | Y28: P | Z28: P | AA28: P | AC28: P | AD28: P | AE28: A | AF28: P | AG28: P | AH28: =COUNTIF(F28:AG28,"P") -> 19 | AI28: =COUNTIF(F28:AG28,"A") -> 1
A29: 2 | B29: 700 | C29: Abdul Rehman | D29: Sajid Ali | E29: Two | H29: P | I29: P | K29: P | L29: P | M29: P | O29: P | P29: P | Q29: P | R29: P | T29: P | V29: P | W29: P | Y29: P | Z29: P | AA29: P | AC29: P | AD29: P | AE29: P | AF29: A | AG29: P | AH29: =COUNTIF(F29:AG29,"P") -> 19 | AI29: =COUNTIF(F29:AG29,"A") -> 1
A30: 3 | B30: 680 | C30: Abdul Wahab | D30: Abdul Hafeez | E30: Two | H30: P | I30: P | K30: P | L30: P | M30: P | O30: P | P30: P | Q30: P | R30: P | T30: A | V30: A | W30: P | Y30: A | Z30: P | AA30: A | AC30: A | AD30: P | AE30: P | AF30: P | AG30: P | AH30: =COUNTIF(F30:AG30,"P") -> 15 | AI30: =COUNTIF(F30:AG30,"A") -> 5
A31: 4 | B31: 650 | C31: Abdullah | D31: Riazuddin | E31: Two | H31: P | I31: P | K31: P | L31: P | M31: P | O31: P | P31: P | Q31: P | R31: P | T31: P | V31: P | W31: P | Y31: A | Z31: A | AA31: P | AC31: P | AD31: P | AE31: P | AF31: P | AG31: P | AH31: =COUNTIF(F31:AG31,"P") -> 18 | AI31: =COUNTIF(F31:AG31,"A") -> 2
A32: 5 | B32: 911 | C32: Burair Abbas | D32: Azhar Abbas | E32: Two | H32: P | I32: P | K32: P | L32: P | M32: P | O32: P | P32: P | Q32: P | R32: P | T32: P | V32: P | W32: P | Y32: P | Z32: P | AA32: P | AC32: P | AD32: P | AE32: P | AF32: P | AG32: P | AH32: =COUNTIF(F32:AG32,"P") -> 20 | AI32: =COUNTIF(F32:AG32,"A") -> 0
A33: 6 | B33: 683 | C33: Faizan | D33: Lutfullah | E33: Two | H33: P | I33: P | K33: P | L33: P | M33: P | O33: P | P33: P | Q33: P | R33: P | T33: P | V33: P | W33: P | Y33: P | Z33: P | AA33: P | AC33: P | AD33: P | AE33: P | AF33: P | AG33: P | AH33: =COUNTIF(F33:AG33,"P") -> 20 | AI33: =COUNTIF(F33:AG33,"A") -> 0
A34: 7 | B34: 662 | C34: Fayaz | D34: Samano Khan | E34: Two | H34: A | I34: A | K34: P | L34: A | M34: P | O34: A | P34: P | Q34: P | R34: P | T34: P | V34: P | W34: P | Y34: P | Z34: P | AA34: P | AC34: P | AD34: P | AE34: P | AF34: P | AG34: P | AH34: =COUNTIF(F34:AG34,"P") -> 16 | AI34: =COUNTIF(F34:AG34,"A") -> 4
A35: 8 | B35: 681 | C35: Ghulam Abbas | D35: Kamran Ali | E35: Two | H35: A | I35: A | K35: P | L35: A | M35: P | O35: A | P35: P | Q35: P | R35: P | T35: P | V35: P | W35: P | Y35: P | Z35: P | AA35: P | AC35: P | AD35: P | AE35: P | AF35: P | AG35: P | AH35: =COUNTIF(F35:AG35,"P") -> 16 | AI35: =COUNTIF(F35:AG35,"A") -> 4
... A51: 24 | B51: 683 | C51: Zain | D51: Zahid Ali | E51: Two | H51: P | I51: P | K51: P | L51: A | M51: P | O51: P | P51: A | Q51: A | R51: P | T51: P | V51: A | W51: P | Y51: A | Z51: A | AA51: A | AC51: A | AD51: P | AE51: P | AF51: P | AG51: P | AH51: =COUNTIF(F51:AG51,"P") -> 12 | AI51: =COUNTIF(F51:AG51,"A") -> 8

Sheet Class-III
A1: Goverment high school (SJCHS)
A2: Monthly Attendence Month of February-2025
A3: S.No | B3: GR | C3: Student Name | D3: Father Name | E3: Class | F3: =TEXT(F4,"ddd") -> Sat | G3: =TEXT(G4,"ddd") -> Sun | H3: =TEXT(H4,"ddd") -> Mon | I3: =TEXT(I4,"ddd") -> Tue | J3: =TEXT(J4,"ddd") -> Wed | K3: =TEXT(K4,"ddd") -> Thu | L3: =TEXT(L4,"ddd") -> Fri | M3: =TEXT(M4,"ddd") -> Sat | ... AG3: =TEXT(AG4,"ddd") -> Fri | AH3: Present | AI3: Absent | AJ3: Year 2024
F4: 45689 | G4: 45690 | H4: 45691 | I4: 45692 | J4: 45693 | K4: 45694 | L4: 45695 | M4: 45696 | N4: 45697 | O4: 45698 | P4: 45699 | Q4: 45700 | R4: 45701 | S4: 45702 | T4: 45703 | U4: 45704 | V4: 45705 | W4: 45706 | X4: 45707 | Y4: 45708 | Z4: 45709 | AA4: 45710 | AB4: 45711 | AC4: 45712 | AD4: 45713 | AE4: 45714 | AF4: 45715 | AG4: 45716 | AJ4: Total days | AK4: =SUM(AK5:AK8) -> 31
A5: 1 | B5: 646 | C5: Abbas Ali | D5: Deedar Ali | E5: Three | F5: PTM - PTM - PTM - PTM - PTM - PTM - PTM - PTM - PTM | G5: SUNDAY - SUNDAY - SUNDAY - SUNDAY - SUNDAY - SUNDAY | H5: P | I5: P | J5: Kashmir Day - Kashmir Day - Kashmir Day | K5: P | L5: P | M5: P | N5: SUNDAY - SUNDAY - SUNDAY - SUNDAY - SUNDAY - SUNDAY | O5: P | P5: P | Q5: P | R5: P | S5: Shab - E Baraat - Shab - E Baraat | T5: P | U5: SUNDAY - SUNDAY - SUNDAY - SUNDAY - SUNDAY - SUNDAY | V5: P | W5: P | X5: URS LAL SHEHBAZ QALANDAR - URS LAL SHEHBAZ QALANDAR | Y5: P | Z5: P | AA5: P | AB5: SUNDAY - SUNDAY - SUNDAY - SUNDAY - SUNDAY - SUNDAY | AC5: P | AD5: P | AE5: P | AF5: P | AG5: P | AH5: =COUNTIF(F5:AG5,"P") -> 20 | AI5: =COUNTIF(F5:AG5,"A") -> 0 | AJ5: Working days | AK5: 26
A6: 2 | B6: 690 | C6: Abdul Rafay | D6: Noor Ul Haq | E6: Three | H6: P | I6: P | K6: P | L6: P | M6: P | O6: P | P6: P | Q6: P | R6: P | T6: P | V6: P | W6: P | Y6: P | Z6: P | AA6: P | AC6: P | AD6: P | AE6: P | AF6: P | AG6: P | AH6: =COUNTIF(F6:AG6,"P") -> 20 | AI6: =COUNTIF(F6:AG6,"A") -> 0 | AJ6: Sunday | AK6: 4
A7: 3 | B7: 684 | C7: Abdul Rahim | D7: Abdul Hafeez | E7: Three | H7: P | I7: P | K7: P | L7: P | M7: P | O7: P | P7: P | Q7: P | R7: P | T7: A | V7: A | W7: P | Y7: A | Z7: P | AA7: A | AC7: A | AD7: P | AE7: P | AF7: P | AG7: P | AH7: =COUNTIF(F7:AG7,"P") -> 15 | AI7: =COUNTIF(F7:AG7,"A") -> 5 | AJ7: Shab-E-Mairaj | AK7: 1
