Workbook

Sheet Compile Sheet-November-2024
A4: Class | B4: Total Enrolment & Attendance November-24
B5: Boys | C5: Girls | D5: Total | E5: total working Days | F5: Total working days-Boys | G5: Total working days-Girls | H5: Total working days-All | I5: P-Days Boys | J5: P-Days Girls | K5: P-Days All | L5: Percentage-Girls | M5: Percentage-Boys | N5: Percentage-Boys | O5: Total average
A6: ECE (ROSE) | B6: 27 | C6: 27 | D6: =SUM(B6:C6) -> 54 | E6: 24 | F6: =B6*E6 -> 648 | G6: =C6*E6 -> 648 | H6: =SUM(F6:G6) -> 1296 | I6: ='ECE (Daffodils)'!V14 -> 0 | J6: ='ECE (Daffodils)'!#REF! -> #REF! | K6: =SUM(I6:J6) -> #REF! | L6: =J6/G6 -> #REF! | M6: =I6/F6 -> 0 | N6: =K6/H6 -> #REF! | O6: =AVERAGE(L6:M6) -> #REF!
A7: ECE (Daffodils) | B7: 31 | C7: 25 | D7: =SUM(B7:C7) -> 56 | E7: 24 | F7: =B7*E7 -> 744 | G7: =C7*E7 -> 600 | H7: =SUM(F7:G7) -> 1344 | I7: ='Class-1'!V14 -> 0 | J7: ='Class-1'!W14 -> A | K7: =SUM(I7:J7) -> 0 | L7: =J7/G7 -> #VALUE! | M7: =I7/F7 -> 0 | N7: =K7/H7 -> 0 | O7: =AVERAGE(L7:M7) -> #VALUE!
A8: One | B8: 32 | C8: 24 | D8: =SUM(B8:C8) -> 56 | E8: 24 | F8: =B8*E8 -> 768 | G8: =C8*E8 -> 576 | H8: =SUM(F8:G8) -> 1344 | I8: ='Class-2'!V13 -> 0 | J8: ='Class-2'!#REF! -> #REF! | K8: =SUM(I8:J8) -> #REF! | L8: =J8/G8 -> #REF! | M8: =I8/F8 -> 0 | N8: =K8/H8 -> #REF! | O8: =AVERAGE(L8:M8) -> #REF!
A9: Two | B9: 26 | C9: 26 | D9: =SUM(B9:C9) -> 52 | E9: 24 | F9: =B9*E9 -> 624 | G9: =C9*E9 -> 624 | H9: =SUM(F9:G9) -> 1248 | I9: ='Class-3'!V14 -> 0 | J9: ='Class-3'!#REF! -> #REF! | K9: =SUM(I9:J9) -> #REF! | L9: =J9/G9 -> #REF! | M9: =I9/F9 -> 0 | N9: =K9/H9 -> #REF! | O9: =AVERAGE(L9:M9) -> #REF!
A10: Three | B10: 28 | C10: 24 | D10: =SUM(B10:C10) -> 52 | E10: 24 | F10: =B10*E10 -> 672 | G10: =C10*E10 -> 576 | H10: =SUM(F10:G10) -> 1248 | I10: ='Class-4'!V13 -> 0 | J10: ='Class-4'!#REF! -> #REF! | K10: =SUM(I10:J10) -> #REF! | L10: =J10/G10 -> #REF! | M10: =I10/F10 -> 0 | N10: =K10/H10 -> #REF! | O10: =AVERAGE(L10:M10) -> #REF!
A11: Four | B11: 21 | C11: 32 | D11: =SUM(B11:C11) -> 53 | E11: 24 | F11: =B11*E11 -> 504 | G11: =C11*E11 -> 768 | H11: =SUM(F11:G11) -> 1272 | I11: ='Class-5'!Z14 -> 248 | J11: ='Class-5'!AA14 -> 230 | K11: =SUM(I11:J11) -> 478 | L11: =J11/G11 -> 0.29947917 | M11: =I11/F11 -> 0.49206349 | N11: =K11/H11 -> 0.37578616 | O11: =AVERAGE(L11:M11) -> 0.39577133
A12: Five | B12: 23 | C12: 23 | D12: =SUM(B12:C12) -> 46 | E12: 24 | F12: =B12*E12 -> 552 | G12: =C12*E12 -> 552 | H12: =SUM(F12:G12) -> 1104 | I12: ='Class-6'!Z14 -> 239 | J12: ='Class-6'!AA14 -> 201 | K12: =SUM(I12:J12) -> 440 | L12: =J12/G12 -> 0.36413043 | M12: =I12/F12 -> 0.43297101 | N12: =K12/H12 -> 0.39855072 | O12: =AVERAGE(L12:M12) -> 0.39855072
A13: Six | B13: 17 | C13: 28 | D13: =SUM(B13:C13) -> 45 | E13: 24 | F13: =B13*E13 -> 408 | G13: =C13*E13 -> 672 | H13: =SUM(F13:G13) -> 1080 | I13: ='Class-7'!Z14 -> 157 | J13: ='Class-7'!AA14 -> 302 | K13: =SUM(I13:J13) -> 459 | L13: =J13/G13 -> 0.44940476 | M13: =I13/F13 -> 0.38480392 | N13: =K13/H13 -> 0.425 | O13: =AVERAGE(L13:M13) -> 0.41710434
A14: Seven | B14: 29 | C14: 19 | D14: =SUM(B14:C14) -> 48 | E14: 24 | F14: =B14*E14 -> 696 | G14: =C14*E14 -> 456 | H14: =SUM(F14:G14) -> 1152 | I14: ='class-8'!Z14 -> 288 | J14: ='class-8'!AA14 -> 138 | K14: =SUM(I14:J14) -> 426 | L14: =J14/G14 -> 0.30263158 | M14: =I14/F14 -> 0.4137931 | N14: =K14/H14 -> 0.36979167 | O14: =AVERAGE(L14:M14) -> 0.35821234
A15: Eight | B15: 19 | C15: 23 | D15: =SUM(B15:C15) -> 42 | E15: 24 | F15: =B15*E15 -> 456 | G15: =C15*E15 -> 552 | H15: =SUM(F15:G15) -> 1008 | I15: ='class-9'!Z14 -> 128 | J15: ='class-9'!AA14 -> 200 | K15: =SUM(I15:J15) -> 328 | L15: =J15/G15 -> 0.36231884 | M15: =I15/F15 -> 0.28070175 | N15: =K15/H15 -> 0.32539683 | O15: =AVERAGE(L15:M15) -> 0.3215103
A16: Ninth | B16: 16 | C16: 19 | D16: =SUM(B16:C16) -> 35 | E16: 24 | F16: =B16*E16 -> 384 | G16: =C16*E16 -> 456 | H16: =SUM(F16:G16) -> 840 | I16: ='class-10'!Z14 -> 128 | J16: ='class-10'!AA14 -> 106 | K16: =SUM(I16:J16) -> 234 | L16: =J16/G16 -> 0.23245614 | M16: =I16/F16 -> 0.33333333 | N16: =K16/H16 -> 0.27857143 | O16: =AVERAGE(L16:M16) -> 0.28289474
A17: Total | B17: =SUM(B6:B16) -> 269 | C17: =SUM(C6:C16) -> 270 | D17: =SUM(D6:D16) -> 539 | E17: =SUM(E6:E16) -> 264 | F17: =SUM(F6:F16) -> 6456 | G17: =SUM(G6:G16) -> 6480 | H17: =SUM(H6:H16) -> 12936 | I17: =SUM(I6:I16) -> 1188 | ... K17: =SUM(K6:K16) -> #REF! | L17: =J17/G17 -> #REF! | M17: =I17/F17 -> 0.18401487 | N17: =AVERAGE(N6:N16) -> #REF! | O17: =AVERAGE(O6:O16) -> #REF!
A18: % | B18: 1 | C18: 1 | D18: 1 | E18: 1 | F18: 1 | G18: 1 | H18: 1 | I18: =I17/F17 -> 0.18401487 | J18: =J17/G17 -> #REF! | K18: =K17/H17 -> #REF! | L18: 0.54 | M18: 0.56 | N18: 0.55 | O18: =AVERAGE(L17:M17) -> #REF!

Sheet ECE ROSE
A1: Goverment high school (SJCHS)
A2: Monthly Attendence Month of AUGUST-2025
A3: S.No | B3: GR | C3: Student Name | D3: Father Name | E3: Class | F3: =TEXT(F4,"ddd") -> Fri | G3: =TEXT(G4,"ddd") -> Sat | H3: =TEXT(H4,"ddd") -> Sun | I3: =TEXT(I4,"ddd") -> Mon | J3: =TEXT(J4,"ddd") -> Tue | K3: =TEXT(K4,"ddd") -> Wed | L3: =TEXT(L4,"ddd") -> Thu | M3: =TEXT(M4,"ddd") -> Fri | ... V3: =TEXT(V4,"ddd") -> Sun | W3: Present | X3: Absent | Y3: Year 2024
F4: 45870 | G4: 45871 | H4: 45872 | I4: 45873 | J4: 45874 | K4: 45875 | L4: 45876 | M4: 45877 | N4: 45878 | O4: 45879 | P4: 45880 | Q4: 45881 | R4: 45882 | S4: 45883 | T4: 45884 | U4: 45885 | V4: 45886 | Y4: Total days | Z4: =SUM(Z5:Z8) -> 17
A5: 1 | C5: Mir Ghulam Mustafa Bhutto | D5: Abdul Khaliq Bhutto | E5: ECE ROSE | F5: P | G5: P | H5: SUNDAY - SUNDAY - SUNDAY - SUNDAY - SUNDAY - | I5: A | J5: P | K5: P | L5: P | M5: P | N5: URS SHAH ABDUL LATIF BITHAI | O5: SUNDAY - SUNDAY - SUNDAY - SUNDAY - SUNDAY - | P5: P | Q5: A | R5: P | S5: INDEPENDENCE DAY | T5: P | U5: P | V5: SUNDAY - SUNDAY - SUNDAY - SUNDAY - SUNDAY - | W5: =COUNTIF(F5:V5,"P") -> 10 | X5: =COUNTIF(F5:V5,"A") -> 2 | Y5: Working days | Z5: 12
A6: 2 | C6: Airah Alber | D6: Abdul Alber | E6: ECE ROSE | F6: P | G6: P | I6: P | J6: P | K6: P | L6: P | M6: A | P6: P | Q6: P | R6: P | T6: P | U6: P | W6: =COUNTIF(F6:V6,"P") -> 11 | X6: =COUNTIF(F6:V6,"A") -> 1 | Y6: Sunday | Z6: 3
A7: 3 | C7: Meerum | D7: Razaullah | E7: ECE ROSE | F7: A | G7: P | I7: P | J7: P | K7: P | L7: P | M7: P | P7: P | Q7: P | R7: P | T7: P | U7: P | W7: =COUNTIF(F7:V7,"P") -> 11 | X7: =COUNTIF(F7:V7,"A") -> 1 | Y7: Off Days | Z7: 2
A8: 4 | C8: Marwa Bibi | D8: Naqeeb Ullah | E8: ECE ROSE | F8: P | G8: P | I8: P | J8: P | K8: P | L8: P | M8: P | P8: P | Q8: P | R8: A | T8: P | U8: P | W8: =COUNTIF(F8:V8,"P") -> 11 | X8: =COUNTIF(F8:V8,"A") -> 1
A9: 5 | C9: Muhammad Huzzaifa | D9: Zain Ullah | E9: ECE ROSE | F9: P | G9: P | I9: P | J9: A | K9: P | L9: P | M9: P | P9: P | Q9: P | R9: P | T9: P | U9: P | W9: =COUNTIF(F9:V9,"P") -> 11 | X9: =COUNTIF(F9:V9,"A") -> 1
A10: 6 | C10: Mustaqim Hussain | D10: Zafar Hussain | E10: ECE ROSE | F10: P | G10: A | I10: P | J10: P | K10: P | L10: P | M10: P | P10: A | Q10: P | R10: P | T10: A | U10: P | W10: =COUNTIF(F10:V10,"P") -> 9 | X10: =COUNTIF(F10:V10,"A") -> 3
A11: 7 | C11: Irshad | D11: Shafiq Shah | E11: ECE ROSE | F11: P | G11: P | I11: P | J11: P | K11: P | L11: P | M11: P | P11: P | Q11: P | R11: P | T11: P | U11: P | W11: =COUNTIF(F11:V11,"P") -> 12 | X11: =COUNTIF(F11:V11,"A") -> 0 | Y11: Present Days Detail
A12: 8 | C12: Aon Ali | D12: Imran Ali | E12: ECE ROSE | F12: P | G12: P | I12: A | J12: P | K12: P | L12: P | M12: P | P12: P | Q12: P | R12: P | T12: P | U12: P | W12: =COUNTIF(F12:V12,"P") -> 11 | X12: =COUNTIF(F12:V12,"A") -> 1 | Y12: Detail | Z12: Boys | AA12: Girls | AB12: Total
A13: 9 | C13: Ajwa Rashid | D13: Rashid Hussain | E13: ECE ROSE | F13: P | G13: P | I13: P | J13: P | K13: A | L13: P | M13: P | P13: P | Q13: P | R13: P | T13: P | U13: P | W13: =COUNTIF(F13:V13,"P") -> 11 | X13: =COUNTIF(F13:V13,"A") -> 1 | Y13: Due Present days | Z13: =29*$Z$5 -> 348 | AA13: =25*$Z$5 -> 300 | AB13: =SUM(Z13:AA13) -> 648
A14: 10 | C14: Muhammad Ramzan | D14: Abdul Karim | E14: ECE ROSE | F14: P | G14: P | I14: P | J14: P | K14: P | L14: P | M14: P | P14: P | Q14: P | R14: P | T14: P | U14: P | W14: =COUNTIF(F14:V14,"P") -> 12 | X14: =COUNTIF(F14:V14,"A") -> 0 | Y14: Actual present days | Z14: =SUM(W29:W31) -> 33 | AA14: =SUM(W5:W28) -> 264 | AB14: =Z14+AA14 -> 297
A15: 11 | C15: Airah Meer | D15: Tanveer Ahmed Jamali | E15: ECE ROSE | F15: P | G15: P | I15: P | J15: P | K15: P | L15: P | M15: A | P15: P | Q15: A | R15: P | T15: P | U15: P | W15: =COUNTIF(F15:V15,"P") -> 10 | X15: =COUNTIF(F15:V15,"A") -> 2 | Y15: % | Z15: =Z14/Z13 -> 0.094827586 | AA15: =AA14/AA13 -> 0.88 | AB15: =AB14/AB13 -> 0.45833333
A16: 12 | C16: Zeeshan Ali | D16: Ahsan Ali | E16: ECE ROSE | F16: A | G16: P | I16: P | J16: P | K16: P | L16: P | M16: P | P16: P | Q16: P | R16: P | T16: P | U16: P | W16: =COUNTIF(F16:V16,"P") -> 11 | X16: =COUNTIF(F16:V16,"A") -> 1
A17: 13 | C17: Farhan Ali | D17: Akbar Ali | E17: ECE ROSE | F17: P | G17: P | I17: P | J17: A | K17: P | L17: P | M17: P | P17: P | Q17: P | R17: P | T17: P | U17: P | W17: =COUNTIF(F17:V17,"P") -> 11 | X17: =COUNTIF(F17:V17,"A") -> 1
A18: 14 | C18: Muhammad Qaiser | D18: Muhammad Qasim Mugheri | E18: ECE ROSE | F18: P | G18: P | I18: P | J18: P | K18: P | L18: P | M18: P | P18: P | Q18: P | R18: P | T18: P | U18: P | W18: =COUNTIF(F18:V18,"P") -> 12 | X18: =COUNTIF(F18:V18,"A") -> 0
A19: 15 | C19: Zoya | D19: Zahid Ali | E19: ECE ROSE | F19: P | G19: P | I19: P | J19: P | K19: P | L19: P | M19: P | P19: P | Q19: P | R19: P | T19: P | U19: P | W19: =COUNTIF(F19:V19,"P") -> 12 | X19: =COUNTIF(F19:V19,"A") -> 0 | Y19: Absent Days Details
A20: 16 | C20: Bibi Batool | D20: Syed Shahid Ali Shah | E20: ECE ROSE | F20: P | G20: A | I20: P | J20: P | K20: P | L20: A | M20: P | P20: P | Q20: P | R20: A | T20: P | U20: P | W20: =COUNTIF(F20:V20,"P") -> 9 | X20: =COUNTIF(F20:V20,"A") -> 3 | Y20: Detail | Z20: Boys | AA20: Girls | AB20: Total
A21: 17 | C21: Hooriya | D21: Sajid Jamali | E21: ECE ROSE | F21: P | G21: P | I21: P | J21: P | K21: P | L21: P | M21: P | P21: P | Q21: P | R21: P | T21: P | U21: P | W21: =COUNTIF(F21:V21,"P") -> 12 | X21: =COUNTIF(F21:V21,"A") -> 0 | Y21: Due Present days | Z21: =29*$Z$5 -> 348 | AA21: =25*$Z$5 -> 300 | AB21: =Z21+AA21 -> 648
A22: 18 | C22: Arwa Fatima | D22: Muhammad Bilawal | E22: ECE ROSE | F22: P | G22: P | I22: P | J22: P | K22: P | L22: P | M22: P | P22: P | Q22: P | R22: P | T22: P | U22: P | W22: =COUNTIF(F22:V22,"P") -> 12 | X22: =COUNTIF(F22:V22,"A") -> 0 | Y22: Absent days | Z22: =Z21-Z14 -> 315 | AA22: =AA21-AA14 -> 36 | AB22: =Z22+AA22 -> 351
A23: 19 | C23: Muhammad Siddiq | D23: Ghulam Nabi | E23: ECE ROSE | F23: A | G23: P | I23: P | J23: P | K23: A | L23: P | M23: P | P23: P | Q23: P | R23: P | T23: P | U23: P | W23: =COUNTIF(F23:V23,"P") -> 10 | X23: =COUNTIF(F23:V23,"A") -> 2 | Y23: % | Z23: =Z22/Z21 -> 0.90517241 | AA23: =AA22/AA21 -> 0.12 | AB23: =AB22/AB21 -> 0.54166667
A24: 20 | C24: Waseem | D24: Abdul Sattar | E24: ECE ROSE | F24: P | G24: P | I24: P | J24: P | K24: P | L24: P | M24: P | P24: P | Q24: P | R24: P | T24: P | U24: P | W24: =COUNTIF(F24:V24,"P") -> 12 | X24: =COUNTIF(F24:V24,"A") -> 0
A25: 21 | C25: Ariyan | D25: Aman Badshah | E25: ECE ROSE | F25: P | G25: A | I25: P | J25: P | K25: P | L25: P | M25: P | P25: P | Q25: P | R25: P | T25: P | U25: P | W25: =COUNTIF(F25:V25,"P") -> 11 | X25: =COUNTIF(F25:V25,"A") -> 1
A26: 22 | C26: Inaya Fatima | D26: Ijaz Ahmed | E26: ECE ROSE | F26: P | G26: P | I26: P | J26: P | K26: P | L26: A | M26: P | P26: P | Q26: P | R26: P | T26: P | U26: P | W26: =COUNTIF(F26:V26,"P") -> 11 | X26: =COUNTIF(F26:V26,"A") -> 1
A27: 23 | C27: Aqib | E27: ECE ROSE | F27: P | G27: A | I27: P | J27: P | K27: P | L27: P | M27: P | P27: P | Q27: P | R27: P | T27: P | U27: P | W27: =COUNTIF(F27:V27,"P") -> 11 | X27: =COUNTIF(F27:V27,"A") -> 1
A28: 24 | C28: Ariyan | D28: Ismail | E28: ECE ROSE | F28: P | G28: P | I28: P | J28: P | K28: P | L28: P | M28: P | P28: P | Q28: P | R28: A | T28: P | U28: P | W28: =COUNTIF(F28:V28,"P") -> 11 | X28: =COUNTIF(F28:V28,"A") -> 1
A29: 25 | C29: Zainab Haneef | D29: Haneef Qadir | E29: ECE ROSE | F29: P | G29: P | I29: P | J29: P | K29: A | L29: P | M29: P | P29: P | Q29: P | R29: P | T29: P | U29: P | W29: =COUNTIF(F29:V29,"P") -> 11 | X29: =COUNTIF(F29:V29,"A") -> 1
A30: 26 | C30: Zainab | D30: Muhammad Ameen | E30: ECE ROSE | F30: A | G30: P | I30: P | J30: P | K30: P | L30: P | M30: P | P30: P | Q30: P | R30: P | T30: P | U30: P | W30: =COUNTIF(F30:V30,"P") -> 11 | X30: =COUNTIF(F30:V30,"A") -> 1
A31: 27 | C31: Zara Fatima | E31: ECE ROSE | F31: P | G31: P | I31: P | J31: P | K31: P | L31: P | M31: A | P31: P | Q31: P | R31: P | T31: P | U31: P | W31: =COUNTIF(F31:V31,"P") -> 11 | X31: =COUNTIF(F31:V31,"A") -> 1

Sheet ECE (Daffodils)
A1: Goverment high school (SJCHS)
A2: Monthly Attendence Month of AUGUST-2025
A3: S.No | B3: GR | C3: Student Name | D3: Father Name | E3: Class | F3: =TEXT(F4,"ddd") -> Fri | G3: =TEXT(G4,"ddd") -> Sat | H3: =TEXT(H4,"ddd") -> Sun | I3: =TEXT(I4,"ddd") -> Mon | J3: =TEXT(J4,"ddd") -> Tue | K3: =TEXT(K4,"ddd") -> Wed | L3: =TEXT(L4,"ddd") -> Thu | M3: =TEXT(M4,"ddd") -> Fri | ... V3: =TEXT(V4,"ddd") -> Sun | W3: Present | X3: Absent | Y3: Year 2024
F4: 45870 | G4: 45871 | H4: 45872 | I4: 45873 | J4: 45874 | K4: 45875 | L4: 45876 | M4: 45877 | N4: 45878 | O4: 45879 | P4: 45880 | Q4: 45881 | R4: 45882 | S4: 45883 | T4: 45884 | U4: 45885 | V4: 45886 | Y4: Total days | Z4: =SUM(Z5:Z8) -> 17
A5: 1 | B5: 112 | C5: Eman | D5: Shahnawaz Khan | E5: ECE | F5: A | G5: P | H5: SUNDAY - SUNDAY - SUNDAY - SUNDAY - SUNDAY - SUNDAY | I5: P | J5: P | K5: P | L5: P | M5: P | N5: URS SHAH ABDUL LATIF BITHAI | O5: SUNDAY - SUNDAY - SUNDAY - SUNDAY - SUNDAY - SUNDAY | P5: P | Q5: P | R5: P | S5: INDEPENDENCE DAY | T5: P | U5: P | V5: SUNDAY - SUNDAY - SUNDAY - SUNDAY - SUNDAY - SUNDAY | W5: =COUNTIF(F5:V5,"P") -> 11 | X5: =COUNTIF(F5:V5,"A") -> 1 | Y5: Working days | Z5: 12
A6: 2 | B6: 135 | C6: Masooma | D6: Faiq Ali | E6: ECE | F6: P | G6: P | I6: P | J6: A | K6: P | L6: P | M6: P | P6: P | Q6: P | R6: P | T6: P | U6: P | W6: =COUNTIF(F6:V6,"P") -> 11 | X6: =COUNTIF(F6:V6,"A") -> 1 | Y6: Sunday | Z6: 3
A7: 3 | B7: 137 | C7: Hafsa Batool | D7: Gul Mohammad Chandio | E7: ECE | F7: P | G7: A | I7: P | J7: P | K7: P | L7: P | M7: P | P7: P | Q7: P | R7: A | T7: P | U7: P | W7: =COUNTIF(F7:V7,"P") -> 10 | X7: =COUNTIF(F7:V7,"A") -> 2 | Y7: Off days | Z7: 2
A8: 4 | B8: 173 | C8: Hoor Fatima | D8: Shahid Ali | E8: ECE | F8: P | G8: P | I8: P | J8: P | K8: P | L8: P | M8: P | P8: P | Q8: P | R8: P | T8: A | U8: P | W8: =COUNTIF(F8:V8,"P") -> 11 | X8: =COUNTIF(F8:V8,"A") -> 1
A9: 5 | B9: 143 | C9: Kinza | D9: Aijaz Ali | E9: ECE | F9: A | G9: P | I9: P | J9: P | K9: A | L9: P | M9: P | P9: P | Q9: P | R9: P | T9: P | U9: P | W9: =COUNTIF(F9:V9,"P") -> 10 | X9: =COUNTIF(F9:V9,"A") -> 2
A10: 6 | B10: 146 | C10: Fatima Ansari | D10: Ayaz Ali Ansari | E10: ECE | F10: A | G10: P | I10: P | J10: P | K10: P | L10: P | M10: P | P10: A | Q10: P | R10: P | T10: P | U10: P | W10: =COUNTIF(F10:V10,"P") -> 10 | X10: =COUNTIF(F10:V10,"A") -> 2
A11: 7 | B11: 148 | C11: Zil-e-Huma | D11: Abdul Qayoom | E11: ECE | F11: P | G11: P | I11: P | J11: P | K11: P | L11: P | M11: P | P11: P | Q11: P | R11: P | T11: P | U11: P | W11: =COUNTIF(F11:V11,"P") -> 12 | X11: =COUNTIF(F11:V11,"A") -> 0 | Y11: Present Days Detail
A12: 8 | B12: 150 | C12: Ayat Fatima | D12: Imran Hussain | E12: ECE | F12: P | G12: P | I12: P | J12: P | K12: P | L12: P | M12: P | P12: P | Q12: P | R12: P | T12: P | U12: P | W12: =COUNTIF(F12:V12,"P") -> 12 | X12: =COUNTIF(F12:V12,"A") -> 0 | Y12: Detail | Z12: Boys | AA12: Girls | AB12: Total
A13: 9 | B13: 151 | C13: Aqsa | D13: Ahsan Ali | E13: ECE | F13: A | G13: P | I13: P | J13: P | K13: P | L13: A | M13: P | P13: P | Q13: A | R13: P | T13: P | U13: P | W13: =COUNTIF(F13:V13,"P") -> 9 | X13: =COUNTIF(F13:V13,"A") -> 3 | Y13: Due Present days | Z13: =29*$Z$5 -> 348 | AA13: =25*$Z$5 -> 300 | AB13: =SUM(Z13:AA13) -> 648
A14: 10 | B14: 160 | C14: Safa | D14: Dil Murad | E14: ECE | F14: P | G14: P | I14: P | J14: P | K14: P | L14: P | M14: P | P14: P | Q14: P | R14: P | T14: A | U14: P | W14: =COUNTIF(F14:V14,"P") -> 11 | X14: =COUNTIF(F14:V14,"A") -> 1 | Y14: Actual present days | Z14: =SUM(W29:W57) -> 324 | AA14: =SUM(W5:W28) -> 260 | AB14: =Z14+AA14 -> 584
A15: 11 | B15: 161 | C15: Hifza | D15: Zakir Ali | E15: ECE | F15: P | G15: P | I15: P | J15: P | K15: P | L15: P | M15: P | P15: P | Q15: P | R15: P | T15: P | U15: P | W15: =COUNTIF(F15:V15,"P") -> 12 | X15: =COUNTIF(F15:V15,"A") -> 0 | Y15: % | Z15: =Z14/Z13 -> 0.93103448 | AA15: =AA14/AA13 -> 0.86666667 | AB15: =AB14/AB13 -> 0.90123457
A16: 12 | B16: 162 | C16: Zameeran | D16: Babar Ali | E16: ECE | F16: P | G16: A | I16: P | J16: P | K16: P | L16: P | M16: P | P16: P | Q16: P | R16: A | T16: P | U16: P | W16: =COUNTIF(F16:V16,"P") -> 10 | X16: =COUNTIF(F16:V16,"A") -> 2
A17: 13 | B17: 163 | C17: Parwisha | D17: Sarfaraz Ahmed | E17: ECE | F17: P | G17: P | I17: P | J17: P | K17: A | L17: P | M17: P | P17: P | Q17: P | R17: P | T17: P | U17: P | W17: =COUNTIF(F17:V17,"P") -> 11 | X17: =COUNTIF(F17:V17,"A") -> 1
A18: 14 | B18: 166 | C18: Aiza | D18: Irshad-Ul-Haq | E18: ECE | F18: P | G18: P | I18: P | J18: P | K18: P | L18: P | M18: P | P18: P | Q18: P | R18: P | T18: P | U18: P | W18: =COUNTIF(F18:V18,"P") -> 12 | X18: =COUNTIF(F18:V18,"A") -> 0
A19: 15 | B19: 168 | C19: Shazia | D19: Rashid Ali | E19: ECE | F19: A | G19: P | I19: P | J19: P | K19: P | L19: P | M19: P | P19: A | Q19: P | R19: P | T19: P | U19: P | W19: =COUNTIF(F19:V19,"P") -> 10 | X19: =COUNTIF(F19:V19,"A") -> 2 | Y19: Absent Days Details
A20: 16 | B20: 170 | C20: Ume Farwa | D20: Meer Ameer-u-Din | E20: ECE | F20: P | G20: P | I20: P | J20: P | K20: P | L20: A | M20: P | P20: P | Q20: P | R20: P | T20: P | U20: P | W20: =COUNTIF(F20:V20,"P") -> 11 | X20: =COUNTIF(F20:V20,"A") -> 1 | Y20: Detail | Z20: Boys | AA20: Girls | AB20: Total
A21: 17 | B21: 171 | C21: Ume Rubab | D21: Mohsin Ali | E21: ECE | F21: P | G21: P | I21: P | J21: P | K21: P | L21: P | M21: P | P21: P | Q21: P | R21: P | T21: P | U21: P | W21: =COUNTIF(F21:V21,"P") -> 12 | X21: =COUNTIF(F21:V21,"A") -> 0 | Y21: Due Present days | Z21: =29*$Z$5 -> 348 | AA21: =25*$Z$5 -> 300 | AB21: =Z21+AA21 -> 648
A22: 18 | B22: 172 | C22: Khatija | D22: M. Afzal | E22: ECE | F22: P | G22: A | I22: P | J22: P | K22: P | L22: P | M22: P | P22: P | Q22: A | R22: P | T22: P | U22: P | W22: =COUNTIF(F22:V22,"P") -> 10 | X22: =COUNTIF(F22:V22,"A") -> 2 | Y22: Absent days | Z22: =Z21-Z14 -> 24 | AA22: =AA21-AA14 -> 40 | AB22: =Z22+AA22 -> 64
A23: 19 | B23: 180 | C23: Fiza | D23: Ahmed | E23: ECE | F23: P | G23: P | I23: P | J23: P | K23: A | L23: P | M23: P | P23: P | Q23: P | R23: P | T23: P | U23: P | W23: =COUNTIF(F23:V23,"P") -> 11 | X23: =COUNTIF(F23:V23,"A") -> 1 | Y23: % | Z23: =Z22/Z21 -> 0.068965517 | AA23: =AA22/AA21 -> 0.13333333 | AB23: =AB22/AB21 -> 0.098765432
A24: 20 | B24: 181 | C24: Eshaal | D24: M. Fahad | E24: ECE | F24: P | G24: P | I24: P | J24: A | K24: P | L24: P | M24: P | P24: P | Q24: P | R24: P | T24: P | U24: P | W24: =COUNTIF(F24:V24,"P") -> 11 | X24: =COUNTIF(F24:V24,"A") -> 1
A25: 21 | B25: 195 | C25: Rija Batool | D25: Ghulam Mehdi | E25: ECE | F25: A | G25: P | I25: P | J25: P | K25: P | L25: P | M25: A | P25: P | Q25: P | R25: P | T25: P | U25: P | W25: =COUNTIF(F25:V25,"P") -> 10 | X25: =COUNTIF(F25:V25,"A") -> 2
A26: 22 | B26: 183 | C26: Mustirah | D26: Faisal | E26: ECE | F26: P | G26: P | I26: P | J26: P | K26: P | L26: A | M26: P | P26: P | Q26: A | R26: P | T26: P | U26: A | W26: =COUNTIF(F26:V26,"P") -> 9 | X26: =COUNTIF(F26:V26,"A") -> 3
A27: 23 | B27: 170 | C27: Hoorain Noor | D27: Muhammad Akram | E27: ECE | F27: P | G27: P | I27: P | J27: P | K27: P | L27: P | M27: P | P27: P | Q27: P | R27: P | T27: P | U27: P | W27: =COUNTIF(F27:V27,"P") -> 12 | X27: =COUNTIF(F27:V27,"A") -> 0
A28: 1 | B28: 189 | C28: Zakria | D28: Iqramudin | E28: ECE | F28: P | G28: P | I28: P | J28: P | K28: P | L28: P | M28: P | P28: P | Q28: P | R28: P | T28: P | U28: P | W28: =COUNTIF(F28:V28,"P") -> 12 | X28: =COUNTIF(F28:V28,"A") -> 0
A29: 2 | B29: 99 | C29: Rehan Ali | D29: Abdul Rehman | E29: ECE | F29: A | G29: P | I29: P | J29: P | K29: P | L29: P | M29: P | P29: P | Q29: P | R29: P | T29: P | U29: P | W29: =COUNTIF(F29:V29,"P") -> 11 | X29: =COUNTIF(F29:V29,"A") -> 1
A30: 3 | B30: 98 | C30: Dilkash | D30: Faraz Hussain | E30: ECE | F30: P | G30: P | I30: P | J30: A | K30: P | L30: P | M30: P | P30: P | Q30: A | R30: P | T30: P | U30: P | W30: =COUNTIF(F30:V30,"P") -> 10 | X30: =COUNTIF(F30:V30,"A") -> 2
A31: 4 | B31: 136 | C31: Ali | D31: Saddam Hussain | E31: ECE | F31: P | G31: P | I31: A | J31: P | K31: P | L31: P | M31: P | P31: P | Q31: P | R31: P | T31: P | U31: P | W31: =COUNTIF(F31:V31,"P") -> 11 | X31: =COUNTIF(F31:V31,"A") -> 1
A32: 5 | B32: 139 | C32: Mohammad Aliyan | D32: Shabir Ahmed Bhutto | E32: ECE | F32: P | G32: P | I32: P | J32: P | K32: P | L32: P | M32: P | P32: P | Q32: P | R32: P | T32: P | U32: P | W32: =COUNTIF(F32:V32,"P") -> 12 | X32: =COUNTIF(F32:V32,"A") -> 0
A33: 6 | B33: 142 | C33: Muhammad Sahil | D33: Irshad Ali | E33: ECE | F33: A | G33: P | I33: P | J33: P | K33: P | L33: A | M33: P | P33: P | Q33: P | R33: P | T33: P | U33: P | W33: =COUNTIF(F33:V33,"P") -> 10 | X33: =COUNTIF(F33:V33,"A") -> 2
A34: 7 | B34: 144 | C34: Zaryab Sultan | D34: Muhammad Zaman | E34: ECE | F34: P | G34: P | I34: P | J34: P | K34: P | L34: P | M34: P | P34: P | Q34: P | R34: P | T34: P | U34: P | W34: =COUNTIF(F34:V34,"P") -> 12 | X34: =COUNTIF(F34:V34,"A") -> 0
A35: 8 | B35: 145 | C35: M. Ibrahim | D35: Fayaz Ali Ansari | E35: ECE | F35: P | G35: P | I35: P | J35: P | K35: P | L35: P | M35: P | P35: P | Q35: P | R35: P | T35: A | U35: P | W35: =COUNTIF(F35:V35,"P") -> 11 | X35: =COUNTIF(F35:V35,"A") -> 1
... A47: 20 | B47: 197 | C47: M. Raheel | D47: masoor ali | E47: ECE | F47: P | G47: P | I47: P | J47: P | K47: P | L47: A | M47: P | P47: P | Q47: P | R47: P | T47: P | U47: P | W47: =COUNTIF(F47:V47,"P") -> 11 | X47: =COUNTIF(F47:V47,"A") -> 1
A48: 21 | B48: 182 | C48: Amanullah | D48: Sajid Ahmed | E48: ECE | F48: P | G48: P | I48: P | J48: P | K48: P | L48: P | M48: P | P48: P | Q48: P | R48: P | T48: P | U48: P | W48: =COUNTIF(F48:V48,"P") -> 12 | X48: =COUNTIF(F48:V48,"A") -> 0 | Y48: 6+
A49: 22 | B49: 186 | C49: Ahmed Ali | D49: Asghar Ali | E49: ECE | F49: P | G49: P | I49: P | J49: P | K49: P | L49: P | M49: P | P49: P | Q49: P | R49: P | T49: P | U49: P | W49: =COUNTIF(F49:V49,"P") -> 12 | X49: =COUNTIF(F49:V49,"A") -> 0
A50: 23 | B50: 188 | C50: M. Qasim | D50: Abdul Hameed | E50: ECE | F50: P | G50: P | I50: P | J50: P | K50: A | L50: P | M50: P | P50: P | Q50: P | R50: P | T50: A | U50: P | W50: =COUNTIF(F50:V50,"P") -> 10 | X50: =COUNTIF(F50:V50,"A") -> 2
A51: 24 | B51: 184 | C51: Saifullah | D51: Farooq Ali | E51: ECE | F51: P | G51: P | I51: P | J51: P | K51: P | L51: P | M51: P | P51: P | Q51: P | R51: P | T51: P | U51: P | W51: =COUNTIF(F51:V51,"P") -> 12 | X51: =COUNTIF(F51:V51,"A") -> 0
...

Sheet Class-1
A1: Goverment high school (SJCHS)
A2: Monthly Attendence Month of MAY-2025
A3: S.No | B3: GR | C3: Student Name | D3: Father Name | E3: Class | F3: =TEXT(F4,"ddd") -> Fri | G3: =TEXT(G4,"ddd") -> Sat | H3: =TEXT(H4,"ddd") -> Sun | I3: =TEXT(I4,"ddd") -> Mon | J3: =TEXT(J4,"ddd") -> Tue | K3: =TEXT(K4,"ddd") -> Wed | L3: =TEXT(L4,"ddd") -> Thu | M3: =TEXT(M4,"ddd") -> Fri | ... W3: =TEXT(W4,"ddd") -> Mon | X3: Present | Y3: Absent | Z3: Year 2024
F4: 45870 | G4: 45871 | H4: 45872 | I4: 45873 | J4: 45874 | K4: 45875 | L4: 45876 | M4: 45877 | N4: 45878 | O4: 45879 | P4: 45880 | Q4: 45881 | R4: 45882 | S4: 45883 | T4: 45884 | U4: 45885 | V4: 45886 | W4: 45887 | Z4: Total days | AA4: =SUM(AA5:AA8) -> 30
A5: 1 | B5: 106 | C5: Alishba Batool | D5: Irfan Ali | E5: ONE | F5: A | G5: A | H5: Sunday Sunday Sunday Sunday | I5: P | J5: P | K5: P | L5: P | M5: P | N5: URS SHAH ABDUL LATIF BITHAI | O5: Sunday Sunday Sunday Sunday | P5: P | Q5: P | R5: P | S5: INDEPENDENCE DAY | T5: P | U5: P | V5: Sunday Sunday Sunday Sunday | W5: A | X5: =COUNTIF(F5:W5,"P") -> 10 | Y5: =COUNTIF(F5:W5,"A") -> 3 | Z5: Working days | AA5: 26
A6: 2 | B6: 75 | C6: Amna | D6: Imtiaz Hussain | E6: ONE | F6: P | G6: P | I6: A | J6: P | K6: P | L6: P | M6: A | P6: P | Q6: P | R6: P | T6: P | U6: P | W6: P | X6: =COUNTIF(F6:W6,"P") -> 11 | Y6: =COUNTIF(F6:W6,"A") -> 2 | Z6: Sunday | AA6: 4
A7: 3 | B7: 109 | C7: Aniza Memon | D7: M. Qasim | E7: ONE | F7: A | G7: P | I7: P | J7: P | K7: P | L7: P | M7: P | P7: P | Q7: P | R7: P | T7: P | U7: P | W7: P | X7: =COUNTIF(F7:W7,"P") -> 12 | Y7: =COUNTIF(F7:W7,"A") -> 1
A8: 4 | B8: 49 | C8: Areeba | D8: Altaf Hussain | E8: ONE | F8: A | G8: A | I8: P | J8: P | K8: P | L8: P | M8: P | P8: P | Q8: A | R8: P | T8: P | U8: P | W8: P | X8: =COUNTIF(F8:W8,"P") -> 10 | Y8: =COUNTIF(F8:W8,"A") -> 3
A9: 5 | B9: 104 | C9: Batool | D9: Amjad Ali | E9: ONE | F9: A | G9: A | I9: P | J9: A | K9: P | L9: P | M9: P | P9: P | Q9: P | R9: P | T9: P | U9: P | W9: P | X9: =COUNTIF(F9:W9,"P") -> 10 | Y9: =COUNTIF(F9:W9,"A") -> 3
A10: 6 | B10: 88 | C10: Dua | D10: Khalid Hussain | E10: ONE | F10: P | G10: A | I10: P | J10: P | K10: P | L10: P | M10: P | P10: P | Q10: P | R10: P | T10: A | U10: P | W10: P | X10: =COUNTIF(F10:W10,"P") -> 11 | Y10: =COUNTIF(F10:W10,"A") -> 2
A11: 7 | B11: 59 | C11: Faiza | D11: Liaqat Ali | E11: ONE | F11: A | G11: A | I11: P | J11: P | K11: P | L11: P | M11: A | P11: P | Q11: P | R11: P | T11: P | U11: P | W11: P | X11: =COUNTIF(F11:W11,"P") -> 10 | Y11: =COUNTIF(F11:W11,"A") -> 3 | Z11: Present Days Detail
A12: 8 | B12: 83 | C12: Fatima | D12: Aziz-ur-Rehman | E12: ONE | F12: A | G12: A | I12: P | J12: P | K12: P | L12: P | M12: P | P12: P | Q12: P | R12: P | T12: P | U12: P | W12: P | X12: =COUNTIF(F12:W12,"P") -> 11 | Y12: =COUNTIF(F12:W12,"A") -> 2 | Z12: Detail | AA12: Boys | AB12: Girls | AC12: Total
A13: 9 | B13: 89 | C13: Hafsa | D13: Hafeezullah | E13: ONE | F13: A | G13: A | I13: P | J13: P | K13: A | L13: P | M13: P | P13: P | Q13: P | R13: P | T13: P | U13: P | W13: P | X13: =COUNTIF(F13:W13,"P") -> 10 | Y13: =COUNTIF(F13:W13,"A") -> 3 | Z13: Due Present days | AA13: =32*$AA$5 -> 832 | AB13: =24*$AA$5 -> 624 | AC13: =SUM(AA13:AB13) -> 1456
A14: 10 | B14: 86 | C14: Insha Arzoo | D14: Meeral | E14: ONE | F14: A | G14: A | I14: P | J14: P | K14: P | L14: P | M14: P | P14: P | Q14: A | R14: P | T14: P | U14: P | W14: A | X14: =COUNTIF(F14:W14,"P") -> 9 | Y14: =COUNTIF(F14:W14,"A") -> 4 | Z14: Actual present days | AA14: =SUM(X31:X61) -> 317 | AB14: =SUM(X5:X30) -> 270 | AC14: =AA14+AB14 -> 587
A15: 11 | B15: 105 | C15: Kauser Fatima | D15: Amir Jamil | E15: ONE | F15: A | G15: A | I15: P | J15: P | K15: P | L15: P | M15: P | P15: A | Q15: P | R15: P | T15: P | U15: P | W15: P | X15: =COUNTIF(F15:W15,"P") -> 10 | Y15: =COUNTIF(F15:W15,"A") -> 3 | Z15: % | AA15: =AA14/AA13 -> 0.38100962 | AB15: =AB14/AB13 -> 0.43269231 | AC15: =AC14/AC13 -> 0.40315934
A16: 12 | B16: 84 | C16: Minha | D16: M. Luqman | E16: ONE | F16: A | G16: P | I16: P | J16: A | K16: P | L16: P | M16: P | P16: P | Q16: P | R16: P | T16: P | U16: P | W16: P | X16: =COUNTIF(F16:W16,"P") -> 11 | Y16: =COUNTIF(F16:W16,"A") -> 2
A17: 13 | B17: 85 | C17: Misbah Bhutto | D17: M. Azeem | E17: ONE | F17: A | G17: A | I17: P | J17: P | K17: P | L17: P | M17: A | P17: P | Q17: P | R17: A | T17: P | U17: P | W17: P | X17: =COUNTIF(F17:W17,"P") -> 9 | Y17: =COUNTIF(F17:W17,"A") -> 4
A18: 14 | B18: 102 | C18: Rimsha | D18: Meer Ameer-ud-Din | E18: ONE | F18: P | G18: A | I18: P | J18: P | K18: P | L18: P | M18: P | P18: P | Q18: P | R18: P | T18: P | U18: A | W18: P | X18: =COUNTIF(F18:W18,"P") -> 11 | Y18: =COUNTIF(F18:W18,"A") -> 2
A19: 15 | B19: 87 | C19: Sidra Batool | D19: Muhammad Khan | E19: ONE | F19: A | G19: A | I19: P | J19: P | K19: P | L19: P | M19: P | P19: P | Q19: P | R19: P | T19: P | U19: P | W19: P | X19: =COUNTIF(F19:W19,"P") -> 11 | Y19: =COUNTIF(F19:W19,"A") -> 2 | Z19: Absent Days Details
A20: 16 | B20: 71 | C20: Sidra | D20: Khalid Hussain | E20: ONE | F20: A | G20: A | I20: P | J20: P | K20: A | L20: P | M20: P | P20: P | Q20: A | R20: P | T20: P | U20: P | W20: A | X20: =COUNTIF(F20:W20,"P") -> 8 | Y20: =COUNTIF(F20:W20,"A") -> 5 | Z20: Detail | AA20: Boys | AB20: Girls | AC20: Total
A21: 17 | B21: 81 | C21: Taniya Bibi | D21: Wazir Ali | E21: ONE | F21: P | G21: A | I21: P | J21: P | K21: P | L21: P | M21: P | P21: P | Q21: P | R21: P | T21: P | U21: P | W21: P | X21: =COUNTIF(F21:W21,"P") -> 12 | Y21: =COUNTIF(F21:W21,"A") -> 1 | Z21: Due Present days | AA21: =32*$AA$5 -> 832 | AB21: =24*$AA$5 -> 624 | AC21: =AA21+AB21 -> 1456
A22: 18 | B22: 82 | C22: Tanzeela | D22: Hizbullah | E22: ONE | F22: A | G22: A | I22: P | J22: P | K22: P | L22: P | M22: P | P22: P | Q22: P | R22: P | T22: P | U22: P | W22: P | X22: =COUNTIF(F22:W22,"P") -> 11 | Y22: =COUNTIF(F22:W22,"A") -> 2 | Z22: Absent days | AA22: =AA21-AA14 -> 515 | AB22: =AB21-AB14 -> 354 | AC22: =AA22+AB22 -> 869
A23: 19 | B23: 68 | C23: Tayaba Fatima | D23: Waseem Ahmed | E23: ONE | F23: A | G23: P | I23: P | J23: P | K23: P | L23: A | M23: P | P23: A | Q23: P | R23: P | T23: P | U23: P | W23: P | X23: =COUNTIF(F23:W23,"P") -> 10 | Y23: =COUNTIF(F23:W23,"A") -> 3 | Z23: % | AA23: =AA22/AA21 -> 0.61899038 | AB23: =AB22/AB21 -> 0.56730769 | AC23: =AC22/AC21 -> 0.59684066
A24: 20 | B24: 69 | C24: Tooba Noor | D24: M. Shareef | E24: ONE | F24: A | G24: A | I24: P | J24: P | K24: P | L24: P | M24: P | P24: P | Q24: P | R24: P | T24: P | U24: A | W24: P | X24: =COUNTIF(F24:W24,"P") -> 10 | Y24: =COUNTIF(F24:W24,"A") -> 3
A25: 21 | B25: 70 | C25: Umm-e-Kulsoom | D25: Shah Ali | E25: ONE | F25: A | G25: A | I25: P | J25: P | K25: P | L25: P | M25: P | P25: P | Q25: P | R25: P | T25: P | U25: P | W25: P | X25: 14 | Y25: =COUNTIF(F25:W25,"A") -> 2
A26: 22 | B26: 103 | C26: Zunaira | D26: Amjad Ali | E26: ONE | F26: A | G26: A | I26: P | J26: A | K26: P | L26: P | M26: P | P26: P | Q26: P | R26: P | T26: P | U26: P | W26: A | X26: =COUNTIF(F26:W26,"P") -> 9 | Y26: =COUNTIF(F26:W26,"A") -> 4
A27: 23 | B27: 149 | C27: Sahib Khatoon | D27: A. Qayoom | E27: ONE | F27: A | G27: A | I27: P | J27: P | K27: P | L27: P | M27: P | P27: P | Q27: P | R27: P | T27: P | U27: P | W27: P | X27: =COUNTIF(F27:W27,"P") -> 11 | Y27: =COUNTIF(F27:W27,"A") -> 2
A28: 24 | B28: 107 | C28: Mehrunisa | D28: Aijaz Ali | E28: ONE | F28: A | G28: A | I28: P | J28: P | K28: A | L28: P | M28: P | P28: P | Q28: A | R28: P | T28: P | U28: P | W28: A | X28: =COUNTIF(F28:W28,"P") -> 8 | Y28: =COUNTIF(F28:W28,"A") -> 5
A29: 25 | C29: Anusha | E29: ONE | F29: A | G29: A | I29: P | J29: P | K29: P | L29: P | M29: P | P29: P | Q29: P | R29: P | T29: A | U29: P | W29: P | X29: =COUNTIF(F29:W29,"P") -> 10 | Y29: =COUNTIF(F29:W29,"A") -> 3
A30: 26 | B30: 169 | C30: Parsa Batool | D30: Imran Ali | E30: ONE | F30: A | G30: A | I30: P | J30: P | K30: P | L30: P | M30: P | P30: P | Q30: P | R30: P | T30: P | U30: P | W30: P | X30: =COUNTIF(F30:W30,"P") -> 11 | Y30: =COUNTIF(F30:W30,"A") -> 2
A31: 1 | B31: 61 | C31: Abrar | D31: Jan Muhammad | E31: ONE | F31: P | G31: A | I31: P | J31: P | K31: A | L31: P | M31: P | P31: P | Q31: P | R31: P | T31: P | U31: P | W31: P | X31: =COUNTIF(F31:W31,"P") -> 11 | Y31: =COUNTIF(F31:W31,"A") -> 2
A32: 2 | B32: 79 | C32: Azan Shafeeque | D32: M. Shafeeque | E32: ONE | F32: A | G32: A | I32: P | J32: P | K32: P | L32: P | M32: P | P32: A | Q32: P | R32: P | T32: P | U32: P | W32: P | X32: =COUNTIF(F32:W32,"P") -> 10 | Y32: =COUNTIF(F32:W32,"A") -> 3
A33: 3 | B33: 16 | C33: Azan Fayaz | D33: Fayaz Hussain | E33: ONE | F33: A | G33: P | I33: A | J33: P | K33: P | L33: P | M33: P | P33: P | Q33: P | R33: P | T33: P | U33: P | W33: P | X33: =COUNTIF(F33:W33,"P") -> 11 | Y33: =COUNTIF(F33:W33,"A") -> 2
A34: 4 | B34: 78 | C34: Adil Ahmed | D34: Faiz Muhammad | E34: ONE | F34: A | G34: A | I34: P | J34: P | K34: P | L34: A | M34: P | P34: P | Q34: P | R34: P | T34: P | U34: A | W34: P | X34: =COUNTIF(F34:W34,"P") -> 9 | Y34: =COUNTIF(F34:W34,"A") -> 4
A35: 5 | B35: 76 | C35: Ab. Qudoos | D35: Sikandar | E35: ONE | F35: A | G35: A | I35: P | J35: P | K35: P | L35: P | M35: P | P35: P | Q35: P | R35: A | T35: P | U35: P | W35: A | X35: =COUNTIF(F35:W35,"P") -> 9 | Y35: =COUNTIF(F35:W35,"A") -> 4
A36: 6 | B36: 108 | C36: Arham | D36: Qasim Memon | E36: ONE | F36: A | G36: A | I36: P | J36: P | K36: P | L36: P | M36: P | P36: P | Q36: P | R36: P | T36: P | U36: P | W36: P | X36: =COUNTIF(F36:W36,"P") -> 11 | Y36: =COUNTIF(F36:W36,"A") -> 2
A37: 7 | B37: 131 | C37: Amar Farooque | D37: M. Farooque | E37: ONE | F37: A | G37: A | I37: P | J37: P | K37: A | L37: P | M37: P | P37: P | Q37: P | R37: P | T37: P | U37: P | W37: P | X37: =COUNTIF(F37:W37,"P") -> 10 | Y37: =COUNTIF(F37:W37,"A") -> 3
A38: 8 | B38: 101 | C38: Ashfaque | D38: M. Zubair | E38: ONE | F38: A | G38: A | I38: P | J38: P | K38: P | L38: P | M38: P | P38: P | Q38: A | R38: P | T38: P | U38: P | W38: P | X38: =COUNTIF(F38:W38,"P") -> 10 | Y38: =COUNTIF(F38:W38,"A") -> 3
A39: 9 | B39: 100 | C39: Fahad | D39: M. Maroof | E39: ONE | F39: A | G39: A | I39: P | J39: P | K39: P | L39: P | M39: P | P39: P | Q39: P | R39: P | T39: A | U39: P | W39: P | X39: =COUNTIF(F39:W39,"P") -> 10 | Y39: =COUNTIF(F39:W39,"A") -> 3
A40: 10 | B40: 90 | C40: Hussain | D40: Hafeezullah | E40: ONE | F40: A | G40: A | I40: P | J40: A | K40: P | L40: P | M40: P | P40: A | Q40: P | R40: P | T40: P | U40: P | W40: P | X40: =COUNTIF(F40:W40,"P") -> 9 | Y40: =COUNTIF(F40:W40,"A") -> 4
...

Sheet Class-2
A1: Goverment high school (SJCHS)
A2: Monthly Attendence Month of MAY-2025
A3: S.No | B3: GR | C3: Student Name | D3: Father Name | E3: Class | F3: =TEXT(F4,"ddd") -> Fri | G3: =TEXT(G4,"ddd") -> Sat | H3: =TEXT(H4,"ddd") -> Sun | I3: =TEXT(I4,"ddd") -> Mon | J3: =TEXT(J4,"ddd") -> Tue | K3: =TEXT(K4,"ddd") -> Wed | L3: =TEXT(L4,"ddd") -> Thu | M3: =TEXT(M4,"ddd") -> Fri | ... V3: =TEXT(V4,"ddd") -> Sun | W3: Present | X3: Absent | Y3: Year 2024
F4: 45870 | G4: 45871 | H4: 45872 | I4: 45873 | J4: 45874 | K4: 45875 | L4: 45876 | M4: 45877 | N4: 45878 | O4: 45879 | P4: 45880 | Q4: 45881 | R4: 45882 | S4: 45883 | T4: 45884 | U4: 45885 | V4: 45886 | Y4: Total days | Z4: =SUM(Z5:Z8) -> 30
A5: 1 | B5: 815 | C5: Anum | D5: M. Arif | E5: TWO | F5: P | G5: P | H5: Sunday Sunday Sunday sunday | I5: P | J5: P | K5: P | L5: P | M5: P | N5: URS SHAH ABDUL LATIF BITHAI | O5: Sunday Sunday Sunday sunday | P5: A | Q5: P | R5: P | S5: INDEPENDENCE DAY | T5: P | U5: P | V5: Sunday Sunday Sunday sunday | W5: =COUNTIF(F5:V5,"P") -> 11 | X5: =COUNTIF(F5:V5,"A") -> 1 | Y5: Working days | Z5: 26
A6: 2 | B6: 819 | C6: Amna | D6: Saeed Ahmed | E6: TWO | F6: A | G6: P | I6: A | J6: P | K6: P | L6: P | M6: P | P6: P | Q6: P | R6: P | T6: A | U6: P | W6: =COUNTIF(F6:V6,"P") -> 9 | X6: =COUNTIF(F6:V6,"A") -> 3 | Y6: Sunday | Z6: 4
A7: 3 | B7: 812 | C7: Adeeba | D7: Qurban Ali | E7: TWO | F7: P | G7: P | I7: P | J7: P | K7: P | L7: P | M7: P | P7: P | Q7: P | R7: P | T7: P | U7: P | W7: =COUNTIF(F7:V7,"P") -> 12 | X7: =COUNTIF(F7:V7,"A") -> 0
A8: 4 | B8: 801 | C8: Emaan Noor | D8: Noor Mohammad | E8: TWO | F8: P | G8: P | I8: P | J8: P | K8: A | L8: P | M8: P | P8: P | Q8: P | R8: P | T8: P | U8: P | W8: =COUNTIF(F8:V8,"P") -> 11 | X8: =COUNTIF(F8:V8,"A") -> 1
A9: 5 | B9: 828 | C9: Horain | D9: Saeed Ahmed | E9: TWO | F9: A | G9: P | I9: P | J9: P | K9: P | L9: P | M9: P | P9: P | Q9: P | R9: P | T9: P | U9: A | W9: =COUNTIF(F9:V9,"P") -> 10 | X9: =COUNTIF(F9:V9,"A") -> 2
A10: 6 | B10: 829 | C10: Hannah | D10: Luqman Ali | E10: TWO | F10: P | G10: P | I10: P | J10: P | K10: P | L10: P | M10: P | P10: A | Q10: P | R10: A | T10: P | U10: P | W10: =COUNTIF(F10:V10,"P") -> 10 | X10: =COUNTIF(F10:V10,"A") -> 2
A11: 7 | B11: 817 | C11: Hareem Fatima | D11: Deedar Ali | E11: TWO | F11: P | G11: P | I11: P | J11: P | K11: P | L11: P | M11: P | P11: P | Q11: P | R11: P | T11: P | U11: P | W11: =COUNTIF(F11:V11,"P") -> 12 | X11: =COUNTIF(F11:V11,"A") -> 0 | Y11: Detail | Z11: Boys | AA11: Girls | AB11: Total
A12: 8 | B12: 807 | C12: Maham Noor | D12: Zaheer Abbas | E12: TWO | F12: P | G12: P | I12: P | J12: P | K12: P | L12: P | M12: P | P12: P | Q12: P | R12: P | T12: P | U12: P | W12: =COUNTIF(F12:V12,"P") -> 12 | X12: =COUNTIF(F12:V12,"A") -> 0 | Y12: Due Present days | Z12: =32*$Z$5 -> 832 | AA12: =24*$Z$5 -> 624 | AB12: =SUM(Z12:AA12) -> 1456
A13: 9 | B13: 827 | C13: Maria | D13: Mehboob Ali | E13: TWO | F13: P | G13: P | I13: P | J13: P | K13: P | L13: P | M13: P | P13: P | Q13: P | R13: P | T13: A | U13: P | W13: =COUNTIF(F13:V13,"P") -> 11 | X13: =COUNTIF(F13:V13,"A") -> 1 | Y13: Actual present days | Z13: =SUM(W25:W54) -> 337 | AA13: =SUM(W5:W24) -> 221 | AB13: =Z13+AA13 -> 558
A14: 10 | B14: 802 | C14: Mehreen | D14: M. Maroof | E14: TWO | F14: P | G14: P | I14: P | J14: P | K14: P | L14: P | M14: P | P14: P | Q14: P | R14: A | T14: P | U14: P | W14: =COUNTIF(F14:V14,"P") -> 11 | X14: =COUNTIF(F14:V14,"A") -> 1 | Y14: % | Z14: =Z13/Z12 -> 0.40504808 | AA14: =AA13/AA12 -> 0.35416667 | AB14: =AB13/AB12 -> 0.38324176
A15: 11 | C15: Mahira | D15: Arbab Ali | E15: TWO | F15: P | G15: A | I15: P | J15: P | K15: P | L15: P | M15: A | P15: P | Q15: P | R15: P | T15: P | U15: P | W15: =COUNTIF(F15:V15,"P") -> 10 | X15: =COUNTIF(F15:V15,"A") -> 2
A16: 12 | B16: 836 | C16: Meerab | D16: Yasir Ahmed | E16: TWO | F16: P | G16: P | I16: P | J16: P | K16: P | L16: P | M16: P | P16: P | Q16: P | R16: P | T16: P | U16: P | W16: =COUNTIF(F16:V16,"P") -> 12 | X16: =COUNTIF(F16:V16,"A") -> 0
A17: 13 | B17: 835 | C17: Qudsia Zehra | D17: Waheed Ali | E17: TWO | F17: P | G17: P | I17: P | J17: A | K17: P | L17: P | M17: P | P17: A | Q17: P | R17: P | T17: P | U17: P | W17: =COUNTIF(F17:V17,"P") -> 10 | X17: =COUNTIF(F17:V17,"A") -> 2
A18: 14 | C18: Paras | D18: Sadam | E18: TWO | F18: P | G18: P | I18: P | J18: P | K18: P | L18: P | M18: P | P18: P | Q18: P | R18: P | T18: P | U18: P | W18: =COUNTIF(F18:V18,"P") -> 12 | X18: =COUNTIF(F18:V18,"A") -> 0 | Y18: Absent Days Details
A19: 15 | B19: 892 | C19: Thamna Batool | D19: Shehzad | E19: TWO | F19: P | G19: P | I19: P | J19: P | K19: P | L19: P | M19: P | P19: P | Q19: P | R19: P | T19: P | U19: P | W19: =COUNTIF(F19:V19,"P") -> 12 | X19: =COUNTIF(F19:V19,"A") -> 0 | Y19: Detail | Z19: Boys | AA19: Girls | AB19: Total
A20: 16 | B20: 838 | C20: Tamana Fatima | D20: Shehzad | E20: TWO | F20: P | G20: P | I20: P | J20: P | K20: P | L20: P | M20: P | P20: P | Q20: P | R20: P | T20: P | U20: P | W20: =COUNTIF(F20:V20,"P") -> 12 | X20: =COUNTIF(F20:V20,"A") -> 0 | Y20: Due Present days | Z20: =32*$Z$5 -> 832 | AA20: =24*$Z$5 -> 624 | AB20: =Z20+AA20 -> 1456
A21: 17 | B21: 808 | C21: Haram | D21: Moien Khan | E21: TWO | F21: P | G21: P | I21: P | J21: P | K21: A | L21: P | M21: P | P21: P | Q21: A | R21: P | T21: P | U21: A | W21: =COUNTIF(F21:V21,"P") -> 9 | X21: =COUNTIF(F21:V21,"A") -> 3 | Y21: Absent days | Z21: =Z20-Z13 -> 495 | AA21: =AA20-AA13 -> 403 | AB21: =Z21+AA21 -> 898
A22: 18 | B22: 823 | C22: Zaiba Bakhtawar | D22: Hameed | E22: TWO | F22: P | G22: P | I22: P | J22: P | K22: P | L22: P | M22: P | P22: P | Q22: P | R22: P | T22: P | U22: P | W22: =COUNTIF(F22:V22,"P") -> 12 | X22: =COUNTIF(F22:V22,"A") -> 0
A23: 19 | B23: 793 | C23: Zainab | D23: A. Aziz | E23: TWO | F23: P | G23: P | I23: P | J23: P | K23: P | L23: P | M23: P | P23: P | Q23: P | R23: P | T23: P | U23: P | W23: =COUNTIF(F23:V23,"P") -> 12 | X23: =COUNTIF(F23:V23,"A") -> 0
A24: 20 | B24: 811 | C24: Zainab | D24: Zulfiqar | E24: TWO | F24: A | G24: P | I24: P | J24: P | K24: P | L24: P | M24: P | P24: P | Q24: P | R24: P | T24: P | U24: P | W24: =COUNTIF(F24:V24,"P") -> 11 | X24: =COUNTIF(F24:V24,"A") -> 1
A25: 1 | B25: 824 | C25: Arsalan | D25: Zulfiqar | E25: TWO | F25: P | G25: P | I25: P | J25: P | K25: A | L25: P | M25: P | P25: P | Q25: A | R25: P | T25: A | U25: P | W25: =COUNTIF(F25:V25,"P") -> 9 | X25: =COUNTIF(F25:V25,"A") -> 3
A26: 2 | B26: 791 | C26: Arsalan | D26: Faheem | E26: TWO | F26: P | G26: A | I26: P | J26: P | K26: P | L26: P | M26: P | P26: P | Q26: P | R26: P | T26: P | U26: P | W26: =COUNTIF(F26:V26,"P") -> 11 | X26: =COUNTIF(F26:V26,"A") -> 1
A27: 3 | B27: 809 | C27: Ahmed Nawaz | D27: Ali Nawaz | E27: TWO | F27: P | G27: P | I27: A | J27: P | K27: P | L27: P | M27: P | P27: P | Q27: P | R27: P | T27: P | U27: P | W27: =COUNTIF(F27:V27,"P") -> 11 | X27: =COUNTIF(F27:V27,"A") -> 1
A28: 4 | B28: 837 | C28: A. Malik | D28: Sohail | E28: TWO | F28: P | G28: P | I28: P | J28: P | K28: P | L28: P | M28: P | P28: P | Q28: P | R28: P | T28: P | U28: P | W28: =COUNTIF(F28:V28,"P") -> 12 | X28: =COUNTIF(F28:V28,"A") -> 0
A29: 5 | B29: 798 | C29: Abdullah | D29: Imtiaz | E29: TWO | F29: P | G29: P | I29: P | J29: P | K29: P | L29: P | M29: P | P29: P | Q29: P | R29: P | T29: P | U29: A | W29: =COUNTIF(F29:V29,"P") -> 11 | X29: =COUNTIF(F29:V29,"A") -> 1
A30: 6 | B30: 816 | C30: Aqeel | D30: A. Ghaffar | E30: TWO | F30: P | G30: P | I30: P | J30: P | K30: P | L30: P | M30: P | P30: P | Q30: P | R30: P | T30: P | U30: P | W30: =COUNTIF(F30:V30,"P") -> 12 | X30: =COUNTIF(F30:V30,"A") -> 0
A31: 7 | C31: A. Qadir | D31: A. Hammad | E31: TWO | F31: P | G31: A | I31: P | J31: A | K31: P | L31: P | M31: P | P31: A | Q31: P | R31: P | T31: P | U31: P | W31: =COUNTIF(F31:V31,"P") -> 9 | X31: =COUNTIF(F31:V31,"A") -> 3
A32: 8 | B32: 795 | C32: Asghar Ali | D32: Akbar Ali | E32: TWO | F32: P | G32: P | I32: P | J32: P | K32: P | L32: P | M32: P | P32: P | Q32: P | R32: P | T32: P | U32: P | W32: =COUNTIF(F32:V32,"P") -> 12 | X32: =COUNTIF(F32:V32,"A") -> 0
A33: 9 | B33: 821 | C33: Hasaan | D33: Manzoor | E33: TWO | F33: P | G33: P | I33: P | J33: P | K33: P | L33: P | M33: P | P33: P | Q33: P | R33: P | T33: A | U33: P | W33: =COUNTIF(F33:V33,"P") -> 11 | X33: =COUNTIF(F33:V33,"A") -> 1
A34: 10 | B34: 776 | C34: Hammad | D34: Rehmatullah | E34: TWO | F34: P | G34: P | I34: P | J34: P | K34: P | L34: P | M34: P | P34: P | Q34: P | R34: P | T34: P | U34: P | W34: =COUNTIF(F34:V34,"P") -> 12 | X34: =COUNTIF(F34:V34,"A") -> 0
A35: 11 | B35: 820 | C35: Hammad | D35: Shahid | E35: TWO | F35: A | G35: P | I35: P | J35: P | K35: A | L35: P | M35: P | P35: P | Q35: A | R35: P | T35: P | U35: P | W35: =COUNTIF(F35:V35,"P") -> 9 | X35: =COUNTIF(F35:V35,"A") -> 3
A36: 12 | B36: 832 | C36: Hussain | D36: A. Bakar | E36: TWO | F36: P | G36: P | I36: P | J36: P | K36: P | L36: P | M36: P | P36: P | Q36: P | R36: P | T36: P | U36: P | W36: =COUNTIF(F36:V36,"P") -> 12 | X36: =COUNTIF(F36:V36,"A") -> 0
A37: 13 | B37: 818 | C37: Haseeb | D37: Saeed | E37: TWO | F37: P | G37: P | I37: P | J37: P | K37: P | L37: P | M37: P | P37: P | Q37: P | R37: P | T37: P | U37: P | W37: =COUNTIF(F37:V37,"P") -> 12 | X37: =COUNTIF(F37:V37,"A") -> 0
A38: 14 | C38: Ismail | D38: M. Raheem | E38: TWO | F38: P | G38: P | I38: P | J38: P | K38: P | L38: P | M38: P | P38: P | Q38: P | R38: P | T38: P | U38: P | W38: =COUNTIF(F38:V38,"P") -> 12 | X38: =COUNTIF(F38:V38,"A") -> 0
A39: 15 | B39: 825 | C39: M. Salar | D39: Saeed Ahmed | E39: TWO | F39: P | G39: P | I39: P | J39: P | K39: P | L39: A | M39: P | P39: P | Q39: P | R39: P | T39: P | U39: P | W39: =COUNTIF(F39:V39,"P") -> 11 | X39: =COUNTIF(F39:V39,"A") -> 1
A40: 16 | B40: 831 | C40: M. Umer | D40: A. Bakar | E40: TWO | F40: P | G40: P | I40: P | J40: P | K40: P | L40: P | M40: P | P40: P | Q40: A | R40: P | T40: P | U40: P | W40: =COUNTIF(F40:V40,"P") -> 11 | X40: =COUNTIF(F40:V40,"A") -> 1
...

Sheet Class-3
A1: Goverment High School (SJCHS)
A2: Monthly Attendence Month of MAY-2025
A3: S.No | B3: GR | C3: Student Name | D3: Father Name | E3: Class | F3: =TEXT(F4,"ddd") -> Fri | G3: =TEXT(G4,"ddd") -> Sat | H3: =TEXT(H4,"ddd") -> Sun | I3: =TEXT(I4,"ddd") -> Mon | J3: =TEXT(J4,"ddd") -> Tue | K3: =TEXT(K4,"ddd") -> Wed | L3: =TEXT(L4,"ddd") -> Thu | M3: =TEXT(M4,"ddd") -> Fri | ... V3: =TEXT(V4,"ddd") -> Sun | W3: Present | X3: Absent | Y3: Year 2024
F4: 45870 | G4: 45871 | H4: 45872 | I4: 45873 | J4: 45874 | K4: 45875 | L4: 45876 | M4: 45877 | N4: 45878 | O4: 45879 | P4: 45880 | Q4: 45881 | R4: 45882 | S4: 45883 | T4: 45884 | U4: 45885 | V4: 45886 | Y4: Total days | Z4: =SUM(Z5:Z8) -> 30
A5: 1 | B5: 772 | C5: Abiha Zehra | D5: Ab. Mateen | E5: Three | F5: A | G5: P | H5: SUNDAY SUNDAY SUNDAY SUNDAY | I5: P | J5: P | K5: P | L5: P | M5: P | N5: URS SHAH ABDUL LATIF BITHAI | O5: SUNDAY SUNDAY SUNDAY SUNDAY | P5: P | Q5: P | R5: P | S5: INDEPENDENCE DAY | T5: A | U5: P | V5: SUNDAY SUNDAY SUNDAY SUNDAY | W5: =COUNTIF(F5:V5,"P") -> 10 | X5: =COUNTIF(F5:V5,"A") -> 2 | Y5: Working days | Z5: 26
A6: 2 | B6: 673 | C6: Aleena Zia | D6: Khuda Baksh | E6: Three | F6: P | G6: P | I6: A | J6: P | K6: A | L6: P | M6: P | P6: P | Q6: P | R6: P | T6: P | U6: P | W6: =COUNTIF(F6:V6,"P") -> 10 | X6: =COUNTIF(F6:V6,"A") -> 2 | Y6: Sunday | Z6: 4
A7: 3 | B7: 6523 | C7: Anumta Jamali | D7: Zaheer Abbas | E7: Three | F7: P | G7: P | I7: P | J7: P | K7: P | L7: P | M7: P | P7: P | Q7: A | R7: P | T7: P | U7: P | W7: =COUNTIF(F7:V7,"P") -> 11 | X7: =COUNTIF(F7:V7,"A") -> 1
A8: 4 | B8: 665 | C8: Ayat | D8: Faiq Ali | E8: Three | F8: P | G8: P | I8: P | J8: P | K8: P | L8: P | M8: P | P8: P | Q8: P | R8: P | T8: P | U8: P | W8: =COUNTIF(F8:V8,"P") -> 12 | X8: =COUNTIF(F8:V8,"A") -> 0
A9: 5 | B9: 656 | C9: Ayesha | D9: Ali Muhammad | E9: Three | F9: P | G9: A | I9: P | J9: P | K9: A | L9: P | M9: P | P9: P | Q9: P | R9: P | T9: P | U9: A | W9: =COUNTIF(F9:V9,"P") -> 9 | X9: =COUNTIF(F9:V9,"A") -> 3
A10: 6 | B10: 910 | C10: Ayesha | D10: Zulfiqar | E10: Three | F10: P | G10: P | I10: P | J10: P | K10: P | L10: P | M10: P | P10: P | Q10: P | R10: P | T10: P | U10: P | W10: =COUNTIF(F10:V10,"P") -> 12 | X10: =COUNTIF(F10:V10,"A") -> 0
A11: 7 | B11: 679 | C11: Dua | D11: Akbar Ali | E11: Three | F11: P | G11: A | I11: P | J11: P | K11: P | L11: P | M11: P | P11: P | Q11: P | R11: P | T11: P | U11: P | W11: =COUNTIF(F11:V11,"P") -> 11 | X11: =COUNTIF(F11:V11,"A") -> 1 | Y11: Present Days Detail
A12: 8 | B12: 675 | C12: Fiza | D12: Akbar Ali | E12: Three | F12: P | G12: P | I12: P | J12: A | K12: P | L12: P | M12: P | P12: P | Q12: P | R12: P | T12: P | U12: P | W12: =COUNTIF(F12:V12,"P") -> 11 | X12: =COUNTIF(F12:V12,"A") -> 1 | Y12: Detail | Z12: Boys | AA12: Girls | AB12: Total
A13: 9 | B13: 774 | C13: Jannat Fatima | D13: Zulfiqar | E13: Three | F13: P | G13: P | I13: P | J13: P | K13: P | L13: A | M13: P | P13: P | Q13: P | R13: P | T13: P | U13: P | W13: =COUNTIF(F13:V13,"P") -> 11 | X13: =COUNTIF(F13:V13,"A") -> 1 | Y13: Due Present days | Z13: =26*$Z$5 -> 676 | AA13: =26*$Z$5 -> 676 | AB13: =SUM(Z13:AA13) -> 1352
A14: 10 | B14: 655 | C14: Kashaf | D14: Abdul Rehman | E14: Three | F14: P | G14: A | I14: P | J14: P | K14: P | L14: P | M14: P | P14: P | Q14: P | R14: A | T14: P | U14: A | W14: =COUNTIF(F14:V14,"P") -> 9 | X14: =COUNTIF(F14:V14,"A") -> 3 | Y14: Actual present days | Z14: =SUM(W29:W52) -> 266 | AA14: =SUM(W5:W28) -> 263 | AB14: =Z14+AA14 -> 529
A15: 11 | B15: 653 | C15: Kashish | D15: M. Noman | E15: Three | F15: P | G15: P | I15: P | J15: P | K15: P | L15: P | M15: P | P15: P | Q15: P | R15: P | T15: P | U15: P | W15: =COUNTIF(F15:V15,"P") -> 12 | X15: =COUNTIF(F15:V15,"A") -> 0 | Y15: % | Z15: =Z14/Z13 -> 0.39349112 | AA15: =AA14/AA13 -> 0.38905325 | AB15: =AB14/AB13 -> 0.39127219
A16: 12 | B16: 657 | C16: Masooma | D16: M. Raheem | E16: Three | F16: A | G16: P | I16: P | J16: P | K16: A | L16: P | M16: P | P16: P | Q16: P | R16: P | T16: P | U16: P | W16: =COUNTIF(F16:V16,"P") -> 10 | X16: =COUNTIF(F16:V16,"A") -> 2
A17: 13 | B17: 672 | C17: Muneeza | D17: Mir Amirudin | E17: Three | F17: P | G17: P | I17: P | J17: P | K17: P | L17: P | M17: P | P17: P | Q17: P | R17: P | T17: P | U17: P | W17: =COUNTIF(F17:V17,"P") -> 12 | X17: =COUNTIF(F17:V17,"A") -> 0
A18: 14 | B18: 702 | C18: Nayyara | D18: Khalid Hussain | E18: Three | F18: P | G18: P | I18: P | J18: P | K18: P | L18: P | M18: P | P18: P | Q18: P | R18: P | T18: P | U18: P | W18: =COUNTIF(F18:V18,"P") -> 12 | X18: =COUNTIF(F18:V18,"A") -> 0
A19: 15 | B19: 659 | C19: Rashida | D19: Sajjad Ahmed | E19: Three | F19: P | G19: P | I19: P | J19: P | K19: P | L19: P | M19: P | P19: P | Q19: P | R19: P | T19: P | U19: P | W19: =COUNTIF(F19:V19,"P") -> 12 | X19: =COUNTIF(F19:V19,"A") -> 0 | Y19: Absent Days Details
A20: 16 | B20: 661 | C20: Rubab Zahra | D20: Abdul Aziz | E20: Three | F20: P | G20: P | I20: P | J20: A | K20: P | L20: P | M20: P | P20: P | Q20: A | R20: P | T20: P | U20: P | W20: =COUNTIF(F20:V20,"P") -> 10 | X20: =COUNTIF(F20:V20,"A") -> 2 | Y20: Detail | Z20: Boys | AA20: Girls | AB20: Total
A21: 17 | B21: 522 | C21: Soha Jamali | D21: Sajid Ali | E21: Three | F21: A | G21: A | I21: P | J21: P | K21: P | L21: P | M21: P | P21: P | Q21: P | R21: P | T21: P | U21: P | W21: =COUNTIF(F21:V21,"P") -> 10 | X21: =COUNTIF(F21:V21,"A") -> 2 | Y21: Due Present days | Z21: =26*$Z$5 -> 676 | AA21: =26*$Z$5 -> 676 | AB21: =Z21+AA21 -> 1352
A22: 18 | B22: 654 | C22: Sehar Fatima | D22: Altaf Hussain | E22: Three | F22: P | G22: P | I22: P | J22: P | K22: P | L22: P | M22: P | P22: P | Q22: P | R22: P | T22: P | U22: P | W22: =COUNTIF(F22:V22,"P") -> 12 | X22: =COUNTIF(F22:V22,"A") -> 0 | Y22: Absent days | Z22: =Z21-Z14 -> 410 | AA22: =AA21-AA14 -> 413 | AB22: =Z22+AA22 -> 823
A23: 19 | B23: 660 | C23: Saba | D23: Asif | E23: Three | F23: P | G23: P | I23: P | J23: P | K23: P | L23: A | M23: P | P23: P | Q23: P | R23: P | T23: P | U23: P | W23: =COUNTIF(F23:V23,"P") -> 11 | X23: =COUNTIF(F23:V23,"A") -> 1 | Y23: % | Z23: =Z22/Z21 -> 0.60650888 | AA23: =AA22/AA21 -> 0.61094675 | AB23: =AB22/AB21 -> 0.60872781
A24: 20 | B24: 841 | C24: Sehrish | D24: Fida Hussain | E24: Three | F24: P | G24: P | I24: P | J24: P | K24: P | L24: P | M24: P | P24: P | Q24: A | R24: P | T24: P | U24: P | W24: =COUNTIF(F24:V24,"P") -> 11 | X24: =COUNTIF(F24:V24,"A") -> 1
A25: 21 | B25: 676 | C25: Tahreem Fatima | D25: Khalid Hussain | E25: Three | F25: A | G25: P | I25: P | J25: P | K25: P | L25: P | M25: P | P25: P | Q25: P | R25: P | T25: P | U25: P | W25: =COUNTIF(F25:V25,"P") -> 11 | X25: =COUNTIF(F25:V25,"A") -> 1
A26: 22 | B26: 658 | C26: Taskeen | D26: Amjad Ali | E26: Three | F26: P | G26: P | I26: P | J26: P | K26: A | L26: P | M26: P | P26: P | Q26: P | R26: P | T26: P | U26: P | W26: =COUNTIF(F26:V26,"P") -> 11 | X26: =COUNTIF(F26:V26,"A") -> 1
A27: 23 | C27: Muntasha Almas | E27: Three | F27: P | G27: P | I27: P | J27: P | K27: P | L27: P | M27: P | P27: P | Q27: P | R27: P | T27: P | U27: P | W27: =COUNTIF(F27:V27,"P") -> 12 | X27: =COUNTIF(F27:V27,"A") -> 0
A28: 24 | B28: 785 | C28: Zainab | D28: Sikandar | E28: Three | F28: P | G28: P | I28: P | J28: P | K28: P | L28: P | M28: P | P28: P | Q28: A | R28: P | T28: P | U28: P | W28: =COUNTIF(F28:V28,"P") -> 11 | X28: =COUNTIF(F28:V28,"A") -> 1
A29: 1 | B29: 700 | C29: Abdul Rehman | D29: Sajid Ali | E29: Three | F29: A | G29: P | I29: P | J29: A | K29: P | L29: P | M29: P | P29: P | Q29: P | R29: P | T29: P | U29: P | W29: =COUNTIF(F29:V29,"P") -> 10 | X29: =COUNTIF(F29:V29,"A") -> 2
A30: 2 | B30: 680 | C30: Abdul Wahab | D30: Abdul Hafeez | E30: Three | F30: P | G30: P | I30: P | J30: P | K30: P | L30: P | M30: P | P30: P | Q30: P | R30: P | T30: P | U30: P | W30: =COUNTIF(F30:V30,"P") -> 12 | X30: =COUNTIF(F30:V30,"A") -> 0
A31: 3 | B31: 650 | C31: Abdullah | D31: Riazuddin | E31: Three | F31: P | G31: P | I31: P | J31: P | K31: P | L31: P | M31: P | P31: A | Q31: P | R31: P | T31: P | U31: P | W31: =COUNTIF(F31:V31,"P") -> 11 | X31: =COUNTIF(F31:V31,"A") -> 1
A32: 4 | B32: 911 | C32: Burair Abbas | D32: Azhar Abbas | E32: Three | F32: P | G32: P | I32: P | J32: P | K32: P | L32: P | M32: P | P32: P | Q32: P | R32: P | T32: P | U32: P | W32: =COUNTIF(F32:V32,"P") -> 12 | X32: =COUNTIF(F32:V32,"A") -> 0
A33: 5 | B33: 683 | C33: Faizan | D33: Lutfullah | E33: Three | F33: P | G33: P | I33: P | J33: P | K33: A | L33: P | M33: P | P33: P | Q33: P | R33: P | T33: P | U33: P | W33: =COUNTIF(F33:V33,"P") -> 11 | X33: =COUNTIF(F33:V33,"A") -> 1
A34: 6 | B34: 662 | C34: Fayaz | D34: Samano Khan | E34: Three | F34: A | G34: P | I34: P | J34: P | K34: P | L34: P | M34: P | P34: P | Q34: P | R34: P | T34: P | U34: P | W34: =COUNTIF(F34:V34,"P") -> 11 | X34: =COUNTIF(F34:V34,"A") -> 1
A35: 7 | B35: 681 | C35: Ghulam Abbas | D35: Kamran Ali | E35: Three | F35: P | G35: A | I35: P | J35: P | K35: P | L35: P | M35: P | P35: P | Q35: A | R35: P | T35: P | U35: P | W35: =COUNTIF(F35:V35,"P") -> 10 | X35: =COUNTIF(F35:V35,"A") -> 2
A36: 8 | B36: 664 | C36: Ghulam Mehdi | D36: Rizwan | E36: Three | F36: P | G36: P | I36: P | J36: P | K36: P | L36: P | M36: P | P36: P | Q36: P | R36: P | T36: P | U36: P | W36: =COUNTIF(F36:V36,"P") -> 12 | X36: =COUNTIF(F36:V36,"A") -> 0
A37: 9 | B37: 663 | C37: Hammad Ali | D37: Sajjad Ali | E37: Three | F37: P | G37: P | I37: P | J37: P | K37: P | L37: A | M37: P | P37: P | Q37: P | R37: P | T37: P | U37: P | W37: =COUNTIF(F37:V37,"P") -> 11 | X37: =COUNTIF(F37:V37,"A") -> 1
A38: 10 | B38: 771 | C38: Haris | D38: Akbar Ali | E38: Three | F38: P | G38: P | I38: P | J38: P | K38: P | L38: P | M38: P | P38: P | Q38: P | R38: P | T38: P | U38: P | W38: =COUNTIF(F38:V38,"P") -> 12 | X38: =COUNTIF(F38:V38,"A") -> 0
A39: 11 | B39: 773 | C39: Hussain | D39: Zaheer Abbas | E39: Three | F39: P | G39: A | I39: P | J39: P | K39: P | L39: P | M39: P | P39: P | Q39: P | R39: A | T39: P | U39: P | W39: =COUNTIF(F39:V39,"P") -> 10 | X39: =COUNTIF(F39:V39,"A") -> 2
... A49: 21 | B49: 677 | C49: Samiullah | D49: Mohammad Shareef | E49: Three | F49: A | G49: P | I49: P | J49: P | K49: P | L49: P | M49: P | P49: P | Q49: P | R49: P | T49: P | U49: P | W49: =COUNTIF(F49:V49,"P") -> 11 | X49: =COUNTIF(F49:V49,"A") -> 1
...

Sheet Class-4
A1: Goverment high school (SJCHS)
A2: Monthly Attendence Month of MAY-2025
A3: S.No | B3: GR | C3: Student Name | D3: Father Name | E3: Class | F3: =TEXT(F4,"ddd") -> Fri | G3: =TEXT(G4,"ddd") -> Sat | H3: =TEXT(H4,"ddd") -> Sun | I3: =TEXT(I4,"ddd") -> Mon | J3: =TEXT(J4,"ddd") -> Tue | K3: =TEXT(K4,"ddd") -> Wed | L3: =TEXT(L4,"ddd") -> Thu | M3: =TEXT(M4,"ddd") -> Fri | ... V3: =TEXT(V4,"ddd") -> Sun | W3: Present | X3: Absent | Y3: Year 2024
F4: 45870 | G4: 45871 | H4: 45872 | I4: 45873 | J4: 45874 | K4: 45875 | L4: 45876 | M4: 45877 | N4: 45878 | O4: 45879 | P4: 45880 | Q4: 45881 | R4: 45882 | S4: 45883 | T4: 45884 | U4: 45885 | V4: 45886 | Y4: Total days | Z4: =SUM(Z5:Z7) -> 26
A5: 1 | B5: 646 | C5: Abbas Ali | D5: Deedar Ali | E5: Four | F5: P | G5: P | H5: Sunday Sunday Sunday Sunday | I5: P | J5: P | K5: P | L5: P | M5: A | N5: URS SHAH ABDUL LATIF BITHAI | O5: Sunday Sunday Sunday Sunday | P5: A | Q5: P | R5: P | S5: INDEPENDENCE DAY | T5: P | U5: P | V5: Sunday Sunday Sunday Sunday | W5: =COUNTIF(F5:V5,"P") -> 10 | X5: =COUNTIF(F5:V5,"A") -> 2 | Y5: Working days | Z5: 26
A6: 2 | B6: 684 | C6: Abdul Rahim | D6: Abdul Hafeez | E6: Four | F6: A | G6: P | I6: P | J6: P | K6: P | L6: P | M6: P | P6: P | Q6: P | R6: P | T6: P | U6: P | W6: =COUNTIF(F6:V6,"P") -> 11 | X6: =COUNTIF(F6:V6,"A") -> 1
A7: 3 | B7: 551 | C7: Abdullah | D7: Munawar Ali | E7: Four | F7: P | G7: P | I7: P | J7: P | K7: P | L7: P | M7: P | P7: P | Q7: P | R7: P | T7: P | U7: P | W7: =COUNTIF(F7:V7,"P") -> 12 | X7: =COUNTIF(F7:V7,"A") -> 0
A8: 4 | B8: 490 | C8: Abdul Qudoos | D8: Waheed Ahmed | E8: Four | F8: P | G8: P | I8: P | J8: P | K8: P | L8: P | M8: P | P8: P | Q8: A | R8: P | T8: P | U8: P | W8: =COUNTIF(F8:V8,"P") -> 11 | X8: =COUNTIF(F8:V8,"A") -> 1
A9: 5 | B9: 647 | C9: Ali Haider | D9: Akber Ali | E9: Four | F9: P | G9: A | I9: P | J9: P | K9: P | L9: P | M9: A | P9: P | Q9: P | R9: P | T9: P | U9: P | W9: =COUNTIF(F9:V9,"P") -> 10 | X9: =COUNTIF(F9:V9,"A") -> 2
A10: 6 | B10: 908 | C10: Atteeque ur Rehman | D10: Raffique Ahmed | E10: Four | F10: P | G10: P | I10: P | J10: P | K10: P | L10: P | M10: P | P10: P | Q10: P | R10: P | T10: P | U10: P | W10: =COUNTIF(F10:V10,"P") -> 12 | X10: =COUNTIF(F10:V10,"A") -> 0 | Y10: Present Days Detail
A11: 7 | B11: 585 | C11: Aqib Ali | D11: Abdul Ghaffar | E11: Four | F11: P | G11: P | I11: P | J11: P | K11: P | L11: P | M11: P | P11: P | Q11: P | R11: P | T11: P | U11: P | W11: =COUNTIF(F11:V11,"P") -> 12 | X11: =COUNTIF(F11:V11,"A") -> 0 | Y11: Detail | Z11: Boys | AA11: Girls | AB11: Total
A12: 8 | B12: 555 | C12: Ayaz Ali | D12: Arbab Ali | E12: Four | F12: P | G12: P | I12: P | J12: P | K12: P | L12: A | M12: P | P12: P | Q12: P | R12: A | T12: P | U12: P | W12: =COUNTIF(F12:V12,"P") -> 10 | X12: =COUNTIF(F12:V12,"A") -> 2 | Y12: Due Present days | Z12: =28*$Z$5 -> 728 | AA12: =24*$Z$5 -> 624 | AB12: =SUM(Z12:AA12) -> 1352
A13: 9 | B13: 691 | C13: Azan | D13: Nisar Ahmed | E13: Four | F13: A | G13: P | I13: P | J13: P | K13: P | L13: P | M13: P | P13: P | Q13: P | R13: P | T13: P | U13: P | W13: =COUNTIF(F13:V13,"P") -> 11 | X13: =COUNTIF(F13:V13,"A") -> 1 | Y13: Actual present days | Z13: =SUM(W5:W29) -> 277 | AA13: =SUM(W31:W53) -> 250 | AB13: =Z13+AA13 -> 527
A14: 10 | B14: 913 | C14: Muhammad Essa | D14: Sajid Ali | E14: Four | F14: P | G14: P | I14: P | J14: P | K14: P | L14: P | M14: P | P14: P | Q14: A | R14: P | T14: P | U14: P | W14: =COUNTIF(F14:V14,"P") -> 11 | X14: =COUNTIF(F14:V14,"A") -> 1 | Y14: % | Z14: =Z13/Z12 -> 0.38049451 | AA14: =AA13/AA12 -> 0.40064103 | AB14: =AB13/AB12 -> 0.3897929
A15: 11 | B15: 528 | C15: Faizan Ahmed | D15: Riaz Ahmed | E15: Four | F15: P | G15: P | I15: P | J15: P | K15: P | L15: P | M15: P | P15: P | Q15: P | R15: P | T15: P | U15: P | W15: =COUNTIF(F15:V15,"P") -> 12 | X15: =COUNTIF(F15:V15,"A") -> 0
A16: 12 | B16: 689 | C16: Haider Ali | D16: Imran Ali | E16: Four | F16: P | G16: P | I16: P | J16: P | K16: A | L16: P | M16: P | P16: P | Q16: P | R16: P | T16: P | U16: P | W16: =COUNTIF(F16:V16,"P") -> 11 | X16: =COUNTIF(F16:V16,"A") -> 1
A17: 13 | B17: 648 | C17: Meer Alam | D17: Dil Murad | E17: Four | F17: P | G17: P | I17: P | J17: P | K17: P | L17: P | M17: P | P17: P | Q17: P | R17: P | T17: P | U17: P | W17: =COUNTIF(F17:V17,"P") -> 12 | X17: =COUNTIF(F17:V17,"A") -> 0
A18: 14 | B18: 578 | C18: M. Ahsan | D18: M. Arif | E18: Four | F18: P | G18: A | I18: P | J18: P | K18: P | L18: P | M18: P | P18: A | Q18: P | R18: P | T18: P | U18: P | W18: =COUNTIF(F18:V18,"P") -> 10 | X18: =COUNTIF(F18:V18,"A") -> 2 | Y18: Absent Days Details
A19: 15 | B19: 573 | C19: M. Qasim | D19: Mohsin Ali | E19: Four | F19: P | G19: P | I19: P | J19: A | K19: P | L19: P | M19: P | P19: P | Q19: P | R19: P | T19: P | U19: P | W19: =COUNTIF(F19:V19,"P") -> 11 | X19: =COUNTIF(F19:V19,"A") -> 1 | Y19: Detail | Z19: Boys | AA19: Girls | AB19: Total
A20: 16 | B20: 479 | C20: M. Shayan | D20: Zulfiqar Ali | E20: Four | F20: P | G20: P | I20: P | J20: P | K20: P | L20: P | M20: P | P20: P | Q20: P | R20: P | T20: P | U20: P | W20: =COUNTIF(F20:V20,"P") -> 12 | X20: =COUNTIF(F20:V20,"A") -> 0 | Y20: Due Present days | Z20: =28*$Z$5 -> 728 | AA20: =24*$Z$5 -> 624 | AB20: =Z20+AA20 -> 1352
A21: 17 | B21: 575 | C21: M. Zawiyar | D21: Zulfiqar Ali Mangi | E21: Four | F21: P | G21: P | I21: P | J21: P | K21: P | L21: P | M21: P | P21: P | Q21: P | R21: P | T21: P | U21: P | W21: =COUNTIF(F21:V21,"P") -> 12 | X21: =COUNTIF(F21:V21,"A") -> 0 | Y21: Absent days | Z21: =Z20-Z13 -> 451 | AA21: =AA20-AA13 -> 374 | AB21: =Z21+AA21 -> 825
A22: 18 | B22: 586 | C22: Muneer Ahmed | D22: Ghous Bux | E22: Four | F22: P | G22: P | I22: P | J22: P | K22: P | L22: P | M22: P | P22: P | Q22: A | R22: P | T22: P | U22: P | W22: =COUNTIF(F22:V22,"P") -> 11 | X22: =COUNTIF(F22:V22,"A") -> 1 | Y22: % | Z22: =Z21/Z20 -> 0.61950549 | AA22: =AA21/AA20 -> 0.59935897 | AB22: =AB21/AB20 -> 0.6102071
