Workbook

Sheet Compile Sheet-October-2024
A4: Class | B4: Total Enrolment & Attendance October-24
B5: Boys | C5: Girls | D5: Total | E5: total working Days | F5: Total working days-Boys | G5: Total working days-Girls | H5: Total working days-All | I5: P-Days Boys | J5: P-Days Girls | K5: P-Days All | L5: Percentage-Girls | M5: Percentage-Boys | N5: Percentage-Boys | O5: Total average
A6: ECE (ROSE) | B6: 26 | C6: 26 | D6: =SUM(B6:C6) -> 52 | E6: 24 | F6: =B6*E6 -> 624 | G6: =C6*E6 -> 624 | H6: =SUM(F6:G6) -> 1248 | I6: ='ECE (ROSE)'!AM12 -> 602 | J6: ='ECE (ROSE)'!AN12 -> 575 | K6: =SUM(I6:J6) -> 1177 | L6: =J6/G6 -> 0.92147436 | M6: =I6/F6 -> 0.96474359 | N6: =K6/H6 -> 0.94310897 | O6: =AVERAGE(L6:M6) -> 0.94310897
A7: ECE (Daffodils) | B7: 31 | C7: 25 | D7: =SUM(B7:C7) -> 56 | E7: 24 | F7: =B7*E7 -> 744 | G7: =C7*E7 -> 600 | H7: =SUM(F7:G7) -> 1344 | I7: ='ECE (Daffodils)'!AM12 -> 720 | J7: ='ECE (Daffodils)'!AN12 -> 530 | K7: =SUM(I7:J7) -> 1250 | L7: =J7/G7 -> 0.88333333 | M7: =I7/F7 -> 0.96774194 | N7: =K7/H7 -> 0.93005952 | O7: =AVERAGE(L7:M7) -> 0.92553763
A8: One | B8: 32 | C8: 24 | D8: =SUM(B8:C8) -> 56 | E8: 24 | F8: =B8*E8 -> 768 | G8: =C8*E8 -> 576 | H8: =SUM(F8:G8) -> 1344 | I8: ='Class-I'!AM12 -> 746 | J8: ='Class-I'!AN12 -> 525 | K8: =SUM(I8:J8) -> 1271 | L8: =J8/G8 -> 0.91145833 | M8: =I8/F8 -> 0.97135417 | N8: =K8/H8 -> 0.94568452 | O8: =AVERAGE(L8:M8) -> 0.94140625
A9: Two | B9: 26 | C9: 26 | D9: =SUM(B9:C9) -> 52 | E9: 24 | F9: =B9*E9 -> 624 | G9: =C9*E9 -> 624 | H9: =SUM(F9:G9) -> 1248 | I9: ='Class-II'!AM12 -> 548 | J9: ='Class-II'!AN12 -> 592 | K9: =SUM(I9:J9) -> 1140 | L9: =J9/G9 -> 0.94871795 | M9: =I9/F9 -> 0.87820513 | N9: =K9/H9 -> 0.91346154 | O9: =AVERAGE(L9:M9) -> 0.91346154
A10: Three | B10: 30 | C10: 26 | D10: =SUM(B10:C10) -> 56 | E10: 24 | F10: =B10*E10 -> 720 | G10: =C10*E10 -> 624 | H10: =SUM(F10:G10) -> 1344 | I10: ='Class-III'!AM12 -> 627 | J10: ='Class-III'!AN12 -> 567 | K10: =SUM(I10:J10) -> 1194 | L10: =J10/G10 -> 0.90865385 | M10: =I10/F10 -> 0.87083333 | N10: =K10/H10 -> 0.88839286 | O10: =AVERAGE(L10:M10) -> 0.88974359
A11: Four | B11: 21 | C11: 32 | D11: =SUM(B11:C11) -> 53 | E11: 24 | F11: =B11*E11 -> 504 | G11: =C11*E11 -> 768 | H11: =SUM(F11:G11) -> 1272 | I11: ='Class-IV'!AM12 -> 431 | J11: ='Class-IV'!AN12 -> 704 | K11: =SUM(I11:J11) -> 1135 | L11: =J11/G11 -> 0.91666667 | M11: =I11/F11 -> 0.85515873 | N11: =K11/H11 -> 0.8922956 | O11: =AVERAGE(L11:M11) -> 0.8859127
A12: Five | B12: 23 | C12: 23 | D12: =SUM(B12:C12) -> 46 | E12: 24 | F12: =B12*E12 -> 552 | G12: =C12*E12 -> 552 | H12: =SUM(F12:G12) -> 1104 | I12: ='Class-V'!AM12 -> 540 | J12: ='Class-V'!AN12 -> 437 | K12: =SUM(I12:J12) -> 977 | L12: =J12/G12 -> 0.79166667 | M12: =I12/F12 -> 0.97826087 | N12: =K12/H12 -> 0.88496377 | O12: =AVERAGE(L12:M12) -> 0.88496377
A13: Six | B13: 17 | C13: 26 | D13: =SUM(B13:C13) -> 43 | E13: 24 | F13: =B13*E13 -> 408 | G13: =C13*E13 -> 624 | H13: =SUM(F13:G13) -> 1032 | I13: ='Class-VI'!AM12 -> 383 | J13: ='Class-VI'!AN12 -> 568 | K13: =SUM(I13:J13) -> 951 | L13: =J13/G13 -> 0.91025641 | M13: =I13/F13 -> 0.93872549 | N13: =K13/H13 -> 0.92151163 | O13: =AVERAGE(L13:M13) -> 0.92449095
A14: Seven | B14: 29 | C14: 19 | D14: =SUM(B14:C14) -> 48 | E14: 24 | F14: =B14*E14 -> 696 | G14: =C14*E14 -> 456 | H14: =SUM(F14:G14) -> 1152 | I14: ='Class-VII'!AL12 -> 624 | J14: ='Class-VII'!AM12 -> 426 | K14: =SUM(I14:J14) -> 1050 | L14: =J14/G14 -> 0.93421053 | M14: =I14/F14 -> 0.89655172 | N14: =K14/H14 -> 0.91145833 | O14: =AVERAGE(L14:M14) -> 0.91538113
A15: Eight | B15: 19 | C15: 25 | D15: =SUM(B15:C15) -> 44 | E15: 24 | F15: =B15*E15 -> 456 | G15: =C15*E15 -> 600 | H15: =SUM(F15:G15) -> 1056 | I15: ='Class-VIII'!AM12 -> 405 | J15: ='Class-VIII'!AN12 -> 575 | K15: =SUM(I15:J15) -> 980 | L15: =J15/G15 -> 0.95833333 | M15: =I15/F15 -> 0.88815789 | N15: =K15/H15 -> 0.9280303 | O15: =AVERAGE(L15:M15) -> 0.92324561
A16: Ninth | B16: 18 | C16: 22 | D16: =SUM(B16:C16) -> 40 | E16: 24 | F16: =B16*E16 -> 432 | G16: =C16*E16 -> 528 | H16: =SUM(F16:G16) -> 960 | I16: ='Class-IX'!AM12 -> 369 | J16: ='Class-IX'!AN12 -> 409 | K16: ='Class-IX'!AO12 -> 778 | L16: =J16/G16 -> 0.77462121 | M16: =I16/F16 -> 0.85416667 | N16: =K16/H16 -> 0.81041667 | O16: =AVERAGE(L16:M16) -> 0.81439394
A17: Total | B17: =SUM(B6:B16) -> 272 | C17: =SUM(C6:C16) -> 274 | D17: =SUM(D6:D16) -> 546 | E17: =SUM(E6:E16) -> 264 | F17: =SUM(F6:F16) -> 6528 | G17: =SUM(G6:G16) -> 6576 | H17: =SUM(H6:H16) -> 13104 | I17: =SUM(I6:I16) -> 5995 | ... K17: =SUM(K6:K16) -> 11903 | L17: =J17/G17 -> 0.89841849 | M17: =I17/F17 -> 0.91835172 | N17: =AVERAGE(N6:N16) -> 0.90630761 | O17: =AVERAGE(O6:O16) -> 0.90560419
A18: % | B18: 1 | C18: 1 | D18: 1 | E18: 1 | F18: 1 | G18: 1 | H18: 1 | I18: =I17/F17 -> 0.91835172 | J18: =J17/G17 -> 0.89841849 | K18: =K17/H17 -> 0.9083486 | L18: 0.54 | M18: 0.56 | N18: 0.55 | O18: =AVERAGE(L17:M17) -> 0.9083851

Sheet ECE (ROSE)
A1: Goverment high school (SJCHS)
A2: Monthly Attendence Month of October-2024
A3: S.No | B3: Student Name | C3: Father Name | D3: Class | E3: =TEXT(E4,"ddd") -> Tue | F3: =TEXT(F4,"ddd") -> Wed | G3: =TEXT(G4,"ddd") -> Thu | H3: =TEXT(H4,"ddd") -> Fri | I3: =TEXT(I4,"ddd") -> Sat | J3: =TEXT(J4,"ddd") -> Sun | K3: =TEXT(K4,"ddd") -> Mon | L3: =TEXT(L4,"ddd") -> Tue | ... AI3: =TEXT(AI4,"ddd") -> Thu | AJ3: Present | AK3: Absent | AL3: Year 2024
E4: 45566 | F4: 45567 | G4: 45568 | H4: 45569 | I4: 45570 | J4: 45571 | K4: 45572 | L4: 45573 | M4: 45574 | N4: 45575 | O4: 45576 | P4: 45577 | Q4: 45578 | R4: 45579 | S4: 45580 | T4: 45581 | U4: 45582 | V4: 45583 | W4: 45584 | X4: 45585 | Y4: 45586 | Z4: 45587 | AA4: 45588 | AB4: 45589 | AC4: 45590 | AD4: 45591 | AE4: 45592 | AF4: 45593 | AG4: 45594 | AH4: 45595 | AI4: 45596 | AL4: Total days | AM4: =SUM(AM5:AM7) -> 31
A5: 1 | B5: Eman | C5: Shahnawaz Khan | D5: ECE | E5: P | F5: P | G5: P | H5: P | I5: P | J5: SUNDAY - SUNDAY - SUNDAY - SUNDAY - SUNDAY | K5: P | L5: P | M5: P | N5: A | O5: P | P5: A | Q5: SUNDAY - SUNDAY - SUNDAY - SUNDAY - SUNDAY | R5: L | S5: A | T5: A | U5: A | V5: A | W5: P | X5: SUNDAY - SUNDAY - SUNDAY - SUNDAY - SUNDAY | Y5: P | Z5: P | AA5: P | AB5: P | AC5: P | AD5: P | AE5: SUNDAY - SUNDAY - SUNDAY - SUNDAY - SUNDAY | AF5: P | AG5: P | AH5: P | AI5: P | AJ5: =COUNTIF(E5:AI5,"P") -> 20 | AK5: =COUNTIF(E5:AI5,"A") -> 6 | AL5: Working days | AM5: 27
A6: 2 | B6: Rehan Ali | C6: Abdul Rehman | D6: ECE | E6: P | F6: P | G6: P | H6: P | I6: P | K6: P | L6: P | M6: P | N6: P | O6: P | P6: P | R6: P | S6: P | T6: P | U6: P | V6: A | W6: A | Y6: A | Z6: A | AA6: A | AB6: A | AC6: A | AD6: A | AF6: P | AG6: P | AH6: P | AI6: P | AJ6: =COUNTIF(E6:AI6,"P") -> 19 | AK6: =COUNTIF(E6:AI6,"A") -> 8 | AL6: Sunday | AM6: 4
A7: 3 | B7: Dilkash | C7: Faraz Hussain | D7: ECE | E7: P | F7: P | G7: P | H7: P | I7: P | K7: P | L7: P | M7: P | N7: P | O7: P | P7: P | R7: P | S7: P | T7: P | U7: P | V7: P | W7: A | Y7: P | Z7: P | AA7: P | AB7: P | AC7: P | AD7: P | AF7: P | AG7: P | AH7: P | AI7: P | AJ7: =COUNTIF(E7:AI7,"P") -> 26 | AK7: =COUNTIF(E7:AI7,"A") -> 1
A8: 4 | B8: Masooma | C8: Faiq Ali | D8: ECE | E8: P | F8: P | G8: P | H8: P | I8: P | K8: P | L8: P | M8: P | N8: P | O8: P | P8: A | R8: P | S8: P | T8: P | U8: P | V8: P | W8: P | Y8: P | Z8: P | AA8: P | AB8: P | AC8: P | AD8: A | AF8: P | AG8: P | AH8: P | AI8: P | AJ8: =COUNTIF(E8:AI8,"P") -> 25 | AK8: =COUNTIF(E8:AI8,"A") -> 2
A9: 5 | B9: Ali | C9: Saddam Hussain | D9: ECE | E9: P | F9: P | G9: P | H9: P | I9: A | K9: P | L9: P | M9: P | N9: P | O9: P | P9: P | R9: P | S9: P | T9: A | U9: A | V9: P | W9: P | Y9: P | Z9: P | AA9: P | AB9: P | AC9: A | AD9: A | AF9: P | AG9: P | AH9: P | AI9: P | AJ9: =COUNTIF(E9:AI9,"P") -> 22 | AK9: =COUNTIF(E9:AI9,"A") -> 5 | AL9: Present Days Detail
A10: 6 | B10: Hafsa Batool | C10: Gul Mohammad Chandio | D10: ECE | E10: P | F10: P | G10: P | H10: P | I10: P | K10: P | L10: P | M10: P | N10: P | O10: P | P10: A | R10: P | S10: P | T10: P | U10: P | V10: P | W10: P | Y10: P | Z10: P | AA10: A | AB10: P | AC10: A | AD10: A | AF10: P | AG10: P | AH10: P | AI10: P | AJ10: =COUNTIF(E10:AI10,"P") -> 23 | AK10: =COUNTIF(E10:AI10,"A") -> 4 | AL10: Detail | AM10: Boys | AN10: Girls | AO10: Total
A11: 7 | B11: Mohammad Aliyan | C11: Shabir Ahmed Bhutto | D11: ECE | E11: P | F11: P | G11: P | H11: P | I11: A | K11: P | L11: P | M11: P | N11: A | O11: P | P11: A | R11: P | S11: P | T11: P | U11: P | V11: P | W11: A | Y11: P | Z11: P | AA11: P | AB11: P | AC11: P | AD11: P | AF11: A | AG11: P | AH11: P | AI11: P | AJ11: =COUNTIF(E11:AI11,"P") -> 22 | AK11: =COUNTIF(E11:AI11,"A") -> 5 | AL11: Due Present days | AM11: =26*$AM$5 -> 702 | AN11: =26*$AM$5 -> 702 | AO11: =SUM(AM11:AN11) -> 1404
A12: 8 | B12: Hoor Fatima | C12: Shahid Ali | D12: ECE | E12: P | F12: P | G12: P | H12: P | I12: P | K12: P | L12: P | M12: P | N12: L | O12: L | P12: L | R12: A | S12: A | T12: P | U12: P | V12: P | W12: P | Y12: P | Z12: P | AA12: A | AB12: P | AC12: P | AD12: P | AF12: P | AG12: P | AH12: P | AI12: P | AJ12: =COUNTIF(E12:AI12,"P") -> 21 | AK12: =COUNTIF(E12:AI12,"A") -> 3 | AL12: Actual present days | AM12: =SUM(AJ6,AJ9,AJ11,AJ13,AJ16,AJ21,AJ22,AJ23,AJ24,AJ25,AJ26,AJ27,AJ32,AJ34,AJ36,AJ40,AJ41,AJ43,AJ44,AJ45,AJ46,AJ50,AJ51,AJ52,AJ53,AJ54) -> 602 | AN12: =SUM(AJ5,AJ7,AJ8,AJ10,AJ12,AJ14,AJ15,AJ17,AJ19,AJ20,AJ28,AJ29,AJ30,AJ31,AJ33,AJ35,AJ37,AJ38,AJ39,AJ42,AJ47,AJ48,AJ49,AJ54,AJ55,AJ56) -> 575 | AO12: =AM12+AN12 -> 1177
A13: 9 | B13: Muhammad Sahil | C13: Irshad Ali | D13: ECE | E13: P | F13: P | G13: P | H13: P | I13: P | K13: P | L13: P | M13: P | N13: P | O13: P | P13: P | R13: P | S13: P | T13: P | U13: P | V13: P | W13: P | Y13: P | Z13: P | AA13: P | AB13: P | AC13: P | AD13: P | AF13: P | AG13: P | AH13: P | AI13: P | AJ13: =COUNTIF(E13:AI13,"P") -> 27 | AK13: =COUNTIF(E13:AI13,"A") -> 0 | AL13: % | AM13: =AM12/AM11 -> 0.85754986 | AN13: =AN12/AN11 -> 0.81908832 | AO13: =AO12/AO11 -> 0.83831909
A14: 10 | B14: Kinza | C14: Aijaz Ali | D14: ECE | E14: P | F14: P | G14: P | H14: P | I14: P | K14: P | L14: P | M14: P | N14: P | O14: P | P14: P | R14: P | S14: P | T14: P | U14: P | V14: A | W14: P | Y14: P | Z14: P | AA14: P | AB14: P | AC14: P | AD14: P | AF14: P | AG14: P | AH14: P | AI14: P | AJ14: =COUNTIF(E14:AI14,"P") -> 26 | AK14: =COUNTIF(E14:AI14,"A") -> 1
A15: 11 | B15: Zaryab Sultan | C15: Muhammad Zaman | D15: ECE | E15: P | F15: P | G15: P | H15: P | I15: P | K15: P | L15: P | M15: P | N15: P | O15: P | P15: P | R15: P | S15: P | T15: P | U15: P | V15: P | W15: A | Y15: P | Z15: P | AA15: P | AB15: P | AC15: P | AD15: A | AF15: P | AG15: P | AH15: P | AI15: P | AJ15: =COUNTIF(E15:AI15,"P") -> 25 | AK15: =COUNTIF(E15:AI15,"A") -> 2
A16: 12 | B16: M. Ibrahim | C16: Fayaz Ali Ansari | D16: ECE | E16: P | F16: P | G16: P | H16: P | I16: P | K16: P | L16: P | M16: P | N16: P | O16: P | P16: P | R16: P | S16: P | T16: P | U16: A | V16: A | W16: A | Y16: A | Z16: A | AA16: A | AB16: A | AC16: A | AD16: A | AF16: P | AG16: P | AH16: P | AI16: P | AJ16: =COUNTIF(E16:AI16,"P") -> 18 | AK16: =COUNTIF(E16:AI16,"A") -> 9
A17: 13 | B17: Fatima Ansari | C17: Ayaz Ali Ansari | D17: ECE | E17: P | F17: P | G17: P | H17: P | I17: P | K17: P | L17: P | M17: P | N17: P | O17: P | P17: P | R17: P | S17: P | T17: P | U17: P | V17: P | W17: A | Y17: P | Z17: P | AA17: P | AB17: P | AC17: A | AD17: A | AF17: P | AG17: P | AH17: P | AI17: P | AJ17: =COUNTIF(E17:AI17,"P") -> 24 | AK17: =COUNTIF(E17:AI17,"A") -> 3 | AL17: Absent Days Details
A18: 14 | B18: Zil-e-Huma | C18: Abdul Qayoom | D18: ECE | E18: A | F18: A | G18: A | H18: P | I18: P | K18: P | L18: P | M18: P | N18: P | O18: P | P18: P | R18: A | S18: P | T18: A | U18: A | V18: A | W18: A | Y18: A | Z18: P | AA18: A | AB18: P | AC18: A | AD18: P | AF18: A | AG18: P | AH18: P | AI18: P | AJ18: =COUNTIF(E18:AI18,"P") -> 15 | AK18: =COUNTIF(E18:AI18,"A") -> 12 | AL18: Detail | AM18: Boys | AN18: Girls | AO18: Total
A19: 15 | B19: Ayat Fatima | C19: Imran Hussain | D19: ECE | E19: P | F19: P | G19: P | H19: P | I19: A | K19: A | L19: P | M19: P | N19: P | O19: P | P19: P | R19: P | S19: L | T19: L | U19: L | V19: L | W19: L | Y19: P | Z19: P | AA19: P | AB19: P | AC19: A | AD19: P | AF19: P | AG19: P | AH19: P | AI19: P | AJ19: =COUNTIF(E19:AI19,"P") -> 19 | AK19: =COUNTIF(E19:AI19,"A") -> 3 | AL19: Due Present days | AM19: =26*$AM$5 -> 702 | AN19: =26*$AM$5 -> 702 | AO19: =AM19+AN19 -> 1404
A20: 16 | B20: Aqsa | C20: Ahsan Ali | D20: ECE | E20: P | F20: L | G20: L | H20: L | I20: L | K20: L | L20: L | M20: L | N20: L | O20: L | P20: L | R20: A | S20: A | T20: A | U20: A | V20: A | W20: A | Y20: A | Z20: A | AA20: A | AB20: A | AC20: P | AD20: A | AF20: P | AG20: P | AH20: P | AI20: P | AJ20: =COUNTIF(E20:AI20,"P") -> 6 | AK20: =COUNTIF(E20:AI20,"A") -> 11 | AL20: Absent days | AM20: =AM19-AM12 -> 100 | AN20: =AN19-AN12 -> 127 | AO20: =AM20+AN20 -> 227
A21: 17 | B21: Muhammad Fawad | C21: Waseem Ahmed Channa | D21: ECE | E21: P | F21: P | G21: P | H21: P | I21: P | K21: P | L21: P | M21: P | N21: P | O21: P | R21: P | S21: P | T21: P | U21: P | V21: P | W21: P | Y21: P | Z21: P | AA21: P | AB21: P | AC21: P | AD21: P | AF21: P | AG21: P | AH21: P | AI21: P | AJ21: =COUNTIF(E21:AI21,"P") -> 26 | AK21: =COUNTIF(E21:AI21,"A") -> 0 | AL21: % | AM21: =AM20/AM19 -> 0.14245014 | AN21: =AN20/AN19 -> 0.18091168 | AO21: =AO20/AO19 -> 0.16168091
A22: 18 | B22: Muhammad Haris | C22: M. Shareef Niyazi | D22: ECE | E22: P | F22: P | G22: A | H22: A | I22: A | K22: P | L22: P | M22: P | N22: P | O22: P | P22: P | R22: P | S22: P | T22: P | U22: P | V22: P | W22: P | Y22: P | Z22: P | AA22: A | AB22: P | AC22: P | AD22: P | AF22: P | AG22: P | AH22: P | AI22: P | AJ22: =COUNTIF(E22:AI22,"P") -> 23 | AK22: =COUNTIF(E22:AI22,"A") -> 4
A23: 19 | B23: Muhammad Ayan | C23: Abdul Ghaffar | D23: ECE | E23: P | F23: P | G23: P | H23: P | I23: P | K23: P | L23: P | M23: P | N23: P | O23: P | P23: P | R23: P | S23: P | T23: P | U23: P | V23: P | W23: P | Y23: P | Z23: P | AA23: P | AB23: A | AC23: P | AD23: P | AF23: P | AG23: P | AH23: P | AI23: P | AJ23: =COUNTIF(E23:AI23,"P") -> 26 | AK23: =COUNTIF(E23:AI23,"A") -> 1
A24: 20 | B24: Danish | C24: Ayaz Ali | D24: ECE | E24: P | F24: P | G24: P | H24: P | I24: P | K24: P | L24: P | M24: P | N24: P | O24: P | P24: P | R24: P | S24: P | T24: P | U24: A | V24: P | W24: P | Y24: P | Z24: P | AA24: P | AB24: P | AC24: P | AD24: P | AF24: P | AG24: P | AH24: P | AI24: A | AJ24: =COUNTIF(E24:AI24,"P") -> 25 | AK24: =COUNTIF(E24:AI24,"A") -> 2
A25: 21 | B25: Mujahid Ali | C25: Sajjad Ali | D25: ECE | E25: P | F25: P | G25: P | H25: A | I25: A | K25: P | L25: P | M25: P | N25: P | O25: P | P25: P | R25: P | S25: P | T25: L | U25: L | V25: L | W25: L | Y25: A | Z25: A | AA25: A | AB25: A | AC25: A | AD25: L | AF25: P | AG25: P | AH25: P | AI25: P | AJ25: =COUNTIF(E25:AI25,"P") -> 15 | AK25: =COUNTIF(E25:AI25,"A") -> 7
A26: 22 | B26: Zawar Ali | C26: Kamran Ali | D26: ECE | E26: P | F26: P | G26: P | H26: P | I26: A | K26: P | L26: P | M26: P | N26: P | O26: P | P26: P | R26: P | S26: P | T26: P | U26: P | V26: P | W26: P | Y26: P | Z26: P | AA26: P | AB26: P | AC26: P | AD26: P | AF26: P | AG26: P | AH26: P | AI26: P | AJ26: =COUNTIF(E26:AI26,"P") -> 26 | AK26: =COUNTIF(E26:AI26,"A") -> 1
A27: 23 | B27: Muhammad Rayyan | C27: Ghulam Murtaza | D27: ECE | E27: P | F27: P | G27: P | H27: P | I27: P | K27: P | L27: P | M27: P | N27: L | O27: L | P27: L | R27: P | S27: A | T27: P | U27: P | V27: A | W27: P | Y27: P | Z27: P | AA27: P | AB27: P | AC27: P | AD27: A | AF27: A | AG27: P | AH27: P | AI27: P | AJ27: =COUNTIF(E27:AI27,"P") -> 20 | AK27: =COUNTIF(E27:AI27,"A") -> 4
A28: 24 | B28: Safa | C28: Dil Murad | D28: ECE | E28: P | F28: P | G28: P | H28: P | I28: P | K28: P | L28: P | M28: P | N28: P | O28: P | P28: P | R28: P | S28: P | T28: P | U28: P | V28: P | W28: P | Y28: P | Z28: P | AA28: P | AB28: A | AC28: A | AD28: P | AF28: P | AG28: P | AH28: P | AI28: P | AJ28: =COUNTIF(E28:AI28,"P") -> 25 | AK28: =COUNTIF(E28:AI28,"A") -> 2
A29: 25 | B29: Hifza | C29: Zakir Ali | D29: ECE | E29: P | F29: P | G29: A | H29: P | I29: P | K29: P | L29: P | M29: P | N29: P | O29: P | P29: P | R29: P | S29: P | T29: P | U29: P | V29: P | W29: P | Y29: P | Z29: P | AA29: P | AB29: P | AC29: P | AD29: P | AF29: P | AG29: P | AH29: P | AI29: P | AJ29: =COUNTIF(E29:AI29,"P") -> 26 | AK29: =COUNTIF(E29:AI29,"A") -> 1
A30: 26 | B30: Zameeran | C30: Babar Ali | D30: ECE | E30: P | F30: P | G30: P | H30: P | I30: P | K30: P | L30: P | M30: P | N30: P | O30: P | P30: P | R30: P | S30: P | T30: A | U30: P | V30: P | W30: P | Y30: P | Z30: P | AA30: P | AB30: P | AC30: A | AD30: P | AF30: P | AG30: P | AH30: P | AI30: P | AJ30: =COUNTIF(E30:AI30,"P") -> 25 | AK30: =COUNTIF(E30:AI30,"A") -> 2
A31: 27 | B31: Parwisha | C31: Sarfaraz Ahmed | D31: ECE | E31: A | F31: A | G31: P | H31: P | I31: P | K31: P | L31: P | M31: P | N31: P | O31: P | P31: P | R31: P | S31: P | T31: P | U31: P | V31: P | W31: P | Y31: P | Z31: P | AA31: A | AB31: P | AC31: P | AD31: P | AF31: P | AG31: P | AH31: P | AI31: P | AJ31: =COUNTIF(E31:AI31,"P") -> 24 | AK31: =COUNTIF(E31:AI31,"A") -> 3
A32: 28 | B32: Muhammad Ahad | C32: Khalid Hussain Abbasi | D32: ECE | E32: A | F32: P | G32: P | H32: P | I32: P | K32: P | L32: P | M32: P | N32: P | O32: A | P32: A | R32: P | S32: P | T32: P | U32: P | V32: P | W32: P | Y32: A | Z32: P | AA32: P | AB32: P | AC32: P | AD32: P | AF32: P | AG32: P | AH32: P | AI32: P | AJ32: =COUNTIF(E32:AI32,"P") -> 23 | AK32: =COUNTIF(E32:AI32,"A") -> 4
A33: 29 | B33: Aiza | C33: Irshad-Ul-Haq | D33: ECE | E33: P | F33: P | G33: P | H33: P | I33: P | K33: P | L33: P | M33: P | N33: P | O33: P | P33: P | R33: P | S33: P | T33: P | U33: P | V33: P | W33: P | Y33: P | Z33: P | AA33: P | AB33: P | AC33: P | AD33: P | AF33: P | AG33: P | AH33: P | AI33: P | AJ33: =COUNTIF(E33:AI33,"P") -> 27 | AK33: =COUNTIF(E33:AI33,"A") -> 0
... A40: 36 | B40: M. Awais | C40: Mehboob Ali | D40: ECE | E40: A | F40: L | G40: P | H40: P | I40: P | K40: P | L40: P | M40: A | N40: P | O40: A | P40: P | R40: P | S40: P | T40: P | U40: P | V40: P | W40: P | Y40: P | Z40: P | AA40: P | AB40: P | AC40: P | AD40: P | AF40: P | AG40: P | AH40: P | AI40: P | AJ40: =COUNTIF(E40:AI40,"P") -> 23 | AK40: =COUNTIF(E40:AI40,"A") -> 3
A41: 37 | B41: M. Raheel | D41: ECE | E41: A | F41: L | G41: P | H41: P | I41: P | K41: P | L41: P | M41: P | N41: P | O41: P | P41: P | R41: P | S41: P | T41: P | U41: P | V41: P | W41: P | Y41: P | Z41: P | AA41: A | AB41: P | AC41: P | AD41: P | AF41: P | AG41: P | AH41: P | AI41: P | AJ41: =COUNTIF(E41:AI41,"P") -> 24 | AK41: =COUNTIF(E41:AI41,"A") -> 2
A42: 38 | B42: Fiza | C42: Ahmed | D42: ECE | E42: P | F42: P | G42: P | H42: P | I42: P | K42: P | L42: P | M42: P | N42: P | O42: P | P42: P | R42: P | S42: P | T42: P | U42: P | V42: P | W42: P | Y42: P | Z42: P | AA42: P | AB42: P | AC42: P | AD42: P | AF42: P | AG42: P | AH42: P | AI42: P | AJ42: =COUNTIF(E42:AI42,"P") -> 27 | AK42: =COUNTIF(E42:AI42,"A") -> 0
A43: 39 | B43: Amanullah | C43: Sajid Ahmed | D43: ECE | E43: P | F43: P | G43: P | H43: P | I43: A | K43: P | L43: P | M43: P | N43: P | O43: A | P43: P | R43: P | S43: P | T43: P | U43: A | V43: P | W43: P | Y43: P | Z43: P | AA43: P | AB43: A | AC43: A | AD43: P | AF43: A | AG43: A | AH43: P | AI43: P | AJ43: =COUNTIF(E43:AI43,"P") -> 20 | AK43: =COUNTIF(E43:AI43,"A") -> 7
A44: 40 | B44: Ahmed Ali | C44: Asghar Ali | D44: ECE | E44: P | F44: P | G44: P | H44: P | I44: A | K44: P | L44: P | M44: P | N44: P | O44: P | P44: P | R44: P | S44: P | T44: P | U44: A | V44: P | W44: P | Y44: P | Z44: P | AA44: P | AB44: P | AC44: P | AD44: P | AF44: P | AG44: P | AH44: P | AI44: P | AJ44: =COUNTIF(E44:AI44,"P") -> 25 | AK44: =COUNTIF(E44:AI44,"A") -> 2
A45: 41 | B45: M. Qasim | C45: Abdul Hameed | D45: ECE | E45: P | F45: P | G45: P | H45: P | I45: P | K45: A | L45: A | M45: P | N45: P | O45: A | P45: P | R45: P | S45: P | T45: P | U45: P | V45: P | W45: P | Y45: A | Z45: A | AA45: P | AB45: P | AC45: P | AD45: A | AF45: P | AG45: P | AH45: P | AI45: A | AJ45: =COUNTIF(E45:AI45,"P") -> 20 | AK45: =COUNTIF(E45:AI45,"A") -> 7
A46: 42 | B46: Shahbaz Ali | C46: Muhammad Ibrahim | D46: ECE | E46: P | F46: P | G46: P | H46: P | I46: P | K46: P | L46: P | M46: P | N46: P | O46: P | P46: A | R46: P | S46: P | T46: P | U46: P | V46: P | W46: P | Y46: P | Z46: P | AA46: P | AB46: P | AC46: P | AD46: P | AF46: P | AG46: P | AH46: P | AI46: P | AJ46: =COUNTIF(E46:AI46,"P") -> 26 | AK46: =COUNTIF(E46:AI46,"A") -> 1
...

Sheet ECE (Daffodils)
A1: Goverment high school (SJCHS)
A2: Monthly Attendence Month of October-2024
A3: S.No | B3: Student Name | C3: Father Name | D3: Class | E3: =TEXT(E4,"ddd") -> Tue | F3: =TEXT(F4,"ddd") -> Wed | G3: =TEXT(G4,"ddd") -> Thu | H3: =TEXT(H4,"ddd") -> Fri | I3: =TEXT(I4,"ddd") -> Sat | J3: =TEXT(J4,"ddd") -> Sun | K3: =TEXT(K4,"ddd") -> Mon | L3: =TEXT(L4,"ddd") -> Tue | ... AI3: =TEXT(AI4,"ddd") -> Thu | AJ3: Present | AK3: Absent | AL3: Year 2024
E4: 45566 | F4: 45567 | G4: 45568 | H4: 45569 | I4: 45570 | J4: 45571 | K4: 45572 | L4: 45573 | M4: 45574 | N4: 45575 | O4: 45576 | P4: 45577 | Q4: 45578 | R4: 45579 | S4: 45580 | T4: 45581 | U4: 45582 | V4: 45583 | W4: 45584 | X4: 45585 | Y4: 45586 | Z4: 45587 | AA4: 45588 | AB4: 45589 | AC4: 45590 | AD4: 45591 | AE4: 45592 | AF4: 45593 | AG4: 45594 | AH4: 45595 | AI4: 45596 | AL4: Total days | AM4: =SUM(AM5:AM7) -> 31
A5: 1 | B5: Alishba Batool | C5: Irfan Ali | D5: ECE | E5: P | F5: P | G5: P | H5: P | I5: A | J5: SUNDAY - SUNDAY - SUNDAY - SUNDAY - SUNDAY - SUNDAY - SUNDAY - SUNDAY - SUNDAY | K5: P | L5: P | M5: P | N5: P | O5: P | P5: P | Q5: SUNDAY - SUNDAY - SUNDAY - SUNDAY - SUNDAY - SUNDAY - SUNDAY - SUNDAY - SUNDAY | R5: P | S5: P | T5: P | U5: P | V5: P | W5: P | X5: SUNDAY - SUNDAY - SUNDAY - SUNDAY - SUNDAY - SUNDAY - SUNDAY - SUNDAY - SUNDAY | Y5: P | Z5: P | AA5: P | AB5: P | AC5: P | AD5: P | AE5: SUNDAY - SUNDAY - SUNDAY - SUNDAY - SUNDAY - SUNDAY - SUNDAY - SUNDAY - SUNDAY | AF5: P | AG5: P | AH5: P | AI5: P | AJ5: =COUNTIF(E5:AI5,"P") -> 26 | AK5: =COUNTIF(E5:AI5,"A") -> 1 | AL5: Working days | AM5: 27
A6: 2 | B6: Amna | C6: Imtiaz Hussain | D6: ECE | E6: P | F6: P | G6: P | H6: P | I6: P | K6: P | L6: P | M6: P | N6: P | O6: P | P6: P | R6: P | S6: P | T6: P | U6: P | V6: A | W6: P | Y6: P | Z6: P | AA6: P | AB6: P | AC6: P | AD6: A | AF6: P | AG6: P | AH6: P | AI6: P | AJ6: =COUNTIF(E6:AI6,"P") -> 25 | AK6: =COUNTIF(E6:AI6,"A") -> 2 | AL6: Sunday | AM6: 4
A7: 3 | B7: Aniza Memon | C7: M. Qasim | D7: ECE | E7: P | F7: P | G7: P | H7: P | I7: A | K7: P | L7: A | M7: P | N7: P | O7: P | P7: A | R7: P | S7: P | T7: P | U7: P | V7: P | W7: A | Y7: A | Z7: P | AA7: A | AB7: P | AC7: A | AD7: A | AF7: P | AG7: P | AH7: P | AI7: P | AJ7: =COUNTIF(E7:AI7,"P") -> 19 | AK7: =COUNTIF(E7:AI7,"A") -> 8
A8: 4 | B8: Areeba | C8: Altaf Hussain | D8: ECE | E8: P | F8: P | G8: P | H8: P | I8: P | K8: P | L8: P | M8: P | N8: A | O8: A | P8: A | R8: A | S8: P | T8: P | U8: P | V8: P | W8: P | Y8: P | Z8: P | AA8: P | AB8: P | AC8: P | AD8: A | AF8: P | AG8: P | AH8: A | AI8: P | AJ8: =COUNTIF(E8:AI8,"P") -> 21 | AK8: =COUNTIF(E8:AI8,"A") -> 6
A9: 5 | B9: Batool | C9: Amjad Ali | D9: ECE | E9: P | F9: P | G9: P | H9: P | I9: A | K9: A | L9: A | M9: A | N9: A | O9: A | P9: L | R9: L | S9: L | T9: L | U9: L | V9: L | W9: L | Y9: L | Z9: L | AA9: L | AB9: L | AC9: L | AD9: L | AF9: L | AG9: L | AH9: L | AI9: L | AJ9: =COUNTIF(E9:AI9,"P") -> 4 | AK9: =COUNTIF(E9:AI9,"A") -> 6 | AL9: Present Days Detail
A10: 6 | B10: Dua | C10: Khalid Hussain | D10: ECE | E10: P | F10: P | G10: P | H10: P | I10: P | K10: P | L10: P | M10: P | N10: P | O10: P | P10: P | R10: P | S10: P | T10: P | U10: P | V10: P | W10: P | Y10: P | Z10: P | AA10: P | AB10: P | AC10: P | AD10: P | AF10: P | AG10: P | AH10: P | AI10: P | AJ10: =COUNTIF(E10:AI10,"P") -> 27 | AK10: =COUNTIF(E10:AI10,"A") -> 0 | AL10: Detail | AM10: Boys | AN10: Girls | AO10: Total
A11: 7 | B11: Faiza | C11: Liaqat Ali | D11: ECE | E11: P | F11: P | G11: P | H11: P | I11: A | K11: P | L11: P | M11: P | N11: P | O11: P | P11: P | R11: P | S11: P | T11: P | U11: P | V11: P | W11: P | Y11: P | Z11: P | AA11: A | AB11: P | AC11: P | AD11: P | AF11: P | AG11: P | AH11: P | AI11: P | AJ11: =COUNTIF(E11:AI11,"P") -> 25 | AK11: =COUNTIF(E11:AI11,"A") -> 2 | AL11: Due Present days | AM11: =31*$AM$5 -> 837 | AN11: =25*$AM$5 -> 675 | AO11: =SUM(AM11:AN11) -> 1512
A12: 8 | B12: Fatima | C12: Aziz-ur-Rehman | D12: ECE | E12: P | F12: P | G12: A | H12: A | I12: A | K12: A | L12: P | M12: P | N12: P | O12: P | P12: P | R12: P | S12: P | T12: P | U12: P | V12: P | W12: P | Y12: P | Z12: P | AA12: P | AB12: P | AC12: P | AD12: P | AF12: P | AG12: P | AH12: P | AI12: P | AJ12: =COUNTIF(E12:AI12,"P") -> 23 | AK12: =COUNTIF(E12:AI12,"A") -> 4 | AL12: Actual present days | AM12: =SUM(AJ30:AJ60) -> 720 | AN12: =SUM(AJ5:AJ29) -> 530 | AO12: =AM12+AN12 -> 1250
A13: 9 | B13: Hafsa | C13: Hafeezullah | D13: ECE | E13: A | F13: A | G13: A | H13: P | I13: P | K13: P | L13: P | M13: P | N13: P | O13: P | P13: P | R13: P | S13: P | T13: P | U13: P | V13: P | W13: P | Y13: P | Z13: P | AA13: P | AB13: P | AC13: P | AD13: P | AF13: P | AG13: P | AH13: P | AI13: P | AJ13: =COUNTIF(E13:AI13,"P") -> 24 | AK13: =COUNTIF(E13:AI13,"A") -> 3 | AL13: % | AM13: =AM12/AM11 -> 0.86021505 | AN13: =AN12/AN11 -> 0.78518519 | AO13: =AO12/AO11 -> 0.82671958
A14: 10 | B14: Insha Arzoo | C14: Meeral | D14: ECE | E14: P | F14: P | G14: P | H14: P | I14: P | K14: P | L14: P | M14: P | N14: P | O14: P | P14: A | R14: P | S14: P | T14: P | U14: A | V14: P | W14: P | Y14: P | Z14: P | AA14: P | AB14: A | AC14: A | AD14: A | AF14: A | AG14: P | AH14: P | AI14: P | AJ14: =COUNTIF(E14:AI14,"P") -> 21 | AK14: =COUNTIF(E14:AI14,"A") -> 6
A15: 11 | B15: Kauser Fatima | C15: Amir Jamil | D15: ECE | E15: P | F15: P | G15: P | H15: P | I15: P | K15: P | L15: P | M15: P | N15: P | O15: P | P15: P | R15: A | S15: P | T15: P | U15: P | V15: P | W15: P | Y15: P | Z15: P | AA15: P | AB15: P | AC15: P | AD15: P | AF15: P | AG15: P | AH15: P | AI15: P | AJ15: =COUNTIF(E15:AI15,"P") -> 26 | AK15: =COUNTIF(E15:AI15,"A") -> 1
A16: 12 | B16: Mehrunisa | C16: Aijaz Ali | D16: ECE | E16: P | F16: P | G16: P | H16: P | I16: A | K16: P | L16: P | M16: P | N16: A | O16: P | P16: P | R16: P | S16: P | T16: A | U16: P | V16: P | W16: P | Y16: P | Z16: P | AA16: P | AB16: P | AC16: P | AD16: P | AF16: P | AG16: P | AH16: P | AI16: A | AJ16: =COUNTIF(E16:AI16,"P") -> 23 | AK16: =COUNTIF(E16:AI16,"A") -> 4
A17: 13 | B17: Mirha | C17: M. Luqman | D17: ECE | E17: P | F17: P | G17: P | H17: P | I17: P | K17: P | L17: P | M17: P | N17: P | O17: P | P17: L | R17: L | S17: P | T17: P | U17: P | V17: P | W17: P | Y17: P | Z17: P | AA17: P | AB17: P | AC17: P | AD17: P | AF17: P | AG17: P | AH17: P | AI17: P | AJ17: =COUNTIF(E17:AI17,"P") -> 25 | AK17: =COUNTIF(E17:AI17,"A") -> 0 | AL17: Absent Days Details
A18: 14 | B18: Misbah Bhutto | C18: M. Azeem | D18: ECE | E18: P | F18: P | G18: P | H18: P | I18: P | K18: P | L18: P | M18: P | N18: P | O18: P | P18: A | R18: A | S18: P | T18: P | U18: P | V18: P | W18: P | Y18: A | Z18: P | AA18: P | AB18: P | AC18: P | AD18: A | AF18: P | AG18: P | AH18: P | AI18: P | AJ18: =COUNTIF(E18:AI18,"P") -> 23 | AK18: =COUNTIF(E18:AI18,"A") -> 4 | AL18: Detail | AM18: Boys | AN18: Girls | AO18: Total
A19: 15 | B19: Rimsha | C19: Meer Ameer-ud-Din | D19: ECE | E19: A | F19: A | G19: A | H19: A | I19: A | K19: P | L19: P | M19: P | N19: P | O19: P | P19: P | R19: A | S19: P | T19: P | U19: P | V19: P | W19: P | Y19: P | Z19: P | AA19: P | AB19: P | AC19: A | AD19: P | AF19: P | AG19: P | AH19: P | AI19: P | AJ19: =COUNTIF(E19:AI19,"P") -> 20 | AK19: =COUNTIF(E19:AI19,"A") -> 7 | AL19: Due Present days | AM19: =31*$AM$5 -> 837 | AN19: =25*$AM$5 -> 675 | AO19: =AM19+AN19 -> 1512
A20: 16 | B20: Sidra | C20: Khalid Hussain | D20: ECE | E20: P | F20: P | G20: P | H20: P | I20: P | K20: P | L20: P | M20: P | N20: P | O20: P | P20: P | R20: P | S20: P | T20: P | U20: P | V20: P | W20: P | Y20: P | Z20: P | AA20: P | AB20: P | AC20: P | AD20: P | AF20: P | AG20: P | AH20: P | AI20: P | AJ20: =COUNTIF(E20:AI20,"P") -> 27 | AK20: =COUNTIF(E20:AI20,"A") -> 0 | AL20: Absent days | AM20: =AM19-AM12 -> 117 | AN20: =AN19-AN12 -> 145 | AO20: =AM20+AN20 -> 262
A21: 17 | B21: Sidra Batool | C21: M. Khan | D21: ECE | E21: P | F21: P | G21: P | H21: P | I21: P | K21: P | L21: P | M21: P | N21: P | O21: P | P21: P | R21: P | S21: P | T21: P | U21: P | V21: P | W21: P | Y21: P | Z21: P | AA21: P | AB21: P | AC21: P | AD21: P | AF21: P | AG21: P | AH21: P | AI21: P | AJ21: =COUNTIF(E21:AI21,"P") -> 27 | AK21: =COUNTIF(E21:AI21,"A") -> 0 | AL21: % | AM21: =AM20/AM19 -> 0.13978495 | AN21: =AN20/AN19 -> 0.21481481 | AO21: =AO20/AO19 -> 0.17328042
A22: 18 | B22: Taniya Bibi | C22: Wazir Ali | D22: ECE | E22: P | F22: P | G22: P | H22: A | I22: P | K22: P | L22: P | M22: P | N22: A | O22: A | P22: P | R22: P | S22: A | T22: P | U22: P | V22: P | W22: P | Y22: P | Z22: A | AA22: P | AB22: P | AC22: P | AD22: P | AF22: A | AG22: P | AH22: P | AI22: A | AJ22: =COUNTIF(E22:AI22,"P") -> 20 | AK22: =COUNTIF(E22:AI22,"A") -> 7
A23: 19 | B23: Tanzeela | C23: Hizbullah | D23: ECE | E23: P | F23: P | G23: A | H23: A | I23: A | K23: A | L23: A | M23: A | N23: A | O23: A | P23: A | R23: A | S23: P | T23: P | U23: P | V23: P | W23: A | Y23: P | Z23: P | AA23: P | AB23: P | AC23: P | AD23: P | AF23: P | AG23: P | AH23: P | AI23: P | AJ23: =COUNTIF(E23:AI23,"P") -> 16 | AK23: =COUNTIF(E23:AI23,"A") -> 11
A24: 20 | B24: Tayaba Fatima | C24: Waseem Ahmed | D24: ECE | E24: P | F24: P | G24: P | H24: P | I24: P | K24: P | L24: P | M24: P | N24: P | O24: P | P24: A | R24: P | S24: P | T24: P | U24: P | V24: P | W24: P | Y24: P | Z24: P | AA24: P | AB24: P | AC24: P | AD24: A | AF24: P | AG24: P | AH24: P | AI24: P | AJ24: =COUNTIF(E24:AI24,"P") -> 25 | AK24: =COUNTIF(E24:AI24,"A") -> 2
A25: 21 | B25: Tooba Noor | C25: M. Shareef | D25: ECE | E25: P | F25: P | G25: P | H25: P | I25: A | K25: P | L25: P | M25: P | N25: P | O25: P | P25: P | R25: P | S25: P | T25: P | U25: P | V25: P | W25: P | Y25: P | Z25: P | AA25: P | AB25: P | AC25: P | AD25: P | AF25: P | AG25: P | AH25: P | AI25: P | AJ25: =COUNTIF(E25:AI25,"P") -> 26 | AK25: =COUNTIF(E25:AI25,"A") -> 1
A26: 22 | B26: Umm-e-Kulsoom | C26: Shah Ali | D26: ECE | E26: P | F26: P | G26: P | H26: P | I26: A | K26: P | L26: P | M26: P | N26: P | O26: P | P26: A | R26: P | S26: P | T26: P | U26: P | V26: P | W26: P | Y26: P | Z26: P | AA26: P | AB26: P | AC26: P | AD26: P | AF26: P | AG26: P | AH26: P | AI26: P | AJ26: =COUNTIF(E26:AI26,"P") -> 25 | AK26: =COUNTIF(E26:AI26,"A") -> 2
A27: 23 | B27: Zunaira | C27: Amjad Ali | D27: ECE | E27: P | F27: A | G27: A | H27: A | I27: A | K27: A | L27: A | M27: A | N27: A | O27: A | P27: A | R27: L | S27: L | T27: L | U27: L | V27: L | W27: L | Y27: L | Z27: L | AA27: L | AB27: L | AC27: L | AD27: L | AF27: L | AG27: L | AH27: L | AI27: L | AJ27: =COUNTIF(E27:AI27,"P") -> 1 | AK27: =COUNTIF(E27:AI27,"A") -> 10
A28: 24 | B28: Sahib Khatoon | C28: A. Qayoom | D28: ECE | E28: A | F28: A | G28: A | H28: A | I28: P | K28: P | L28: P | M28: P | N28: P | O28: A | P28: P | R28: A | S28: P | T28: A | U28: L | V28: L | W28: L | Y28: L | Z28: P | AA28: A | AB28: P | AC28: A | AD28: A | AF28: P | AG28: P | AH28: P | AI28: P | AJ28: =COUNTIF(E28:AI28,"P") -> 13 | AK28: =COUNTIF(E28:AI28,"A") -> 10
A29: 25 | B29: Parsa Batool | D29: ECE | E29: P | F29: A | G29: P | H29: A | I29: A | K29: P | L29: P | M29: P | N29: A | O29: P | P29: A | R29: P | S29: P | T29: P | U29: A | V29: P | W29: P | Y29: P | Z29: P | AA29: P | AB29: P | AC29: A | AD29: P | AF29: P | AG29: A | AH29: P | AI29: A | AJ29: =COUNTIF(E29:AI29,"P") -> 18 | AK29: =COUNTIF(E29:AI29,"A") -> 9
A30: 1 | B30: Abrar | C30: Jan Muhammad | D30: ECE | E30: P | F30: A | G30: L | H30: L | I30: A | K30: P | L30: P | M30: P | N30: P | O30: P | P30: P | R30: P | S30: P | T30: P | U30: P | V30: P | W30: P | Y30: P | Z30: P | AA30: P | AB30: P | AC30: P | AD30: P | AF30: P | AG30: P | AH30: P | AI30: P | AJ30: =COUNTIF(E30:AI30,"P") -> 23 | AK30: =COUNTIF(E30:AI30,"A") -> 2
A31: 2 | B31: Azan Shafeeque | C31: M. Shafeeque | D31: ECE | E31: P | F31: A | G31: A | H31: A | I31: A | K31: P | L31: P | M31: P | N31: P | O31: P | P31: P | R31: P | S31: P | T31: P | U31: P | V31: P | W31: P | Y31: P | Z31: P | AA31: P | AB31: P | AC31: P | AD31: P | AF31: P | AG31: P | AH31: P | AI31: P | AJ31: =COUNTIF(E31:AI31,"P") -> 23 | AK31: =COUNTIF(E31:AI31,"A") -> 4
A32: 3 | B32: Azan Fayaz | C32: Fayaz Hussain | D32: ECE | E32: P | F32: P | G32: P | H32: P | I32: A | K32: P | L32: P | M32: P | N32: P | O32: P | P32: P | R32: P | S32: P | T32: P | U32: P | V32: P | W32: P | Y32: P | Z32: P | AA32: P | AB32: P | AC32: P | AD32: P | AF32: P | AG32: P | AH32: P | AI32: P | AJ32: =COUNTIF(E32:AI32,"P") -> 26 | AK32: =COUNTIF(E32:AI32,"A") -> 1
A33: 4 | B33: Adil Ahmed | C33: Faiz Muhammad | D33: ECE | E33: P | F33: P | G33: P | H33: P | I33: A | K33: P | L33: P | M33: P | N33: P | O33: P | P33: A | R33: P | S33: P | T33: P | U33: P | V33: A | W33: P | Y33: P | Z33: P | AA33: P | AB33: P | AC33: P | AD33: P | AF33: P | AG33: P | AH33: P | AI33: P | AJ33: =COUNTIF(E33:AI33,"P") -> 24 | AK33: =COUNTIF(E33:AI33,"A") -> 3
A34: 5 | B34: Ab. Qudoos | C34: Sikandar | D34: ECE | E34: P | F34: P | G34: P | H34: P | I34: A | K34: P | L34: P | M34: P | N34: P | O34: P | P34: P | R34: P | S34: P | T34: P | U34: P | V34: P | W34: P | Y34: P | Z34: P | AA34: P | AB34: P | AC34: P | AD34: P | AF34: P | AG34: P | AH34: P | AI34: P | AJ34: =COUNTIF(E34:AI34,"P") -> 26 | AK34: =COUNTIF(E34:AI34,"A") -> 1
A35: 6 | B35: Ab. Rehman | C35: M. Aslam | D35: ECE | E35: P | F35: P | G35: P | H35: P | I35: P | K35: P | L35: P | M35: P | N35: P | O35: A | P35: A | R35: A | S35: A | T35: P | U35: P | V35: P | W35: A | Y35: P | Z35: P | AA35: P | AB35: P | AC35: P | AD35: P | AF35: P | AG35: P | AH35: P | AI35: A | AJ35: =COUNTIF(E35:AI35,"P") -> 21 | AK35: =COUNTIF(E35:AI35,"A") -> 6
A36: 7 | B36: Ahmed Zia | C36: Zia Buksh | D36: ECE | E36: P | F36: A | G36: P | H36: P | I36: P | K36: A | L36: P | M36: P | N36: P | O36: P | P36: P | R36: P | S36: P | T36: P | U36: A | V36: P | W36: P | Y36: P | Z36: P | AA36: P | AB36: P | AC36: A | AD36: A | AF36: P | AG36: P | AH36: P | AI36: P | AJ36: =COUNTIF(E36:AI36,"P") -> 22 | AK36: =COUNTIF(E36:AI36,"A") -> 5
A37: 8 | B37: Arham | C37: Qasim Memon | D37: ECE | E37: P | F37: P | G37: P | H37: P | I37: P | K37: P | L37: A | M37: P | N37: P | O37: P | P37: A | R37: P | S37: P | T37: P | U37: P | V37: P | W37: A | Y37: A | Z37: P | AA37: P | AB37: P | AC37: A | AD37: A | AF37: P | AG37: P | AH37: P | AI37: P | AJ37: =COUNTIF(E37:AI37,"P") -> 21 | AK37: =COUNTIF(E37:AI37,"A") -> 6
A38: 9 | B38: Amar Farooque | C38: M. Farooque | D38: ECE | E38: P | F38: P | G38: P | H38: A | I38: P | K38: P | L38: P | M38: P | N38: P | O38: A | P38: P | R38: P | S38: P | T38: P | U38: P | V38: A | W38: P | Y38: P | Z38: P | AA38: A | AB38: P | AC38: A | AD38: P | AF38: A | AG38: P | AH38: A | AI38: A | AJ38: =COUNTIF(E38:AI38,"P") -> 19 | AK38: =COUNTIF(E38:AI38,"A") -> 8
A39: 10 | B39: Ashfaque | C39: M. Zubair | D39: ECE | E39: P | F39: P | G39: P | H39: P | I39: P | K39: P | L39: P | M39: P | N39: P | O39: P | P39: P | R39: P | S39: P | T39: P | U39: P | V39: P | W39: P | Y39: P | Z39: P | AA39: P | AB39: P | AC39: P | AD39: P | AF39: P | AG39: P | AH39: P | AI39: P | AJ39: =COUNTIF(E39:AI39,"P") -> 27 | AK39: =COUNTIF(E39:AI39,"A") -> 0
A40: 11 | B40: Fahad | C40: M. Maroof | D40: ECE | E40: P | F40: P | G40: P | H40: P | I40: A | K40: A | L40: A | M40: P | N40: P | O40: P | P40: P | R40: P | S40: P | T40: P | U40: P | V40: P | W40: P | Y40: P | Z40: L | AA40: L | AB40: L | AC40: L | AD40: P | AF40: P | AG40: P | AH40: P | AI40: A | AJ40: =COUNTIF(E40:AI40,"P") -> 19 | AK40: =COUNTIF(E40:AI40,"A") -> 4
...

Sheet Class-I
A1: Goverment high school (SJCHS)
A2: Monthly Attendence Month of October-2024
A3: S.No | B3: Student Name | C3: Father Name | D3: Class | E3: =TEXT(E4,"ddd") -> Tue | F3: =TEXT(F4,"ddd") -> Wed | G3: =TEXT(G4,"ddd") -> Thu | H3: =TEXT(H4,"ddd") -> Fri | I3: =TEXT(I4,"ddd") -> Sat | J3: =TEXT(J4,"ddd") -> Sun | K3: =TEXT(K4,"ddd") -> Mon | L3: =TEXT(L4,"ddd") -> Tue | ... AI3: =TEXT(AI4,"ddd") -> Thu | AJ3: Present | AK3: Absent | AL3: Year 2024
E4: 45566 | F4: 45567 | G4: 45568 | H4: 45569 | I4: 45570 | J4: 45571 | K4: 45572 | L4: 45573 | M4: 45574 | N4: 45575 | O4: 45576 | P4: 45577 | Q4: 45578 | R4: 45579 | S4: 45580 | T4: 45581 | U4: 45582 | V4: 45583 | W4: 45584 | X4: 45585 | Y4: 45586 | Z4: 45587 | AA4: 45588 | AB4: 45589 | AC4: 45590 | AD4: 45591 | AE4: 45592 | AF4: 45593 | AG4: 45594 | AH4: 45595 | AI4: 45596 | AL4: Total days | AM4: =SUM(AM5:AM7) -> 31
A5: 1 | B5: Anum | C5: M. Arif | D5: One | E5: P | F5: P | G5: P | H5: P | I5: P | J5: SUNDAY - SUNDAY - SUNDAY - SUNDAY - SUNDAY - SUNDAY - SUNDAY | K5: P | L5: P | M5: P | N5: P | O5: P | P5: P | Q5: SUNDAY - SUNDAY - SUNDAY - SUNDAY - SUNDAY - SUNDAY - SUNDAY | R5: P | S5: P | T5: P | U5: P | V5: P | W5: P | X5: SUNDAY - SUNDAY - SUNDAY - SUNDAY - SUNDAY - SUNDAY - SUNDAY | Y5: A | Z5: P | AA5: P | AB5: P | AC5: P | AD5: P | AE5: SUNDAY - SUNDAY - SUNDAY - SUNDAY - SUNDAY - SUNDAY - SUNDAY | AF5: P | AG5: P | AH5: P | AI5: P | AJ5: =COUNTIF(E5:AI5,"P") -> 26 | AK5: =COUNTIF(E5:AI5,"A") -> 1 | AL5: Working days | AM5: 27
A6: 2 | B6: Ayat | C6: Meer Mohammad | D6: One | E6: A | F6: P | G6: P | H6: A | I6: P | K6: P | L6: P | M6: P | N6: P | O6: P | P6: A | R6: P | S6: P | T6: P | U6: P | V6: P | W6: A | Y6: P | Z6: P | AA6: P | AB6: A | AC6: A | AD6: A | AF6: A | AG6: A | AH6: A | AI6: A | AJ6: =COUNTIF(E6:AI6,"P") -> 16 | AK6: =COUNTIF(E6:AI6,"A") -> 11 | AL6: Sunday | AM6: 4
A7: 3 | B7: Amna | C7: Saeed Ahmed | D7: One | E7: P | F7: P | G7: P | H7: P | I7: P | K7: P | L7: P | M7: P | N7: P | O7: P | P7: P | R7: P | S7: A | T7: P | U7: P | V7: P | W7: P | Y7: P | Z7: P | AA7: P | AB7: P | AC7: P | AD7: P | AF7: P | AG7: P | AH7: P | AI7: P | AJ7: =COUNTIF(E7:AI7,"P") -> 26 | AK7: =COUNTIF(E7:AI7,"A") -> 1
A8: 4 | B8: Adeeba | C8: Qurban Ali | D8: One | E8: P | F8: P | G8: A | H8: A | I8: A | K8: P | L8: P | M8: P | N8: P | O8: P | P8: P | R8: P | S8: P | T8: P | U8: A | V8: P | W8: A | Y8: P | Z8: P | AA8: P | AB8: P | AC8: A | AD8: P | AF8: P | AG8: P | AH8: P | AI8: P | AJ8: =COUNTIF(E8:AI8,"P") -> 21 | AK8: =COUNTIF(E8:AI8,"A") -> 6
A9: 5 | B9: Emaan Noor | C9: Noor Mohammad | D9: One | E9: P | F9: P | G9: P | H9: P | I9: A | K9: P | L9: P | M9: P | N9: P | O9: P | P9: P | R9: P | S9: P | T9: P | U9: P | V9: P | W9: P | Y9: P | Z9: P | AA9: P | AB9: P | AC9: P | AD9: P | AF9: P | AG9: P | AH9: P | AI9: P | AJ9: =COUNTIF(E9:AI9,"P") -> 26 | AK9: =COUNTIF(E9:AI9,"A") -> 1 | AL9: Present Days Detail
A10: 6 | B10: Horain | C10: Saeed Ahmed | D10: One | E10: P | F10: P | G10: A | H10: P | I10: A | K10: P | L10: A | M10: P | N10: P | O10: P | P10: A | R10: P | S10: P | T10: P | U10: A | V10: P | W10: P | Y10: P | Z10: P | AA10: P | AB10: P | AC10: A | AD10: P | AF10: P | AG10: P | AH10: P | AI10: P | AJ10: =COUNTIF(E10:AI10,"P") -> 21 | AK10: =COUNTIF(E10:AI10,"A") -> 6 | AL10: Detail | AM10: Boys | AN10: Girls | AO10: Total
A11: 7 | B11: Hannah | C11: Luqman Ali | D11: One | E11: P | F11: P | G11: P | H11: P | I11: P | K11: P | L11: P | M11: P | N11: P | O11: L | P11: A | R11: A | S11: P | T11: P | U11: P | V11: P | W11: P | Y11: P | Z11: P | AA11: P | AB11: P | AC11: P | AD11: P | AF11: P | AG11: P | AH11: P | AI11: P | AJ11: =COUNTIF(E11:AI11,"P") -> 24 | AK11: =COUNTIF(E11:AI11,"A") -> 2 | AL11: Due Present days | AM11: =32*$AM$5 -> 864 | AN11: =24*$AM$5 -> 648 | AO11: =SUM(AM11:AN11) -> 1512
A12: 8 | B12: Horiya | C12: Siddique | D12: One | E12: P | F12: P | G12: P | H12: P | I12: A | K12: P | L12: P | M12: P | N12: P | O12: P | P12: P | R12: P | S12: P | T12: P | U12: P | V12: P | W12: P | Y12: P | Z12: P | AA12: P | AB12: P | AC12: P | AD12: A | AF12: P | AG12: P | AH12: P | AI12: P | AJ12: =COUNTIF(E12:AI12,"P") -> 25 | AK12: =COUNTIF(E12:AI12,"A") -> 2 | AL12: Actual present days | AM12: =SUM(AJ29:AJ60) -> 746 | AN12: =SUM(AJ5:AJ28) -> 525 | AO12: =AM12+AN12 -> 1271
A13: 9 | B13: Hareem Fatima | C13: Deedar Ali | D13: One | E13: P | F13: P | G13: P | H13: P | I13: A | K13: P | L13: P | M13: P | N13: P | O13: P | P13: P | R13: P | S13: P | T13: P | U13: P | V13: P | W13: A | Y13: P | Z13: P | AA13: P | AB13: P | AC13: P | AD13: P | AF13: P | AG13: P | AH13: P | AI13: P | AJ13: =COUNTIF(E13:AI13,"P") -> 25 | AK13: =COUNTIF(E13:AI13,"A") -> 2 | AL13: % | AM13: =AM12/AM11 -> 0.86342593 | AN13: =AN12/AN11 -> 0.81018519 | AO13: =AO12/AO11 -> 0.84060847
A14: 10 | B14: Maham Noor | C14: Zaheer Abbas | D14: One | E14: P | F14: P | G14: P | H14: P | I14: A | K14: P | L14: P | M14: P | N14: P | O14: P | P14: P | R14: P | S14: P | T14: P | U14: P | V14: P | W14: P | Y14: P | Z14: P | AA14: P | AB14: P | AC14: P | AD14: P | AF14: P | AG14: P | AH14: P | AI14: P | AJ14: =COUNTIF(E14:AI14,"P") -> 26 | AK14: =COUNTIF(E14:AI14,"A") -> 1
A15: 11 | B15: Maria | C15: Mehboob Ali | D15: One | E15: P | F15: P | G15: A | H15: A | I15: A | K15: P | L15: P | M15: P | N15: A | O15: A | P15: A | R15: A | S15: P | T15: A | U15: P | V15: P | W15: A | Y15: A | Z15: A | AA15: A | AB15: A | AC15: A | AD15: A | AF15: P | AG15: A | AH15: P | AI15: P | AJ15: =COUNTIF(E15:AI15,"P") -> 11 | AK15: =COUNTIF(E15:AI15,"A") -> 16
A16: 12 | B16: Mehreen | C16: M. Maroof | D16: One | E16: P | F16: P | G16: P | H16: P | I16: A | K16: P | L16: A | M16: P | N16: P | O16: P | P16: P | R16: P | S16: P | T16: P | U16: P | V16: P | W16: P | Y16: P | Z16: L | AA16: L | AB16: A | AC16: A | AD16: P | AF16: P | AG16: P | AH16: P | AI16: P | AJ16: =COUNTIF(E16:AI16,"P") -> 21 | AK16: =COUNTIF(E16:AI16,"A") -> 4
A17: 13 | B17: Mahira | C17: Arbab Ali | D17: One | E17: P | F17: A | G17: P | H17: A | I17: A | K17: A | L17: A | M17: A | N17: A | O17: A | P17: A | R17: P | S17: P | T17: P | U17: P | V17: P | W17: P | Y17: P | Z17: P | AA17: P | AB17: P | AC17: A | AD17: P | AF17: A | AG17: A | AH17: A | AI17: P | AJ17: =COUNTIF(E17:AI17,"P") -> 14 | AK17: =COUNTIF(E17:AI17,"A") -> 13 | AL17: Absent Days Details
A18: 14 | B18: Meerab | C18: Yasir Ahmed | D18: One | E18: A | F18: A | G18: A | H18: A | I18: A | K18: P | L18: P | M18: P | N18: P | O18: P | P18: P | R18: P | S18: P | T18: P | U18: P | V18: P | W18: P | Y18: A | Z18: A | AA18: A | AB18: A | AC18: A | AD18: A | AF18: P | AG18: P | AH18: P | AI18: P | AJ18: =COUNTIF(E18:AI18,"P") -> 16 | AK18: =COUNTIF(E18:AI18,"A") -> 11 | AL18: Detail | AM18: Boys | AN18: Girls | AO18: Total
A19: 15 | B19: Qudsia Zehra | C19: Awaheed Ali | D19: One | E19: A | F19: A | G19: P | H19: P | I19: P | K19: P | L19: P | M19: P | N19: P | O19: P | P19: P | R19: P | S19: P | T19: P | U19: P | V19: P | W19: P | Y19: P | Z19: P | AA19: P | AB19: P | AC19: P | AD19: A | AF19: P | AG19: P | AH19: P | AI19: P | AJ19: =COUNTIF(E19:AI19,"P") -> 24 | AK19: =COUNTIF(E19:AI19,"A") -> 3 | AL19: Due Present days | AM19: =32*$AM$5 -> 864 | AN19: =24*$AM$5 -> 648 | AO19: =AM19+AN19 -> 1512
A20: 16 | B20: Paras | C20: Sadam | D20: One | E20: P | F20: P | G20: P | H20: P | I20: A | K20: A | L20: P | M20: P | N20: P | O20: P | P20: A | R20: P | S20: P | T20: P | U20: P | V20: P | W20: A | Y20: P | Z20: P | AA20: P | AB20: P | AC20: P | AD20: A | AF20: P | AG20: P | AH20: P | AI20: P | AJ20: =COUNTIF(E20:AI20,"P") -> 22 | AK20: =COUNTIF(E20:AI20,"A") -> 5 | AL20: Absent days | AM20: =AM19-AM12 -> 118 | AN20: =AN19-AN12 -> 123 | AO20: =AM20+AN20 -> 241
A21: 17 | B21: Thamna Batool | C21: Shehzad | D21: One | E21: P | F21: P | G21: P | H21: P | I21: A | K21: P | L21: P | M21: P | N21: P | O21: P | P21: P | R21: P | S21: P | T21: P | U21: P | V21: A | W21: A | Y21: P | Z21: A | AA21: P | AB21: P | AC21: P | AD21: P | AF21: P | AG21: P | AH21: A | AI21: P | AJ21: =COUNTIF(E21:AI21,"P") -> 22 | AK21: =COUNTIF(E21:AI21,"A") -> 5 | AL21: % | AM21: =AM20/AM19 -> 0.13657407 | AN21: =AN20/AN19 -> 0.18981481 | AO21: =AO20/AO19 -> 0.15939153
A22: 18 | B22: Tamana Fatima | C22: Shehzad | D22: One | E22: P | F22: P | G22: P | H22: P | I22: A | K22: P | L22: P | M22: P | N22: P | O22: P | P22: P | R22: P | S22: P | T22: P | U22: P | V22: A | W22: A | Y22: P | Z22: A | AA22: P | AB22: P | AC22: P | AD22: P | AF22: P | AG22: P | AH22: A | AI22: P | AJ22: =COUNTIF(E22:AI22,"P") -> 22 | AK22: =COUNTIF(E22:AI22,"A") -> 5
A23: 19 | B23: Zaiba Bakhtawar | C23: Hameed | D23: One | E23: P | F23: P | G23: P | H23: P | I23: A | K23: P | L23: P | M23: P | N23: P | O23: P | P23: A | R23: P | S23: P | T23: P | U23: P | V23: P | W23: P | Y23: P | Z23: P | AA23: P | AB23: P | AC23: P | AD23: A | AF23: P | AG23: P | AH23: P | AI23: P | AJ23: =COUNTIF(E23:AI23,"P") -> 24 | AK23: =COUNTIF(E23:AI23,"A") -> 3
A24: 20 | B24: Zainab | C24: A. Aziz | D24: One | E24: P | F24: P | G24: P | H24: P | I24: A | K24: P | L24: P | M24: P | N24: P | O24: P | P24: P | R24: P | S24: P | T24: P | U24: P | V24: P | W24: A | Y24: P | Z24: P | AA24: P | AB24: P | AC24: P | AD24: P | AF24: P | AG24: P | AH24: P | AI24: P | AJ24: =COUNTIF(E24:AI24,"P") -> 25 | AK24: =COUNTIF(E24:AI24,"A") -> 2
A25: 21 | B25: Zainab | C25: Zulfiqar | D25: One | E25: P | F25: P | G25: P | H25: P | I25: A | K25: P | L25: P | M25: P | N25: P | O25: P | P25: A | R25: P | S25: P | T25: P | U25: P | V25: P | W25: P | Y25: P | Z25: P | AA25: P | AB25: P | AC25: P | AD25: P | AF25: P | AG25: P | AH25: P | AI25: P | AJ25: =COUNTIF(E25:AI25,"P") -> 25 | AK25: =COUNTIF(E25:AI25,"A") -> 2
A26: 22 | B26: Waniya | C26: Asad Ali | D26: One | E26: P | F26: A | G26: P | H26: P | I26: A | K26: P | L26: P | M26: P | N26: P | O26: P | P26: P | R26: P | S26: P | T26: P | U26: P | V26: A | W26: P | Y26: P | Z26: P | AA26: P | AB26: P | AC26: P | AD26: A | AF26: A | AG26: P | AH26: P | AI26: P | AJ26: =COUNTIF(E26:AI26,"P") -> 22 | AK26: =COUNTIF(E26:AI26,"A") -> 5
A27: 23 | B27: Haram | C27: Moien Khan | D27: One | E27: P | F27: P | G27: P | H27: P | I27: P | K27: P | L27: P | M27: P | N27: P | O27: P | P27: P | R27: A | S27: P | T27: P | U27: P | V27: A | W27: A | Y27: A | Z27: P | AA27: P | AB27: P | AC27: P | AD27: P | AF27: P | AG27: P | AH27: P | AI27: P | AJ27: =COUNTIF(E27:AI27,"P") -> 23 | AK27: =COUNTIF(E27:AI27,"A") -> 4
A28: 24 | B28: Ayesha | C28: A. Latif | D28: One | E28: P | F28: P | G28: P | H28: P | I28: A | K28: P | L28: P | M28: L | N28: L | O28: L | P28: L | R28: P | S28: P | T28: P | U28: P | V28: P | W28: P | Y28: A | Z28: P | AA28: P | AB28: A | AC28: A | AD28: A | AF28: P | AG28: P | AH28: P | AI28: P | AJ28: =COUNTIF(E28:AI28,"P") -> 18 | AK28: =COUNTIF(E28:AI28,"A") -> 5
A29: 1 | B29: Arsalan | C29: Zulfiqar | D29: One | E29: P | F29: P | G29: P | H29: P | I29: A | K29: P | L29: P | M29: P | N29: P | O29: P | P29: P | R29: P | S29: P | T29: P | U29: P | V29: P | W29: A | Y29: P | Z29: P | AA29: P | AB29: P | AC29: P | AD29: A | AF29: P | AG29: P | AH29: P | AI29: P | AJ29: =COUNTIF(E29:AI29,"P") -> 24 | AK29: =COUNTIF(E29:AI29,"A") -> 3
A30: 2 | B30: Arsalan | C30: Faheem | D30: One | E30: P | F30: P | G30: P | H30: P | I30: A | K30: P | L30: P | M30: P | N30: P | O30: P | P30: P | R30: P | S30: P | T30: P | U30: P | V30: L | W30: L | Y30: P | Z30: P | AA30: P | AB30: P | AC30: A | AD30: P | AF30: P | AG30: P | AH30: P | AI30: A | AJ30: =COUNTIF(E30:AI30,"P") -> 22 | AK30: =COUNTIF(E30:AI30,"A") -> 3
A31: 3 | B31: A. Nawaz | C31: M. Nawaz | D31: One | E31: P | F31: P | G31: P | H31: P | I31: A | K31: P | L31: P | M31: P | N31: P | O31: P | P31: P | R31: P | S31: P | T31: P | U31: P | V31: P | W31: P | Y31: P | Z31: A | AA31: A | AB31: A | AC31: A | AD31: P | AF31: P | AG31: P | AH31: P | AI31: P | AJ31: =COUNTIF(E31:AI31,"P") -> 22 | AK31: =COUNTIF(E31:AI31,"A") -> 5
A32: 4 | B32: A. Malik | C32: Sohail | D32: One | E32: P | F32: P | G32: A | H32: P | I32: P | K32: A | L32: P | M32: P | N32: P | O32: P | P32: A | R32: A | S32: P | T32: P | U32: P | V32: A | W32: P | Y32: P | Z32: P | AA32: P | AB32: P | AC32: A | AD32: P | AF32: A | AG32: A | AH32: A | AI32: P | AJ32: =COUNTIF(E32:AI32,"P") -> 18 | AK32: =COUNTIF(E32:AI32,"A") -> 9
A33: 5 | B33: Abdullah | C33: Imtiaz | D33: One | E33: P | F33: P | G33: P | H33: P | I33: P | K33: P | L33: P | M33: P | N33: P | O33: P | P33: P | R33: P | S33: P | T33: P | U33: P | V33: P | W33: P | Y33: P | Z33: P | AA33: P | AB33: P | AC33: P | AD33: A | AF33: P | AG33: P | AH33: P | AI33: P | AJ33: =COUNTIF(E33:AI33,"P") -> 26 | AK33: =COUNTIF(E33:AI33,"A") -> 1
... A60: 32 | B60: Zain Ali | C60: Altaf | D60: One | E60: P | F60: P | G60: P | H60: P | I60: P | K60: P | L60: P | M60: P | N60: A | O60: A | P60: P | R60: P | S60: P | T60: P | U60: P | V60: P | W60: P | Y60: P | Z60: P | AA60: P | AB60: P | AC60: P | AD60: A | AF60: A | AG60: P | AH60: P | AI60: P | AJ60: =COUNTIF(E60:AI60,"P") -> 23 | AK60: =COUNTIF(E60:AI60,"A") -> 4

Sheet Class-II
A1: Goverment High School (SJCHS)
A2: Monthly Attendence Month of October-2024
A3: S.No | B3: Student Name | C3: Father Name | D3: Class | E3: =TEXT(E4,"ddd") -> Tue | F3: =TEXT(F4,"ddd") -> Wed | G3: =TEXT(G4,"ddd") -> Thu | H3: =TEXT(H4,"ddd") -> Fri | I3: =TEXT(I4,"ddd") -> Sat | J3: =TEXT(J4,"ddd") -> Sun | K3: =TEXT(K4,"ddd") -> Mon | L3: =TEXT(L4,"ddd") -> Tue | ... AI3: =TEXT(AI4,"ddd") -> Thu | AJ3: Present | AK3: Absent | AL3: Year 2024
E4: 45566 | F4: 45567 | G4: 45568 | H4: 45569 | I4: 45570 | J4: 45571 | K4: 45572 | L4: 45573 | M4: 45574 | N4: 45575 | O4: 45576 | P4: 45577 | Q4: 45578 | R4: 45579 | S4: 45580 | T4: 45581 | U4: 45582 | V4: 45583 | W4: 45584 | X4: 45585 | Y4: 45586 | Z4: 45587 | AA4: 45588 | AB4: 45589 | AC4: 45590 | AD4: 45591 | AE4: 45592 | AF4: 45593 | AG4: 45594 | AH4: 45595 | AI4: 45596 | AL4: Total days | AM4: =SUM(AM5:AM7) -> 31
A5: 1 | B5: Abiha Zehra | C5: Ab. Mateen | D5: Two | E5: P | F5: P | G5: P | H5: P | I5: PTM - PTM - PTM - PTM - PTM - PTM - PTM - PTM - PTM - PTM | J5: SUNDAY - SUNDAY - SUNDAY - SUNDAY - SUNDAY - SUNDAY | K5: P | L5: P | M5: P | N5: P | O5: P | P5: P | Q5: SUNDAY - SUNDAY - SUNDAY - SUNDAY - SUNDAY - SUNDAY | R5: P | S5: P | T5: P | U5: A | V5: P | W5: P | X5: SUNDAY - SUNDAY - SUNDAY - SUNDAY - SUNDAY - SUNDAY | Y5: P | Z5: A | AA5: P | AB5: A | AC5: A | AD5: A | AE5: SUNDAY - SUNDAY - SUNDAY - SUNDAY - SUNDAY - SUNDAY | AF5: P | AG5: A | AH5: A | AI5: P | AJ5: =COUNTIF(E5:AI5,"P") -> 19 | AK5: =COUNTIF(E5:AI5,"A") -> 7 | AL5: Working days | AM5: 26
A6: 2 | B6: Aleena Zia | C6: Khuda Baksh | D6: Two | E6: P | F6: A | G6: P | H6: P | K6: A | L6: P | M6: P | N6: P | O6: P | P6: P | R6: P | S6: P | T6: P | U6: A | V6: P | W6: P | Y6: P | Z6: P | AA6: P | AB6: P | AC6: P | AD6: A | AF6: P | AG6: P | AH6: P | AI6: P | AJ6: =COUNTIF(E6:AI6,"P") -> 22 | AK6: =COUNTIF(E6:AI6,"A") -> 4 | AL6: Sunday | AM6: 4
A7: 3 | B7: Anumta Jamali | C7: Zaheer Abbas | D7: Two | E7: P | F7: P | G7: P | H7: P | K7: A | L7: A | M7: A | N7: A | O7: A | P7: A | R7: P | S7: P | T7: P | U7: P | V7: P | W7: P | Y7: P | Z7: P | AA7: P | AB7: P | AC7: P | AD7: P | AF7: P | AG7: P | AH7: P | AI7: P | AJ7: =COUNTIF(E7:AI7,"P") -> 20 | AK7: =COUNTIF(E7:AI7,"A") -> 6 | AL7: PTM | AM7: 1
A8: 4 | B8: Anusha | C8: Mukhtiyar Ali | D8: Two | E8: P | F8: P | G8: P | H8: P | K8: P | L8: P | M8: P | N8: P | O8: P | P8: P | R8: P | S8: P | T8: P | U8: P | V8: A | W8: P | Y8: P | Z8: P | AA8: P | AB8: P | AC8: L | AD8: L | AF8: L | AG8: L | AH8: L | AI8: L | AJ8: =COUNTIF(E8:AI8,"P") -> 19 | AK8: =COUNTIF(E8:AI8,"A") -> 1
A9: 5 | B9: Ayat | C9: Faiq Ali | D9: Two | E9: P | F9: P | G9: P | H9: P | K9: P | L9: P | M9: P | N9: P | O9: P | P9: A | R9: P | S9: P | T9: P | U9: P | V9: P | W9: P | Y9: P | Z9: P | AA9: P | AB9: P | AC9: P | AD9: A | AF9: P | AG9: P | AH9: P | AI9: P | AJ9: =COUNTIF(E9:AI9,"P") -> 24 | AK9: =COUNTIF(E9:AI9,"A") -> 2 | AL9: Present Days Detail
A10: 6 | B10: Ayesha | C10: Ali Muhammad | D10: Two | E10: P | F10: P | G10: P | H10: P | K10: A | L10: P | M10: A | N10: P | O10: P | P10: P | R10: P | S10: P | T10: P | U10: P | V10: P | W10: P | Y10: A | Z10: A | AA10: P | AB10: P | AC10: P | AD10: P | AF10: A | AG10: P | AH10: P | AI10: P | AJ10: =COUNTIF(E10:AI10,"P") -> 21 | AK10: =COUNTIF(E10:AI10,"A") -> 5 | AL10: Detail | AM10: Boys | AN10: Girls | AO10: Total
A11: 7 | B11: Dua | C11: Akbar Ali | D11: Two | E11: P | F11: P | G11: P | H11: P | K11: P | L11: P | M11: P | N11: P | O11: P | P11: P | R11: P | S11: P | T11: P | U11: P | V11: P | W11: P | Y11: P | Z11: P | AA11: P | AB11: P | AC11: P | AD11: P | AF11: P | AG11: P | AH11: P | AI11: P | AJ11: =COUNTIF(E11:AI11,"P") -> 26 | AK11: =COUNTIF(E11:AI11,"A") -> 0 | AL11: Due Present days | AM11: =26*$AM$5 -> 676 | AN11: =26*$AM$5 -> 676 | AO11: =SUM(AM11:AN11) -> 1352
A12: 8 | B12: Fiza | C12: Akbar Ali | D12: Two | E12: P | F12: P | G12: P | H12: P | K12: P | L12: P | M12: P | N12: P | O12: P | P12: P | R12: P | S12: P | T12: P | U12: P | V12: P | W12: P | Y12: P | Z12: P | AA12: P | AB12: A | AC12: P | AD12: P | AF12: P | AG12: P | AH12: P | AI12: P | AJ12: =COUNTIF(E12:AI12,"P") -> 25 | AK12: =COUNTIF(E12:AI12,"A") -> 1 | AL12: Actual present days | AM12: =SUM(AJ31:AJ56) -> 548 | AN12: =SUM(AJ5:AJ30) -> 592 | AO12: =AM12+AN12 -> 1140
A13: 9 | B13: Jannat Fatima | C13: Zulfiqar | D13: Two | E13: P | F13: P | G13: P | H13: P | K13: P | L13: P | M13: P | N13: A | O13: P | P13: P | R13: P | S13: P | T13: P | U13: A | V13: P | W13: P | Y13: P | Z13: P | AA13: P | AB13: A | AC13: P | AD13: A | AF13: P | AG13: P | AH13: P | AI13: P | AJ13: =COUNTIF(E13:AI13,"P") -> 22 | AK13: =COUNTIF(E13:AI13,"A") -> 4 | AL13: % | AM13: =AM12/AM11 -> 0.81065089 | AN13: =AN12/AN11 -> 0.87573964 | AO13: =AO12/AO11 -> 0.84319527
A14: 10 | B14: Kashaf | C14: Abdul Rehman | D14: Two | E14: P | F14: P | G14: P | H14: P | K14: P | L14: P | M14: P | N14: P | O14: P | P14: P | R14: P | S14: P | T14: P | U14: P | V14: A | W14: A | Y14: P | Z14: P | AA14: P | AB14: A | AC14: P | AD14: A | AF14: P | AG14: P | AH14: P | AI14: P | AJ14: =COUNTIF(E14:AI14,"P") -> 22 | AK14: =COUNTIF(E14:AI14,"A") -> 4
A15: 11 | B15: Masooma | C15: M. Raheem | D15: Two | E15: P | F15: P | G15: P | H15: P | K15: P | L15: P | M15: A | N15: P | O15: P | P15: P | R15: P | S15: P | T15: P | U15: P | V15: P | W15: P | Y15: P | Z15: P | AA15: P | AB15: P | AC15: P | AD15: P | AF15: P | AG15: P | AH15: P | AI15: P | AJ15: =COUNTIF(E15:AI15,"P") -> 25 | AK15: =COUNTIF(E15:AI15,"A") -> 1
A16: 12 | B16: Muneeza | C16: Mir Amirudin | D16: Two | E16: A | F16: A | G16: A | H16: A | K16: A | L16: P | M16: A | N16: L | O16: P | P16: P | R16: P | S16: P | T16: P | U16: P | V16: P | W16: P | Y16: P | Z16: P | AA16: P | AB16: P | AC16: A | AD16: P | AF16: P | AG16: P | AH16: A | AI16: P | AJ16: =COUNTIF(E16:AI16,"P") -> 17 | AK16: =COUNTIF(E16:AI16,"A") -> 8
A17: 13 | B17: Nayyara | C17: Khalid Hussain | D17: Two | E17: P | F17: P | G17: P | H17: P | K17: A | L17: P | M17: P | N17: P | O17: A | P17: A | R17: A | S17: P | T17: P | U17: P | V17: P | W17: P | Y17: P | Z17: P | AA17: P | AB17: P | AC17: P | AD17: P | AF17: P | AG17: P | AH17: P | AI17: P | AJ17: =COUNTIF(E17:AI17,"P") -> 22 | AK17: =COUNTIF(E17:AI17,"A") -> 4 | AL17: Absent Days Details
A18: 14 | B18: Rashida | C18: Sajjad Ahmed | D18: Two | E18: P | F18: P | G18: P | H18: P | K18: P | L18: P | M18: P | N18: P | O18: P | P18: P | R18: P | S18: P | T18: P | U18: P | V18: A | W18: A | Y18: P | Z18: P | AA18: P | AB18: P | AC18: P | AD18: P | AF18: P | AG18: P | AH18: P | AI18: A | AJ18: =COUNTIF(E18:AI18,"P") -> 23 | AK18: =COUNTIF(E18:AI18,"A") -> 3 | AL18: Detail | AM18: Boys | AN18: Girls | AO18: Total
A19: 15 | B19: Rubab Zahra | C19: Abdul Aziz | D19: Two | E19: P | F19: P | G19: P | H19: P | K19: P | L19: P | M19: P | N19: P | O19: P | P19: P | R19: P | S19: P | T19: P | U19: P | V19: P | W19: P | Y19: P | Z19: P | AA19: P | AB19: P | AC19: P | AD19: P | AF19: P | AG19: P | AH19: P | AI19: P | AJ19: =COUNTIF(E19:AI19,"P") -> 26 | AK19: =COUNTIF(E19:AI19,"A") -> 0 | AL19: Due Present days | AM19: =26*$AM$5 -> 676 | AN19: =26*$AM$5 -> 676 | AO19: =AM19+AN19 -> 1352
A20: 16 | B20: Soha Jamali | C20: Sajid Ali | D20: Two | E20: P | F20: P | G20: P | H20: P | K20: P | L20: P | M20: P | N20: P | O20: P | P20: P | R20: P | S20: P | T20: P | U20: P | V20: P | W20: P | Y20: P | Z20: P | AA20: P | AB20: P | AC20: P | AD20: P | AF20: P | AG20: P | AH20: P | AI20: P | AJ20: =COUNTIF(E20:AI20,"P") -> 26 | AK20: =COUNTIF(E20:AI20,"A") -> 0 | AL20: Absent days | AM20: =AM19-AM12 -> 128 | AN20: =AN19-AN12 -> 84 | AO20: =AM20+AN20 -> 212
A21: 17 | B21: Tahreem Fatima | C21: Khalid Hussain | D21: Two | E21: P | F21: P | G21: P | H21: P | K21: P | L21: P | M21: P | N21: P | O21: P | P21: P | R21: P | S21: P | T21: P | U21: P | V21: P | W21: P | Y21: P | Z21: P | AA21: P | AB21: P | AC21: P | AD21: P | AF21: P | AG21: P | AH21: P | AI21: P | AJ21: =COUNTIF(E21:AI21,"P") -> 26 | AK21: =COUNTIF(E21:AI21,"A") -> 0 | AL21: % | AM21: =AM20/AM19 -> 0.18934911 | AN21: =AN20/AN19 -> 0.12426036 | AO21: =AO20/AO19 -> 0.15680473
A22: 18 | B22: Sehar Fatima | C22: Altaf Hussain | D22: Two | E22: P | F22: P | G22: P | H22: P | K22: P | L22: P | M22: P | N22: P | O22: P | P22: P | R22: P | S22: P | T22: P | U22: P | V22: P | W22: P | Y22: P | Z22: P | AA22: P | AB22: P | AC22: P | AD22: P | AF22: P | AG22: P | AH22: P | AI22: P | AJ22: =COUNTIF(E22:AI22,"P") -> 26 | AK22: =COUNTIF(E22:AI22,"A") -> 0
A23: 19 | B23: Taskeen | C23: Amjad Ali | D23: Two | E23: P | F23: P | G23: P | H23: P | K23: A | L23: A | M23: A | N23: L | O23: L | P23: L | R23: L | S23: L | T23: L | U23: L | V23: L | W23: L | Y23: A | Z23: A | AA23: A | AB23: A | AC23: A | AD23: A | AF23: A | AG23: A | AH23: A | AI23: A | AJ23: =COUNTIF(E23:AI23,"P") -> 4 | AK23: =COUNTIF(E23:AI23,"A") -> 13
A24: 20 | B24: Zainab | C24: Sikandar | D24: Two | E24: P | F24: P | G24: P | H24: P | K24: P | L24: P | M24: P | N24: P | O24: P | P24: P | R24: P | S24: P | T24: P | U24: A | V24: P | W24: P | Y24: P | Z24: P | AA24: P | AB24: P | AC24: P | AD24: P | AF24: P | AG24: P | AH24: P | AI24: P | AJ24: =COUNTIF(E24:AI24,"P") -> 25 | AK24: =COUNTIF(E24:AI24,"A") -> 1
A25: 21 | B25: Kashish | C25: M. Noman | D25: Two | E25: P | F25: P | G25: P | H25: P | K25: A | L25: P | M25: P | N25: P | O25: P | P25: P | R25: P | S25: P | T25: P | U25: P | V25: P | W25: P | Y25: P | Z25: P | AA25: P | AB25: P | AC25: P | AD25: P | AF25: P | AG25: P | AH25: P | AI25: P | AJ25: =COUNTIF(E25:AI25,"P") -> 25 | AK25: =COUNTIF(E25:AI25,"A") -> 1
A26: 22 | B26: Saba | C26: Asif | D26: Two | E26: P | F26: P | G26: P | H26: P | K26: P | L26: P | M26: P | N26: P | O26: P | P26: P | R26: P | S26: P | T26: P | U26: P | V26: P | W26: P | Y26: P | Z26: P | AA26: P | AB26: P | AC26: P | AD26: P | AF26: P | AG26: P | AH26: P | AI26: P | AJ26: =COUNTIF(E26:AI26,"P") -> 26 | AK26: =COUNTIF(E26:AI26,"A") -> 0
A27: 23 | B27: Afsana | C27: Ab. Hafeez | D27: Two | E27: P | F27: P | G27: P | H27: P | K27: P | L27: P | M27: P | N27: P | O27: P | P27: P | R27: P | S27: P | T27: P | U27: P | V27: P | W27: P | Y27: P | Z27: P | AA27: P | AB27: P | AC27: P | AD27: P | AF27: P | AG27: P | AH27: P | AI27: P | AJ27: =COUNTIF(E27:AI27,"P") -> 26 | AK27: =COUNTIF(E27:AI27,"A") -> 0
A28: 24 | B28: Ayesha | C28: Ab. Hafeez | D28: Two | E28: P | F28: P | G28: P | H28: P | K28: P | L28: P | M28: P | N28: P | O28: P | P28: P | R28: P | S28: P | T28: P | U28: P | V28: P | W28: P | Y28: P | Z28: P | AA28: P | AB28: P | AC28: P | AD28: P | AF28: P | AG28: P | AH28: P | AI28: P | AJ28: =COUNTIF(E28:AI28,"P") -> 26 | AK28: =COUNTIF(E28:AI28,"A") -> 0
