Workbook

Sheet Compile Sheet-November-2024
A4: Class | B4: Total Enrolment & Attendance November-24
B5: Boys | C5: Girls | D5: Total | E5: total working Days | F5: Total working days-Boys | G5: Total working days-Girls | H5: Total working days-All | I5: P-Days Boys | J5: P-Days Girls | K5: P-Days All | L5: Percentage-Girls | M5: Percentage-Boys | N5: Percentage-Boys | O5: Total average
A6: ECE (ROSE) | B6: 27 | C6: 27 | D6: =SUM(B6:C6) -> 54 | E6: 24 | F6: =B6*E6 -> 648 | G6: =C6*E6 -> 648 | H6: =SUM(F6:G6) -> 1296 | I6: ='ECE (Daffodils)'!V14 -> P | J6: ='ECE (Daffodils)'!W14 -> 0 | K6: =SUM(I6:J6) -> 0 | L6: =J6/G6 -> 0 | M6: =I6/F6 -> #VALUE! | N6: =K6/H6 -> 0 | O6: =AVERAGE(L6:M6) -> #VALUE!
A7: ECE (Daffodils) | B7: 31 | C7: 25 | D7: =SUM(B7:C7) -> 56 | E7: 24 | F7: =B7*E7 -> 744 | G7: =C7*E7 -> 600 | H7: =SUM(F7:G7) -> 1344 | I7: ='Class-1'!V14 -> P | J7: ='Class-1'!W14 -> 0 | K7: =SUM(I7:J7) -> 0 | L7: =J7/G7 -> 0 | M7: =I7/F7 -> #VALUE! | N7: =K7/H7 -> 0 | O7: =AVERAGE(L7:M7) -> #VALUE!
A8: One | B8: 32 | C8: 24 | D8: =SUM(B8:C8) -> 56 | E8: 24 | F8: =B8*E8 -> 768 | G8: =C8*E8 -> 576 | H8: =SUM(F8:G8) -> 1344 | I8: ='Class-2'!V13 -> P | J8: ='Class-2'!W13 -> 0 | K8: =SUM(I8:J8) -> 0 | L8: =J8/G8 -> 0 | M8: =I8/F8 -> #VALUE! | N8: =K8/H8 -> 0 | O8: =AVERAGE(L8:M8) -> #VALUE!
A9: Two | B9: 26 | C9: 26 | D9: =SUM(B9:C9) -> 52 | E9: 24 | F9: =B9*E9 -> 624 | G9: =C9*E9 -> 624 | H9: =SUM(F9:G9) -> 1248 | I9: ='Class-3'!V14 -> P | J9: ='Class-3'!W14 -> 0 | K9: =SUM(I9:J9) -> 0 | L9: =J9/G9 -> 0 | M9: =I9/F9 -> #VALUE! | N9: =K9/H9 -> 0 | O9: =AVERAGE(L9:M9) -> #VALUE!
A10: Three | B10: 28 | C10: 24 | D10: =SUM(B10:C10) -> 52 | E10: 24 | F10: =B10*E10 -> 672 | G10: =C10*E10 -> 576 | H10: =SUM(F10:G10) -> 1248 | I10: ='Class-4'!V13 -> A | J10: ='Class-4'!W13 -> 0 | K10: =SUM(I10:J10) -> 0 | L10: =J10/G10 -> 0 | M10: =I10/F10 -> #VALUE! | N10: =K10/H10 -> 0 | O10: =AVERAGE(L10:M10) -> #VALUE!
A11: Four | B11: 21 | C11: 32 | D11: =SUM(B11:C11) -> 53 | E11: 24 | F11: =B11*E11 -> 504 | G11: =C11*E11 -> 768 | H11: =SUM(F11:G11) -> 1272 | I11: ='Class-5'!AN14 -> 348 | J11: ='Class-5'!AO14 -> 383 | K11: =SUM(I11:J11) -> 731 | L11: =J11/G11 -> 0.49869792 | M11: =I11/F11 -> 0.69047619 | N11: =K11/H11 -> 0.57468553 | O11: =AVERAGE(L11:M11) -> 0.59458705
A12: Five | B12: 23 | C12: 23 | D12: =SUM(B12:C12) -> 46 | E12: 24 | F12: =B12*E12 -> 552 | G12: =C12*E12 -> 552 | H12: =SUM(F12:G12) -> 1104 | I12: ='Class-6'!AN14 -> 433 | J12: ='Class-6'!AO14 -> 384 | K12: =SUM(I12:J12) -> 817 | L12: =J12/G12 -> 0.69565217 | M12: =I12/F12 -> 0.78442029 | N12: =K12/H12 -> 0.74003623 | O12: =AVERAGE(L12:M12) -> 0.74003623
A13: Six | B13: 17 | C13: 28 | D13: =SUM(B13:C13) -> 45 | E13: 24 | F13: =B13*E13 -> 408 | G13: =C13*E13 -> 672 | H13: =SUM(F13:G13) -> 1080 | I13: ='Class-7'!AN14 -> 294 | J13: ='Class-7'!AO14 -> 548 | K13: =SUM(I13:J13) -> 842 | L13: =J13/G13 -> 0.81547619 | M13: =I13/F13 -> 0.72058824 | N13: =K13/H13 -> 0.77962963 | O13: =AVERAGE(L13:M13) -> 0.76803221
A14: Seven | B14: 29 | C14: 19 | D14: =SUM(B14:C14) -> 48 | E14: 24 | F14: =B14*E14 -> 696 | G14: =C14*E14 -> 456 | H14: =SUM(F14:G14) -> 1152 | I14: ='class-8'!AN14 -> 527 | J14: ='class-8'!AO14 -> 247 | K14: =SUM(I14:J14) -> 774 | L14: =J14/G14 -> 0.54166667 | M14: =I14/F14 -> 0.75718391 | N14: =K14/H14 -> 0.671875 | O14: =AVERAGE(L14:M14) -> 0.64942529
A15: Eight | B15: 19 | C15: 23 | D15: =SUM(B15:C15) -> 42 | E15: 24 | F15: =B15*E15 -> 456 | G15: =C15*E15 -> 552 | H15: =SUM(F15:G15) -> 1008 | I15: ='class-9'!AN14 -> 232 | J15: ='class-9'!AO14 -> 377 | K15: =SUM(I15:J15) -> 609 | L15: =J15/G15 -> 0.68297101 | M15: =I15/F15 -> 0.50877193 | N15: =K15/H15 -> 0.60416667 | O15: =AVERAGE(L15:M15) -> 0.59587147
A16: Ninth | B16: 16 | C16: 19 | D16: =SUM(B16:C16) -> 35 | E16: 24 | F16: =B16*E16 -> 384 | G16: =C16*E16 -> 456 | H16: =SUM(F16:G16) -> 840 | I16: ='class-10'!AN14 -> 207 | J16: ='class-10'!AO14 -> 212 | K16: =SUM(I16:J16) -> 419 | L16: =J16/G16 -> 0.46491228 | M16: =I16/F16 -> 0.5390625 | N16: =K16/H16 -> 0.49880952 | O16: =AVERAGE(L16:M16) -> 0.50198739
A17: Total | B17: =SUM(B6:B16) -> 269 | C17: =SUM(C6:C16) -> 270 | D17: =SUM(D6:D16) -> 539 | E17: =SUM(E6:E16) -> 264 | F17: =SUM(F6:F16) -> 6456 | G17: =SUM(G6:G16) -> 6480 | H17: =SUM(H6:H16) -> 12936 | I17: =SUM(I6:I16) -> 2041 | ... K17: =SUM(K6:K16) -> 4192 | L17: =J17/G17 -> 0.33194444 | M17: =I17/F17 -> 0.31614002 | N17: =AVERAGE(N6:N16) -> 0.35174569 | O17: =AVERAGE(O6:O16) -> #VALUE!
A18: % | B18: 1 | C18: 1 | D18: 1 | E18: 1 | F18: 1 | G18: 1 | H18: 1 | I18: =I17/F17 -> 0.31614002 | J18: =J17/G17 -> 0.33194444 | K18: =K17/H17 -> 0.3240569 | L18: 0.54 | M18: 0.56 | N18: 0.55 | O18: =AVERAGE(L17:M17) -> 0.32404223

Sheet ECE ROSE
A1: Goverment high school (SJCHS)
A2: Monthly Attendence Month of MAY-2025
A3: S.No | B3: GR | C3: Student Name | D3: Father Name | E3: Class | F3: =TEXT(F4,"ddd") -> Thu | G3: =TEXT(G4,"ddd") -> Fri | H3: =TEXT(H4,"ddd") -> Sat | I3: =TEXT(I4,"ddd") -> Sun | J3: =TEXT(J4,"ddd") -> Mon | K3: =TEXT(K4,"ddd") -> Tue | L3: =TEXT(L4,"ddd") -> Wed | M3: =TEXT(M4,"ddd") -> Thu | ... AJ3: =TEXT(AJ4,"ddd") -> Sat | AK3: Present | AL3: Absent | AM3: Year 2024
F4: 45778 | G4: 45779 | H4: 45780 | I4: 45781 | J4: 45782 | K4: 45783 | L4: 45784 | M4: 45785 | N4: 45786 | O4: 45787 | P4: 45788 | Q4: 45789 | R4: 45790 | S4: 45791 | T4: 45792 | U4: 45793 | V4: 45794 | W4: 45795 | X4: 45796 | Y4: 45797 | Z4: 45798 | AA4: 45799 | AB4: 45800 | AC4: 45801 | AD4: 45802 | AE4: 45803 | AF4: 45804 | AG4: 45805 | AH4: 45806 | AI4: 45807 | AJ4: 45808 | AM4: Total days | AN4: =SUM(AN5:AN8) -> 30
A5: 1 | C5: Mir Ghulam Mustafa Bhutto | D5: Abdul Khaliq Bhutto | E5: ECE ROSE | F5: LABOUR DAY LABOUR DAY LABOUR DAY | G5: P | H5: P | I5: SUNDAY - SUNDAY - SUNDAY - SUNDAY - SUNDAY - | J5: P | K5: P | L5: P | M5: P | N5: P | O5: P | P5: SUNDAY - SUNDAY - SUNDAY - SUNDAY - SUNDAY - | Q5: P | R5: P | S5: P | T5: P | U5: P | V5: P | W5: SUNDAY - SUNDAY - SUNDAY - SUNDAY - SUNDAY - | X5: P | Y5: P | Z5: P | AA5: P | AB5: P | AD5: SUNDAY - SUNDAY - SUNDAY - SUNDAY - SUNDAY - | AK5: =COUNTIF(F5:AJ5,"P") -> 19 | AL5: =COUNTIF(F5:AJ5,"A") -> 0 | AM5: Working days | AN5: 26
A6: 2 | C6: Airah Alber | D6: Abdul Alber | E6: ECE ROSE | G6: P | H6: P | J6: P | K6: P | L6: P | M6: P | N6: P | O6: P | Q6: P | R6: L | S6: P | T6: P | U6: P | V6: P | X6: P | Y6: P | Z6: P | AA6: P | AB6: P | AK6: =COUNTIF(F6:AJ6,"P") -> 18 | AL6: =COUNTIF(F6:AJ6,"A") -> 0 | AM6: Sunday | AN6: 4
A7: 3 | C7: Meerum | D7: Razaullah | E7: ECE ROSE | G7: P | H7: P | J7: P | K7: P | L7: P | M7: P | N7: P | O7: P | Q7: P | R7: P | S7: P | T7: P | U7: P | V7: P | X7: P | Y7: P | Z7: P | AA7: P | AB7: P | AK7: =COUNTIF(F7:AJ7,"P") -> 19 | AL7: =COUNTIF(F7:AJ7,"A") -> 0
A8: 4 | C8: Marwa Bibi | D8: Naqeeb Ullah | E8: ECE ROSE | G8: P | H8: P | J8: P | K8: P | L8: P | M8: P | N8: P | O8: P | Q8: P | R8: P | S8: P | T8: P | U8: P | V8: P | X8: P | Y8: P | Z8: P | AA8: P | AB8: P | AK8: =COUNTIF(F8:AJ8,"P") -> 19 | AL8: =COUNTIF(F8:AJ8,"A") -> 0
A9: 5 | C9: Muhammad Huzzaifa | D9: Zain Ullah | E9: ECE ROSE | G9: P | H9: P | J9: P | K9: P | L9: P | M9: P | N9: P | O9: P | Q9: P | R9: P | S9: P | T9: P | U9: P | V9: P | X9: P | Y9: P | Z9: P | AA9: P | AB9: P | AK9: =COUNTIF(F9:AJ9,"P") -> 19 | AL9: =COUNTIF(F9:AJ9,"A") -> 0
A10: 6 | C10: Mustaqim Hussain | D10: Zafar Hussain | E10: ECE ROSE | G10: P | H10: P | J10: P | K10: P | L10: P | M10: P | N10: P | O10: P | Q10: P | R10: P | S10: P | T10: P | U10: P | V10: P | X10: P | Y10: A | Z10: P | AA10: P | AB10: P | AK10: =COUNTIF(F10:AJ10,"P") -> 18 | AL10: =COUNTIF(F10:AJ10,"A") -> 1
A11: 7 | C11: Irshad | D11: Shafiq Shah | E11: ECE ROSE | G11: A | H11: A | J11: A | K11: P | L11: P | M11: P | N11: P | O11: P | Q11: P | R11: P | S11: P | T11: P | U11: P | V11: P | X11: P | Y11: P | Z11: P | AA11: P | AB11: P | AK11: =COUNTIF(F11:AJ11,"P") -> 16 | AL11: =COUNTIF(F11:AJ11,"A") -> 3 | AM11: Present Days Detail
A12: 8 | C12: Aon Ali | D12: Imran Ali | E12: ECE ROSE | G12: A | H12: A | J12: P | K12: P | L12: A | M12: P | N12: A | O12: A | Q12: P | R12: L | S12: L | T12: P | U12: A | V12: A | X12: A | Y12: P | Z12: P | AA12: P | AB12: P | AK12: =COUNTIF(F12:AJ12,"P") -> 9 | AL12: =COUNTIF(F12:AJ12,"A") -> 8 | AM12: Detail | AN12: Boys | AO12: Girls | AP12: Total
A13: 9 | C13: Ajwa Rashid | D13: Rashid Hussain | E13: ECE ROSE | G13: P | H13: P | J13: P | K13: P | L13: P | M13: P | N13: P | O13: P | Q13: P | R13: P | S13: P | T13: P | U13: P | V13: P | X13: P | Y13: P | Z13: P | AA13: P | AB13: P | AK13: =COUNTIF(F13:AJ13,"P") -> 19 | AL13: =COUNTIF(F13:AJ13,"A") -> 0 | AM13: Due Present days | AN13: =29*$AN$5 -> 754 | AO13: =25*$AN$5 -> 650 | AP13: =SUM(AN13:AO13) -> 1404
A14: 10 | C14: Muhammad Ramzan | D14: Abdul Karim | E14: ECE ROSE | G14: P | H14: P | J14: P | K14: P | L14: P | M14: P | N14: P | O14: P | Q14: P | R14: P | S14: P | T14: P | U14: P | V14: P | X14: P | Y14: P | Z14: P | AA14: P | AB14: P | AK14: =COUNTIF(F14:AJ14,"P") -> 19 | AL14: =COUNTIF(F14:AJ14,"A") -> 0 | AM14: Actual present days | AN14: =SUM(AK29:AK31) -> 43 | AO14: =SUM(AK5:AK28) -> 404 | AP14: =AN14+AO14 -> 447
A15: 11 | C15: Airah Meer | D15: Tanveer Ahmed Jamali | E15: ECE ROSE | G15: P | H15: P | J15: P | K15: P | L15: P | M15: P | N15: P | O15: P | Q15: P | R15: L | S15: P | T15: P | U15: P | V15: P | X15: P | Y15: P | Z15: P | AA15: P | AB15: P | AK15: =COUNTIF(F15:AJ15,"P") -> 18 | AL15: =COUNTIF(F15:AJ15,"A") -> 0 | AM15: % | AN15: =AN14/AN13 -> 0.057029178 | AO15: =AO14/AO13 -> 0.62153846 | AP15: =AP14/AP13 -> 0.31837607
A16: 12 | C16: Zeeshan Ali | D16: Ahsan Ali | E16: ECE ROSE | G16: p | H16: P | J16: P | K16: P | L16: P | M16: P | N16: P | O16: P | Q16: P | R16: L | S16: L | T16: L | U16: L | V16: L | X16: P | Y16: P | Z16: P | AA16: P | AB16: P | AK16: =COUNTIF(F16:AJ16,"P") -> 14 | AL16: =COUNTIF(F16:AJ16,"A") -> 0
A17: 13 | C17: Farhan Ali | D17: Akbar Ali | E17: ECE ROSE | G17: P | H17: P | J17: P | K17: P | L17: P | M17: P | N17: P | O17: P | Q17: P | R17: P | S17: P | T17: P | U17: P | V17: P | X17: P | Y17: P | Z17: P | AA17: P | AB17: P | AK17: =COUNTIF(F17:AJ17,"P") -> 19 | AL17: =COUNTIF(F17:AJ17,"A") -> 0
A18: 14 | C18: Muhammad Qaiser | D18: Muhammad Qasim Mugheri | E18: ECE ROSE | G18: P | H18: P | J18: P | K18: P | L18: P | M18: A | N18: A | O18: P | Q18: P | R18: P | S18: P | T18: P | U18: P | V18: P | X18: P | Y18: P | Z18: P | AA18: P | AB18: P | AK18: =COUNTIF(F18:AJ18,"P") -> 17 | AL18: =COUNTIF(F18:AJ18,"A") -> 2
A19: 15 | C19: Zoya | D19: Zahid Ali | E19: ECE ROSE | G19: P | H19: P | J19: P | K19: P | L19: P | M19: A | N19: A | O19: A | Q19: P | R19: A | S19: L | T19: L | U19: A | V19: A | X19: P | Y19: P | Z19: P | AA19: P | AB19: P | AK19: =COUNTIF(F19:AJ19,"P") -> 11 | AL19: =COUNTIF(F19:AJ19,"A") -> 6 | AM19: Absent Days Details
A20: 16 | C20: Bibi Batool | D20: Syed Shahid Ali Shah | E20: ECE ROSE | G20: P | H20: P | J20: P | K20: P | L20: P | M20: P | N20: P | O20: P | Q20: P | R20: P | S20: P | T20: P | U20: P | V20: P | X20: P | Y20: P | Z20: P | AA20: P | AB20: P | AK20: =COUNTIF(F20:AJ20,"P") -> 19 | AL20: =COUNTIF(F20:AJ20,"A") -> 0 | AM20: Detail | AN20: Boys | AO20: Girls | AP20: Total
A21: 17 | C21: Hooriya | D21: Sajid Jamali | E21: ECE ROSE | G21: P | H21: P | J21: P | K21: P | L21: P | M21: P | N21: P | O21: P | Q21: P | R21: P | S21: P | T21: P | U21: P | V21: P | X21: P | Y21: P | Z21: P | AA21: P | AB21: P | AK21: =COUNTIF(F21:AJ21,"P") -> 19 | AL21: =COUNTIF(F21:AJ21,"A") -> 0 | AM21: Due Present days | AN21: =29*$AN$5 -> 754 | AO21: =25*$AN$5 -> 650 | AP21: =AN21+AO21 -> 1404
A22: 18 | C22: Arwa Fatima | D22: Muhammad Bilawal | E22: ECE ROSE | G22: P | H22: P | J22: P | K22: P | L22: P | M22: P | N22: P | O22: P | Q22: P | R22: P | S22: P | T22: P | U22: P | V22: P | X22: P | Y22: P | Z22: P | AA22: P | AB22: P | AK22: =COUNTIF(F22:AJ22,"P") -> 19 | AL22: =COUNTIF(F22:AJ22,"A") -> 0 | AM22: Absent days | AN22: =AN21-AN14 -> 711 | AO22: =AO21-AO14 -> 246 | AP22: =AN22+AO22 -> 957
A23: 19 | C23: Muhammad Siddiq | D23: Ghulam Nabi | E23: ECE ROSE | G23: A | H23: A | J23: A | K23: P | L23: P | M23: P | N23: P | O23: P | Q23: P | R23: P | S23: P | T23: P | U23: P | V23: P | X23: P | Y23: P | Z23: P | AA23: P | AB23: P | AK23: =COUNTIF(F23:AJ23,"P") -> 16 | AL23: =COUNTIF(F23:AJ23,"A") -> 3 | AM23: % | AN23: =AN22/AN21 -> 0.94297082 | AO23: =AO22/AO21 -> 0.37846154 | AP23: =AP22/AP21 -> 0.68162393
A24: 20 | C24: Waseem | D24: Abdul Sattar | E24: ECE ROSE | G24: P | H24: P | J24: P | K24: P | L24: P | M24: P | N24: P | O24: P | Q24: P | R24: P | S24: P | T24: P | U24: P | V24: P | X24: P | Y24: P | Z24: P | AA24: P | AB24: P | AK24: =COUNTIF(F24:AJ24,"P") -> 19 | AL24: =COUNTIF(F24:AJ24,"A") -> 0
A25: 21 | C25: Ariyan | D25: Aman Badshah | E25: ECE ROSE | G25: P | H25: P | J25: A | K25: P | L25: P | M25: P | N25: P | O25: P | Q25: P | R25: P | S25: P | T25: P | U25: P | V25: P | X25: P | Y25: P | Z25: P | AA25: P | AB25: P | AK25: =COUNTIF(F25:AJ25,"P") -> 18 | AL25: =COUNTIF(F25:AJ25,"A") -> 1
A26: 22 | C26: Inaya Fatima | D26: Ijaz Ahmed | E26: ECE ROSE | G26: A | H26: A | J26: P | K26: P | L26: P | M26: P | N26: P | O26: P | Q26: P | R26: P | S26: P | T26: P | U26: P | V26: P | X26: P | Y26: P | Z26: P | AA26: P | AB26: P | AK26: =COUNTIF(F26:AJ26,"P") -> 17 | AL26: =COUNTIF(F26:AJ26,"A") -> 2
A27: 23 | C27: Aqib | E27: ECE ROSE | G27: A | H27: A | J27: A | K27: P | L27: P | M27: A | N27: A | O27: A | Q27: P | R27: P | S27: P | T27: P | U27: P | V27: P | X27: P | Y27: P | Z27: P | AA27: P | AB27: P | AK27: =COUNTIF(F27:AJ27,"P") -> 13 | AL27: =COUNTIF(F27:AJ27,"A") -> 6
A28: 24 | C28: Ariyan | D28: Ismail | E28: ECE ROSE | G28: P | H28: P | J28: P | K28: P | L28: P | M28: P | N28: A | O28: A | Q28: P | R28: P | S28: P | T28: P | U28: A | V28: A | X28: L | Y28: L | Z28: L | AA28: L | AB28: L | AK28: =COUNTIF(F28:AJ28,"P") -> 10 | AL28: =COUNTIF(F28:AJ28,"A") -> 4
A29: 25 | C29: Zainab Haneef | D29: Haneef Qadir | E29: ECE ROSE | G29: A | H29: A | J29: A | K29: A | L29: P | M29: P | N29: P | O29: P | Q29: P | R29: P | S29: P | T29: P | U29: P | V29: P | X29: P | Y29: P | Z29: P | AA29: P | AB29: P | AK29: =COUNTIF(F29:AJ29,"P") -> 15 | AL29: =COUNTIF(F29:AJ29,"A") -> 4
A30: 26 | C30: Zainab | D30: Muhammad Ameen | E30: ECE ROSE | G30: P | H30: P | J30: A | K30: A | L30: A | M30: P | N30: P | O30: P | Q30: P | R30: P | S30: A | T30: L | U30: A | V30: A | X30: P | Y30: P | Z30: P | AA30: P | AB30: A | AK30: =COUNTIF(F30:AJ30,"P") -> 11 | AL30: =COUNTIF(F30:AJ30,"A") -> 7
A31: 27 | C31: Zara Fatima | E31: ECE ROSE | G31: A | H31: A | J31: P | K31: P | L31: P | M31: P | N31: P | O31: P | Q31: P | R31: P | S31: P | T31: P | U31: P | V31: P | X31: P | Y31: P | Z31: P | AA31: P | AB31: P | AK31: =COUNTIF(F31:AJ31,"P") -> 17 | AL31: =COUNTIF(F31:AJ31,"A") -> 2

Sheet ECE (Daffodils)
A1: Goverment high school (SJCHS)
A2: Monthly Attendence Month of MAY-2025
A3: S.No | B3: GR | C3: Student Name | D3: Father Name | E3: Class | F3: =TEXT(F4,"ddd") -> Thu | G3: =TEXT(G4,"ddd") -> Fri | H3: =TEXT(H4,"ddd") -> Sat | I3: =TEXT(I4,"ddd") -> Sun | J3: =TEXT(J4,"ddd") -> Mon | K3: =TEXT(K4,"ddd") -> Tue | L3: =TEXT(L4,"ddd") -> Wed | M3: =TEXT(M4,"ddd") -> Thu | ... AJ3: =TEXT(AJ4,"ddd") -> Sat | AK3: Present | AL3: Absent | AM3: Year 2024
F4: 45778 | G4: 45779 | H4: 45780 | I4: 45781 | J4: 45782 | K4: 45783 | L4: 45784 | M4: 45785 | N4: 45786 | O4: 45787 | P4: 45788 | Q4: 45789 | R4: 45790 | S4: 45791 | T4: 45792 | U4: 45793 | V4: 45794 | W4: 45795 | X4: 45796 | Y4: 45797 | Z4: 45798 | AA4: 45799 | AB4: 45800 | AC4: 45801 | AD4: 45802 | AE4: 45803 | AF4: 45804 | AG4: 45805 | AH4: 45806 | AI4: 45807 | AJ4: 45808 | AM4: Total days | AN4: =SUM(AN5:AN8) -> 30
A5: 1 | B5: 112 | C5: Eman | D5: Shahnawaz Khan | E5: ECE | F5: LABOUR DAY LABOUR DAY LABOUR DAY | G5: A | H5: A | I5: SUNDAY - SUNDAY - SUNDAY - SUNDAY - SUNDAY - SUNDAY | J5: A | K5: A | L5: A | M5: A | N5: A | O5: A | P5: SUNDAY - SUNDAY - SUNDAY - SUNDAY - SUNDAY - SUNDAY | Q5: A | R5: A | S5: A | T5: A | U5: A | V5: A | W5: SUNDAY - SUNDAY - SUNDAY - SUNDAY - SUNDAY - SUNDAY | X5: A | Y5: A | Z5: A | AA5: A | AB5: A | AD5: SUNDAY - SUNDAY - SUNDAY - SUNDAY - SUNDAY - SUNDAY | AK5: =COUNTIF(F5:AJ5,"P") -> 0 | AL5: =COUNTIF(F5:AJ5,"A") -> 19 | AM5: Working days | AN5: 26
A6: 2 | B6: 135 | C6: Masooma | D6: Faiq Ali | E6: ECE | G6: A | H6: P | J6: P | K6: A | L6: P | M6: A | N6: P | O6: A | Q6: P | R6: P | S6: A | T6: P | U6: P | V6: P | X6: P | Y6: A | Z6: A | AA6: P | AB6: P | AK6: =COUNTIF(F6:AJ6,"P") -> 12 | AL6: =COUNTIF(F6:AJ6,"A") -> 7 | AM6: Sunday | AN6: 4
A7: 3 | B7: 137 | C7: Hafsa Batool | D7: Gul Mohammad Chandio | E7: ECE | G7: A | H7: P | J7: P | K7: P | L7: P | M7: P | N7: P | O7: A | Q7: A | R7: P | S7: P | T7: P | U7: P | V7: P | X7: P | Y7: P | Z7: A | AA7: P | AB7: P | AK7: =COUNTIF(F7:AJ7,"P") -> 15 | AL7: =COUNTIF(F7:AJ7,"A") -> 4
A8: 4 | B8: 173 | C8: Hoor Fatima | D8: Shahid Ali | E8: ECE | G8: P | H8: P | J8: P | K8: P | L8: P | M8: P | N8: P | O8: P | Q8: P | R8: P | S8: P | T8: P | U8: P | V8: P | X8: P | Y8: P | Z8: A | AA8: P | AB8: P | AK8: =COUNTIF(F8:AJ8,"P") -> 18 | AL8: =COUNTIF(F8:AJ8,"A") -> 1
A9: 5 | B9: 143 | C9: Kinza | D9: Aijaz Ali | E9: ECE | G9: P | H9: P | J9: P | K9: P | L9: P | M9: A | N9: P | O9: P | Q9: P | R9: P | S9: P | T9: P | U9: P | V9: P | X9: P | Y9: P | Z9: P | AA9: P | AB9: P | AK9: =COUNTIF(F9:AJ9,"P") -> 18 | AL9: =COUNTIF(F9:AJ9,"A") -> 1
A10: 6 | B10: 146 | C10: Fatima Ansari | D10: Ayaz Ali Ansari | E10: ECE | G10: A | H10: A | J10: A | K10: A | L10: A | M10: A | N10: A | O10: A | Q10: A | R10: A | S10: P | T10: P | U10: P | V10: A | X10: P | Y10: P | Z10: A | AA10: P | AB10: P | AK10: =COUNTIF(F10:AJ10,"P") -> 7 | AL10: =COUNTIF(F10:AJ10,"A") -> 12
A11: 7 | B11: 148 | C11: Zil-e-Huma | D11: Abdul Qayoom | E11: ECE | G11: A | H11: A | J11: A | K11: A | L11: A | M11: A | N11: A | O11: A | Q11: A | R11: P | S11: P | T11: A | U11: P | V11: P | X11: A | Y11: P | Z11: A | AA11: P | AB11: P | AK11: =COUNTIF(F11:AJ11,"P") -> 7 | AL11: =COUNTIF(F11:AJ11,"A") -> 12 | AM11: Present Days Detail
A12: 8 | B12: 150 | C12: Ayat Fatima | D12: Imran Hussain | E12: ECE | G12: P | H12: P | J12: P | K12: P | L12: P | M12: A | N12: P | O12: P | Q12: P | R12: P | S12: P | T12: P | U12: A | V12: P | X12: P | Y12: P | Z12: P | AA12: P | AB12: P | AK12: =COUNTIF(F12:AJ12,"P") -> 17 | AL12: =COUNTIF(F12:AJ12,"A") -> 2 | AM12: Detail | AN12: Boys | AO12: Girls | AP12: Total
A13: 9 | B13: 151 | C13: Aqsa | D13: Ahsan Ali | E13: ECE | G13: P | H13: P | J13: P | K13: P | L13: P | M13: P | N13: A | O13: P | Q13: P | R13: P | S13: P | T13: P | U13: P | V13: P | X13: P | Y13: P | Z13: P | AA13: P | AB13: P | AK13: =COUNTIF(F13:AJ13,"P") -> 18 | AL13: =COUNTIF(F13:AJ13,"A") -> 1 | AM13: Due Present days | AN13: =29*$AN$5 -> 754 | AO13: =25*$AN$5 -> 650 | AP13: =SUM(AN13:AO13) -> 1404
A14: 10 | B14: 160 | C14: Safa | D14: Dil Murad | E14: ECE | G14: A | H14: A | J14: P | K14: P | L14: P | M14: P | N14: P | O14: P | Q14: P | R14: A | S14: P | T14: P | U14: P | V14: P | X14: P | Y14: P | Z14: P | AA14: P | AB14: P | AK14: =COUNTIF(F14:AJ14,"P") -> 16 | AL14: =COUNTIF(F14:AJ14,"A") -> 3 | AM14: Actual present days | AN14: =SUM(AK29:AK57) -> 395 | AO14: =SUM(AK5:AK28) -> 242 | AP14: =AN14+AO14 -> 637
A15: 11 | B15: 161 | C15: Hifza | D15: Zakir Ali | E15: ECE | G15: A | H15: A | J15: P | K15: P | L15: A | M15: A | N15: P | O15: P | Q15: A | R15: P | S15: P | T15: P | U15: P | V15: P | X15: P | Y15: P | Z15: P | AA15: P | AB15: A | AK15: =COUNTIF(F15:AJ15,"P") -> 13 | AL15: =COUNTIF(F15:AJ15,"A") -> 6 | AM15: % | AN15: =AN14/AN13 -> 0.52387268 | AO15: =AO14/AO13 -> 0.37230769 | AP15: =AP14/AP13 -> 0.4537037
A16: 12 | B16: 162 | C16: Zameeran | D16: Babar Ali | E16: ECE | G16: A | H16: P | J16: P | K16: A | L16: P | M16: P | N16: P | O16: P | Q16: A | R16: P | S16: A | T16: A | U16: A | V16: A | X16: A | Y16: A | Z16: A | AA16: A | AB16: P | AK16: =COUNTIF(F16:AJ16,"P") -> 8 | AL16: =COUNTIF(F16:AJ16,"A") -> 11
A17: 13 | B17: 163 | C17: Parwisha | D17: Sarfaraz Ahmed | E17: ECE | G17: P | H17: P | J17: P | K17: P | L17: P | M17: P | N17: P | O17: A | Q17: P | R17: P | S17: P | T17: P | U17: P | V17: P | X17: P | Y17: P | Z17: P | AA17: P | AB17: P | AK17: =COUNTIF(F17:AJ17,"P") -> 18 | AL17: =COUNTIF(F17:AJ17,"A") -> 1
A18: 14 | B18: 166 | C18: Aiza | D18: Irshad-Ul-Haq | E18: ECE | G18: A | H18: A | J18: A | K18: A | L18: A | M18: A | N18: A | O18: A | Q18: A | R18: A | S18: A | T18: A | U18: A | V18: A | X18: A | Y18: A | Z18: A | AA18: A | AB18: A | AK18: =COUNTIF(F18:AJ18,"P") -> 0 | AL18: =COUNTIF(F18:AJ18,"A") -> 19
A19: 15 | B19: 168 | C19: Shazia | D19: Rashid Ali | E19: ECE | G19: P | H19: P | J19: P | K19: P | L19: A | M19: P | N19: P | O19: P | Q19: P | R19: P | S19: P | T19: P | U19: P | V19: P | X19: P | Y19: P | Z19: P | AA19: P | AB19: P | AK19: =COUNTIF(F19:AJ19,"P") -> 18 | AL19: =COUNTIF(F19:AJ19,"A") -> 1 | AM19: Absent Days Details
A20: 16 | B20: 170 | C20: Ume Farwa | D20: Meer Ameer-u-Din | E20: ECE | G20: A | H20: A | J20: P | K20: P | L20: A | M20: A | N20: P | O20: P | Q20: A | R20: A | S20: P | T20: A | U20: A | V20: A | X20: P | Y20: P | Z20: P | AA20: P | AB20: P | AK20: =COUNTIF(F20:AJ20,"P") -> 10 | AL20: =COUNTIF(F20:AJ20,"A") -> 9 | AM20: Detail | AN20: Boys | AO20: Girls | AP20: Total
A21: 17 | B21: 171 | C21: Ume Rubab | D21: Mohsin Ali | E21: ECE | G21: A | H21: P | J21: A | K21: A | L21: A | M21: A | N21: A | O21: A | Q21: A | R21: A | S21: A | T21: A | U21: A | V21: A | X21: A | Y21: A | Z21: A | AA21: A | AB21: A | AK21: =COUNTIF(F21:AJ21,"P") -> 1 | AL21: =COUNTIF(F21:AJ21,"A") -> 18 | AM21: Due Present days | AN21: =29*$AN$5 -> 754 | AO21: =25*$AN$5 -> 650 | AP21: =AN21+AO21 -> 1404
A22: 18 | B22: 172 | C22: Khatija | D22: M. Afzal | E22: ECE | G22: A | H22: A | J22: A | K22: A | L22: A | M22: A | N22: A | O22: A | Q22: A | R22: A | S22: A | T22: A | U22: A | V22: A | X22: A | Y22: A | Z22: A | AA22: A | AB22: A | AK22: =COUNTIF(F22:AJ22,"P") -> 0 | AL22: =COUNTIF(F22:AJ22,"A") -> 19 | AM22: Absent days | AN22: =AN21-AN14 -> 359 | AO22: =AO21-AO14 -> 408 | AP22: =AN22+AO22 -> 767
A23: 19 | B23: 180 | C23: Fiza | D23: Ahmed | E23: ECE | G23: A | H23: P | J23: P | K23: P | L23: P | M23: A | N23: P | O23: P | Q23: P | R23: P | S23: P | T23: A | U23: A | V23: A | X23: A | Y23: A | Z23: A | AA23: A | AB23: A | AK23: =COUNTIF(F23:AJ23,"P") -> 9 | AL23: =COUNTIF(F23:AJ23,"A") -> 10 | AM23: % | AN23: =AN22/AN21 -> 0.47612732 | AO23: =AO22/AO21 -> 0.62769231 | AP23: =AP22/AP21 -> 0.5462963
A24: 20 | B24: 181 | C24: Eshaal | D24: M. Fahad | E24: ECE | G24: A | H24: A | J24: A | K24: A | L24: A | M24: A | N24: A | O24: A | Q24: A | R24: A | S24: A | T24: A | U24: A | V24: A | X24: A | Y24: A | Z24: A | AA24: A | AB24: A | AK24: =COUNTIF(F24:AJ24,"P") -> 0 | AL24: =COUNTIF(F24:AJ24,"A") -> 19
A25: 21 | B25: 195 | C25: Rija Batool | D25: Ghulam Mehdi | E25: ECE | G25: A | H25: P | J25: A | K25: A | L25: A | M25: A | N25: A | O25: A | Q25: A | R25: A | S25: A | T25: A | U25: A | V25: A | X25: P | Y25: A | Z25: A | AA25: A | AB25: A | AK25: =COUNTIF(F25:AJ25,"P") -> 2 | AL25: =COUNTIF(F25:AJ25,"A") -> 17
A26: 22 | B26: 183 | C26: Mustirah | D26: Faisal | E26: ECE | G26: P | H26: P | J26: A | K26: A | L26: P | M26: P | N26: P | O26: A | Q26: P | R26: P | S26: P | T26: P | U26: A | V26: P | X26: P | Y26: P | Z26: P | AA26: P | AB26: A | AK26: =COUNTIF(F26:AJ26,"P") -> 14 | AL26: =COUNTIF(F26:AJ26,"A") -> 5
A27: 23 | B27: 170 | C27: Hoorain Noor | D27: Muhammad Akram | E27: ECE | G27: P | H27: P | J27: P | K27: P | L27: P | M27: P | N27: P | O27: P | Q27: P | R27: P | S27: P | T27: P | U27: P | V27: P | X27: P | Y27: P | Z27: P | AA27: P | AB27: P | AK27: =COUNTIF(F27:AJ27,"P") -> 19 | AL27: =COUNTIF(F27:AJ27,"A") -> 0
A28: 1 | B28: 189 | C28: Zakria | D28: Iqramudin | E28: ECE | G28: A | H28: A | J28: A | K28: A | L28: A | M28: A | N28: A | O28: A | Q28: A | R28: A | S28: A | T28: A | U28: A | V28: P | X28: A | Y28: P | Z28: A | AA28: A | AB28: A | AK28: =COUNTIF(F28:AJ28,"P") -> 2 | AL28: =COUNTIF(F28:AJ28,"A") -> 17
A29: 2 | B29: 99 | C29: Rehan Ali | D29: Abdul Rehman | E29: ECE | G29: P | H29: P | J29: P | K29: P | L29: P | M29: P | N29: P | O29: P | Q29: A | R29: A | S29: P | T29: P | U29: P | V29: P | X29: P | Y29: P | Z29: P | AA29: P | AB29: P | AK29: =COUNTIF(F29:AJ29,"P") -> 17 | AL29: =COUNTIF(F29:AJ29,"A") -> 2
A30: 3 | B30: 98 | C30: Dilkash | D30: Faraz Hussain | E30: ECE | G30: A | H30: A | J30: P | K30: P | L30: P | M30: P | N30: P | O30: A | Q30: P | R30: P | S30: P | T30: P | U30: P | V30: P | X30: P | Y30: P | Z30: A | AA30: P | AB30: P | AK30: =COUNTIF(F30:AJ30,"P") -> 15 | AL30: =COUNTIF(F30:AJ30,"A") -> 4
A31: 4 | B31: 136 | C31: Ali | D31: Saddam Hussain | E31: ECE | G31: A | H31: A | J31: P | K31: P | L31: P | M31: P | N31: P | O31: P | Q31: P | R31: P | S31: P | T31: P | U31: P | V31: P | X31: P | Y31: P | Z31: P | AA31: P | AB31: P | AK31: =COUNTIF(F31:AJ31,"P") -> 17 | AL31: =COUNTIF(F31:AJ31,"A") -> 2
A32: 5 | B32: 139 | C32: Mohammad Aliyan | D32: Shabir Ahmed Bhutto | E32: ECE | G32: A | H32: P | J32: A | K32: P | L32: A | M32: P | N32: P | O32: A | Q32: P | R32: P | S32: A | T32: P | U32: P | V32: P | X32: P | Y32: P | Z32: P | AA32: P | AB32: P | AK32: =COUNTIF(F32:AJ32,"P") -> 14 | AL32: =COUNTIF(F32:AJ32,"A") -> 5
A33: 6 | B33: 142 | C33: Muhammad Sahil | D33: Irshad Ali | E33: ECE | G33: P | H33: P | J33: P | K33: P | L33: P | M33: A | N33: P | O33: P | Q33: P | R33: P | S33: P | T33: P | U33: P | V33: P | X33: P | Y33: P | Z33: P | AA33: P | AB33: P | AK33: =COUNTIF(F33:AJ33,"P") -> 18 | AL33: =COUNTIF(F33:AJ33,"A") -> 1
A34: 7 | B34: 144 | C34: Zaryab Sultan | D34: Muhammad Zaman | E34: ECE | G34: P | H34: P | J34: P | K34: P | L34: P | M34: P | N34: P | O34: P | Q34: P | R34: P | S34: P | T34: P | U34: P | V34: P | X34: P | Y34: P | Z34: P | AA34: P | AB34: P | AK34: =COUNTIF(F34:AJ34,"P") -> 19 | AL34: =COUNTIF(F34:AJ34,"A") -> 0
A35: 8 | B35: 145 | C35: M. Ibrahim | D35: Fayaz Ali Ansari | E35: ECE | G35: A | H35: P | J35: A | K35: A | L35: A | M35: A | N35: A | O35: A | Q35: A | R35: A | S35: A | T35: A | U35: A | V35: A | X35: A | Y35: A | Z35: A | AA35: A | AB35: A | AK35: =COUNTIF(F35:AJ35,"P") -> 1 | AL35: =COUNTIF(F35:AJ35,"A") -> 18
... A47: 20 | B47: 197 | C47: M. Raheel | D47: masoor ali | E47: ECE | G47: P | H47: A | J47: P | K47: P | L47: P | M47: P | N47: P | O47: P | Q47: P | R47: P | S47: P | T47: P | U47: P | V47: P | X47: P | Y47: P | Z47: P | AA47: P | AB47: P | AK47: =COUNTIF(F47:AJ47,"P") -> 18 | AL47: =COUNTIF(F47:AJ47,"A") -> 1
A48: 21 | B48: 182 | C48: Amanullah | D48: Sajid Ahmed | E48: ECE | G48: A | H48: P | J48: P | K48: P | L48: P | M48: P | N48: A | O48: A | Q48: A | R48: P | S48: P | T48: A | U48: P | V48: A | X48: P | Y48: P | Z48: P | AA48: P | AB48: P | AK48: =COUNTIF(F48:AJ48,"P") -> 13 | AL48: =COUNTIF(F48:AJ48,"A") -> 6 | AM48: 6+
A49: 22 | B49: 186 | C49: Ahmed Ali | D49: Asghar Ali | E49: ECE | G49: P | H49: P | J49: P | K49: P | L49: P | M49: P | N49: P | O49: P | Q49: P | R49: A | S49: L | T49: L | U49: P | V49: P | X49: P | Y49: P | Z49: P | AA49: P | AB49: P | AK49: =COUNTIF(F49:AJ49,"P") -> 16 | AL49: =COUNTIF(F49:AJ49,"A") -> 1
A50: 23 | B50: 188 | C50: M. Qasim | D50: Abdul Hameed | E50: ECE | G50: A | H50: P | J50: P | K50: P | L50: P | M50: A | N50: P | O50: P | Q50: P | R50: P | S50: P | T50: P | U50: A | V50: P | X50: P | Y50: P | Z50: P | AA50: P | AB50: P | AK50: =COUNTIF(F50:AJ50,"P") -> 16 | AL50: =COUNTIF(F50:AJ50,"A") -> 3
A51: 24 | B51: 184 | C51: Saifullah | D51: Farooq Ali | E51: ECE | G51: A | H51: A | J51: A | K51: P | L51: P | M51: A | N51: P | O51: A | Q51: A | R51: P | S51: P | T51: P | U51: P | V51: P | X51: P | Y51: A | Z51: P | AA51: P | AB51: P | AK51: =COUNTIF(F51:AJ51,"P") -> 12 | AL51: =COUNTIF(F51:AJ51,"A") -> 7
...

Sheet Class-1
A1: Goverment high school (SJCHS)
A2: Monthly Attendence Month of MAY-2025
A3: S.No | B3: GR | C3: Student Name | D3: Father Name | E3: Class | F3: Thu | G3: Fri | H3: Sat | I3: Sun | J3: Mon | K3: Tue | L3: Wed | M3: Thu | N3: Fri | O3: Sat | P3: Sun | Q3: Mon | R3: Tue | S3: Wed | T3: Thu | U3: Fri | V3: Sat | W3: Sun | X3: Mon | Y3: Tue | Z3: Wed | AA3: Thu | AB3: Fri | AC3: Sat | AD3: Sun | AE3: Mon | AF3: Tue | AG3: Wed | AH3: Thu | AI3: Fri | AJ3: Sat | AK3: Present | AL3: Absent | AM3: Year 2024
F4: 45778 | G4: 45779 | H4: 45780 | I4: 45781 | J4: 45782 | K4: 45783 | L4: 45784 | M4: 45785 | N4: 45786 | O4: 45787 | P4: 45788 | Q4: 45789 | R4: 45790 | S4: 45791 | T4: 45792 | U4: 45793 | V4: 45794 | W4: 45795 | X4: 45796 | Y4: 45797 | Z4: 45798 | AA4: 45799 | AB4: 45800 | AC4: 45801 | AD4: 45802 | AE4: 45803 | AF4: 45804 | AG4: 45805 | AH4: 45806 | AI4: 45807 | AJ4: 45808 | AM4: Total days | AN4: =SUM(AN5:AN8) -> 30
A5: 1 | B5: 106 | C5: Alishba Batool | D5: Irfan Ali | E5: ONE | F5: LABOUR DAY LABOUR DAY LABOUR DAY | G5: P | H5: P | I5: Sunday Sunday Sunday Sunday | J5: P | K5: P | L5: P | M5: P | N5: P | O5: p | P5: Sunday Sunday Sunday Sunday | Q5: p | R5: P | S5: p | T5: p | U5: p | V5: A | W5: Sunday Sunday Sunday Sunday | X5: P | Y5: P | Z5: P | AA5: P | AD5: Sunday Sunday Sunday Sunday | AK5: =COUNTIF(F5:AI5,"P") -> 17 | AL5: =COUNTIF(F5:AI5,"A") -> 1 | AM5: Working days | AN5: 26
A6: 2 | B6: 75 | C6: Amna | D6: Imtiaz Hussain | E6: ONE | G6: P | H6: P | J6: P | K6: P | L6: P | M6: P | N6: P | O6: P | Q6: P | R6: P | S6: p | T6: A | U6: P | V6: P | X6: P | Y6: P | Z6: P | AA6: P | AK6: =COUNTIF(F6:AI6,"P") -> 17 | AL6: =COUNTIF(F6:AI6,"A") -> 1 | AM6: Sunday | AN6: 4
A7: 3 | B7: 109 | C7: Aniza Memon | D7: M. Qasim | E7: ONE | G7: P | H7: A | J7: P | K7: P | L7: A | M7: A | N7: A | O7: A | Q7: A | R7: P | S7: P | T7: A | U7: A | V7: A | X7: A | Y7: P | Z7: P | AA7: P | AK7: =COUNTIF(F7:AI7,"P") -> 8 | AL7: =COUNTIF(F7:AI7,"A") -> 10
A8: 4 | B8: 49 | C8: Areeba | D8: Altaf Hussain | E8: ONE | G8: A | H8: A | J8: P | K8: P | L8: A | M8: P | N8: P | O8: P | Q8: P | R8: P | S8: P | T8: P | U8: P | V8: P | X8: P | Y8: P | Z8: P | AA8: P | AK8: =COUNTIF(F8:AI8,"P") -> 15 | AL8: =COUNTIF(F8:AI8,"A") -> 3
A9: 5 | B9: 104 | C9: Batool | D9: Amjad Ali | E9: ONE | G9: A | H9: A | J9: A | K9: A | L9: A | M9: A | N9: A | O9: A | Q9: A | R9: A | S9: A | T9: A | U9: A | V9: A | X9: A | Y9: A | Z9: A | AA9: P | AK9: =COUNTIF(F9:AI9,"P") -> 1 | AL9: =COUNTIF(F9:AI9,"A") -> 17
A10: 6 | B10: 88 | C10: Dua | D10: Khalid Hussain | E10: ONE | G10: A | H10: P | J10: P | K10: P | L10: P | M10: P | N10: P | O10: P | Q10: P | R10: P | S10: P | T10: P | U10: P | V10: P | X10: P | Y10: P | Z10: A | AA10: P | AK10: =COUNTIF(F10:AI10,"P") -> 16 | AL10: =COUNTIF(F10:AI10,"A") -> 2
A11: 7 | B11: 59 | C11: Faiza | D11: Liaqat Ali | E11: ONE | G11: P | H11: P | J11: P | K11: P | L11: P | M11: P | N11: P | O11: P | Q11: P | R11: A | S11: P | T11: A | U11: P | V11: P | X11: P | Y11: P | Z11: P | AA11: P | AK11: =COUNTIF(F11:AI11,"P") -> 16 | AL11: =COUNTIF(F11:AI11,"A") -> 2 | AM11: Present Days Detail
A12: 8 | B12: 83 | C12: Fatima | D12: Aziz-ur-Rehman | E12: ONE | G12: P | H12: P | J12: P | K12: P | L12: P | M12: A | N12: P | O12: P | Q12: A | R12: P | S12: P | T12: P | U12: P | V12: P | X12: P | Y12: P | Z12: P | AA12: P | AK12: =COUNTIF(F12:AI12,"P") -> 16 | AL12: =COUNTIF(F12:AI12,"A") -> 2 | AM12: Detail | AN12: Boys | AO12: Girls | AP12: Total
A13: 9 | B13: 89 | C13: Hafsa | D13: Hafeezullah | E13: ONE | G13: P | H13: P | J13: P | K13: P | L13: P | M13: P | N13: P | O13: P | Q13: P | R13: P | S13: P | T13: P | U13: P | V13: P | X13: P | Y13: P | Z13: P | AA13: P | AK13: =COUNTIF(F13:AI13,"P") -> 18 | AL13: =COUNTIF(F13:AI13,"A") -> 0 | AM13: Due Present days | AN13: =32*$AN$5 -> 832 | AO13: =24*$AN$5 -> 624 | AP13: =SUM(AN13:AO13) -> 1456
A14: 10 | B14: 86 | C14: Insha Arzoo | D14: Meeral | E14: ONE | G14: A | H14: P | J14: P | K14: A | L14: P | M14: A | N14: A | O14: P | Q14: P | R14: P | S14: P | T14: P | U14: P | V14: P | X14: A | Y14: P | Z14: P | AA14: P | AK14: =COUNTIF(F14:AI14,"P") -> 13 | AL14: =COUNTIF(F14:AI14,"A") -> 5 | AM14: Actual present days | AN14: =SUM(AK31:AK61) -> 448 | AO14: =SUM(AK5:AK30) -> 296 | AP14: =AN14+AO14 -> 744
A15: 11 | B15: 105 | C15: Kauser Fatima | D15: Amir Jamil | E15: ONE | G15: P | H15: P | J15: P | K15: P | L15: P | M15: P | N15: P | O15: P | Q15: P | R15: P | S15: A | T15: P | U15: A | V15: P | X15: P | Y15: A | Z15: P | AA15: P | AK15: =COUNTIF(F15:AI15,"P") -> 15 | AL15: =COUNTIF(F15:AI15,"A") -> 3 | AM15: % | AN15: =AN14/AN13 -> 0.53846154 | AO15: =AO14/AO13 -> 0.47435897 | AP15: =AP14/AP13 -> 0.51098901
A16: 12 | B16: 84 | C16: Minha | D16: M. Luqman | E16: ONE | G16: p | H16: p | J16: p | K16: p | L16: P | M16: A | N16: A | O16: A | Q16: A | R16: P | S16: A | T16: A | U16: A | V16: P | X16: A | Y16: A | Z16: A | AA16: A | AK16: =COUNTIF(F16:AI16,"P") -> 7 | AL16: =COUNTIF(F16:AI16,"A") -> 11
A17: 13 | B17: 85 | C17: Misbah Bhutto | D17: M. Azeem | E17: ONE | G17: P | H17: P | J17: P | K17: P | L17: P | M17: P | N17: A | O17: P | Q17: P | R17: P | S17: P | T17: P | U17: P | V17: A | X17: A | Y17: P | Z17: P | AA17: P | AK17: =COUNTIF(F17:AI17,"P") -> 15 | AL17: =COUNTIF(F17:AI17,"A") -> 3
A18: 14 | B18: 102 | C18: Rimsha | D18: Meer Ameer-ud-Din | E18: ONE | G18: A | H18: A | J18: P | K18: P | L18: P | M18: A | N18: P | O18: A | Q18: P | R18: P | S18: A | T18: P | U18: A | V18: P | X18: A | Y18: P | Z18: A | AA18: P | AK18: =COUNTIF(F18:AI18,"P") -> 10 | AL18: =COUNTIF(F18:AI18,"A") -> 8
A19: 15 | B19: 87 | C19: Sidra Batool | D19: Muhammad Khan | E19: ONE | G19: P | H19: P | J19: P | K19: P | L19: P | M19: A | N19: P | O19: P | Q19: P | R19: P | S19: P | T19: P | U19: P | V19: P | X19: P | Y19: P | Z19: P | AA19: P | AK19: =COUNTIF(F19:AI19,"P") -> 17 | AL19: =COUNTIF(F19:AI19,"A") -> 1 | AM19: Absent Days Details
A20: 16 | B20: 71 | C20: Sidra | D20: Khalid Hussain | E20: ONE | G20: A | H20: P | J20: A | K20: A | L20: A | M20: P | N20: P | O20: P | Q20: P | R20: A | S20: A | T20: A | U20: P | V20: P | X20: P | Y20: P | Z20: A | AA20: P | AK20: =COUNTIF(F20:AI20,"P") -> 10 | AL20: =COUNTIF(F20:AI20,"A") -> 8 | AM20: Detail | AN20: Boys | AO20: Girls | AP20: Total
A21: 17 | B21: 81 | C21: Taniya Bibi | D21: Wazir Ali | E21: ONE | G21: P | H21: A | J21: A | K21: A | L21: A | M21: A | N21: A | O21: A | Q21: A | R21: A | S21: A | T21: A | U21: A | V21: A | X21: A | Y21: A | Z21: A | AA21: A | AK21: =COUNTIF(F21:AI21,"P") -> 1 | AL21: =COUNTIF(F21:AI21,"A") -> 17 | AM21: Due Present days | AN21: =32*$AN$5 -> 832 | AO21: =24*$AN$5 -> 624 | AP21: =AN21+AO21 -> 1456
A22: 18 | B22: 82 | C22: Tanzeela | D22: Hizbullah | E22: ONE | G22: A | H22: A | J22: A | K22: A | L22: P | M22: P | N22: P | O22: P | Q22: P | R22: P | S22: P | T22: P | U22: P | V22: P | X22: P | Y22: P | Z22: P | AA22: P | AK22: =COUNTIF(F22:AI22,"P") -> 14 | AL22: =COUNTIF(F22:AI22,"A") -> 4 | AM22: Absent days | AN22: =AN21-AN14 -> 384 | AO22: =AO21-AO14 -> 328 | AP22: =AN22+AO22 -> 712
A23: 19 | B23: 68 | C23: Tayaba Fatima | D23: Waseem Ahmed | E23: ONE | G23: A | H23: A | J23: P | K23: P | L23: P | M23: P | N23: P | O23: P | Q23: P | R23: A | S23: P | T23: P | U23: P | V23: A | X23: P | Y23: P | Z23: P | AA23: P | AK23: =COUNTIF(F23:AI23,"P") -> 14 | AL23: =COUNTIF(F23:AI23,"A") -> 4 | AM23: % | AN23: =AN22/AN21 -> 0.46153846 | AO23: =AO22/AO21 -> 0.52564103 | AP23: =AP22/AP21 -> 0.48901099
A24: 20 | B24: 69 | C24: Tooba Noor | D24: M. Shareef | E24: ONE | G24: A | H24: P | J24: P | K24: P | L24: P | M24: A | N24: P | O24: P | Q24: P | R24: P | S24: P | T24: P | U24: P | V24: P | X24: P | Y24: P | Z24: P | AA24: P | AK24: =COUNTIF(F24:AI24,"P") -> 16 | AL24: =COUNTIF(F24:AI24,"A") -> 2
A25: 21 | B25: 70 | C25: Umm-e-Kulsoom | D25: Shah Ali | E25: ONE | G25: P | H25: A | J25: P | K25: P | L25: P | M25: P | N25: P | O25: P | Q25: P | R25: P | S25: P | T25: A | U25: P | V25: P | X25: P | Y25: P | Z25: P | AA25: P | AK25: 14 | AL25: =COUNTIF(F25:AI25,"A") -> 2
A26: 22 | B26: 103 | C26: Zunaira | D26: Amjad Ali | E26: ONE | G26: A | H26: A | J26: A | K26: A | L26: A | M26: A | N26: A | O26: A | Q26: A | R26: A | S26: A | T26: A | U26: A | V26: A | X26: A | Y26: A | Z26: A | AA26: A | AK26: =COUNTIF(F26:AI26,"P") -> 0 | AL26: =COUNTIF(F26:AI26,"A") -> 18
A27: 23 | B27: 149 | C27: Sahib Khatoon | D27: A. Qayoom | E27: ONE | G27: A | H27: A | J27: A | K27: A | L27: A | M27: A | N27: A | O27: A | Q27: A | R27: P | S27: P | T27: A | U27: P | V27: P | X27: A | Y27: A | Z27: A | AA27: P | AK27: =COUNTIF(F27:AI27,"P") -> 5 | AL27: =COUNTIF(F27:AI27,"A") -> 13
A28: 24 | B28: 107 | C28: Mehrunisa | D28: Aijaz Ali | E28: ONE | G28: A | H28: A | J28: A | K28: A | L28: A | M28: A | N28: A | O28: A | Q28: A | R28: A | S28: A | T28: A | U28: A | V28: A | X28: A | Y28: A | Z28: A | AA28: A | AK28: =COUNTIF(F28:AI28,"P") -> 0 | AL28: =COUNTIF(F28:AI28,"A") -> 18
A29: 25 | C29: Anusha | E29: ONE | G29: p | H29: p | J29: A | K29: A | L29: A | M29: A | N29: P | O29: A | Q29: P | R29: A | S29: P | T29: P | U29: P | V29: P | X29: P | Y29: P | Z29: P | AA29: P | AK29: =COUNTIF(F29:AI29,"P") -> 12 | AL29: =COUNTIF(F29:AI29,"A") -> 6
A30: 26 | B30: 169 | C30: Parsa Batool | D30: Imran Ali | E30: ONE | G30: A | H30: P | J30: P | K30: P | L30: A | M30: A | N30: P | O30: P | Q30: P | R30: P | S30: A | T30: P | U30: A | V30: A | X30: P | Y30: A | Z30: A | AA30: A | AK30: =COUNTIF(F30:AI30,"P") -> 9 | AL30: =COUNTIF(F30:AI30,"A") -> 9
A31: 1 | B31: 61 | C31: Abrar | D31: Jan Muhammad | E31: ONE | G31: P | H31: P | J31: P | K31: P | L31: P | M31: P | N31: P | O31: P | Q31: P | R31: P | S31: P | T31: P | U31: P | V31: P | X31: P | Y31: P | Z31: P | AA31: P | AK31: =COUNTIF(F31:AI31,"P") -> 18 | AL31: =COUNTIF(F31:AI31,"A") -> 0
A32: 2 | B32: 79 | C32: Azan Shafeeque | D32: M. Shafeeque | E32: ONE | G32: P | H32: P | J32: P | K32: P | L32: P | M32: P | N32: P | O32: A | Q32: P | R32: P | S32: P | T32: P | U32: P | V32: P | X32: P | Y32: P | Z32: P | AA32: P | AK32: =COUNTIF(F32:AI32,"P") -> 17 | AL32: =COUNTIF(F32:AI32,"A") -> 1
A33: 3 | B33: 16 | C33: Azan Fayaz | D33: Fayaz Hussain | E33: ONE | G33: P | H33: P | J33: A | K33: P | L33: P | M33: P | N33: P | O33: P | Q33: P | R33: P | S33: P | T33: P | U33: P | V33: P | X33: P | Y33: P | Z33: P | AA33: P | AK33: =COUNTIF(F33:AI33,"P") -> 17 | AL33: =COUNTIF(F33:AI33,"A") -> 1
A34: 4 | B34: 78 | C34: Adil Ahmed | D34: Faiz Muhammad | E34: ONE | G34: P | H34: P | J34: P | K34: P | L34: P | M34: P | N34: P | O34: A | Q34: P | R34: P | S34: P | T34: P | U34: A | V34: A | X34: P | Y34: P | Z34: P | AA34: P | AK34: =COUNTIF(F34:AI34,"P") -> 15 | AL34: =COUNTIF(F34:AI34,"A") -> 3
A35: 5 | B35: 76 | C35: Ab. Qudoos | D35: Sikandar | E35: ONE | G35: P | H35: P | J35: P | K35: P | L35: P | M35: P | N35: P | O35: P | Q35: P | R35: P | S35: P | T35: P | U35: P | V35: P | X35: A | Y35: P | Z35: P | AA35: P | AK35: =COUNTIF(F35:AI35,"P") -> 17 | AL35: =COUNTIF(F35:AI35,"A") -> 1
A36: 6 | B36: 108 | C36: Arham | D36: Qasim Memon | E36: ONE | G36: P | H36: A | J36: P | K36: P | L36: A | M36: A | N36: P | O36: A | Q36: P | R36: A | S36: P | T36: A | U36: A | V36: A | X36: A | Y36: P | Z36: P | AA36: P | AK36: =COUNTIF(F36:AI36,"P") -> 9 | AL36: =COUNTIF(F36:AI36,"A") -> 9
A37: 7 | B37: 131 | C37: Amar Farooque | D37: M. Farooque | E37: ONE | G37: A | H37: A | J37: A | K37: A | L37: A | M37: A | N37: A | O37: A | Q37: A | R37: A | S37: A | T37: A | U37: A | V37: A | X37: A | Y37: A | Z37: A | AA37: A | AK37: =COUNTIF(F37:AI37,"P") -> 0 | AL37: =COUNTIF(F37:AI37,"A") -> 18
A38: 8 | B38: 101 | C38: Ashfaque | D38: M. Zubair | E38: ONE | G38: P | H38: P | J38: A | K38: P | L38: A | M38: P | N38: A | O38: A | Q38: P | R38: P | S38: P | T38: P | U38: P | V38: P | X38: P | Y38: P | Z38: P | AA38: P | AK38: =COUNTIF(F38:AI38,"P") -> 14 | AL38: =COUNTIF(F38:AI38,"A") -> 4
A39: 9 | B39: 100 | C39: Fahad | D39: M. Maroof | E39: ONE | G39: A | H39: P | J39: P | K39: P | L39: A | M39: P | N39: A | O39: P | Q39: A | R39: P | S39: P | T39: P | U39: P | V39: A | X39: P | Y39: P | Z39: P | AA39: P | AK39: =COUNTIF(F39:AI39,"P") -> 13 | AL39: =COUNTIF(F39:AI39,"A") -> 5
A40: 10 | B40: 90 | C40: Hussain | D40: Hafeezullah | E40: ONE | G40: P | H40: P | J40: P | K40: P | L40: P | M40: P | N40: P | O40: P | Q40: P | R40: P | S40: P | T40: P | U40: P | V40: P | X40: P | Y40: P | Z40: P | AA40: P | AK40: =COUNTIF(F40:AI40,"P") -> 18 | AL40: =COUNTIF(F40:AI40,"A") -> 0
...

Sheet Class-2
A1: Goverment high school (SJCHS)
A2: Monthly Attendence Month of MAY-2025
A3: S.No | B3: GR | C3: Student Name | D3: Father Name | E3: Class | F3: Thu | G3: Fri | H3: Sat | I3: Sun | J3: Mon | K3: Tue | L3: Wed | M3: Thu | N3: Fri | O3: Sat | P3: Sun | Q3: Mon | R3: Tue | S3: Wed | T3: Thu | U3: Fri | V3: Sat | W3: Sun | X3: Mon | Y3: Tue | Z3: Wed | AA3: Thu | AB3: Fri | AC3: Sat | AD3: Sun | AE3: Mon | AF3: Tue | AG3: Wed | AH3: Thu | AI3: Fri | AJ3: Sat | AK3: Present | AL3: Absent | AM3: Year 2024
F4: 01,MAY | G4: 45779 | H4: 45780 | I4: 45781 | J4: 45782 | K4: 45783 | L4: 45784 | M4: 45785 | N4: 45786 | O4: 45787 | P4: 45788 | Q4: 45789 | R4: 45790 | S4: 45791 | T4: 45792 | U4: 45793 | V4: 45794 | W4: 45795 | X4: 45796 | Y4: 45797 | Z4: 45798 | AA4: 45799 | AB4: 45800 | AC4: 45801 | AD4: 45802 | AE4: 45803 | AF4: 45804 | AG4: 45805 | AH4: 45806 | AI4: 45807 | AJ4: 45808 | AM4: Total days | AN4: =SUM(AN5:AN8) -> 30
A5: 1 | B5: 815 | C5: Anum | D5: M. Arif | E5: TWO | F5: LABOUR DAY LABOUR DAY LABOUR DAY | G5: p | H5: p | I5: Sunday Sunday Sunday sunday | J5: p | K5: p | L5: p | M5: p | N5: p | O5: p | P5: Sunday Sunday Sunday sunday | Q5: A | R5: P | S5: P | T5: P | U5: P | V5: P | W5: Sunday Sunday Sunday sunday | X5: L | Y5: L | Z5: P | AA5: P | AD5: Sunday Sunday Sunday sunday | AK5: =COUNTIF(F5:AI5,"P") -> 15 | AL5: =COUNTIF(F5:AI5,"A") -> 1 | AM5: Working days | AN5: 26
A6: 2 | B6: 819 | C6: Amna | D6: Saeed Ahmed | E6: TWO | G6: P | H6: P | J6: P | K6: A | L6: P | M6: P | N6: P | O6: P | Q6: P | R6: P | S6: P | T6: P | U6: P | V6: P | X6: P | Y6: P | Z6: P | AA6: P | AK6: =COUNTIF(F6:AI6,"P") -> 17 | AL6: =COUNTIF(F6:AI6,"A") -> 1 | AM6: Sunday | AN6: 4
A7: 3 | B7: 812 | C7: Adeeba | D7: Qurban Ali | E7: TWO | G7: P | H7: P | J7: P | K7: P | L7: P | M7: P | N7: A | O7: P | Q7: P | R7: P | S7: P | T7: P | U7: P | V7: A | X7: P | Y7: P | Z7: P | AA7: P | AK7: =COUNTIF(F7:AI7,"P") -> 16 | AL7: =COUNTIF(F7:AI7,"A") -> 2
A8: 4 | B8: 801 | C8: Emaan Noor | D8: Noor Mohammad | E8: TWO | G8: P | H8: P | J8: P | K8: P | L8: P | M8: P | N8: A | O8: P | Q8: P | R8: P | S8: P | T8: P | U8: A | V8: A | X8: P | Y8: P | Z8: P | AA8: P | AK8: =COUNTIF(F8:AI8,"P") -> 15 | AL8: =COUNTIF(F8:AI8,"A") -> 3
A9: 5 | B9: 828 | C9: Horain | D9: Saeed Ahmed | E9: TWO | G9: P | H9: P | J9: P | K9: A | L9: P | M9: P | N9: P | O9: A | Q9: P | R9: P | S9: A | T9: P | U9: A | V9: P | X9: P | Y9: A | Z9: P | AA9: P | AK9: =COUNTIF(F9:AI9,"P") -> 13 | AL9: =COUNTIF(F9:AI9,"A") -> 5
A10: 6 | B10: 829 | C10: Hannah | D10: Luqman Ali | E10: TWO | G10: P | H10: P | J10: P | K10: P | L10: A | M10: A | N10: A | O10: A | Q10: A | R10: P | S10: A | T10: A | U10: A | V10: A | X10: A | Y10: A | Z10: A | AA10: A | AK10: =COUNTIF(F10:AI10,"P") -> 5 | AL10: =COUNTIF(F10:AI10,"A") -> 13
A11: 7 | B11: 817 | C11: Hareem Fatima | D11: Deedar Ali | E11: TWO | G11: P | H11: P | J11: P | K11: P | L11: P | M11: P | N11: P | O11: P | Q11: P | R11: P | S11: P | T11: P | U11: P | V11: P | X11: P | Y11: P | Z11: P | AA11: P | AK11: =COUNTIF(F11:AI11,"P") -> 18 | AL11: =COUNTIF(F11:AI11,"A") -> 0 | AM11: Detail | AN11: Boys | AO11: Girls | AP11: Total
A12: 8 | B12: 807 | C12: Maham Noor | D12: Zaheer Abbas | E12: TWO | G12: A | H12: A | J12: A | K12: A | L12: A | M12: A | N12: A | O12: A | Q12: A | R12: A | S12: P | T12: P | U12: P | V12: P | X12: P | Y12: P | Z12: P | AA12: P | AK12: =COUNTIF(F12:AI12,"P") -> 8 | AL12: =COUNTIF(F12:AI12,"A") -> 10 | AM12: Due Present days | AN12: =32*$AN$5 -> 832 | AO12: =24*$AN$5 -> 624 | AP12: =SUM(AN12:AO12) -> 1456
A13: 9 | B13: 827 | C13: Maria | D13: Mehboob Ali | E13: TWO | G13: P | H13: P | J13: P | K13: P | L13: P | M13: P | N13: P | O13: P | Q13: P | R13: P | S13: P | T13: P | U13: P | V13: P | X13: P | Y13: P | Z13: P | AA13: P | AK13: =COUNTIF(F13:AI13,"P") -> 18 | AL13: =COUNTIF(F13:AI13,"A") -> 0 | AM13: Actual present days | AN13: =SUM(AK25:AK54) -> 424 | AO13: =SUM(AK5:AK24) -> 281 | AP13: =AN13+AO13 -> 705
A14: 10 | B14: 802 | C14: Mehreen | D14: M. Maroof | E14: TWO | G14: A | H14: P | J14: P | K14: P | L14: P | M14: A | N14: P | O14: P | Q14: P | R14: P | S14: P | T14: P | U14: P | V14: P | X14: P | Y14: P | Z14: P | AA14: A | AK14: =COUNTIF(F14:AI14,"P") -> 15 | AL14: =COUNTIF(F14:AI14,"A") -> 3 | AM14: % | AN14: =AN13/AN12 -> 0.50961538 | AO14: =AO13/AO12 -> 0.45032051 | AP14: =AP13/AP12 -> 0.4842033
A15: 11 | C15: Mahira | D15: Arbab Ali | E15: TWO | G15: A | H15: P | J15: P | K15: A | L15: A | M15: P | N15: P | O15: A | Q15: P | R15: P | S15: P | T15: P | U15: P | V15: P | X15: A | Y15: P | Z15: A | AA15: P | AK15: =COUNTIF(F15:AI15,"P") -> 12 | AL15: =COUNTIF(F15:AI15,"A") -> 6
A16: 12 | B16: 836 | C16: Meerab | D16: Yasir Ahmed | E16: TWO | G16: P | H16: A | J16: P | K16: P | L16: P | M16: P | N16: P | O16: P | Q16: P | R16: P | S16: P | T16: P | U16: P | V16: P | X16: P | Y16: P | Z16: P | AA16: P | AK16: =COUNTIF(F16:AI16,"P") -> 17 | AL16: =COUNTIF(F16:AI16,"A") -> 1
A17: 13 | B17: 835 | C17: Qudsia Zehra | D17: Waheed Ali | E17: TWO | G17: A | H17: A | J17: A | K17: A | L17: A | M17: A | N17: A | O17: A | Q17: A | R17: A | S17: A | T17: A | U17: A | V17: A | X17: A | Y17: A | Z17: A | AA17: A | AK17: =COUNTIF(F17:AI17,"P") -> 0 | AL17: =COUNTIF(F17:AI17,"A") -> 18
A18: 14 | C18: Paras | D18: Sadam | E18: TWO | G18: P | H18: A | J18: P | K18: A | L18: P | M18: P | N18: P | O18: A | Q18: P | R18: P | S18: P | T18: P | U18: P | V18: A | X18: P | Y18: P | Z18: P | AA18: P | AK18: =COUNTIF(F18:AI18,"P") -> 14 | AL18: =COUNTIF(F18:AI18,"A") -> 4 | AM18: Absent Days Details
A19: 15 | B19: 892 | C19: Thamna Batool | D19: Shehzad | E19: TWO | G19: P | H19: P | J19: P | K19: P | L19: P | M19: P | N19: P | O19: P | Q19: P | R19: P | S19: P | T19: P | U19: A | V19: P | X19: P | Y19: P | Z19: P | AA19: P | AK19: =COUNTIF(F19:AI19,"P") -> 17 | AL19: =COUNTIF(F19:AI19,"A") -> 1 | AM19: Detail | AN19: Boys | AO19: Girls | AP19: Total
A20: 16 | B20: 838 | C20: Tamana Fatima | D20: Shehzad | E20: TWO | G20: P | H20: P | J20: P | K20: P | L20: P | M20: P | N20: P | O20: P | Q20: P | R20: P | S20: P | T20: P | U20: A | V20: P | X20: P | Y20: P | Z20: P | AA20: P | AK20: =COUNTIF(F20:AI20,"P") -> 17 | AL20: =COUNTIF(F20:AI20,"A") -> 1 | AM20: Due Present days | AN20: =32*$AN$5 -> 832 | AO20: =24*$AN$5 -> 624 | AP20: =AN20+AO20 -> 1456
A21: 17 | B21: 808 | C21: Haram | D21: Moien Khan | E21: TWO | G21: A | H21: A | J21: P | K21: P | L21: P | M21: P | N21: P | O21: P | Q21: P | R21: P | S21: P | T21: P | U21: A | V21: A | X21: P | Y21: P | Z21: A | AA21: A | AK21: =COUNTIF(F21:AI21,"P") -> 12 | AL21: =COUNTIF(F21:AI21,"A") -> 6 | AM21: Absent days | AN21: =AN20-AN13 -> 408 | AO21: =AO20-AO13 -> 343 | AP21: =AN21+AO21 -> 751
A22: 18 | B22: 823 | C22: Zaiba Bakhtawar | D22: Hameed | E22: TWO | G22: P | H22: P | J22: P | K22: P | L22: A | M22: P | N22: P | O22: P | Q22: P | R22: A | S22: P | T22: P | U22: P | V22: P | X22: P | Y22: P | Z22: P | AA22: P | AK22: =COUNTIF(F22:AI22,"P") -> 16 | AL22: =COUNTIF(F22:AI22,"A") -> 2
A23: 19 | B23: 793 | C23: Zainab | D23: A. Aziz | E23: TWO | G23: P | H23: P | J23: P | K23: P | L23: P | M23: P | N23: P | O23: P | Q23: P | R23: P | S23: P | T23: P | U23: P | V23: P | X23: P | Y23: P | Z23: P | AA23: P | AK23: =COUNTIF(F23:AI23,"P") -> 18 | AL23: =COUNTIF(F23:AI23,"A") -> 0
A24: 20 | B24: 811 | C24: Zainab | D24: Zulfiqar | E24: TWO | G24: P | H24: P | J24: P | K24: P | L24: P | M24: P | N24: P | O24: P | Q24: P | R24: P | S24: P | T24: P | U24: P | V24: P | X24: P | Y24: P | Z24: P | AA24: P | AK24: =COUNTIF(F24:AI24,"P") -> 18 | AL24: =COUNTIF(F24:AI24,"A") -> 0
A25: 1 | B25: 824 | C25: Arsalan | D25: Zulfiqar | E25: TWO | G25: P | H25: A | J25: P | K25: P | L25: P | M25: P | N25: P | O25: P | Q25: P | R25: P | S25: P | T25: P | U25: P | V25: P | X25: P | Y25: P | Z25: P | AA25: P | AK25: =COUNTIF(F25:AI25,"P") -> 17 | AL25: =COUNTIF(F25:AI25,"A") -> 1
A26: 2 | B26: 791 | C26: Arsalan | D26: Faheem | E26: TWO | G26: A | H26: A | J26: P | K26: P | L26: P | M26: A | N26: P | O26: P | Q26: P | R26: P | S26: P | T26: P | U26: A | V26: A | X26: P | Y26: P | Z26: P | AA26: P | AK26: =COUNTIF(F26:AI26,"P") -> 13 | AL26: =COUNTIF(F26:AI26,"A") -> 5
A27: 3 | B27: 809 | C27: Ahmed Nawaz | D27: Ali Nawaz | E27: TWO | G27: P | H27: P | J27: P | K27: P | L27: P | M27: P | N27: P | O27: P | Q27: A | R27: P | S27: P | T27: P | U27: P | V27: P | X27: P | Y27: P | Z27: P | AA27: P | AK27: =COUNTIF(F27:AI27,"P") -> 17 | AL27: =COUNTIF(F27:AI27,"A") -> 1
A28: 4 | B28: 837 | C28: A. Malik | D28: Sohail | E28: TWO | G28: P | H28: A | J28: P | K28: A | L28: A | M28: A | N28: P | O28: A | Q28: A | R28: P | S28: P | T28: P | U28: A | V28: P | X28: P | Y28: P | Z28: P | AA28: A | AK28: =COUNTIF(F28:AI28,"P") -> 10 | AL28: =COUNTIF(F28:AI28,"A") -> 8
A29: 5 | B29: 798 | C29: Abdullah | D29: Imtiaz | E29: TWO | G29: P | H29: P | J29: P | K29: P | L29: P | M29: P | N29: P | O29: P | Q29: P | R29: P | S29: P | T29: P | U29: A | V29: P | X29: P | Y29: P | Z29: P | AA29: P | AK29: =COUNTIF(F29:AI29,"P") -> 17 | AL29: =COUNTIF(F29:AI29,"A") -> 1
A30: 6 | B30: 816 | C30: Aqeel | D30: A. Ghaffar | E30: TWO | G30: P | H30: P | J30: A | K30: A | L30: A | M30: A | N30: A | O30: A | Q30: P | R30: P | S30: P | T30: P | U30: P | V30: P | X30: P | Y30: P | Z30: P | AA30: P | AK30: =COUNTIF(F30:AI30,"P") -> 12 | AL30: =COUNTIF(F30:AI30,"A") -> 6
A31: 7 | C31: A. Qadir | D31: A. Hammad | E31: TWO | G31: P | H31: P | J31: A | K31: A | L31: P | M31: A | N31: A | O31: A | Q31: A | R31: P | S31: A | T31: A | U31: A | V31: P | X31: P | Y31: P | Z31: A | AA31: A | AK31: =COUNTIF(F31:AI31,"P") -> 7 | AL31: =COUNTIF(F31:AI31,"A") -> 11
A32: 8 | B32: 795 | C32: Asghar Ali | D32: Akbar Ali | E32: TWO | G32: P | H32: A | J32: P | K32: P | L32: P | M32: P | N32: P | O32: P | Q32: P | R32: P | S32: P | T32: P | U32: P | V32: P | X32: P | Y32: P | Z32: P | AA32: P | AK32: =COUNTIF(F32:AI32,"P") -> 17 | AL32: =COUNTIF(F32:AI32,"A") -> 1
A33: 9 | B33: 821 | C33: Hasaan | D33: Manzoor | E33: TWO | G33: A | H33: A | J33: A | K33: A | L33: A | M33: A | N33: A | O33: A | Q33: P | R33: P | S33: P | T33: A | U33: P | V33: A | X33: A | Y33: A | Z33: P | AA33: P | AK33: =COUNTIF(F33:AI33,"P") -> 6 | AL33: =COUNTIF(F33:AI33,"A") -> 12
A34: 10 | B34: 776 | C34: Hammad | D34: Rehmatullah | E34: TWO | G34: P | H34: P | J34: P | K34: P | L34: P | M34: P | N34: P | O34: P | Q34: P | R34: P | S34: P | T34: P | U34: P | V34: P | X34: P | Y34: P | Z34: P | AA34: P | AK34: =COUNTIF(F34:AI34,"P") -> 18 | AL34: =COUNTIF(F34:AI34,"A") -> 0
A35: 11 | B35: 820 | C35: Hammad | D35: Shahid | E35: TWO | G35: P | H35: P | J35: P | K35: P | L35: P | M35: P | N35: P | O35: P | Q35: P | R35: P | S35: P | T35: P | U35: P | V35: P | X35: A | Y35: P | Z35: P | AA35: P | AK35: =COUNTIF(F35:AI35,"P") -> 17 | AL35: =COUNTIF(F35:AI35,"A") -> 1
A36: 12 | B36: 832 | C36: Hussain | D36: A. Bakar | E36: TWO | G36: P | H36: A | J36: P | K36: P | L36: P | M36: P | N36: P | O36: P | Q36: P | R36: P | S36: P | T36: P | U36: P | V36: P | X36: P | Y36: P | Z36: P | AA36: P | AK36: =COUNTIF(F36:AI36,"P") -> 17 | AL36: =COUNTIF(F36:AI36,"A") -> 1
A37: 13 | B37: 818 | C37: Haseeb | D37: Saeed | E37: TWO | G37: P | H37: A | J37: P | K37: A | L37: P | M37: P | N37: P | O37: P | Q37: P | R37: P | S37: P | T37: P | U37: P | V37: P | X37: P | Y37: P | Z37: P | AA37: P | AK37: =COUNTIF(F37:AI37,"P") -> 16 | AL37: =COUNTIF(F37:AI37,"A") -> 2
A38: 14 | C38: Ismail | D38: M. Raheem | E38: TWO | G38: A | H38: P | J38: A | K38: P | L38: P | M38: P | N38: A | O38: P | Q38: P | R38: P | S38: P | T38: P | U38: A | V38: P | X38: P | Y38: P | Z38: A | AA38: A | AK38: =COUNTIF(F38:AI38,"P") -> 12 | AL38: =COUNTIF(F38:AI38,"A") -> 6
A39: 15 | B39: 825 | C39: M. Salar | D39: Saeed Ahmed | E39: TWO | G39: P | H39: P | J39: P | K39: P | L39: P | M39: P | N39: P | O39: A | Q39: P | R39: P | S39: A | T39: P | U39: P | V39: P | X39: P | Y39: P | Z39: P | AA39: P | AK39: =COUNTIF(F39:AI39,"P") -> 16 | AL39: =COUNTIF(F39:AI39,"A") -> 2
A40: 16 | B40: 831 | C40: M. Umer | D40: A. Bakar | E40: TWO | G40: P | H40: A | J40: P | K40: P | L40: P | M40: P | N40: P | O40: P | Q40: P | R40: P | S40: A | T40: P | U40: P | V40: P | X40: P | Y40: P | Z40: P | AA40: P | AK40: =COUNTIF(F40:AI40,"P") -> 16 | AL40: =COUNTIF(F40:AI40,"A") -> 2
...

Sheet Class-3
A1: Goverment High School (SJCHS)
A2: Monthly Attendence Month of MAY-2025
A3: S.No | B3: GR | C3: Student Name | D3: Father Name | E3: Class | F3: Thu | G3: Fri | H3: Sat | I3: Sun | J3: Mon | K3: Tue | L3: Wed | M3: Thu | N3: Fri | O3: Sat | P3: Sun | Q3: Mon | R3: Tue | S3: Wed | T3: Thu | U3: Fri | V3: Sat | W3: Sun | X3: Mon | Y3: Tue | Z3: Wed | AA3: Thu | AB3: Fri | AC3: Sat | AD3: Sun | AE3: Mon | AF3: Tue | AG3: Wed | AH3: Thu | AI3: Fri | AJ3: Sat | AK3: Present | AL3: Absent | AM3: Year 2024
F4: 01,MAY | G4: 45779 | H4: 45780 | I4: 45781 | J4: 45782 | K4: 45783 | L4: 45784 | M4: 45785 | N4: 45786 | O4: 45787 | P4: 45788 | Q4: 45789 | R4: 45790 | S4: 45791 | T4: 45792 | U4: 45793 | V4: 45794 | W4: 45795 | X4: 45796 | Y4: 45797 | Z4: 45798 | AA4: 45799 | AB4: 45800 | AC4: 45801 | AD4: 45802 | AE4: 45803 | AF4: 45804 | AG4: 45805 | AH4: 45806 | AI4: 45807 | AJ4: 45808 | AM4: Total days | AN4: =SUM(AN5:AN8) -> 30
A5: 1 | B5: 772 | C5: Abiha Zehra | D5: Ab. Mateen | E5: Three | F5: LABOUR DAY LABOUR DAY LABOUR DAY | G5: A | H5: A | I5: SUNDAY SUNDAY SUNDAY SUNDAY | J5: P | K5: P | L5: P | M5: P | N5: A | O5: A | P5: SUNDAY SUNDAY SUNDAY SUNDAY | Q5: P | R5: P | S5: P | T5: P | U5: P | V5: P | W5: SUNDAY SUNDAY SUNDAY SUNDAY | X5: P | Y5: P | Z5: P | AA5: P | AB5: P | AD5: SUNDAY SUNDAY SUNDAY SUNDAY | AK5: =COUNTIF(F5:AI5,"P") -> 15 | AL5: =COUNTIF(F5:AI5,"A") -> 4 | AM5: Working days | AN5: 26
A6: 2 | B6: 673 | C6: Aleena Zia | D6: Khuda Baksh | E6: Three | G6: P | H6: A | J6: P | K6: P | L6: P | M6: P | N6: P | O6: P | Q6: P | R6: P | S6: P | T6: P | U6: P | V6: P | X6: P | Y6: P | Z6: P | AA6: P | AB6: P | AK6: =COUNTIF(F6:AI6,"P") -> 18 | AL6: =COUNTIF(F6:AI6,"A") -> 1 | AM6: Sunday | AN6: 4
A7: 3 | B7: 6523 | C7: Anumta Jamali | D7: Zaheer Abbas | E7: Three | G7: P | H7: P | J7: P | K7: P | L7: P | M7: P | N7: P | O7: P | Q7: P | R7: P | S7: P | T7: P | U7: P | V7: P | X7: P | Y7: P | Z7: P | AA7: P | AB7: P | AK7: =COUNTIF(F7:AI7,"P") -> 19 | AL7: =COUNTIF(F7:AI7,"A") -> 0
A8: 4 | B8: 665 | C8: Ayat | D8: Faiq Ali | E8: Three | G8: P | H8: P | J8: P | K8: A | L8: P | M8: A | N8: P | O8: P | Q8: P | R8: P | S8: P | T8: P | U8: A | V8: P | X8: P | Y8: P | Z8: P | AA8: P | AB8: P | AK8: =COUNTIF(F8:AI8,"P") -> 16 | AL8: =COUNTIF(F8:AI8,"A") -> 3
A9: 5 | B9: 656 | C9: Ayesha | D9: Ali Muhammad | E9: Three | G9: A | H9: A | J9: A | K9: A | L9: A | M9: A | N9: A | O9: A | Q9: A | R9: A | S9: A | T9: A | U9: A | V9: A | X9: P | Y9: P | Z9: P | AA9: P | AB9: P | AK9: =COUNTIF(F9:AI9,"P") -> 5 | AL9: =COUNTIF(F9:AI9,"A") -> 14
A10: 6 | B10: 910 | C10: Ayesha | D10: Zulfiqar | E10: Three | G10: P | H10: P | J10: P | K10: P | L10: P | M10: P | N10: P | O10: P | Q10: A | R10: P | S10: P | T10: P | U10: P | V10: P | X10: P | Y10: P | Z10: P | AA10: P | AB10: P | AK10: =COUNTIF(F10:AI10,"P") -> 18 | AL10: =COUNTIF(F10:AI10,"A") -> 1
A11: 7 | B11: 679 | C11: Dua | D11: Akbar Ali | E11: Three | G11: P | H11: A | J11: P | K11: P | L11: P | M11: P | N11: P | O11: P | Q11: P | R11: A | S11: P | T11: P | U11: P | V11: P | X11: P | Y11: P | Z11: P | AA11: P | AB11: P | AK11: =COUNTIF(F11:AI11,"P") -> 17 | AL11: =COUNTIF(F11:AI11,"A") -> 2 | AM11: Present Days Detail
A12: 8 | B12: 675 | C12: Fiza | D12: Akbar Ali | E12: Three | G12: P | H12: P | J12: P | K12: P | L12: P | M12: P | N12: P | O12: P | Q12: P | R12: P | S12: P | T12: P | U12: P | V12: P | X12: P | Y12: P | Z12: P | AA12: P | AB12: P | AK12: =COUNTIF(F12:AI12,"P") -> 19 | AL12: =COUNTIF(F12:AI12,"A") -> 0 | AM12: Detail | AN12: Boys | AO12: Girls | AP12: Total
A13: 9 | B13: 774 | C13: Jannat Fatima | D13: Zulfiqar | E13: Three | G13: A | H13: A | J13: A | K13: A | L13: P | M13: P | N13: P | O13: P | Q13: P | R13: P | S13: P | T13: P | U13: P | V13: P | X13: A | Y13: P | Z13: P | AA13: P | AB13: A | AK13: =COUNTIF(F13:AI13,"P") -> 13 | AL13: =COUNTIF(F13:AI13,"A") -> 6 | AM13: Due Present days | AN13: =26*$AN$5 -> 676 | AO13: =26*$AN$5 -> 676 | AP13: =SUM(AN13:AO13) -> 1352
A14: 10 | B14: 655 | C14: Kashaf | D14: Abdul Rehman | E14: Three | G14: P | H14: P | J14: P | K14: P | L14: P | M14: P | N14: P | O14: P | Q14: P | R14: P | S14: P | T14: P | U14: P | V14: P | X14: P | Y14: P | Z14: P | AA14: P | AB14: P | AK14: =COUNTIF(F14:AI14,"P") -> 19 | AL14: =COUNTIF(F14:AI14,"A") -> 0 | AM14: Actual present days | AN14: =SUM(AK29:AK52) -> 350 | AO14: =SUM(AK5:AK28) -> 347 | AP14: =AN14+AO14 -> 697
A15: 11 | B15: 653 | C15: Kashish | D15: M. Noman | E15: Three | G15: A | H15: P | J15: P | K15: P | L15: P | M15: P | N15: P | O15: P | Q15: P | R15: P | S15: P | T15: P | U15: P | V15: P | X15: A | Y15: P | Z15: P | AA15: P | AB15: P | AK15: =COUNTIF(F15:AI15,"P") -> 17 | AL15: =COUNTIF(F15:AI15,"A") -> 2 | AM15: % | AN15: =AN14/AN13 -> 0.51775148 | AO15: =AO14/AO13 -> 0.51331361 | AP15: =AP14/AP13 -> 0.51553254
A16: 12 | B16: 657 | C16: Masooma | D16: M. Raheem | E16: Three | G16: A | H16: A | J16: A | K16: P | L16: A | M16: A | N16: A | O16: P | Q16: P | R16: A | S16: P | T16: P | U16: P | V16: P | X16: P | Y16: P | Z16: P | AA16: A | AB16: P | AK16: =COUNTIF(F16:AI16,"P") -> 11 | AL16: =COUNTIF(F16:AI16,"A") -> 8
A17: 13 | B17: 672 | C17: Muneeza | D17: Mir Amirudin | E17: Three | G17: A | H17: A | J17: A | K17: A | L17: P | M17: A | N17: P | O17: P | Q17: P | R17: P | S17: A | T17: P | U17: A | V17: P | X17: A | Y17: P | Z17: A | AA17: P | AB17: P | AK17: =COUNTIF(F17:AI17,"P") -> 10 | AL17: =COUNTIF(F17:AI17,"A") -> 9
A18: 14 | B18: 702 | C18: Nayyara | D18: Khalid Hussain | E18: Three | G18: A | H18: P | J18: P | K18: P | L18: P | M18: P | N18: P | O18: P | Q18: A | R18: A | S18: P | T18: P | U18: P | V18: P | X18: P | Y18: A | Z18: P | AA18: P | AB18: P | AK18: =COUNTIF(F18:AI18,"P") -> 15 | AL18: =COUNTIF(F18:AI18,"A") -> 4
A19: 15 | B19: 659 | C19: Rashida | D19: Sajjad Ahmed | E19: Three | G19: A | H19: A | J19: A | K19: A | L19: A | M19: A | N19: A | O19: A | Q19: A | R19: A | S19: A | T19: A | U19: A | V19: A | X19: A | Y19: A | Z19: A | AA19: A | AB19: A | AK19: =COUNTIF(F19:AI19,"P") -> 0 | AL19: =COUNTIF(F19:AI19,"A") -> 19 | AM19: Absent Days Details
A20: 16 | B20: 661 | C20: Rubab Zahra | D20: Abdul Aziz | E20: Three | G20: P | H20: P | J20: P | K20: P | L20: P | M20: P | N20: P | O20: P | Q20: P | R20: P | S20: P | T20: P | U20: P | V20: P | X20: P | Y20: P | Z20: P | AA20: P | AB20: P | AK20: =COUNTIF(F20:AI20,"P") -> 19 | AL20: =COUNTIF(F20:AI20,"A") -> 0 | AM20: Detail | AN20: Boys | AO20: Girls | AP20: Total
A21: 17 | B21: 522 | C21: Soha Jamali | D21: Sajid Ali | E21: Three | G21: P | H21: P | J21: P | K21: P | L21: P | M21: P | N21: P | O21: P | Q21: P | R21: P | S21: P | T21: P | U21: A | V21: P | X21: P | Y21: P | Z21: P | AA21: P | AB21: P | AK21: =COUNTIF(F21:AI21,"P") -> 18 | AL21: =COUNTIF(F21:AI21,"A") -> 1 | AM21: Due Present days | AN21: =26*$AN$5 -> 676 | AO21: =26*$AN$5 -> 676 | AP21: =AN21+AO21 -> 1352
