Workbook

Sheet Compile Sheet-August-2024
A4: Class | B4: Total Enrolment & Attendance August-24
B5: Boys | C5: Girls | D5: Total | E5: total working Days | F5: Total working days-Boys | G5: Total working days-Girls | H5: Total working days-All | I5: P-Days Boys | J5: P-Days Girls | K5: P-Days All | L5: Percentage-Girls | M5: Percentage-Boys | N5: Percentage-Boys | O5: Total average
A6: ECE (ROSE) | B6: 20 | C6: 21 | D6: =SUM(B6:C6) -> 41 | E6: 11 | F6: =B6*E6 -> 220 | G6: =C6*E6 -> 231 | H6: =SUM(F6:G6) -> 451 | I6: ='ECE (ROSE)'!Y16 -> 120 | J6: ='ECE (ROSE)'!Z16 -> 142 | K6: =SUM(I6:J6) -> 262 | L6: =J6/G6 -> 0.61471861 | M6: =I6/F6 -> 0.54545455 | N6: =K6/H6 -> 0.58093126 | O6: =AVERAGE(L6:M6) -> 0.58008658
A7: ECE (Daffodils) | B7: 29 | C7: 24 | D7: =SUM(B7:C7) -> 53 | E7: 11 | F7: =B7*E7 -> 319 | G7: =C7*E7 -> 264 | H7: =SUM(F7:G7) -> 583 | I7: ='ECE (DAFFODILS)'!Y16 -> 185 | J7: ='ECE (DAFFODILS)'!Z16 -> 206 | K7: =SUM(I7:J7) -> 391 | L7: =J7/G7 -> 0.78030303 | M7: =I7/F7 -> 0.5799373 | N7: =K7/H7 -> 0.67066895 | O7: =AVERAGE(L7:M7) -> 0.68012017
A8: One | B8: 32 | C8: 24 | D8: =SUM(B8:C8) -> 56 | E8: 11 | F8: =B8*E8 -> 352 | G8: =C8*E8 -> 264 | H8: =SUM(F8:G8) -> 616 | I8: ='Class-I'!Y16 -> 145 | J8: ='Class-I'!Z16 -> 230 | K8: =SUM(I8:J8) -> 375 | L8: =J8/G8 -> 0.87121212 | M8: =I8/F8 -> 0.41193182 | N8: =K8/H8 -> 0.60876623 | O8: =AVERAGE(L8:M8) -> 0.64157197
A9: Two | B9: 26 | C9: 22 | D9: =SUM(B9:C9) -> 48 | E9: 11 | F9: =B9*E9 -> 286 | G9: =C9*E9 -> 242 | H9: =SUM(F9:G9) -> 528 | I9: ='Class-II'!Y16 -> 220 | J9: ='Class-II'!Z16 -> 159 | K9: =SUM(I9:J9) -> 379 | L9: =J9/G9 -> 0.65702479 | M9: =I9/F9 -> 0.76923077 | N9: =K9/H9 -> 0.71780303 | O9: =AVERAGE(L9:M9) -> 0.71312778
A10: Three | B10: 28 | C10: 23 | D10: =SUM(B10:C10) -> 51 | E10: 11 | F10: =B10*E10 -> 308 | G10: =C10*E10 -> 253 | H10: =SUM(F10:G10) -> 561 | I10: ='Class-III'!Y16 -> 205 | J10: ='Class-III'!Z16 -> 182 | K10: =SUM(I10:J10) -> 387 | L10: =J10/G10 -> 0.71936759 | M10: =I10/F10 -> 0.66558442 | N10: =K10/H10 -> 0.68983957 | O10: =AVERAGE(L10:M10) -> 0.692476
A11: Four | B11: 17 | C11: 31 | D11: =SUM(B11:C11) -> 48 | E11: 11 | F11: =B11*E11 -> 187 | G11: =C11*E11 -> 341 | H11: =SUM(F11:G11) -> 528 | I11: ='Class-IV'!Y16 -> 141 | J11: ='Class-IV'!Z16 -> 175 | K11: =SUM(I11:J11) -> 316 | L11: =J11/G11 -> 0.51319648 | M11: =I11/F11 -> 0.7540107 | N11: =K11/H11 -> 0.59848485 | O11: =AVERAGE(L11:M11) -> 0.63360359
A12: Five | B12: 27 | C12: 22 | D12: =SUM(B12:C12) -> 49 | E12: 11 | F12: =B12*E12 -> 297 | G12: =C12*E12 -> 242 | H12: =SUM(F12:G12) -> 539 | I12: ='Class-V'!Y16 -> 160 | J12: ='Class-V'!Z16 -> 189 | K12: =SUM(I12:J12) -> 349 | L12: =J12/G12 -> 0.78099174 | M12: =I12/F12 -> 0.53872054 | N12: =K12/H12 -> 0.64749536 | O12: =AVERAGE(L12:M12) -> 0.65985614
A13: Six | B13: 17 | C13: 26 | D13: =SUM(B13:C13) -> 43 | E13: 11 | F13: =B13*E13 -> 187 | G13: =C13*E13 -> 286 | H13: =SUM(F13:G13) -> 473 | I13: ='Class-VI'!Y16 -> 130 | J13: ='Class-VI'!Z16 -> 206 | K13: =SUM(I13:J13) -> 336 | L13: =J13/G13 -> 0.72027972 | M13: =I13/F13 -> 0.69518717 | N13: =K13/H13 -> 0.71035941 | O13: =AVERAGE(L13:M13) -> 0.70773344
A14: Seven | B14: 29 | C14: 17 | D14: =SUM(B14:C14) -> 46 | E14: 11 | F14: =B14*E14 -> 319 | G14: =C14*E14 -> 187 | H14: =SUM(F14:G14) -> 506 | I14: ='Class-VII'!X16 -> 248 | J14: ='Class-VII'!Y16 -> 134 | K14: =SUM(I14:J14) -> 382 | L14: =J14/G14 -> 0.71657754 | M14: =I14/F14 -> 0.77742947 | N14: =K14/H14 -> 0.75494071 | O14: =AVERAGE(L14:M14) -> 0.7470035
A15: Eight | B15: 16 | C15: 18 | D15: =SUM(B15:C15) -> 34 | E15: 11 | F15: =B15*E15 -> 176 | G15: =C15*E15 -> 198 | H15: =SUM(F15:G15) -> 374 | I15: ='Class-VIII'!Y16 -> 90 | J15: ='Class-VIII'!Z16 -> 171 | K15: =SUM(I15:J15) -> 261 | L15: =J15/G15 -> 0.86363636 | M15: =I15/F15 -> 0.51136364 | N15: =K15/H15 -> 0.69786096 | O15: =AVERAGE(L15:M15) -> 0.6875
A16: Ninth | B16: 13 | C16: 17 | D16: =SUM(B16:C16) -> 30 | E16: 11 | F16: =B16*E16 -> 143 | G16: =C16*E16 -> 187 | H16: =SUM(F16:G16) -> 330 | I16: ='Class-IX'!Y16 -> 77 | J16: ='Class-IX'!Z16 -> 61 | K16: =SUM(I16:J16) -> 138 | L16: =J16/G16 -> 0.32620321 | M16: =I16/F16 -> 0.53846154 | N16: =K16/H16 -> 0.41818182 | O16: =AVERAGE(L16:M16) -> 0.43233237
A17: Total | B17: =SUM(B6:B16) -> 254 | C17: =SUM(C6:C16) -> 245 | D17: =SUM(D6:D16) -> 499 | E17: =SUM(E6:E16) -> 121 | F17: =SUM(F6:F16) -> 2794 | G17: =SUM(G6:G16) -> 2695 | H17: =SUM(H6:H16) -> 5489 | I17: =SUM(I6:I16) -> 1721 | ... K17: =SUM(K6:K16) -> 3576 | L17: =J17/G17 -> 0.68831169 | M17: =I17/F17 -> 0.61596278 | N17: =AVERAGE(N6:N16) -> 0.6450302 | O17: =AVERAGE(O6:O16) -> 0.65231014
A18: % | B18: 1 | C18: 1 | D18: 1 | E18: 1 | F18: 1 | G18: 1 | H18: 1 | I18: =I17/F17 -> 0.61596278 | J18: =J17/G17 -> 0.68831169 | K18: =K17/H17 -> 0.65148479 | L18: 0.54 | M18: 0.56 | N18: 0.55 | O18: =AVERAGE(L17:M17) -> 0.65213723

Sheet ECE (ROSE)
A1: Goverment high school (SJCHS)
A2: Monthly Attendence Month of August-2024
A3: S.No | B3: Student Name | C3: Father Name | D3: Class | E3: =TEXT(E4,"ddd") -> Thu | F3: =TEXT(F4,"ddd") -> Fri | G3: =TEXT(G4,"ddd") -> Sat | H3: =TEXT(H4,"ddd") -> Sun | I3: =TEXT(I4,"ddd") -> Mon | J3: =TEXT(J4,"ddd") -> Tue | K3: =TEXT(K4,"ddd") -> Wed | L3: =TEXT(L4,"ddd") -> Thu | ... U3: =TEXT(U4,"ddd") -> Sat | V3: Present | W3: Absent | X3: Year 2024
E4: 45519 | F4: 45520 | G4: 45521 | H4: 45522 | I4: 45523 | J4: 45524 | K4: 45525 | L4: 45526 | M4: 45527 | N4: 45528 | O4: 45529 | P4: 45530 | Q4: 45531 | R4: 45532 | S4: 45533 | T4: 45534 | U4: 45535 | X4: Total days | Y4: =SUM(Y5:Y11) -> 31
A5: 1 | B5: Eman | C5: Shahnawaz Khan | D5: ECE | E5: A | F5: A | G5: A | H5: SUNDAY - SUNDAY - SUNDAY - SUNDAY | I5: P | J5: LATIF DAY - LATIF DAY - LATIF DAY | K5: P | L5: A | M5: P | N5: P | O5: SUNDAY - SUNDAY - SUNDAY - SUNDAY | P5: OFF DUE TO CHEHLUM - OFF DUE TO CHEHLUM | Q5: P | R5: A | S5: P | T5: OFF DUE TO HEAVY RAIN | U5: A | V5: =COUNTIF(E5:U5,"P") -> 6 | W5: =COUNTIF(E5:U5,"A") -> 6 | X5: Working days | Y5: 11
A6: 2 | B6: Rehan Ali | C6: Abdul Rehman | D6: ECE | E6: P | F6: P | G6: P | I6: A | K6: P | L6: P | M6: P | N6: P | Q6: P | R6: A | S6: A | U6: A | V6: =COUNTIF(E6:U6,"P") -> 8 | W6: =COUNTIF(E6:U6,"A") -> 4 | X6: Sunday | Y6: 4
A7: 3 | B7: Dilkash | C7: Faraz Hussain | D7: ECE | E7: A | F7: A | G7: A | I7: A | K7: P | L7: P | M7: P | N7: A | Q7: P | R7: A | S7: P | U7: A | V7: =COUNTIF(E7:U7,"P") -> 5 | W7: =COUNTIF(E7:U7,"A") -> 7 | X7: Summer Vications | Y7: 12
A8: 4 | B8: Masooma | C8: Faiq Ali | D8: ECE | E8: P | F8: P | G8: A | I8: P | K8: P | L8: P | M8: P | N8: A | Q8: P | R8: A | S8: P | U8: A | V8: =COUNTIF(E8:U8,"P") -> 8 | W8: =COUNTIF(E8:U8,"A") -> 4 | X8: URS | Y8: 1
A9: 5 | B9: Ali | C9: Saddam Hussain | D9: ECE | E9: P | F9: P | G9: P | I9: P | K9: P | L9: P | M9: P | N9: A | Q9: P | R9: A | S9: P | U9: A | V9: =COUNTIF(E9:U9,"P") -> 9 | W9: =COUNTIF(E9:U9,"A") -> 3 | X9: Mango Day | Y9: 1
A10: 6 | B10: Hafsa Batool | C10: Gul Mohammad Chandio | D10: ECE | E10: A | F10: A | G10: A | I10: P | K10: P | L10: P | M10: P | N10: P | Q10: P | R10: P | S10: A | U10: A | V10: =COUNTIF(E10:U10,"P") -> 7 | W10: =COUNTIF(E10:U10,"A") -> 5 | X10: Chehlum | Y10: 1
A11: 7 | B11: Mohammad Aliyan | C11: Shabir Ahmed Bhutto | D11: ECE | E11: A | F11: A | G11: P | I11: P | K11: P | L11: P | M11: P | N11: A | Q11: P | R11: A | S11: P | U11: A | V11: =COUNTIF(E11:U11,"P") -> 7 | W11: =COUNTIF(E11:U11,"A") -> 5 | X11: OFF Due to Heavy Rain | Y11: 1
A12: 8 | B12: Hoor Fatima | C12: Shahid Ali | D12: ECE | E12: A | F12: A | G12: P | I12: A | K12: P | L12: P | M12: P | N12: P | Q12: P | R12: A | S12: P | U12: A | V12: =COUNTIF(E12:U12,"P") -> 7 | W12: =COUNTIF(E12:U12,"A") -> 5
A13: 9 | B13: Muhammad Sahil | C13: Irshad Ali | D13: ECE | E13: A | F13: A | G13: P | I13: P | K13: P | L13: P | M13: P | N13: P | Q13: P | R13: P | S13: P | U13: A | V13: =COUNTIF(E13:U13,"P") -> 9 | W13: =COUNTIF(E13:U13,"A") -> 3 | X13: Present Days Detail
A14: 10 | B14: Kinza | C14: Aijaz Ali | D14: ECE | E14: A | F14: A | G14: P | I14: P | K14: P | L14: P | M14: P | N14: P | Q14: P | R14: P | S14: P | U14: A | V14: =COUNTIF(E14:U14,"P") -> 9 | W14: =COUNTIF(E14:U14,"A") -> 3 | X14: Detail | Y14: Boys | Z14: Girls | AA14: Total
A15: 11 | B15: Zaryab Sultan | C15: Muhammad Zaman | D15: ECE | E15: A | F15: A | G15: P | I15: P | K15: P | L15: P | M15: P | N15: A | Q15: P | R15: A | S15: A | U15: A | V15: =COUNTIF(E15:U15,"P") -> 6 | W15: =COUNTIF(E15:U15,"A") -> 6 | X15: Due Present days | Y15: =20*11 -> 220 | Z15: =21*11 -> 231 | AA15: =SUM(Y15:Z15) -> 451
A16: 12 | B16: M. Ibrahim | C16: Fayaz Ali Ansari | D16: ECE | E16: A | F16: A | G16: A | I16: P | K16: P | L16: P | M16: P | N16: P | Q16: P | R16: P | S16: P | U16: A | V16: =COUNTIF(E16:U16,"P") -> 8 | W16: =COUNTIF(E16:U16,"A") -> 4 | X16: Actual present days | Y16: =V6+V9+V11+V13+V16+V21+V22+V23+V24+V25+V26+V27+V32+V34+V36+V38+V39+V41+V40+V40 -> 120 | Z16: =V5+V7+V8+V10+V12+V14+V15+V17+V18+V19+V28+V29+V30+V31+V33+V35+V37+V40+V44+V45 -> 142 | AA16: =Y16+Z16 -> 262
A17: 13 | B17: Fatima Ansari | C17: Ayaz Ali Ansari | D17: ECE | E17: A | F17: A | G17: A | I17: P | K17: P | L17: P | M17: P | N17: P | Q17: A | R17: A | S17: A | U17: A | V17: =COUNTIF(E17:U17,"P") -> 5 | W17: =COUNTIF(E17:U17,"A") -> 7 | X17: % | Y17: =Y16/Y15 -> 0.54545455 | Z17: =Z16/Z15 -> 0.61471861 | AA17: =AA16/AA15 -> 0.58093126
A18: 14 | B18: Zil-e-Huma | C18: Abdul Qayoom | D18: ECE | E18: A | F18: A | G18: A | I18: P | K18: P | L18: P | M18: P | N18: P | Q18: P | R18: A | S18: A | U18: A | V18: =COUNTIF(E18:U18,"P") -> 6 | W18: =COUNTIF(E18:U18,"A") -> 6
A19: 15 | B19: Ayat Fatima | C19: Imran Hussain | D19: ECE | E19: A | F19: P | G19: P | I19: P | K19: P | L19: P | M19: P | N19: P | Q19: P | R19: A | S19: P | U19: A | V19: =COUNTIF(E19:U19,"P") -> 9 | W19: =COUNTIF(E19:U19,"A") -> 3
A20: 16 | B20: Aqsa | C20: Ahsan Ali | D20: ECE | E20: A | F20: A | G20: A | I20: P | K20: P | L20: P | M20: P | N20: P | Q20: P | R20: A | S20: P | U20: A | V20: =COUNTIF(E20:U20,"P") -> 7 | W20: =COUNTIF(E20:U20,"A") -> 5
A21: 17 | B21: Muhammad Fawad | C21: Waseem Ahmed Channa | D21: ECE | E21: A | F21: A | G21: A | I21: P | K21: P | L21: A | M21: P | N21: P | Q21: A | R21: A | S21: A | U21: A | V21: =COUNTIF(E21:U21,"P") -> 4 | W21: =COUNTIF(E21:U21,"A") -> 8 | X21: Absent Days Details
A22: 18 | B22: Muhammad Haris | C22: M. Shareef Niyazi | D22: ECE | E22: A | F22: P | G22: P | I22: P | K22: P | L22: P | M22: P | N22: A | Q22: P | R22: A | S22: A | U22: A | V22: =COUNTIF(E22:U22,"P") -> 7 | W22: =COUNTIF(E22:U22,"A") -> 5 | X22: Detail | Y22: Boys | Z22: Girls | AA22: Total
A23: 19 | B23: Muhammad Ayan | C23: Abdul Ghaffar | D23: ECE | E23: P | F23: P | G23: P | I23: P | K23: P | L23: P | M23: P | N23: P | Q23: P | R23: A | S23: P | U23: A | V23: =COUNTIF(E23:U23,"P") -> 10 | W23: =COUNTIF(E23:U23,"A") -> 2 | X23: Due Present days | Y23: =20*11 -> 220 | Z23: =21*11 -> 231 | AA23: =Y23+Z23 -> 451
A24: 20 | B24: Danish | C24: Ayaz Ali | D24: ECE | E24: A | F24: P | G24: P | I24: A | K24: P | L24: P | M24: P | N24: P | Q24: P | R24: P | S24: A | U24: A | V24: =COUNTIF(E24:U24,"P") -> 8 | W24: =COUNTIF(E24:U24,"A") -> 4 | X24: Absent days | Y24: =Y23-Y16 -> 100 | Z24: =Z23-Z16 -> 89 | AA24: =Y24+Z24 -> 189
A25: 21 | B25: Mujahid Ali | C25: Sajjad Ali | D25: ECE | E25: A | F25: A | G25: P | I25: P | K25: P | L25: P | M25: P | N25: A | Q25: P | R25: A | S25: P | U25: A | V25: =COUNTIF(E25:U25,"P") -> 7 | W25: =COUNTIF(E25:U25,"A") -> 5 | X25: % | Y25: =Y24/Y23 -> 0.45454545 | Z25: =Z24/Z23 -> 0.38528139 | AA25: =AA24/AA23 -> 0.41906874
A26: 22 | B26: Zawar Ali | C26: Kamran Ali | D26: ECE | E26: - | F26: - | G26: - | I26: - | K26: - | L26: - | M26: - | N26: - | Q26: P | R26: A | S26: A | U26: A | V26: =COUNTIF(E26:U26,"P") -> 1 | W26: =COUNTIF(E26:U26,"A") -> 3
A27: 23 | B27: Muhammad Rayyan | C27: Ghulam Murtaza | D27: ECE | E27: - | F27: - | G27: - | I27: - | K27: - | L27: - | M27: - | N27: - | Q27: - | R27: - | S27: - | U27: - | V27: =COUNTIF(E27:U27,"P") -> 0 | W27: =COUNTIF(E27:U27,"A") -> 0
A28: 24 | B28: Safa | C28: Dil Murad | D28: ECE | E28: A | F28: P | G28: P | I28: P | K28: P | L28: P | M28: P | N28: P | Q28: P | R28: P | S28: P | U28: A | V28: =COUNTIF(E28:U28,"P") -> 10 | W28: =COUNTIF(E28:U28,"A") -> 2
A29: 25 | B29: Hifza | C29: Zakir Ali | D29: ECE | E29: P | F29: P | G29: A | I29: A | K29: A | L29: A | M29: A | N29: P | Q29: A | R29: A | S29: P | U29: A | V29: =COUNTIF(E29:U29,"P") -> 4 | W29: =COUNTIF(E29:U29,"A") -> 8
A30: 26 | B30: Zameeran | C30: Babar Ali | D30: ECE | E30: P | F30: P | G30: P | I30: P | K30: P | L30: P | M30: A | N30: L | Q30: A | R30: P | S30: A | U30: A | V30: =COUNTIF(E30:U30,"P") -> 7 | W30: =COUNTIF(E30:U30,"A") -> 4
A31: 27 | B31: Parwisha | C31: Sarfaraz Ahmed | D31: ECE | E31: A | F31: A | G31: A | I31: P | K31: P | L31: P | M31: P | N31: P | Q31: P | R31: A | S31: A | U31: A | V31: =COUNTIF(E31:U31,"P") -> 6 | W31: =COUNTIF(E31:U31,"A") -> 6
A32: 28 | B32: Muhammad Ahad | C32: Khalid Hussain Abbasi | D32: ECE | E32: A | F32: A | G32: A | I32: P | K32: P | L32: A | M32: P | N32: A | Q32: A | R32: A | S32: A | U32: A | V32: =COUNTIF(E32:U32,"P") -> 3 | W32: =COUNTIF(E32:U32,"A") -> 9
A33: 29 | B33: Aiza | C33: Irshad-Ul-Haq | D33: ECE | E33: P | F33: P | G33: P | I33: P | K33: P | L33: P | M33: P | N33: P | Q33: P | R33: A | S33: A | U33: A | V33: =COUNTIF(E33:U33,"P") -> 9 | W33: =COUNTIF(E33:U33,"A") -> 3
A34: 30 | B34: Muhammad Hamza | C34: Irshad-Ul-Haq | D34: ECE | E34: P | F34: P | G34: P | I34: P | K34: P | L34: P | M34: L | N34: P | Q34: P | R34: A | S34: A | U34: A | V34: =COUNTIF(E34:U34,"P") -> 8 | W34: =COUNTIF(E34:U34,"A") -> 3
A35: 31 | B35: Shazia | C35: Rashid Ali | D35: ECE | E35: A | F35: A | G35: A | I35: P | K35: P | L35: P | M35: P | N35: P | Q35: A | R35: A | S35: P | U35: A | V35: =COUNTIF(E35:U35,"P") -> 6 | W35: =COUNTIF(E35:U35,"A") -> 6
A36: 32 | B36: M. Ayan | C36: Sanaullah Qureshi | D36: ECE | E36: A | F36: A | G36: A | I36: A | K36: A | L36: P | M36: P | N36: A | Q36: P | R36: A | S36: A | U36: A | V36: =COUNTIF(E36:U36,"P") -> 3 | W36: =COUNTIF(E36:U36,"A") -> 9
A37: 33 | B37: Ume Farwa | C37: Meer Ameer-u-Din | D37: ECE | E37: P | F37: P | G37: P | I37: P | K37: P | L37: P | M37: A | N37: A | Q37: P | R37: P | S37: P | U37: A | V37: =COUNTIF(E37:U37,"P") -> 9 | W37: =COUNTIF(E37:U37,"A") -> 3
A38: 34 | B38: M. Awais | C38: Mehboob Ali | D38: ECE | E38: - | F38: - | G38: - | I38: - | K38: - | L38: - | M38: P | N38: P | Q38: A | R38: P | S38: P | U38: A | V38: =COUNTIF(E38:U38,"P") -> 4 | W38: =COUNTIF(E38:U38,"A") -> 2
A39: 35 | B39: M. Raheel | D39: ECE | E39: - | F39: - | G39: - | I39: - | K39: - | L39: - | M39: P | N39: P | Q39: A | R39: P | S39: P | U39: A | V39: =COUNTIF(E39:U39,"P") -> 4 | W39: =COUNTIF(E39:U39,"A") -> 2
A40: 36 | B40: Fiza | C40: Ahmed | D40: ECE | E40: A | F40: A | G40: P | I40: P | K40: P | L40: P | M40: P | N40: P | Q40: P | R40: A | S40: A | U40: A | V40: =COUNTIF(E40:U40,"P") -> 7 | W40: =COUNTIF(E40:U40,"A") -> 5
...

Sheet ECE (DAFFODILS)
A1: Goverment high school (SJCHS)
A2: Monthly Attendence Month of August-2024
A3: S.No | B3: Student Name | C3: Father Name | D3: Class | E3: =TEXT(E4,"ddd") -> Thu | F3: =TEXT(F4,"ddd") -> Fri | G3: =TEXT(G4,"ddd") -> Sat | H3: =TEXT(H4,"ddd") -> Sun | I3: =TEXT(I4,"ddd") -> Mon | J3: =TEXT(J4,"ddd") -> Tue | K3: =TEXT(K4,"ddd") -> Wed | L3: =TEXT(L4,"ddd") -> Thu | ... U3: =TEXT(U4,"ddd") -> Sat | V3: Present | W3: Absent | X3: Year 2024
E4: 45519 | F4: 45520 | G4: 45521 | H4: 45522 | I4: 45523 | J4: 45524 | K4: 45525 | L4: 45526 | M4: 45527 | N4: 45528 | O4: 45529 | P4: 45530 | Q4: 45531 | R4: 45532 | S4: 45533 | T4: 45534 | U4: 45535 | X4: Total days | Y4: =SUM(Y5:Y11) -> 31
A5: 1 | B5: Alishba Batool | C5: Irfan Ali | D5: ECE | E5: P | F5: P | G5: P | H5: SUNDAY - SUNDAY - SUNDAY - SUNDAY - SUNDAY - SUNDAY | I5: P | J5: LATIF DAY - LATIF DAY - LATIF DAY - LATIF DAY - LATIF DAY | K5: P | L5: P | M5: P | N5: MANGO DAY - MANGO DAY - MANGO DAY - MANGO DAY - MANGO DAY | O5: SUNDAY - SUNDAY - SUNDAY - SUNDAY - SUNDAY - SUNDAY | P5: OFF DUE TO CHEHLUM OF HAZRAT IMAM HUSSAIN (A.S) | Q5: A | R5: P | S5: P | T5: OFF DUE TO HEAVY RAIN - OFF DUE TO HEAVY RAIN | V5: =COUNTIF(E5:U5,"P") -> 9 | W5: =COUNTIF(E5:U5,"A") -> 1 | X5: Working days | Y5: 11
A6: 2 | B6: Amna | C6: Imtiaz Hussain | D6: ECE | E6: A | F6: P | G6: P | I6: P | K6: P | L6: P | M6: P | Q6: P | R6: P | S6: A | V6: =COUNTIF(E6:U6,"P") -> 8 | W6: =COUNTIF(E6:U6,"A") -> 2 | X6: Sunday | Y6: 4
A7: 3 | B7: Aniza Memon | C7: M. Qasim | D7: ECE | E7: P | F7: P | G7: P | I7: P | K7: P | L7: P | M7: P | Q7: P | R7: A | S7: P | V7: =COUNTIF(E7:U7,"P") -> 9 | W7: =COUNTIF(E7:U7,"A") -> 1 | X7: Summer Vications | Y7: 12
A8: 4 | B8: Areeba | C8: Altaf Hussain | D8: ECE | E8: A | F8: P | G8: P | I8: P | K8: P | L8: P | M8: P | Q8: P | R8: A | S8: A | V8: =COUNTIF(E8:U8,"P") -> 7 | W8: =COUNTIF(E8:U8,"A") -> 3 | X8: URS | Y8: 1
A9: 5 | B9: Batool | C9: Amjad Ali | D9: ECE | E9: P | F9: P | G9: P | I9: P | K9: P | L9: P | M9: P | Q9: A | R9: A | S9: P | V9: =COUNTIF(E9:U9,"P") -> 8 | W9: =COUNTIF(E9:U9,"A") -> 2 | X9: Mango Day | Y9: 1
A10: 6 | B10: Dua | C10: Khalid Hussain | D10: ECE | E10: A | F10: P | G10: P | I10: P | K10: P | L10: P | M10: P | Q10: A | R10: A | S10: P | V10: =COUNTIF(E10:U10,"P") -> 7 | W10: =COUNTIF(E10:U10,"A") -> 3 | X10: Chehlum | Y10: 1
A11: 7 | B11: Faiza | C11: Liaqat Ali | D11: ECE | E11: P | F11: P | G11: P | I11: P | K11: P | L11: P | M11: P | Q11: A | R11: A | S11: P | V11: =COUNTIF(E11:U11,"P") -> 8 | W11: =COUNTIF(E11:U11,"A") -> 2 | X11: OFF Due to Heavy Rain | Y11: 1
A12: 8 | B12: Fatima | C12: Aziz-ur-Rehman | D12: ECE | E12: P | F12: P | G12: P | I12: P | K12: P | L12: P | M12: P | Q12: P | R12: A | S12: P | V12: =COUNTIF(E12:U12,"P") -> 9 | W12: =COUNTIF(E12:U12,"A") -> 1
A13: 9 | B13: Hafsa | C13: Hafeezullah | D13: ECE | E13: A | F13: P | G13: P | I13: P | K13: P | L13: P | M13: P | Q13: A | R13: A | S13: P | V13: =COUNTIF(E13:U13,"P") -> 7 | W13: =COUNTIF(E13:U13,"A") -> 3 | X13: Present Days Detail
A14: 10 | B14: Insha Arzoo | C14: Meeral | D14: ECE | E14: A | F14: P | G14: P | I14: P | K14: P | L14: P | M14: A | Q14: A | R14: A | S14: P | V14: =COUNTIF(E14:U14,"P") -> 6 | W14: =COUNTIF(E14:U14,"A") -> 4 | X14: Detail | Y14: Boys | Z14: Girls | AA14: Total
A15: 11 | B15: Kauser Fatima | C15: Amir Jamil | D15: ECE | E15: P | F15: P | G15: P | I15: P | K15: P | L15: P | M15: P | Q15: A | R15: A | S15: A | V15: =COUNTIF(E15:U15,"P") -> 7 | W15: =COUNTIF(E15:U15,"A") -> 3 | X15: Due Present days | Y15: =29*11 -> 319 | Z15: =24*11 -> 264 | AA15: =SUM(Y15:Z15) -> 583
A16: 12 | B16: Mehrunisa | C16: Aijaz Ali | D16: ECE | E16: A | F16: P | G16: P | I16: P | K16: P | L16: P | M16: P | Q16: A | R16: A | S16: P | V16: =COUNTIF(E16:U16,"P") -> 7 | W16: =COUNTIF(E16:U16,"A") -> 3 | X16: Actual present days | Y16: =SUM(V5:V28) -> 185 | Z16: =SUM(V29:V57) -> 206 | AA16: =Y16+Z16 -> 391
A17: 13 | B17: Mirha | C17: M. Luqman | D17: ECE | E17: P | F17: P | G17: P | I17: P | K17: P | L17: P | M17: A | Q17: A | R17: A | S17: P | V17: =COUNTIF(E17:U17,"P") -> 7 | W17: =COUNTIF(E17:U17,"A") -> 3 | X17: % | Y17: =Y16/Y15 -> 0.5799373 | Z17: =Z16/Z15 -> 0.78030303 | AA17: =AA16/AA15 -> 0.67066895
A18: 14 | B18: Misbah Bhutto | C18: M. Azeem | D18: ECE | E18: A | F18: A | G18: P | I18: P | K18: P | L18: P | M18: P | Q18: A | R18: P | S18: P | V18: =COUNTIF(E18:U18,"P") -> 7 | W18: =COUNTIF(E18:U18,"A") -> 3
A19: 15 | B19: Rimsha | C19: Meer Ameer-ud-Din | D19: ECE | E19: P | F19: P | G19: P | I19: P | K19: P | L19: P | M19: P | Q19: P | R19: P | S19: P | V19: =COUNTIF(E19:U19,"P") -> 10 | W19: =COUNTIF(E19:U19,"A") -> 0
A20: 16 | B20: Sidra | C20: Khalid Hussain | D20: ECE | E20: A | F20: P | G20: P | I20: P | K20: P | L20: P | M20: P | Q20: A | R20: A | S20: P | V20: =COUNTIF(E20:U20,"P") -> 7 | W20: =COUNTIF(E20:U20,"A") -> 3
A21: 17 | B21: Sidra Batool | C21: M. Khan | D21: ECE | E21: A | F21: P | G21: P | I21: P | K21: P | L21: P | M21: P | Q21: P | R21: P | S21: P | V21: =COUNTIF(E21:U21,"P") -> 9 | W21: =COUNTIF(E21:U21,"A") -> 1 | X21: Absent Days Details
A22: 18 | B22: Taniya Bibi | C22: Wazir Ali | D22: ECE | E22: A | F22: A | G22: A | I22: P | K22: P | L22: P | M22: A | Q22: A | R22: A | S22: P | V22: =COUNTIF(E22:U22,"P") -> 4 | W22: =COUNTIF(E22:U22,"A") -> 6 | X22: Detail | Y22: Boys | Z22: Girls | AA22: Total
A23: 19 | B23: Tanzeela | C23: Hizbullah | D23: ECE | E23: P | F23: P | G23: P | I23: P | K23: P | L23: P | M23: P | Q23: P | R23: A | S23: P | V23: =COUNTIF(E23:U23,"P") -> 9 | W23: =COUNTIF(E23:U23,"A") -> 1 | X23: Due Present days | Y23: =29*11 -> 319 | Z23: =24*11 -> 264 | AA23: =Y23+Z23 -> 583
A24: 20 | B24: Tayaba Fatima | C24: Waseem Ahmed | D24: ECE | E24: P | F24: P | G24: P | I24: P | K24: P | L24: A | M24: P | Q24: A | R24: A | S24: A | V24: =COUNTIF(E24:U24,"P") -> 6 | W24: =COUNTIF(E24:U24,"A") -> 4 | X24: Absent days | Y24: =Y23-Y16 -> 134 | Z24: =Z23-Z16 -> 58 | AA24: =Y24+Z24 -> 192
A25: 21 | B25: Tooba Noor | C25: M. Shareef | D25: ECE | E25: P | F25: P | G25: P | I25: P | K25: P | L25: P | M25: P | Q25: P | R25: A | S25: A | V25: =COUNTIF(E25:U25,"P") -> 8 | W25: =COUNTIF(E25:U25,"A") -> 2 | X25: % | Y25: =Y24/Y23 -> 0.4200627 | Z25: =Z24/Z23 -> 0.21969697 | AA25: =AA24/AA23 -> 0.32933105
A26: 22 | B26: Umm-e-Kulsoom | C26: Shah Ali | D26: ECE | E26: P | F26: P | G26: P | I26: P | K26: P | L26: P | M26: P | Q26: P | R26: A | S26: P | V26: =COUNTIF(E26:U26,"P") -> 9 | W26: =COUNTIF(E26:U26,"A") -> 1
A27: 23 | B27: Zunaira | C27: Amjad Ali | D27: ECE | E27: P | F27: P | G27: P | I27: P | K27: P | L27: P | M27: P | Q27: P | R27: A | S27: P | V27: =COUNTIF(E27:U27,"P") -> 9 | W27: =COUNTIF(E27:U27,"A") -> 1
A28: 24 | B28: Sahib Khatoon | C28: A. Qayoom | D28: ECE | E28: P | F28: P | G28: P | I28: P | K28: P | L28: P | M28: P | Q28: P | R28: A | S28: A | V28: =COUNTIF(E28:U28,"P") -> 8 | W28: =COUNTIF(E28:U28,"A") -> 2
A29: 1 | B29: Abrar | C29: Jan Muhammad | D29: ECE | E29: A | F29: A | G29: A | I29: A | K29: P | L29: P | M29: P | Q29: P | R29: P | S29: A | V29: =COUNTIF(E29:U29,"P") -> 5 | W29: =COUNTIF(E29:U29,"A") -> 5
A30: 2 | B30: Azan Shafeeque | C30: M. Shafeeque | D30: ECE | E30: P | F30: P | G30: P | I30: P | K30: P | L30: P | M30: P | Q30: A | R30: A | S30: A | U30: P | V30: =COUNTIF(E30:U30,"P") -> 8 | W30: =COUNTIF(E30:U30,"A") -> 3
A31: 3 | B31: Azan Fayaz | C31: Fayaz Hussain | D31: ECE | E31: A | F31: A | G31: P | I31: P | K31: P | L31: P | M31: P | Q31: P | R31: A | S31: A | V31: =COUNTIF(E31:U31,"P") -> 6 | W31: =COUNTIF(E31:U31,"A") -> 4
A32: 4 | B32: Adil Ahmed | C32: Faiz Muhammad | D32: ECE | E32: A | F32: P | G32: P | I32: P | K32: P | L32: A | M32: P | Q32: P | R32: A | S32: P | V32: =COUNTIF(E32:U32,"P") -> 7 | W32: =COUNTIF(E32:U32,"A") -> 3
A33: 5 | B33: Ab. Qudoos | C33: Sikandar | D33: ECE | E33: A | F33: A | G33: A | I33: A | K33: P | L33: A | M33: A | Q33: P | R33: P | S33: P | V33: =COUNTIF(E33:U33,"P") -> 4 | W33: =COUNTIF(E33:U33,"A") -> 6
A34: 6 | B34: Ab. Rehman | C34: M. Aslam | D34: ECE | E34: A | F34: A | G34: A | I34: A | K34: P | L34: P | M34: P | Q34: A | R34: A | S34: A | V34: =COUNTIF(E34:U34,"P") -> 3 | W34: =COUNTIF(E34:U34,"A") -> 7
A35: 7 | B35: Ahmed Zia | C35: Zia Buksh | D35: ECE | E35: A | F35: P | G35: P | I35: P | K35: P | L35: L | M35: P | Q35: P | R35: A | S35: P | V35: =COUNTIF(E35:U35,"P") -> 7 | W35: =COUNTIF(E35:U35,"A") -> 2
A36: 8 | B36: Arham | C36: Mujtaba Ahmed | D36: ECE | E36: A | F36: A | G36: A | I36: A | K36: A | L36: A | M36: A | Q36: A | R36: A | S36: A | V36: =COUNTIF(E36:U36,"P") -> 0 | W36: =COUNTIF(E36:U36,"A") -> 10
A37: 9 | B37: Arham | C37: Qasim Memon | D37: ECE | E37: P | F37: P | G37: P | I37: P | K37: P | L37: P | M37: P | Q37: P | R37: A | S37: P | V37: =COUNTIF(E37:U37,"P") -> 9 | W37: =COUNTIF(E37:U37,"A") -> 1
A38: 10 | B38: Amar Farooque | C38: M. Farooque | D38: ECE | E38: P | F38: P | G38: P | I38: P | K38: P | L38: P | M38: A | Q38: A | R38: A | S38: A | V38: =COUNTIF(E38:U38,"P") -> 6 | W38: =COUNTIF(E38:U38,"A") -> 4
A39: 11 | B39: Ashfaque | C39: M. Zubair | D39: ECE | E39: P | F39: P | G39: P | I39: A | K39: P | L39: P | M39: P | Q39: P | R39: P | S39: P | V39: =COUNTIF(E39:U39,"P") -> 9 | W39: =COUNTIF(E39:U39,"A") -> 1
A40: 12 | B40: Fahad | C40: M. Maroof | D40: ECE | E40: P | F40: A | G40: P | I40: P | K40: P | L40: P | M40: A | Q40: A | R40: A | S40: P | V40: =COUNTIF(E40:U40,"P") -> 6 | W40: =COUNTIF(E40:U40,"A") -> 4
...

Sheet Class-I
A1: Goverment high school (SJCHS)
A2: Monthly Attendence Month of August-2024
A3: S.No | B3: Student Name | C3: Father Name | D3: Class | E3: =TEXT(E4,"ddd") -> Thu | F3: =TEXT(F4,"ddd") -> Fri | G3: =TEXT(G4,"ddd") -> Sat | H3: =TEXT(H4,"ddd") -> Sun | I3: =TEXT(I4,"ddd") -> Mon | J3: =TEXT(J4,"ddd") -> Tue | K3: =TEXT(K4,"ddd") -> Wed | L3: =TEXT(L4,"ddd") -> Thu | ... U3: =TEXT(U4,"ddd") -> Sat | V3: Present | W3: Absent | X3: Year 2024
E4: 45519 | F4: 45520 | G4: 45521 | H4: 45522 | I4: 45523 | J4: 45524 | K4: 45525 | L4: 45526 | M4: 45527 | N4: 45528 | O4: 45529 | P4: 45530 | Q4: 45531 | R4: 45532 | S4: 45533 | T4: 45534 | U4: 45535 | X4: Total days | Y4: =SUM(Y5:Y11) -> 31
A5: 1 | B5: Anum | C5: M. Arif | D5: One | E5: P | F5: P | G5: P | H5: SUNDAY - SUNDAY - SUNDAY - SUNDAY - SUNDAY - SUNDAY | I5: P | J5: (URS) SHAH ABDUL LATIF BHITAI (URS) | K5: P | L5: P | M5: A | N5: MANGO DAY (ACTIVITY) - MANGO DAY (ACTIVITY) | O5: SUNDAY - SUNDAY - SUNDAY - SUNDAY - SUNDAY - SUNDAY | P5: CHEHLUM - CHEHLUM - CHEHLUM - CHEHLUM - CHEHLUM | Q5: P | R5: P | S5: P | T5: OFF DUE TO HEAVY RAIN - OFF DUE TO HEAVY RAIN | U5: A | V5: =COUNTIF(E5:U5,"P") -> 9 | W5: =COUNTIF(E5:U5,"A") -> 2 | X5: Working days | Y5: 11
A6: 2 | B6: Ayat | C6: Meer Mohammad | D6: One | E6: P | F6: P | G6: P | I6: P | K6: P | L6: P | M6: A | Q6: A | R6: A | S6: P | U6: A | V6: =COUNTIF(E6:U6,"P") -> 7 | W6: =COUNTIF(E6:U6,"A") -> 4 | X6: Sunday | Y6: 4
A7: 3 | B7: Amna | C7: Saeed Ahmed | D7: One | E7: A | F7: P | G7: A | I7: P | K7: P | L7: P | M7: P | Q7: P | R7: A | S7: A | U7: A | V7: =COUNTIF(E7:U7,"P") -> 6 | W7: =COUNTIF(E7:U7,"A") -> 5 | X7: Summer Vications | Y7: 12
A8: 4 | B8: Adeeba | C8: Qurban Ali | D8: One | E8: - | F8: A | G8: A | I8: P | K8: P | L8: P | M8: P | Q8: A | R8: P | S8: P | U8: A | V8: =COUNTIF(E8:U8,"P") -> 6 | W8: =COUNTIF(E8:U8,"A") -> 4 | X8: URS | Y8: 1
A9: 5 | B9: Emaan Noor | C9: Noor Mohammad | D9: One | E9: A | F9: P | G9: P | I9: P | K9: P | L9: P | M9: P | Q9: A | R9: A | S9: A | U9: A | V9: =COUNTIF(E9:U9,"P") -> 6 | W9: =COUNTIF(E9:U9,"A") -> 5 | X9: Mango Day | Y9: 1
A10: 6 | B10: Horain | C10: Saeed Ahmed | D10: One | E10: P | F10: P | G10: P | I10: P | K10: P | L10: P | M10: A | Q10: A | R10: A | S10: P | U10: A | V10: =COUNTIF(E10:U10,"P") -> 7 | W10: =COUNTIF(E10:U10,"A") -> 4 | X10: Chehlum | Y10: 1
A11: 7 | B11: Hannah | C11: Luqman Ali | D11: One | E11: P | F11: P | G11: P | I11: P | K11: P | L11: P | M11: P | Q11: A | R11: A | S11: P | U11: A | V11: =COUNTIF(E11:U11,"P") -> 8 | W11: =COUNTIF(E11:U11,"A") -> 3 | X11: OFF Due to Heavy Rain | Y11: 1
A12: 8 | B12: Horiya | C12: Siddique | D12: One | E12: A | F12: P | G12: P | I12: P | K12: P | L12: P | M12: P | Q12: P | R12: A | S12: P | U12: A | V12: =COUNTIF(E12:U12,"P") -> 8 | W12: =COUNTIF(E12:U12,"A") -> 3
A13: 9 | B13: Hareem Fatima | C13: Deedar Ali | D13: One | E13: A | F13: P | G13: P | I13: P | K13: P | L13: P | M13: P | Q13: P | R13: A | S13: P | U13: A | V13: =COUNTIF(E13:U13,"P") -> 8 | W13: =COUNTIF(E13:U13,"A") -> 3 | X13: Present Days Detail
A14: 10 | B14: Maham Noor | C14: Zaheer Abbas | D14: One | E14: P | F14: P | G14: P | I14: P | K14: P | L14: P | M14: P | Q14: P | R14: P | S14: P | U14: A | V14: =COUNTIF(E14:U14,"P") -> 10 | W14: =COUNTIF(E14:U14,"A") -> 1 | X14: Detail | Y14: Boys | Z14: Girls | AA14: Total
A15: 11 | B15: Maria | C15: Mehboob Ali | D15: One | E15: A | F15: P | G15: P | I15: P | K15: P | L15: P | M15: P | Q15: A | R15: A | S15: A | U15: A | V15: =COUNTIF(E15:U15,"P") -> 6 | W15: =COUNTIF(E15:U15,"A") -> 5 | X15: Due Present days | Y15: =32*11 -> 352 | Z15: =24*11 -> 264 | AA15: =SUM(Y15:Z15) -> 616
A16: 12 | B16: Mehreen | C16: M. Maroof | D16: One | E16: A | F16: P | G16: P | I16: P | K16: P | L16: P | M16: A | Q16: A | R16: A | S16: P | U16: A | V16: =COUNTIF(E16:U16,"P") -> 6 | W16: =COUNTIF(E16:U16,"A") -> 5 | X16: Actual present days | Y16: =SUM(V5:V28) -> 145 | Z16: =SUM(V29:V60) -> 230 | AA16: =Y16+Z16 -> 375
A17: 13 | B17: Mahira | C17: Arbab Ali | D17: One | E17: A | F17: A | G17: A | I17: P | K17: A | L17: P | M17: P | Q17: A | R17: A | S17: A | U17: A | V17: =COUNTIF(E17:U17,"P") -> 3 | W17: =COUNTIF(E17:U17,"A") -> 8 | X17: % | Y17: =Y16/Y15 -> 0.41193182 | Z17: =Z16/Z15 -> 0.87121212 | AA17: =AA16/AA15 -> 0.60876623
A18: 14 | B18: Meerab | C18: Yasir Ahmed | D18: One | E18: - | F18: - | G18: - | I18: - | K18: - | L18: P | M18: P | Q18: P | R18: P | S18: A | U18: A | V18: =COUNTIF(E18:U18,"P") -> 4 | W18: =COUNTIF(E18:U18,"A") -> 2
A19: 15 | B19: Qudsia Zehra | C19: Awaheed Ali | D19: One | E19: - | F19: - | G19: - | I19: - | K19: - | L19: - | M19: P | Q19: P | R19: P | S19: P | U19: A | V19: =COUNTIF(E19:U19,"P") -> 4 | W19: =COUNTIF(E19:U19,"A") -> 1
A20: 16 | B20: Paras | C20: Sadam | D20: One | E20: A | F20: A | G20: A | I20: P | K20: P | L20: P | M20: P | Q20: P | R20: A | S20: P | U20: A | V20: =COUNTIF(E20:U20,"P") -> 6 | W20: =COUNTIF(E20:U20,"A") -> 5
A21: 17 | B21: Thamna Batool | C21: Shehzad | D21: One | E21: - | F21: - | G21: - | I21: - | K21: - | L21: - | M21: P | Q21: A | R21: A | S21: P | U21: A | V21: =COUNTIF(E21:U21,"P") -> 2 | W21: =COUNTIF(E21:U21,"A") -> 3 | X21: Absent Days Details
A22: 18 | B22: Tamana Fatima | C22: Shehzad | D22: One | E22: - | F22: - | G22: - | I22: - | K22: - | L22: - | M22: P | Q22: A | R22: A | S22: P | U22: A | V22: =COUNTIF(E22:U22,"P") -> 2 | W22: =COUNTIF(E22:U22,"A") -> 3 | X22: Detail | Y22: Boys | Z22: Girls | AA22: Total
A23: 19 | B23: Zaiba Bakhtawar | C23: Hameed | D23: One | E23: P | F23: P | G23: P | I23: P | K23: P | L23: P | M23: P | Q23: P | R23: A | S23: P | U23: A | V23: =COUNTIF(E23:U23,"P") -> 9 | W23: =COUNTIF(E23:U23,"A") -> 2 | X23: Due Present days | Y23: =32*11 -> 352 | Z23: =24*11 -> 264 | AA23: =Y23+Z23 -> 616
A24: 20 | B24: Zainab | C24: A. Aziz | D24: One | E24: A | F24: P | G24: P | I24: P | K24: P | L24: P | M24: P | Q24: P | R24: A | S24: P | U24: A | V24: =COUNTIF(E24:U24,"P") -> 8 | W24: =COUNTIF(E24:U24,"A") -> 3 | X24: Absent days | Y24: =Y23-Y16 -> 207 | Z24: =Z23-Z16 -> 34 | AA24: =Y24+Z24 -> 241
A25: 21 | B25: Zainab | C25: Zulfiqar | D25: One | E25: A | F25: P | G25: P | I25: P | K25: P | L25: P | M25: P | Q25: P | R25: A | S25: P | U25: A | V25: =COUNTIF(E25:U25,"P") -> 8 | W25: =COUNTIF(E25:U25,"A") -> 3 | X25: % | Y25: =Y24/Y23 -> 0.58806818 | Z25: =Z24/Z23 -> 0.12878788 | AA25: =AA24/AA23 -> 0.39123377
A26: 22 | B26: Waniya | C26: Asad Ali | D26: One | E26: A | F26: A | G26: A | I26: P | K26: A | L26: P | M26: P | Q26: P | R26: A | S26: A | U26: A | V26: =COUNTIF(E26:U26,"P") -> 4 | W26: =COUNTIF(E26:U26,"A") -> 7
A27: 23 | B27: Haram | C27: Moien Khan | D27: One | E27: P | F27: P | G27: A | I27: P | K27: P | L27: P | M27: P | Q27: P | R27: P | S27: A | U27: A | V27: =COUNTIF(E27:U27,"P") -> 8 | W27: =COUNTIF(E27:U27,"A") -> 3
A28: 24 | B28: Ayesha | C28: A. Latif | D28: One | E28: - | F28: - | G28: - | I28: - | K28: - | L28: - | M28: - | Q28: - | R28: - | S28: - | U28: - | V28: =COUNTIF(E28:U28,"P") -> 0 | W28: =COUNTIF(E28:U28,"A") -> 0
A29: 1 | B29: Arsalan | C29: Zulfiqar | D29: One | E29: A | F29: A | G29: P | I29: P | K29: P | L29: P | M29: P | Q29: P | R29: A | S29: P | U29: A | V29: =COUNTIF(E29:U29,"P") -> 7 | W29: =COUNTIF(E29:U29,"A") -> 4
A30: 2 | B30: Arsalan | C30: Faheem | D30: One | E30: A | F30: A | G30: P | I30: P | K30: P | L30: P | M30: P | Q30: A | R30: A | S30: A | U30: A | V30: =COUNTIF(E30:U30,"P") -> 5 | W30: =COUNTIF(E30:U30,"A") -> 6
A31: 3 | B31: A. Nawaz | C31: M. Nawaz | D31: One | E31: A | F31: A | G31: P | I31: P | K31: P | L31: P | M31: P | Q31: P | R31: A | S31: P | U31: A | V31: =COUNTIF(E31:U31,"P") -> 7 | W31: =COUNTIF(E31:U31,"A") -> 4
A32: 4 | B32: A. Malik | C32: Sohail | D32: One | E32: A | F32: A | G32: P | I32: P | K32: P | L32: P | M32: P | Q32: A | R32: A | S32: A | U32: A | V32: =COUNTIF(E32:U32,"P") -> 5 | W32: =COUNTIF(E32:U32,"A") -> 6
A33: 5 | B33: Abdullah | C33: Imtiaz | D33: One | E33: P | F33: A | G33: A | I33: P | K33: P | L33: P | M33: P | Q33: P | R33: P | S33: A | U33: A | V33: =COUNTIF(E33:U33,"P") -> 7 | W33: =COUNTIF(E33:U33,"A") -> 4
A34: 6 | B34: Aqeel | C34: A. Ghaffar | D34: One | E34: P | F34: P | G34: P | I34: P | K34: P | L34: P | M34: P | Q34: P | R34: A | S34: P | U34: A | V34: =COUNTIF(E34:U34,"P") -> 9 | W34: =COUNTIF(E34:U34,"A") -> 2
A35: 7 | B35: A. Wasay | C35: Aslam | D35: One | E35: P | F35: A | G35: A | I35: A | K35: P | L35: P | M35: P | Q35: A | R35: A | S35: A | U35: A | V35: =COUNTIF(E35:U35,"P") -> 4 | W35: =COUNTIF(E35:U35,"A") -> 7
A36: 8 | B36: A. Qadir | C36: A. Hammad | D36: One | E36: P | F36: P | G36: P | I36: P | K36: P | L36: A | M36: P | Q36: A | R36: A | S36: P | U36: A | V36: =COUNTIF(E36:U36,"P") -> 7 | W36: =COUNTIF(E36:U36,"A") -> 4
A37: 9 | B37: Asghar Ali | C37: Akbar Ali | D37: One | E37: P | F37: P | G37: P | I37: P | K37: P | L37: P | M37: P | Q37: P | R37: A | S37: P | U37: A | V37: =COUNTIF(E37:U37,"P") -> 9 | W37: =COUNTIF(E37:U37,"A") -> 2
... A60: 32 | B60: Zain Ali | C60: Altaf | D60: One | E60: A | F60: P | G60: A | I60: P | K60: P | L60: P | M60: P | Q60: P | R60: A | S60: A | U60: A | V60: =COUNTIF(E60:U60,"P") -> 6 | W60: =COUNTIF(E60:U60,"A") -> 5

Sheet Class-II
A1: Goverment High School (SJCHS)
A2: Monthly Attendence Month of August-2024
A3: S.No | B3: Student Name | C3: Father Name | D3: Class | E3: =TEXT(E4,"ddd") -> Thu | F3: =TEXT(F4,"ddd") -> Fri | G3: =TEXT(G4,"ddd") -> Sat | H3: =TEXT(H4,"ddd") -> Sun | I3: =TEXT(I4,"ddd") -> Mon | J3: =TEXT(J4,"ddd") -> Tue | K3: =TEXT(K4,"ddd") -> Wed | L3: =TEXT(L4,"ddd") -> Thu | ... U3: =TEXT(U4,"ddd") -> Sat | V3: Present | W3: Absent | X3: Year 2024
E4: 45519 | F4: 45520 | G4: 45521 | H4: 45522 | I4: 45523 | J4: 45524 | K4: 45525 | L4: 45526 | M4: 45527 | N4: 45528 | O4: 45529 | P4: 45530 | Q4: 45531 | R4: 45532 | S4: 45533 | T4: 45534 | U4: 45535 | X4: Total days | Y4: =SUM(Y5:Y11) -> 31
A5: 1 | B5: Abiha Zehra | C5: Ab. Mateen | D5: Two | E5: A | F5: A | G5: A | H5: SUNDAY - SUNDAY - SUNDAY - SUNDAY - SUNDAY | I5: A | J5: SHAH ABDUL LATIF DAY - SHAH ABDUL LATIF DAY | K5: P | L5: P | M5: P | N5: P | O5: SUNDAY - SUNDAY - SUNDAY - SUNDAY - SUNDAY | P5: CHEHLUM - CHEHLUM - CHEHLUM - CHEHLUM | Q5: A | R5: A | S5: A | T5: OFF DUE TO RAIN - OFF DUE TO RAIN | V5: =COUNTIF(E5:U5,"P") -> 4 | W5: =COUNTIF(E5:U5,"A") -> 7 | X5: Working days | Y5: 11
A6: 2 | B6: Aleena Zia | C6: Khuda Baksh | D6: Two | E6: P | F6: P | G6: P | I6: P | K6: P | L6: P | M6: P | N6: P | Q6: P | R6: A | S6: P | V6: =COUNTIF(E6:U6,"P") -> 10 | W6: =COUNTIF(E6:U6,"A") -> 1 | X6: Sunday | Y6: 4
A7: 3 | B7: Anumta Jamali | C7: Zaheer Abbas | D7: Two | E7: P | F7: P | G7: P | I7: P | K7: P | L7: P | M7: P | N7: A | Q7: A | R7: A | S7: A | V7: =COUNTIF(E7:U7,"P") -> 7 | W7: =COUNTIF(E7:U7,"A") -> 4 | X7: Summer Vications | Y7: 12
A8: 4 | B8: Anusha | C8: Mukhtiyar Ali | D8: Two | E8: P | F8: P | G8: P | I8: P | K8: P | L8: P | M8: P | N8: A | Q8: A | R8: A | S8: P | V8: =COUNTIF(E8:U8,"P") -> 8 | W8: =COUNTIF(E8:U8,"A") -> 3 | X8: URS | Y8: 1
A9: 5 | B9: Ayat | C9: Faiq Ali | D9: Two | E9: P | F9: P | G9: P | I9: P | K9: P | L9: P | M9: P | N9: A | Q9: P | R9: A | S9: P | V9: =COUNTIF(E9:U9,"P") -> 9 | W9: =COUNTIF(E9:U9,"A") -> 2 | X9: Mango Day | Y9: 1
A10: 6 | B10: Ayesha | C10: Ali Muhammad | D10: Two | E10: P | F10: P | G10: P | I10: P | K10: P | L10: P | M10: P | N10: A | Q10: A | R10: A | S10: A | V10: =COUNTIF(E10:U10,"P") -> 7 | W10: =COUNTIF(E10:U10,"A") -> 4 | X10: Chehlum | Y10: 1
A11: 7 | B11: Dua | C11: Akbar Ali | D11: Two | E11: P | F11: P | G11: P | I11: P | K11: P | L11: P | M11: P | N11: A | Q11: P | R11: A | S11: P | V11: =COUNTIF(E11:U11,"P") -> 9 | W11: =COUNTIF(E11:U11,"A") -> 2 | X11: OFF Due to Heavy Rain | Y11: 1
A12: 8 | B12: Fiza | C12: Akbar Ali | D12: Two | E12: P | F12: P | G12: P | I12: P | K12: P | L12: P | M12: P | N12: A | Q12: P | R12: A | S12: P | V12: =COUNTIF(E12:U12,"P") -> 9 | W12: =COUNTIF(E12:U12,"A") -> 2
A13: 9 | B13: Jannat Fatima | C13: Zulfiqar | D13: Two | E13: P | F13: P | G13: P | I13: P | K13: P | L13: P | M13: P | N13: A | Q13: A | R13: A | S13: P | V13: =COUNTIF(E13:U13,"P") -> 8 | W13: =COUNTIF(E13:U13,"A") -> 3 | X13: Present Days Detail
A14: 10 | B14: Kashaf | C14: Abdul Rehman | D14: Two | E14: A | F14: A | G14: P | I14: P | K14: A | L14: P | M14: P | N14: A | Q14: P | R14: A | S14: A | V14: =COUNTIF(E14:U14,"P") -> 5 | W14: =COUNTIF(E14:U14,"A") -> 6 | X14: Detail | Y14: Boys | Z14: Girls | AA14: Total
A15: 11 | B15: Masooma | C15: M. Raheem | D15: Two | E15: - | F15: - | G15: - | I15: P | K15: P | L15: P | M15: A | N15: A | Q15: P | R15: A | S15: A | V15: =COUNTIF(E15:U15,"P") -> 4 | W15: =COUNTIF(E15:U15,"A") -> 4 | X15: Due Present days | Y15: =26*11 -> 286 | Z15: =22*11 -> 242 | AA15: =SUM(Y15:Z15) -> 528
A16: 12 | B16: Muneeza | C16: Mir Amirudin | D16: Two | E16: P | F16: P | G16: P | I16: P | K16: A | L16: P | M16: P | N16: A | Q16: A | R16: P | S16: P | V16: =COUNTIF(E16:U16,"P") -> 8 | W16: =COUNTIF(E16:U16,"A") -> 3 | X16: Actual present days | Y16: =SUM(V27:V52) -> 220 | Z16: =SUM(V5:V26) -> 159 | AA16: =Y16+Z16 -> 379
A17: 13 | B17: Nayyara | C17: Khalid Hussain | D17: Two | E17: A | F17: A | G17: P | I17: P | K17: P | L17: P | M17: P | N17: A | Q17: A | R17: A | S17: A | V17: =COUNTIF(E17:U17,"P") -> 5 | W17: =COUNTIF(E17:U17,"A") -> 6 | X17: % | Y17: =Y16/Y15 -> 0.76923077 | Z17: =Z16/Z15 -> 0.65702479 | AA17: =AA16/AA15 -> 0.71780303
A18: 14 | B18: Rashida | C18: Sajjad Ahmed | D18: Two | E18: A | F18: A | G18: A | I18: P | K18: P | L18: P | M18: P | N18: A | Q18: A | R18: A | S18: A | V18: =COUNTIF(E18:U18,"P") -> 4 | W18: =COUNTIF(E18:U18,"A") -> 7
A19: 15 | B19: Rubab Zahra | C19: Abdul Aziz | D19: Two | E19: A | F19: A | G19: P | I19: P | K19: P | L19: P | M19: P | N19: P | Q19: P | R19: A | S19: P | V19: =COUNTIF(E19:U19,"P") -> 8 | W19: =COUNTIF(E19:U19,"A") -> 3
A20: 16 | B20: Saba Jamali | C20: Sajid Ali | D20: Two | E20: A | F20: A | G20: P | I20: P | K20: P | L20: P | M20: P | N20: A | Q20: A | R20: A | S20: P | V20: =COUNTIF(E20:U20,"P") -> 6 | W20: =COUNTIF(E20:U20,"A") -> 5
A21: 17 | B21: Tahreem Fatima | C21: Khalid Hussain | D21: Two | E21: A | F21: A | G21: P | I21: P | K21: P | L21: P | M21: P | N21: P | Q21: P | R21: A | S21: P | V21: =COUNTIF(E21:U21,"P") -> 8 | W21: =COUNTIF(E21:U21,"A") -> 3 | X21: Absent Days Details
A22: 18 | B22: Sehar Fatima | C22: Altaf Hussain | D22: Two | E22: A | F22: A | G22: P | I22: P | K22: P | L22: P | M22: P | N22: A | Q22: P | R22: A | S22: P | V22: =COUNTIF(E22:U22,"P") -> 7 | W22: =COUNTIF(E22:U22,"A") -> 4 | X22: Detail | Y22: Boys | Z22: Girls | AA22: Total
A23: 19 | B23: Taskeen | C23: Amjad Ali | D23: Two | E23: A | F23: P | G23: P | I23: P | K23: P | L23: A | M23: P | N23: A | Q23: P | R23: A | S23: P | V23: =COUNTIF(E23:U23,"P") -> 7 | W23: =COUNTIF(E23:U23,"A") -> 4 | X23: Due Present days | Y23: =26*11 -> 286 | Z23: =22*11 -> 242 | AA23: =Y23+Z23 -> 528
A24: 20 | B24: Zainab | C24: Sikandar | D24: Two | E24: A | F24: P | G24: P | I24: P | K24: P | L24: P | M24: P | N24: P | Q24: P | R24: P | S24: P | V24: =COUNTIF(E24:U24,"P") -> 10 | W24: =COUNTIF(E24:U24,"A") -> 1 | X24: Absent days | Y24: =Y23-Y16 -> 66 | Z24: =Z23-Z16 -> 83 | AA24: =Y24+Z24 -> 149
A25: 21 | B25: Kashish | C25: M. Noman | D25: Two | E25: P | F25: P | G25: P | I25: P | K25: P | L25: P | M25: P | N25: A | Q25: A | R25: P | S25: A | V25: =COUNTIF(E25:U25,"P") -> 8 | W25: =COUNTIF(E25:U25,"A") -> 3 | X25: % | Y25: =Y24/Y23 -> 0.23076923 | Z25: =Z24/Z23 -> 0.34297521 | AA25: =AA24/AA23 -> 0.28219697
A26: 22 | B26: Saba | C26: Asif | D26: Two | E26: A | F26: A | G26: P | I26: P | K26: P | L26: P | M26: P | N26: P | Q26: P | R26: A | S26: P | V26: =COUNTIF(E26:U26,"P") -> 8 | W26: =COUNTIF(E26:U26,"A") -> 3
A27: 1 | B27: Abdul Musawir | C27: M. Ismail | D27: Two | E27: P | F27: P | G27: P | I27: P | K27: P | L27: P | M27: P | N27: P | Q27: P | R27: P | S27: P | V27: =COUNTIF(E27:U27,"P") -> 11 | W27: =COUNTIF(E27:U27,"A") -> 0
A28: 2 | B28: Abdul Rehman | C28: Sajid Ali | D28: Two | E28: P | F28: P | G28: P | I28: P | K28: P | L28: P | M28: P | N28: P | Q28: P | R28: A | S28: A | V28: =COUNTIF(E28:U28,"P") -> 9 | W28: =COUNTIF(E28:U28,"A") -> 2
A29: 3 | B29: Abdul Wahab | C29: Abdul Hafeez | D29: Two | E29: P | F29: P | G29: P | I29: P | K29: P | L29: A | M29: P | N29: P | Q29: P | R29: A | S29: A | V29: =COUNTIF(E29:U29,"P") -> 8 | W29: =COUNTIF(E29:U29,"A") -> 3
A30: 4 | B30: Abdullah | C30: Riazuddin | D30: Two | E30: P | F30: P | G30: P | I30: P | K30: P | L30: P | M30: A | N30: P | Q30: P | R30: P | S30: P | V30: =COUNTIF(E30:U30,"P") -> 10 | W30: =COUNTIF(E30:U30,"A") -> 1
A31: 5 | B31: Ali Shanawar | C31: Mukhtiyar | D31: Two | E31: P | F31: P | G31: P | I31: P | K31: P | L31: P | M31: P | N31: A | Q31: A | R31: A | S31: A | V31: =COUNTIF(E31:U31,"P") -> 7 | W31: =COUNTIF(E31:U31,"A") -> 4
A32: 6 | B32: Faizan | C32: Lutfullah | D32: Two | E32: P | F32: P | G32: P | I32: P | K32: P | L32: P | M32: P | N32: P | Q32: P | R32: A | S32: P | V32: =COUNTIF(E32:U32,"P") -> 10 | W32: =COUNTIF(E32:U32,"A") -> 1
A33: 7 | B33: Fayaz | C33: Samano Khan | D33: Two | E33: A | F33: A | G33: A | I33: A | K33: P | L33: P | M33: P | N33: A | Q33: A | R33: P | S33: P | V33: =COUNTIF(E33:U33,"P") -> 5 | W33: =COUNTIF(E33:U33,"A") -> 6
A34: 8 | B34: Ghulam Abbas | C34: Kamran Ali | D34: Two | E34: P | F34: P | G34: P | I34: P | K34: P | L34: P | M34: P | N34: P | Q34: P | R34: P | S34: P | V34: =COUNTIF(E34:U34,"P") -> 11 | W34: =COUNTIF(E34:U34,"A") -> 0
A35: 9 | B35: Ghulam Mehdi | C35: Rizwan | D35: Two | E35: P | F35: P | G35: P | I35: P | K35: P | L35: P | M35: P | N35: A | Q35: A | R35: A | S35: P | V35: =COUNTIF(E35:U35,"P") -> 8 | W35: =COUNTIF(E35:U35,"A") -> 3
A36: 10 | B36: Hammad Ali | C36: Sajjad Ali | D36: Two | E36: A | F36: P | G36: A | I36: P | K36: P | L36: P | M36: P | N36: A | Q36: P | R36: A | S36: P | V36: =COUNTIF(E36:U36,"P") -> 7 | W36: =COUNTIF(E36:U36,"A") -> 4
A37: 11 | B37: Haris | C37: Akbar Ali | D37: Two | E37: P | F37: P | G37: P | I37: P | K37: P | L37: P | M37: A | N37: P | Q37: P | R37: A | S37: P | V37: =COUNTIF(E37:U37,"P") -> 9 | W37: =COUNTIF(E37:U37,"A") -> 2
... A52: 26 | B52: Burair Abbas | C52: Azhar Abbas | D52: Two | E52: - | F52: - | G52: - | I52: - | K52: - | L52: - | M52: P | N52: P | Q52: P | R52: A | S52: A | V52: =COUNTIF(E52:U52,"P") -> 3 | W52: =COUNTIF(E52:U52,"A") -> 2

Sheet Class-III
A1: Goverment high school (SJCHS)
A2: Monthly Attendence Month of August-2024
A3: S.No | B3: Student Name | C3: Father Name | D3: Class | E3: =TEXT(E4,"ddd") -> Thu | F3: =TEXT(F4,"ddd") -> Fri | G3: =TEXT(G4,"ddd") -> Sat | H3: =TEXT(H4,"ddd") -> Sun | I3: =TEXT(I4,"ddd") -> Mon | J3: =TEXT(J4,"ddd") -> Tue | K3: =TEXT(K4,"ddd") -> Wed | L3: =TEXT(L4,"ddd") -> Thu | ... U3: =TEXT(U4,"ddd") -> Sat | V3: Present | W3: Absent | X3: Year 2024
E4: 45519 | F4: 45520 | G4: 45521 | H4: 45522 | I4: 45523 | J4: 45524 | K4: 45525 | L4: 45526 | M4: 45527 | N4: 45528 | O4: 45529 | P4: 45530 | Q4: 45531 | R4: 45532 | S4: 45533 | T4: 45534 | U4: 45535 | X4: Total days | Y4: =SUM(Y5:Y11) -> 31
A5: 1 | B5: Anjuman | C5: Ab. Ghaffar | D5: Three | E5: P | F5: P | G5: A | H5: SUNDAY - SUNDAY - SUNDAY - SUNDAY - SUNDAY - SUNDAY | I5: P | J5: (URS) SHAH ABDUL LATIF BHITTAI (URS) | K5: P | L5: P | M5: P | N5: P | O5: SUNDAY - SUNDAY - SUNDAY - SUNDAY - SUNDAY - SUNDAY | P5: CHEHLUM - CHEHLUM - CHEHLUM - CHEHLUM - CHEHLUM | Q5: P | R5: A | S5: P | T5: OFF DUE TO HEAVY RAIN - OFF DUE TO HEAVY RAIN | V5: =COUNTIF(E5:U5,"P") -> 9 | W5: =COUNTIF(E5:U5,"A") -> 2 | X5: Working days | Y5: 11
A6: 2 | B6: Ayeza | C6: M. Ameen Solangi | D6: Three | E6: P | F6: P | G6: P | I6: P | K6: P | L6: P | M6: P | N6: P | Q6: P | R6: A | S6: P | V6: =COUNTIF(E6:U6,"P") -> 10 | W6: =COUNTIF(E6:U6,"A") -> 1 | X6: Sunday | Y6: 4
A7: 3 | B7: Dua Batool | C7: Muneer Ahmed Tahiri | D7: Three | E7: P | F7: P | G7: P | I7: P | K7: P | L7: P | M7: P | N7: P | Q7: P | R7: A | S7: A | V7: =COUNTIF(E7:U7,"P") -> 9 | W7: =COUNTIF(E7:U7,"A") -> 2 | X7: Summer Vications | Y7: 12
A8: 4 | B8: Fiza | C8: Hamid Ali Siyal | D8: Three | E8: P | F8: P | G8: P | I8: P | K8: P | L8: P | M8: P | N8: P | Q8: P | R8: A | S8: P | V8: =COUNTIF(E8:U8,"P") -> 10 | W8: =COUNTIF(E8:U8,"A") -> 1 | X8: URS | Y8: 1
A9: 5 | B9: Hadeeqa | C9: Haji Malah | D9: Three | E9: P | F9: P | G9: P | I9: P | K9: P | L9: A | M9: P | N9: P | Q9: P | R9: A | S9: P | V9: =COUNTIF(E9:U9,"P") -> 9 | W9: =COUNTIF(E9:U9,"A") -> 2 | X9: Mango Day | Y9: 1
A10: 6 | B10: Hajul | C10: Manzoor Ahmed Memon | D10: Three | E10: P | F10: P | G10: P | I10: P | K10: A | L10: P | M10: P | N10: P | Q10: A | R10: P | S10: A | V10: =COUNTIF(E10:U10,"P") -> 8 | W10: =COUNTIF(E10:U10,"A") -> 3 | X10: Chehlum | Y10: 1
A11: 7 | B11: Hafsa Jamali | C11: Rehmatullah | D11: Three | E11: P | F11: P | G11: P | I11: P | K11: P | L11: P | M11: P | N11: P | Q11: P | R11: P | S11: P | V11: =COUNTIF(E11:U11,"P") -> 11 | W11: =COUNTIF(E11:U11,"A") -> 0 | X11: OFF Due to Heavy Rain | Y11: 1
A12: 8 | B12: Insha | C12: Fazal Mohammad | D12: Three | E12: P | F12: P | G12: P | I12: P | K12: P | L12: P | M12: P | N12: P | Q12: P | R12: P | S12: A | V12: =COUNTIF(E12:U12,"P") -> 10 | W12: =COUNTIF(E12:U12,"A") -> 1
A13: 9 | B13: Kashaf | C13: M. Noman | D13: Three | E13: P | F13: P | G13: P | I13: P | K13: P | L13: P | M13: P | N13: P | Q13: P | R13: A | S13: P | V13: =COUNTIF(E13:U13,"P") -> 10 | W13: =COUNTIF(E13:U13,"A") -> 1 | X13: Present Days Detail
A14: 10 | B14: Kashaf | C14: Shahid Hussain | D14: Three | E14: A | F14: A | G14: A | I14: P | K14: P | L14: P | M14: P | N14: A | Q14: A | R14: A | S14: P | V14: =COUNTIF(E14:U14,"P") -> 5 | W14: =COUNTIF(E14:U14,"A") -> 6 | X14: Detail | Y14: Boys | Z14: Girls | AA14: Total
A15: 11 | B15: Maryam | C15: Irfan Ali | D15: Three | E15: A | F15: A | G15: A | I15: A | K15: A | L15: A | M15: A | N15: A | Q15: A | R15: A | S15: A | V15: =COUNTIF(E15:U15,"P") -> 0 | W15: =COUNTIF(E15:U15,"A") -> 11 | X15: Due Present days | Y15: =28*11 -> 308 | Z15: =23*11 -> 253 | AA15: =SUM(Y15:Z15) -> 561
A16: 12 | B16: Noor-E-Sahar | C16: Mir Ameerudin | D16: Three | E16: P | F16: P | G16: P | I16: P | K16: P | L16: P | M16: P | N16: P | Q16: P | R16: P | S16: P | V16: =COUNTIF(E16:U16,"P") -> 11 | W16: =COUNTIF(E16:U16,"A") -> 0 | X16: Actual present days | Y16: =SUM(V28:V55) -> 205 | Z16: =SUM(V5:V27) -> 182 | AA16: =Y16+Z16 -> 387
A17: 13 | B17: Sehrish Ali | C17: Shah Ali | D17: Three | E17: P | F17: P | G17: P | I17: P | K17: P | L17: P | M17: P | N17: P | Q17: P | R17: A | S17: A | V17: =COUNTIF(E17:U17,"P") -> 9 | W17: =COUNTIF(E17:U17,"A") -> 2 | X17: % | Y17: =Y16/Y15 -> 0.66558442 | Z17: =Z16/Z15 -> 0.71936759 | AA17: =AA16/AA15 -> 0.68983957
A18: 14 | B18: Shafia | C18: Meer Muhammad | D18: Three | E18: P | F18: P | G18: P | I18: P | K18: P | L18: P | M18: A | N18: A | Q18: A | R18: A | S18: A | V18: =COUNTIF(E18:U18,"P") -> 6 | W18: =COUNTIF(E18:U18,"A") -> 5
A19: 15 | B19: Sawebia | C19: Hafeezullah | D19: Three | E19: P | F19: P | G19: P | I19: P | K19: P | L19: P | M19: P | N19: A | Q19: A | R19: A | S19: P | V19: =COUNTIF(E19:U19,"P") -> 8 | W19: =COUNTIF(E19:U19,"A") -> 3
A20: 16 | B20: Sughra | C20: Suhrab Ali | D20: Three | E20: P | F20: P | G20: P | I20: P | K20: P | L20: P | M20: P | N20: P | Q20: P | R20: A | S20: P | V20: =COUNTIF(E20:U20,"P") -> 10 | W20: =COUNTIF(E20:U20,"A") -> 1
A21: 17 | B21: Tashfeen | C21: M. Idrees | D21: Three | E21: P | F21: P | G21: P | I21: P | K21: P | L21: P | M21: P | N21: P | Q21: A | R21: A | S21: P | V21: =COUNTIF(E21:U21,"P") -> 9 | W21: =COUNTIF(E21:U21,"A") -> 2 | X21: Absent Days Details
A22: 18 | B22: Tasmiya | C22: Shehbaz Ahmed | D22: Three | E22: P | F22: P | G22: P | I22: P | K22: P | L22: P | M22: P | N22: A | Q22: A | R22: A | S22: P | V22: =COUNTIF(E22:U22,"P") -> 8 | W22: =COUNTIF(E22:U22,"A") -> 3 | X22: Detail | Y22: Boys | Z22: Girls | AA22: Total
A23: 19 | B23: Tayyaba | C23: M. Farooque Sarki | D23: Three | E23: P | F23: P | G23: P | I23: P | K23: P | L23: P | M23: P | N23: P | Q23: P | R23: A | S23: A | V23: =COUNTIF(E23:U23,"P") -> 9 | W23: =COUNTIF(E23:U23,"A") -> 2 | X23: Due Present days | Y23: =28*11 -> 308 | Z23: =23*11 -> 253 | AA23: =Y23+Z23 -> 561
A24: 20 | B24: Hafsa | C24: Fahad | D24: Three | E24: A | F24: A | G24: P | I24: P | K24: A | L24: P | M24: P | N24: P | Q24: P | R24: A | S24: A | V24: =COUNTIF(E24:U24,"P") -> 6 | W24: =COUNTIF(E24:U24,"A") -> 5 | X24: Absent days | Y24: =Y23-Y16 -> 103 | Z24: =Z23-Z16 -> 71 | AA24: =Y24+Z24 -> 174
A25: 21 | B25: Hooriya | C25: Fahad | D25: Three | E25: A | F25: A | G25: P | I25: P | K25: A | L25: P | M25: P | N25: P | Q25: P | R25: A | S25: A | V25: =COUNTIF(E25:U25,"P") -> 6 | W25: =COUNTIF(E25:U25,"A") -> 5 | X25: % | Y25: =Y24/Y23 -> 0.33441558 | Z25: =Z24/Z23 -> 0.28063241 | AA25: =AA24/AA23 -> 0.31016043
A26: 22 | B26: Zainab Batool | C26: Mohsin Ali | D26: Three | E26: L | F26: L | G26: L | I26: L | K26: A | L26: A | M26: A | N26: A | Q26: A | R26: P | S26: A | V26: =COUNTIF(E26:U26,"P") -> 1 | W26: =COUNTIF(E26:U26,"A") -> 6
A27: 23 | B27: Rida-E-Zainab | C27: Faraz Hyder | D27: Three | E27: P | F27: P | G27: P | I27: P | K27: P | L27: P | M27: P | N27: P | Q27: A | R27: A | S27: A | V27: =COUNTIF(E27:U27,"P") -> 8 | W27: =COUNTIF(E27:U27,"A") -> 3
A28: 1 | B28: Abdul Qudoos | C28: Waheed Ahmed | D28: Three | E28: P | F28: P | G28: P | I28: P | K28: P | L28: P | M28: P | N28: P | Q28: P | R28: A | S28: A | V28: =COUNTIF(E28:U28,"P") -> 9 | W28: =COUNTIF(E28:U28,"A") -> 2
A29: 2 | B29: Abbas Ali | C29: Deedar Ali | D29: Three | E29: P | F29: P | G29: P | I29: P | K29: P | L29: P | M29: P | N29: P | Q29: P | R29: A | S29: P | V29: =COUNTIF(E29:U29,"P") -> 10 | W29: =COUNTIF(E29:U29,"A") -> 1
A30: 3 | B30: Abdul Rafay | C30: Noor Ul Haq | D30: Three | E30: P | F30: P | G30: P | I30: P | K30: P | L30: P | M30: P | N30: P | Q30: P | R30: P | S30: P | V30: =COUNTIF(E30:U30,"P") -> 11 | W30: =COUNTIF(E30:U30,"A") -> 0
A31: 4 | B31: Abdul Rahim | C31: Abdul Hafeez | D31: Three | E31: A | F31: P | G31: P | I31: P | K31: P | L31: P | M31: P | N31: A | Q31: P | R31: A | S31: A | V31: =COUNTIF(E31:U31,"P") -> 7 | W31: =COUNTIF(E31:U31,"A") -> 4
A32: 5 | B32: Abdullah | C32: Munawar Ali | D32: Three | E32: A | F32: A | G32: P | I32: P | K32: P | L32: P | M32: P | N32: A | Q32: P | R32: A | S32: P | V32: =COUNTIF(E32:U32,"P") -> 7 | W32: =COUNTIF(E32:U32,"A") -> 4
A33: 6 | B33: Ali Haider | C33: Akber Ali | D33: Three | E33: P | F33: P | G33: P | I33: P | K33: P | L33: P | M33: P | N33: P | Q33: P | R33: A | S33: P | V33: =COUNTIF(E33:U33,"P") -> 10 | W33: =COUNTIF(E33:U33,"A") -> 1
A34: 7 | B34: Aqib Ali | C34: Abdul Ghaffar | D34: Three | E34: P | F34: P | G34: P | I34: P | K34: P | L34: P | M34: P | N34: A | Q34: P | R34: A | S34: A | V34: =COUNTIF(E34:U34,"P") -> 8 | W34: =COUNTIF(E34:U34,"A") -> 3
A35: 8 | B35: Asad Ali | C35: Ali Ejaz | D35: Three | E35: A | F35: A | G35: A | I35: P | K35: P | L35: P | M35: P | N35: A | Q35: A | R35: A | S35: P | V35: =COUNTIF(E35:U35,"P") -> 5 | W35: =COUNTIF(E35:U35,"A") -> 6
A36: 9 | B36: Ayaz Ali | C36: Arbab Ali | D36: Three | E36: A | F36: A | G36: P | I36: P | K36: P | L36: P | M36: P | N36: A | Q36: A | R36: A | S36: P | V36: =COUNTIF(E36:U36,"P") -> 6 | W36: =COUNTIF(E36:U36,"A") -> 5
A37: 10 | B37: Azan | C37: Nisar Ahmed | D37: Three | E37: A | F37: A | G37: P | I37: P | K37: P | L37: P | M37: P | N37: P | Q37: A | R37: A | S37: P | V37: =COUNTIF(E37:U37,"P") -> 7 | W37: =COUNTIF(E37:U37,"A") -> 4
... A55: 28 | B55: Subhan | C55: Ishfaque | D55: Three | E55: - | F55: - | G55: - | I55: P | K55: P | L55: A | M55: P | N55: A | Q55: P | R55: A | S55: P | V55: =COUNTIF(E55:U55,"P") -> 5 | W55: =COUNTIF(E55:U55,"A") -> 3

Sheet Class-IV
A1: Goverment high school (SJCHS)
A2: Monthly Attendence Month of August-2024
A3: S.No | B3: Student Name | C3: Father Name | D3: Class | E3: =TEXT(E4,"ddd") -> Thu | F3: =TEXT(F4,"ddd") -> Fri | G3: =TEXT(G4,"ddd") -> Sat | H3: =TEXT(H4,"ddd") -> Sun | I3: =TEXT(I4,"ddd") -> Mon | J3: =TEXT(J4,"ddd") -> Tue | K3: =TEXT(K4,"ddd") -> Wed | L3: =TEXT(L4,"ddd") -> Thu | ... U3: =TEXT(U4,"ddd") -> Sat | V3: Present | W3: Absent | X3: Year 2024
E4: 45519 | F4: 45520 | G4: 45521 | H4: 45522 | I4: 45523 | J4: 45524 | K4: 45525 | L4: 45526 | M4: 45527 | N4: 45528 | O4: 45529 | P4: 45530 | Q4: 45531 | R4: 45532 | S4: 45533 | T4: 45534 | U4: 45535 | X4: Total days | Y4: =SUM(Y5:Y11) -> 31
A5: 1 | B5: Ambreen Junejo | C5: Abdul Ghaffar | D5: Four | E5: P | F5: A | G5: A | H5: SUNDAY - SUNDAY - SUNDAY - SUNDAY - SUNDAY | I5: P | J5: URS SHAH ABDUL LATIF BHITTAI | K5: P | L5: P | M5: P | N5: P | O5: SUNDAY - SUNDAY - SUNDAY - SUNDAY - SUNDAY | P5: CHEHLUM - CHEHLUM - CHEHLUM - CHEHLUM - CHEHLUM | Q5: P | R5: A | S5: P | T5: OFF DUE TO HEAVY RAIN - OFF DUE TO HEAVY RAIN | U5: A | V5: =COUNTIF(E5:U5,"P") -> 8 | W5: =COUNTIF(E5:U5,"A") -> 4 | X5: Working days | Y5: 11
A6: 2 | B6: Areeba | C6: Muhammad Arif | D6: Four | E6: P | F6: A | G6: P | I6: P | K6: A | L6: P | M6: L | N6: A | Q6: P | R6: P | S6: P | U6: P | V6: =COUNTIF(E6:U6,"P") -> 8 | W6: =COUNTIF(E6:U6,"A") -> 3 | X6: Sunday | Y6: 4
A7: 3 | B7: Bakhtawar | C7: Taj Muhammad | D7: Four | E7: A | F7: A | G7: P | I7: A | K7: A | L7: A | M7: A | N7: P | Q7: A | R7: A | S7: P | U7: A | V7: =COUNTIF(E7:U7,"P") -> 3 | W7: =COUNTIF(E7:U7,"A") -> 9 | X7: Summer Vications | Y7: 12
A8: 4 | B8: Bibi Zehra | C8: Liaqat Ali | D8: Four | E8: P | F8: A | G8: A | I8: P | K8: A | L8: P | M8: P | N8: P | Q8: A | R8: A | S8: P | U8: A | V8: =COUNTIF(E8:U8,"P") -> 6 | W8: =COUNTIF(E8:U8,"A") -> 6 | X8: URS | Y8: 1
A9: 5 | B9: Bushra | C9: Rana | D9: Four | E9: A | F9: P | G9: P | I9: P | K9: P | L9: P | M9: A | N9: P | Q9: A | R9: A | S9: P | U9: P | V9: =COUNTIF(E9:U9,"P") -> 8 | W9: =COUNTIF(E9:U9,"A") -> 4 | X9: Mango Day | Y9: 1
A10: 6 | B10: Dua Soomro | C10: Muhammad Shafeeque | D10: Four | E10: A | F10: P | G10: P | I10: P | K10: P | L10: P | M10: P | N10: P | Q10: A | R10: A | S10: A | U10: . | V10: =COUNTIF(E10:U10,"P") -> 7 | W10: =COUNTIF(E10:U10,"A") -> 4 | X10: Chehlum | Y10: 1
A11: 7 | B11: Fatima Gul | C11: Shahnawaz Khan | D11: Four | E11: A | F11: P | G11: P | I11: A | K11: A | L11: A | M11: A | N11: P | Q11: P | R11: A | S11: P | U11: P | V11: =COUNTIF(E11:U11,"P") -> 6 | W11: =COUNTIF(E11:U11,"A") -> 6 | X11: OFF Due to Heavy Rain | Y11: 1
A12: 8 | B12: Ghulam Sakina | C12: Rafeeq Ahmed | D12: Four | E12: P | F12: P | G12: P | I12: P | K12: A | L12: P | M12: P | N12: A | Q12: P | R12: A | S12: A | U12: A | V12: =COUNTIF(E12:U12,"P") -> 7 | W12: =COUNTIF(E12:U12,"A") -> 5
A13: 9 | B13: Gul Sanober | C13: Sabir Hussain | D13: Four | E13: A | F13: A | G13: A | I13: A | K13: A | L13: A | M13: A | N13: A | Q13: A | R13: A | S13: A | U13: A | V13: =COUNTIF(E13:U13,"P") -> 0 | W13: =COUNTIF(E13:U13,"A") -> 12 | X13: Present Days Detail
A14: 10 | B14: Hiba Bhutto | C14: Muhammad Azeem | D14: Four | E14: P | F14: P | G14: P | I14: P | K14: P | L14: P | M14: P | N14: A | Q14: A | R14: P | S14: P | U14: A | V14: =COUNTIF(E14:U14,"P") -> 9 | W14: =COUNTIF(E14:U14,"A") -> 3 | X14: Detail | Y14: Boys | Z14: Girls | AA14: Total
A15: 11 | B15: Isha | C15: Fazal Muhammad | D15: Four | E15: P | F15: P | G15: P | I15: P | K15: P | L15: P | M15: P | N15: A | Q15: P | R15: P | S15: P | U15: A | V15: =COUNTIF(E15:U15,"P") -> 10 | W15: =COUNTIF(E15:U15,"A") -> 2 | X15: Due Present days | Y15: =17*11 -> 187 | Z15: =31*11 -> 341 | AA15: =SUM(Y15:Z15) -> 528
A16: 12 | B16: Khadija tul Qubra | C16: Adnan Jameel | D16: Four | E16: A | F16: P | G16: P | I16: P | K16: A | L16: P | M16: A | N16: P | Q16: P | R16: A | S16: P | U16: A | V16: =COUNTIF(E16:U16,"P") -> 7 | W16: =COUNTIF(E16:U16,"A") -> 5 | X16: Actual present days | Y16: =SUM(V36:V52) -> 141 | Z16: =SUM(V5:V31) -> 175 | AA16: =Y16+Z16 -> 316
A17: 13 | B17: Khushboo Fatima | C17: Abdul Rehman | D17: Four | E17: A | F17: P | G17: P | I17: P | K17: P | L17: P | M17: P | N17: P | Q17: A | R17: A | S17: P | U17: A | V17: =COUNTIF(E17:U17,"P") -> 8 | W17: =COUNTIF(E17:U17,"A") -> 4 | X17: % | Y17: =Y16/Y15 -> 0.7540107 | Z17: =Z16/Z15 -> 0.51319648 | AA17: =AA16/AA15 -> 0.59848485
A18: 14 | B18: Laraib | C18: Zulfiqar Ali | D18: Four | E18: A | F18: A | G18: A | I18: P | K18: P | L18: P | M18: P | N18: P | Q18: P | R18: A | S18: P | U18: A | V18: =COUNTIF(E18:U18,"P") -> 7 | W18: =COUNTIF(E18:U18,"A") -> 5
A19: 15 | B19: Maheen | C19: Sohail Ahmed | D19: Four | E19: A | F19: P | G19: A | I19: P | K19: P | L19: P | M19: P | N19: A | Q19: P | R19: A | S19: P | U19: A | V19: =COUNTIF(E19:U19,"P") -> 7 | W19: =COUNTIF(E19:U19,"A") -> 5
A20: 16 | B20: Maryam | C20: Mehboob Ali | D20: Four | E20: A | F20: P | G20: P | I20: P | K20: P | L20: P | M20: P | N20: P | Q20: A | R20: A | S20: P | U20: A | V20: =COUNTIF(E20:U20,"P") -> 8 | W20: =COUNTIF(E20:U20,"A") -> 4
A21: 17 | B21: Minal Ali | C21: Faraz Hyder | D21: Four | E21: P | F21: A | G21: P | I21: P | K21: A | L21: P | M21: P | N21: P | Q21: P | R21: A | S21: A | U21: A | V21: =COUNTIF(E21:U21,"P") -> 7 | W21: =COUNTIF(E21:U21,"A") -> 5 | X21: Absent Days Details
A22: 18 | B22: Misbah | C22: Faiz Muhammad | D22: Four | E22: P | F22: P | G22: A | I22: P | K22: A | L22: P | M22: P | N22: P | Q22: P | R22: A | S22: P | U22: A | V22: =COUNTIF(E22:U22,"P") -> 8 | W22: =COUNTIF(E22:U22,"A") -> 4 | X22: Detail | Y22: Boys | Z22: Girls | AA22: Total
A23: 19 | B23: Muntasha | C23: Ghulam Murtaza | D23: Four | E23: A | F23: A | G23: A | I23: A | K23: A | L23: A | M23: A | N23: A | Q23: P | R23: A | S23: A | U23: A | V23: =COUNTIF(E23:U23,"P") -> 1 | W23: =COUNTIF(E23:U23,"A") -> 11 | X23: Due Present days | Y23: =17*11 -> 187 | Z23: =31*11 -> 341 | AA23: =Y23+Z23 -> 528
A24: 20 | B24: Nimra | C24: Muhammad Ghaffar Jokhio | D24: Four | E24: A | F24: A | G24: P | I24: A | K24: P | L24: P | M24: P | N24: P | Q24: A | R24: A | S24: P | U24: A | V24: =COUNTIF(E24:U24,"P") -> 6 | W24: =COUNTIF(E24:U24,"A") -> 6 | X24: Absent days | Y24: =Y23-Y16 -> 46 | Z24: =Z23-Z16 -> 166 | AA24: =Y24+Z24 -> 212
A25: 21 | B25: Nisha | C25: Meraal | D25: Four | E25: A | F25: P | G25: A | I25: P | K25: P | L25: P | M25: P | N25: A | Q25: A | R25: A | S25: P | U25: A | V25: =COUNTIF(E25:U25,"P") -> 6 | W25: =COUNTIF(E25:U25,"A") -> 6 | X25: % | Y25: =Y24/Y23 -> 0.2459893 | Z25: =Z24/Z23 -> 0.48680352 | AA25: =AA24/AA23 -> 0.40151515
A26: 22 | B26: Noor Nisa | C26: Amjad Ali | D26: Four | E26: A | F26: A | G26: A | I26: A | K26: A | L26: A | M26: A | N26: A | Q26: A | R26: A | S26: A | U26: A | V26: =COUNTIF(E26:U26,"P") -> 0 | W26: =COUNTIF(E26:U26,"A") -> 12
A27: 23 | B27: Nuzahat | C27: Khalid Hussain Abbasi | D27: Four | E27: A | F27: P | G27: P | I27: P | K27: A | L27: A | M27: P | N27: P | Q27: P | R27: A | S27: A | U27: A | V27: =COUNTIF(E27:U27,"P") -> 6 | W27: =COUNTIF(E27:U27,"A") -> 6
A28: 24 | B28: Rooba | C28: Lakhmir Khan | D28: Four | E28: A | F28: P | G28: P | I28: P | K28: P | L28: P | M28: A | N28: A | Q28: P | R28: A | S28: A | U28: A | V28: =COUNTIF(E28:U28,"P") -> 6 | W28: =COUNTIF(E28:U28,"A") -> 6
