Workbook

Sheet Compile Sheet-September-2024
A4: Class | B4: Total Enrolment & Attendance Septemebr-24
B5: Boys | C5: Girls | D5: Total | E5: total working Days | F5: Total working days-Boys | G5: Total working days-Girls | H5: Total working days-All | I5: P-Days Boys | J5: P-Days Girls | K5: P-Days All | L5: Percentage-Girls | M5: Percentage-Boys | N5: Percentage-Boys | O5: Total average
A6: ECE (ROSE) | B6: 26 | C6: 23 | D6: =SUM(B6:C6) -> 49 | E6: 24 | F6: =B6*E6 -> 624 | G6: =C6*E6 -> 552 | H6: =SUM(F6:G6) -> 1176 | I6: ='ECE (ROSE)'!AL12 -> 444 | J6: ='ECE (ROSE)'!AM12 -> 447 | K6: =SUM(I6:J6) -> 891 | L6: =J6/G6 -> 0.80978261 | M6: =I6/F6 -> 0.71153846 | N6: =K6/H6 -> 0.75765306 | O6: =AVERAGE(L6:M6) -> 0.76066054
A7: ECE (Daffodils) | B7: 32 | C7: 24 | D7: =SUM(B7:C7) -> 56 | E7: 24 | F7: =B7*E7 -> 768 | G7: =C7*E7 -> 576 | H7: =SUM(F7:G7) -> 1344 | I7: ='ECE (Daffodils)'!AL12 -> 678 | J7: ='ECE (Daffodils)'!AM12 -> 518 | K7: =SUM(I7:J7) -> 1196 | L7: =J7/G7 -> 0.89930556 | M7: =I7/F7 -> 0.8828125 | N7: =K7/H7 -> 0.88988095 | O7: =AVERAGE(L7:M7) -> 0.89105903
A8: One | B8: 32 | C8: 24 | D8: =SUM(B8:C8) -> 56 | E8: 24 | F8: =B8*E8 -> 768 | G8: =C8*E8 -> 576 | H8: =SUM(F8:G8) -> 1344 | I8: ='Class-I'!AL12 -> 683 | J8: ='Class-I'!AM12 -> 476 | K8: =SUM(I8:J8) -> 1159 | L8: =J8/G8 -> 0.82638889 | M8: =I8/F8 -> 0.88932292 | N8: =K8/H8 -> 0.86235119 | O8: =AVERAGE(L8:M8) -> 0.8578559
A9: Two | B9: 25 | C9: 26 | D9: =SUM(B9:C9) -> 51 | E9: 24 | F9: =B9*E9 -> 600 | G9: =C9*E9 -> 624 | H9: =SUM(F9:G9) -> 1224 | I9: ='Class-II'!AL12 -> 515 | J9: ='Class-II'!AM12 -> 508 | K9: =SUM(I9:J9) -> 1023 | L9: =J9/G9 -> 0.81410256 | M9: =I9/F9 -> 0.85833333 | N9: =K9/H9 -> 0.83578431 | O9: =AVERAGE(L9:M9) -> 0.83621795
A10: Three | B10: 29 | C10: 26 | D10: =SUM(B10:C10) -> 55 | E10: 24 | F10: =B10*E10 -> 696 | G10: =C10*E10 -> 624 | H10: =SUM(F10:G10) -> 1320 | I10: ='Class-III'!AL12 -> 541 | J10: ='Class-III'!AM12 -> 476 | K10: =SUM(I10:J10) -> 1017 | L10: =J10/G10 -> 0.76282051 | M10: =I10/F10 -> 0.77729885 | N10: =K10/H10 -> 0.77045455 | O10: =AVERAGE(L10:M10) -> 0.77005968
A11: Four | B11: 21 | C11: 32 | D11: =SUM(B11:C11) -> 53 | E11: 24 | F11: =B11*E11 -> 504 | G11: =C11*E11 -> 768 | H11: =SUM(F11:G11) -> 1272 | I11: ='Class-IV'!AL13 -> 362 | J11: ='Class-IV'!AM13 -> 579 | K11: =SUM(I11:J11) -> 941 | L11: =J11/G11 -> 0.75390625 | M11: =I11/F11 -> 0.71825397 | N11: =K11/H11 -> 0.73977987 | O11: =AVERAGE(L11:M11) -> 0.73608011
A12: Five | B12: 23 | C12: 23 | D12: =SUM(B12:C12) -> 46 | E12: 24 | F12: =B12*E12 -> 552 | G12: =C12*E12 -> 552 | H12: =SUM(F12:G12) -> 1104 | I12: ='Class-V'!AL13 -> 429 | J12: ='Class-V'!AM13 -> 465 | K12: =SUM(I12:J12) -> 894 | L12: =J12/G12 -> 0.8423913 | M12: =I12/F12 -> 0.77717391 | N12: =K12/H12 -> 0.80978261 | O12: =AVERAGE(L12:M12) -> 0.80978261
A13: Six | B13: 17 | C13: 28 | D13: =SUM(B13:C13) -> 45 | E13: 24 | F13: =B13*E13 -> 408 | G13: =C13*E13 -> 672 | H13: =SUM(F13:G13) -> 1080 | I13: ='Class-VI'!AL13 -> 336 | J13: ='Class-VI'!AM13 -> 539 | K13: =SUM(I13:J13) -> 875 | L13: =J13/G13 -> 0.80208333 | M13: =I13/F13 -> 0.82352941 | N13: =K13/H13 -> 0.81018519 | O13: =AVERAGE(L13:M13) -> 0.81280637
A14: Seven | B14: 30 | C14: 17 | D14: =SUM(B14:C14) -> 47 | E14: 24 | F14: =B14*E14 -> 720 | G14: =C14*E14 -> 408 | H14: =SUM(F14:G14) -> 1128 | I14: ='Class-VII'!AK13 -> 541 | J14: ='Class-VII'!AL13 -> 327 | K14: =SUM(I14:J14) -> 868 | L14: =J14/G14 -> 0.80147059 | M14: =I14/F14 -> 0.75138889 | N14: =K14/H14 -> 0.76950355 | O14: =AVERAGE(L14:M14) -> 0.77642974
A15: Eight | B15: 20 | C15: 24 | D15: =SUM(B15:C15) -> 44 | E15: 24 | F15: =B15*E15 -> 480 | G15: =C15*E15 -> 576 | H15: =SUM(F15:G15) -> 1056 | I15: ='Class-VIII'!AL12 -> 353 | J15: ='Class-VIII'!AM12 -> 520 | K15: =SUM(I15:J15) -> 873 | L15: =J15/G15 -> 0.90277778 | M15: =I15/F15 -> 0.73541667 | N15: =K15/H15 -> 0.82670455 | O15: =AVERAGE(L15:M15) -> 0.81909722
A16: Ninth | B16: 17 | C16: 22 | D16: =SUM(B16:C16) -> 39 | E16: 24 | F16: =B16*E16 -> 408 | G16: =C16*E16 -> 528 | H16: =SUM(F16:G16) -> 936 | I16: ='Class-IX'!AL12 -> 322 | J16: ='Class-IX'!AM12 -> 351 | K16: ='[1]Class-IX'!AO12 -> 778 | L16: =J16/G16 -> 0.66477273 | M16: =I16/F16 -> 0.78921569 | N16: =K16/H16 -> 0.83119658 | O16: =AVERAGE(L16:M16) -> 0.72699421
A17: Total | B17: =SUM(B6:B16) -> 272 | C17: =SUM(C6:C16) -> 269 | D17: =SUM(D6:D16) -> 541 | E17: =SUM(E6:E16) -> 264 | F17: =SUM(F6:F16) -> 6528 | G17: =SUM(G6:G16) -> 6456 | H17: =SUM(H6:H16) -> 12984 | I17: =SUM(I6:I16) -> 5204 | ... K17: =SUM(K6:K16) -> 10515 | L17: =J17/G17 -> 0.80638166 | M17: =I17/F17 -> 0.79718137 | N17: =AVERAGE(N6:N16) -> 0.80938876 | O17: =AVERAGE(O6:O16) -> 0.79973121
A18: % | B18: 1 | C18: 1 | D18: 1 | E18: 1 | F18: 1 | G18: 1 | H18: 1 | I18: =I17/F17 -> 0.79718137 | J18: =J17/G17 -> 0.80638166 | K18: =K17/H17 -> 0.80984288 | L18: 0.54 | M18: 0.56 | N18: 0.55 | O18: =AVERAGE(L17:M17) -> 0.80178152

Sheet ECE (ROSE)
A1: Goverment high school (SJCHS)
A2: Monthly Attendence Month of September-2024
A3: S.No | B3: Student Name | C3: Father Name | D3: Class | E3: =TEXT(E4,"ddd") -> Sun | F3: =TEXT(F4,"ddd") -> Mon | G3: =TEXT(G4,"ddd") -> Tue | H3: =TEXT(H4,"ddd") -> Wed | I3: =TEXT(I4,"ddd") -> Thu | J3: =TEXT(J4,"ddd") -> Fri | K3: =TEXT(K4,"ddd") -> Sat | L3: =TEXT(L4,"ddd") -> Sun | ... AH3: =TEXT(AH4,"ddd") -> Mon | AI3: Present | AJ3: Absent | AK3: Year 2024
E4: 45536 | F4: 45537 | G4: 45538 | H4: 45539 | I4: 45540 | J4: 45541 | K4: 45542 | L4: 45543 | M4: 45544 | N4: 45545 | O4: 45546 | P4: 45547 | Q4: 45548 | R4: 45549 | S4: 45550 | T4: 45551 | U4: 45552 | V4: 45553 | W4: 45554 | X4: 45555 | Y4: 45556 | Z4: 45557 | AA4: 45558 | AB4: 45559 | AC4: 45560 | AD4: 45561 | AE4: 45562 | AF4: 45563 | AG4: 45564 | AH4: 45565 | AK4: Total days | AL4: =SUM(AL5:AL7) -> 30
A5: 1 | B5: Eman | C5: Shahnawaz Khan | D5: ECE | E5: SUNDAY - SUNDAY - SUNDAY - SUNDAY - SUNDAY | F5: A | G5: A | H5: P | I5: P | J5: P | K5: P | L5: SUNDAY - SUNDAY - SUNDAY - SUNDAY - SUNDAY | M5: P | N5: P | O5: P | P5: P | Q5: A | R5: A | S5: SUNDAY - SUNDAY - SUNDAY - SUNDAY - SUNDAY | T5: A | U5: 12 RABI UL AWWAL - 12 RABI UL AWWAL | V5: P | W5: P | X5: P | Y5: A | Z5: SUNDAY - SUNDAY - SUNDAY - SUNDAY - SUNDAY | AA5: P | AB5: P | AC5: P | AD5: P | AE5: P | AF5: P | AG5: SUNDAY - SUNDAY - SUNDAY - SUNDAY - SUNDAY | AH5: P | AI5: =COUNTIF(E5:AH5,"P") -> 18 | AJ5: =COUNTIF(E5:AH5,"A") -> 6 | AK5: Working days | AL5: 24
A6: 2 | B6: Rehan Ali | C6: Abdul Rehman | D6: ECE | F6: P | G6: P | H6: P | I6: P | J6: P | K6: P | M6: P | N6: P | O6: P | P6: P | Q6: P | R6: P | T6: A | V6: P | W6: P | X6: P | Y6: P | AA6: P | AB6: P | AC6: P | AD6: P | AE6: A | AF6: P | AH6: P | AI6: =COUNTIF(E6:AH6,"P") -> 22 | AJ6: =COUNTIF(E6:AH6,"A") -> 2 | AK6: Sunday | AL6: 5
A7: 3 | B7: Dilkash | C7: Faraz Hussain | D7: ECE | F7: P | G7: P | H7: P | I7: P | J7: A | K7: A | M7: P | N7: P | O7: A | P7: P | Q7: A | R7: A | T7: P | V7: P | W7: P | X7: P | Y7: A | AA7: P | AB7: P | AC7: P | AD7: P | AE7: P | AF7: P | AH7: P | AI7: =COUNTIF(E7:AH7,"P") -> 18 | AJ7: =COUNTIF(E7:AH7,"A") -> 6 | AK7: 12 Rabi Ul Awwal | AL7: 1
A8: 4 | B8: Masooma | C8: Faiq Ali | D8: ECE | F8: P | G8: P | H8: P | I8: P | J8: A | K8: P | M8: P | N8: A | O8: P | P8: A | Q8: P | R8: P | T8: P | V8: P | W8: P | X8: P | Y8: P | AA8: P | AB8: P | AC8: A | AD8: P | AE8: P | AF8: A | AH8: P | AI8: =COUNTIF(E8:AH8,"P") -> 19 | AJ8: =COUNTIF(E8:AH8,"A") -> 5
A9: 5 | B9: Ali | C9: Saddam Hussain | D9: ECE | F9: P | G9: A | H9: P | I9: P | J9: A | K9: A | M9: P | N9: P | O9: P | P9: P | Q9: P | R9: P | T9: P | V9: P | W9: P | X9: P | Y9: A | AA9: P | AB9: P | AC9: A | AD9: P | AE9: P | AF9: A | AH9: A | AI9: =COUNTIF(E9:AH9,"P") -> 17 | AJ9: =COUNTIF(E9:AH9,"A") -> 7 | AK9: Present Days Detail
A10: 6 | B10: Hafsa Batool | C10: Gul Mohammad Chandio | D10: ECE | F10: A | G10: P | H10: P | I10: P | J10: P | K10: P | M10: P | N10: A | O10: P | P10: P | Q10: P | R10: P | T10: A | V10: A | W10: A | X10: A | Y10: A | AA10: P | AB10: A | AC10: A | AD10: P | AE10: P | AF10: A | AH10: P | AI10: =COUNTIF(E10:AH10,"P") -> 14 | AJ10: =COUNTIF(E10:AH10,"A") -> 10 | AK10: Detail | AL10: Boys | AM10: Girls | AN10: Total
A11: 7 | B11: Mohammad Aliyan | C11: Shabir Ahmed Bhutto | D11: ECE | F11: P | G11: P | H11: A | I11: P | J11: P | K11: A | M11: P | N11: P | O11: P | P11: P | Q11: A | R11: A | T11: A | V11: P | W11: P | X11: P | Y11: A | AA11: P | AB11: P | AC11: P | AD11: P | AE11: P | AF11: A | AH11: P | AI11: =COUNTIF(E11:AH11,"P") -> 17 | AJ11: =COUNTIF(E11:AH11,"A") -> 7 | AK11: Due Present days | AL11: =26*AL5 -> 624 | AM11: =23*AL5 -> 552 | AN11: =SUM(AL11:AM11) -> 1176
A12: 8 | B12: Hoor Fatima | C12: Shahid Ali | D12: ECE | F12: P | G12: P | H12: P | I12: P | J12: P | K12: P | M12: P | N12: P | O12: P | P12: P | Q12: P | R12: P | T12: P | V12: P | W12: P | X12: P | Y12: A | AA12: P | AB12: P | AC12: A | AD12: P | AE12: P | AF12: P | AH12: P | AI12: =COUNTIF(E12:AH12,"P") -> 22 | AJ12: =COUNTIF(E12:AH12,"A") -> 2 | AK12: Actual present days | AL12: =SUM(AI6,AI9,AI11,AI13,AI15,AI16,AI21,AI22,AI23,AI24,AI25,AI26,AI27,AI32,AI34,AI36,AI40,AI41,AI43,AI44,AI45,AI50,AI51,AI52,AI53) -> 444 | AM12: =SUM(AI5,AI8,AI10,AI12,AI14,AI15,AI17,AI18,AI19,AI20,AI28,AI29,AI30,AI31,AI33,AI35,AI37,AI38,AI39,AI42,AI47,AI48,AI49) -> 447 | AN12: =AL12+AM12 -> 891
A13: 9 | B13: Muhammad Sahil | C13: Irshad Ali | D13: ECE | F13: P | G13: P | H13: P | I13: P | J13: P | K13: P | M13: P | N13: P | O13: P | P13: P | Q13: P | R13: P | T13: P | V13: P | W13: P | X13: P | Y13: P | AA13: P | AB13: P | AC13: P | AD13: P | AE13: P | AF13: P | AH13: P | AI13: =COUNTIF(E13:AH13,"P") -> 24 | AJ13: =COUNTIF(E13:AH13,"A") -> 0 | AK13: % | AL13: =AL12/AL11 -> 0.71153846 | AM13: =AM12/AM11 -> 0.80978261 | AN13: =AN12/AN11 -> 0.75765306
A14: 10 | B14: Kinza | C14: Aijaz Ali | D14: ECE | F14: P | G14: P | H14: P | I14: P | J14: P | K14: P | M14: P | N14: P | O14: P | P14: P | Q14: P | R14: P | T14: P | V14: P | W14: P | X14: P | Y14: P | AA14: P | AB14: P | AC14: P | AD14: P | AE14: P | AF14: P | AH14: P | AI14: =COUNTIF(E14:AH14,"P") -> 24 | AJ14: =COUNTIF(E14:AH14,"A") -> 0
A15: 11 | B15: Zaryab Sultan | C15: Muhammad Zaman | D15: ECE | F15: P | G15: P | H15: P | I15: P | J15: P | K15: A | M15: A | N15: A | O15: A | P15: A | Q15: A | R15: A | T15: P | V15: A | W15: A | X15: P | Y15: P | AA15: P | AB15: P | AC15: P | AD15: P | AE15: P | AF15: P | AH15: P | AI15: =COUNTIF(E15:AH15,"P") -> 15 | AJ15: =COUNTIF(E15:AH15,"A") -> 9
A16: 12 | B16: M. Ibrahim | C16: Fayaz Ali Ansari | D16: ECE | F16: P | G16: P | H16: A | I16: P | J16: P | K16: P | M16: P | N16: P | O16: P | P16: P | Q16: A | R16: P | T16: P | V16: P | W16: P | X16: P | Y16: P | AA16: P | AB16: P | AC16: P | AD16: P | AE16: P | AF16: P | AH16: P | AI16: =COUNTIF(E16:AH16,"P") -> 22 | AJ16: =COUNTIF(E16:AH16,"A") -> 2
A17: 13 | B17: Fatima Ansari | C17: Ayaz Ali Ansari | D17: ECE | F17: P | G17: P | H17: P | I17: P | J17: A | K17: P | M17: P | N17: P | O17: P | P17: P | Q17: A | R17: P | T17: P | V17: P | W17: P | X17: P | Y17: A | AA17: P | AB17: P | AC17: P | AD17: P | AE17: P | AF17: P | AH17: P | AI17: =COUNTIF(E17:AH17,"P") -> 21 | AJ17: =COUNTIF(E17:AH17,"A") -> 3 | AK17: Absent Days Details
A18: 14 | B18: Zil-e-Huma | C18: Abdul Qayoom | D18: ECE | F18: P | G18: P | H18: P | I18: P | J18: P | K18: A | M18: P | N18: P | O18: P | P18: P | Q18: P | R18: P | T18: A | V18: A | W18: P | X18: A | Y18: P | AA18: P | AB18: P | AC18: P | AD18: P | AE18: P | AF18: P | AH18: A | AI18: =COUNTIF(E18:AH18,"P") -> 19 | AJ18: =COUNTIF(E18:AH18,"A") -> 5 | AK18: Detail | AL18: Boys | AM18: Girls | AN18: Total
A19: 15 | B19: Ayat Fatima | C19: Imran Hussain | D19: ECE | F19: P | G19: P | H19: P | I19: P | J19: A | K19: A | M19: L | N19: L | O19: A | P19: A | Q19: A | R19: P | T19: P | V19: P | W19: P | X19: P | Y19: P | AA19: P | AB19: P | AC19: P | AD19: P | AE19: P | AF19: P | AH19: P | AI19: =COUNTIF(E19:AH19,"P") -> 17 | AJ19: =COUNTIF(E19:AH19,"A") -> 5 | AK19: Due Present days | AL19: =26*AL5 -> 624 | AM19: =23*AL5 -> 552 | AN19: =AL19+AM19 -> 1176
A20: 16 | B20: Aqsa | C20: Ahsan Ali | D20: ECE | F20: P | G20: P | H20: P | I20: A | J20: A | K20: P | M20: P | N20: P | O20: P | P20: P | Q20: P | R20: P | T20: P | V20: P | W20: P | X20: P | Y20: P | AA20: A | AB20: P | AC20: P | AD20: P | AE20: P | AF20: P | AH20: P | AI20: =COUNTIF(E20:AH20,"P") -> 21 | AJ20: =COUNTIF(E20:AH20,"A") -> 3 | AK20: Absent days | AL20: =AL19-AL12 -> 180 | AM20: =AM19-AM12 -> 105 | AN20: =AL20+AM20 -> 285
A21: 17 | B21: Muhammad Fawad | C21: Waseem Ahmed Channa | D21: ECE | F21: P | G21: P | H21: P | I21: P | J21: P | K21: A | M21: P | N21: P | O21: P | P21: P | Q21: P | R21: P | T21: P | V21: P | W21: P | X21: P | Y21: P | AA21: P | AB21: P | AC21: P | AD21: P | AE21: P | AF21: P | AH21: P | AI21: =COUNTIF(E21:AH21,"P") -> 23 | AJ21: =COUNTIF(E21:AH21,"A") -> 1 | AK21: % | AL21: =AL20/AL19 -> 0.28846154 | AM21: =AM20/AM19 -> 0.19021739 | AN21: =AN20/AN19 -> 0.24234694
A22: 18 | B22: Muhammad Haris | C22: M. Shareef Niyazi | D22: ECE | F22: P | G22: P | H22: P | I22: P | J22: P | K22: P | M22: P | N22: P | O22: P | P22: P | Q22: P | R22: P | T22: P | V22: A | W22: A | X22: A | Y22: A | AA22: P | AB22: P | AC22: P | AD22: P | AE22: P | AF22: P | AH22: P | AI22: =COUNTIF(E22:AH22,"P") -> 20 | AJ22: =COUNTIF(E22:AH22,"A") -> 4
A23: 19 | B23: Muhammad Ayan | C23: Abdul Ghaffar | D23: ECE | F23: P | G23: P | H23: A | I23: P | J23: A | K23: A | M23: P | N23: P | O23: P | P23: P | Q23: P | R23: P | T23: P | V23: P | W23: P | X23: P | Y23: P | AA23: P | AB23: P | AC23: P | AD23: P | AE23: P | AF23: P | AH23: P | AI23: =COUNTIF(E23:AH23,"P") -> 21 | AJ23: =COUNTIF(E23:AH23,"A") -> 3
A24: 20 | B24: Danish | C24: Ayaz Ali | D24: ECE | F24: P | G24: P | H24: P | I24: P | J24: P | K24: P | M24: P | N24: P | O24: P | P24: P | Q24: P | R24: P | T24: P | V24: P | W24: P | X24: P | Y24: P | AA24: P | AB24: P | AC24: P | AD24: P | AE24: P | AF24: P | AH24: P | AI24: =COUNTIF(E24:AH24,"P") -> 24 | AJ24: =COUNTIF(E24:AH24,"A") -> 0
A25: 21 | B25: Mujahid Ali | C25: Sajjad Ali | D25: ECE | F25: P | G25: P | H25: P | I25: A | J25: A | K25: P | M25: P | N25: P | O25: P | P25: P | Q25: P | R25: P | T25: P | V25: P | W25: P | X25: P | Y25: P | AA25: P | AB25: P | AC25: P | AD25: P | AE25: P | AF25: P | AH25: P | AI25: =COUNTIF(E25:AH25,"P") -> 22 | AJ25: =COUNTIF(E25:AH25,"A") -> 2
A26: 22 | B26: Zawar Ali | C26: Kamran Ali | D26: ECE | F26: P | G26: A | H26: P | I26: P | J26: A | K26: P | M26: P | N26: P | O26: P | P26: P | Q26: P | R26: P | T26: A | V26: P | W26: P | X26: P | Y26: P | AA26: P | AB26: P | AC26: P | AD26: P | AE26: P | AF26: P | AH26: P | AI26: =COUNTIF(E26:AH26,"P") -> 21 | AJ26: =COUNTIF(E26:AH26,"A") -> 3
A27: 23 | B27: Muhammad Rayyan | C27: Ghulam Murtaza | D27: ECE | F27: A | G27: A | H27: A | I27: A | J27: A | K27: A | M27: A | N27: A | O27: A | P27: A | Q27: A | R27: A | T27: A | V27: A | W27: A | X27: A | Y27: A | AA27: A | AB27: P | AC27: A | AD27: P | AE27: P | AF27: P | AH27: P | AI27: =COUNTIF(E27:AH27,"P") -> 5 | AJ27: =COUNTIF(E27:AH27,"A") -> 19
A28: 24 | B28: Safa | C28: Dil Murad | D28: ECE | F28: P | G28: P | H28: P | I28: P | J28: P | K28: A | M28: P | N28: P | O28: P | P28: P | Q28: P | R28: P | T28: P | V28: P | W28: P | X28: P | Y28: P | AA28: P | AB28: P | AC28: P | AD28: P | AE28: P | AF28: P | AH28: P | AI28: =COUNTIF(E28:AH28,"P") -> 23 | AJ28: =COUNTIF(E28:AH28,"A") -> 1
A29: 25 | B29: Hifza | C29: Zakir Ali | D29: ECE | F29: P | G29: A | H29: A | I29: P | J29: A | K29: P | M29: P | N29: P | O29: P | P29: P | Q29: P | R29: P | T29: P | V29: P | W29: P | X29: A | Y29: P | AA29: P | AB29: P | AC29: P | AD29: P | AE29: P | AF29: P | AH29: P | AI29: =COUNTIF(E29:AH29,"P") -> 20 | AJ29: =COUNTIF(E29:AH29,"A") -> 4
A30: 26 | B30: Zameeran | C30: Babar Ali | D30: ECE | F30: P | G30: P | H30: P | I30: P | J30: P | K30: P | M30: P | N30: P | O30: P | P30: P | Q30: P | R30: P | T30: P | V30: P | W30: P | X30: P | Y30: A | AA30: A | AB30: A | AC30: P | AD30: P | AE30: P | AF30: P | AH30: P | AI30: =COUNTIF(E30:AH30,"P") -> 21 | AJ30: =COUNTIF(E30:AH30,"A") -> 3
A31: 27 | B31: Parwisha | C31: Sarfaraz Ahmed | D31: ECE | F31: P | G31: P | H31: P | I31: P | J31: P | K31: P | M31: P | N31: P | O31: P | P31: P | Q31: P | R31: P | T31: P | V31: P | W31: P | X31: P | Y31: P | AA31: A | AB31: P | AC31: P | AD31: P | AE31: P | AF31: A | AH31: A | AI31: =COUNTIF(E31:AH31,"P") -> 21 | AJ31: =COUNTIF(E31:AH31,"A") -> 3
A32: 28 | B32: Muhammad Ahad | C32: Khalid Hussain Abbasi | D32: ECE | F32: P | G32: P | H32: P | I32: P | J32: A | K32: P | M32: P | N32: P | O32: P | P32: P | Q32: P | R32: P | T32: P | V32: P | W32: P | X32: A | Y32: P | AA32: P | AB32: P | AC32: P | AD32: A | AE32: P | AF32: P | AH32: P | AI32: =COUNTIF(E32:AH32,"P") -> 21 | AJ32: =COUNTIF(E32:AH32,"A") -> 3
A33: 29 | B33: Aiza | C33: Irshad-Ul-Haq | D33: ECE | F33: P | G33: P | H33: P | I33: P | J33: P | K33: P | M33: P | N33: P | O33: P | P33: P | Q33: P | R33: P | T33: P | V33: P | W33: P | X33: L | Y33: L | AA33: A | AB33: P | AC33: P | AD33: P | AE33: P | AF33: P | AH33: P | AI33: =COUNTIF(E33:AH33,"P") -> 21 | AJ33: =COUNTIF(E33:AH33,"A") -> 1
... A40: 36 | B40: M. Awais | C40: Mehboob Ali | D40: ECE | F40: P | G40: P | H40: A | I40: P | J40: A | K40: P | M40: P | N40: P | O40: P | P40: P | Q40: P | R40: P | T40: P | V40: P | W40: P | X40: P | Y40: P | AA40: A | AB40: A | AC40: A | AD40: P | AE40: P | AF40: P | AH40: P | AI40: =COUNTIF(E40:AH40,"P") -> 19 | AJ40: =COUNTIF(E40:AH40,"A") -> 5
A41: 37 | B41: M. Raheel | D41: ECE | F41: P | G41: P | H41: P | I41: P | J41: A | K41: P | M41: P | N41: P | O41: P | P41: P | Q41: P | R41: P | T41: P | V41: P | W41: P | X41: P | Y41: P | AA41: A | AB41: P | AC41: P | AD41: P | AE41: P | AF41: P | AH41: P | AI41: =COUNTIF(E41:AH41,"P") -> 22 | AJ41: =COUNTIF(E41:AH41,"A") -> 2
A42: 38 | B42: Fiza | C42: Ahmed | D42: ECE | F42: P | G42: P | H42: P | I42: P | J42: A | K42: P | M42: P | N42: P | O42: P | P42: P | Q42: P | R42: P | T42: P | V42: P | W42: P | X42: P | Y42: P | AA42: P | AB42: P | AC42: P | AD42: P | AE42: P | AF42: P | AH42: P | AI42: =COUNTIF(E42:AH42,"P") -> 23 | AJ42: =COUNTIF(E42:AH42,"A") -> 1
A43: 39 | B43: Amanullah | C43: Sajid Ahmed | D43: ECE | F43: P | G43: P | H43: P | I43: P | J43: A | K43: P | M43: P | N43: P | O43: P | P43: P | Q43: P | R43: P | T43: P | V43: P | W43: P | X43: P | Y43: P | AA43: P | AB43: P | AC43: P | AD43: A | AE43: P | AF43: P | AH43: P | AI43: =COUNTIF(E43:AH43,"P") -> 22 | AJ43: =COUNTIF(E43:AH43,"A") -> 2
A44: 40 | B44: Ahmed Ali | C44: Asghar Ali | D44: ECE | F44: P | G44: P | H44: P | I44: P | J44: A | K44: P | M44: P | N44: P | O44: P | P44: P | Q44: A | R44: P | T44: P | V44: P | W44: P | X44: P | Y44: P | AA44: P | AB44: P | AC44: P | AD44: P | AE44: P | AF44: P | AH44: P | AI44: =COUNTIF(E44:AH44,"P") -> 22 | AJ44: =COUNTIF(E44:AH44,"A") -> 2
A45: 41 | B45: M. Qasim | C45: Abdul Hameed | D45: ECE | F45: P | G45: A | H45: P | I45: P | J45: P | K45: P | M45: P | N45: P | O45: P | P45: P | Q45: P | R45: A | T45: P | V45: P | W45: P | X45: P | Y45: P | AA45: P | AB45: P | AC45: P | AD45: P | AE45: P | AF45: P | AH45: P | AI45: =COUNTIF(E45:AH45,"P") -> 22 | AJ45: =COUNTIF(E45:AH45,"A") -> 2
A46: 42 | B46: Shahbaz Ali | C46: Muhammad Ibrahim | D46: ECE | F46: P | G46: P | H46: P | I46: P | J46: A | K46: P | M46: P | N46: P | O46: P | P46: P | Q46: P | R46: P | T46: P | V46: P | W46: P | X46: P | Y46: P | AA46: P | AB46: P | AC46: P | AD46: P | AE46: P | AF46: P | AH46: P | AI46: =COUNTIF(E46:AH46,"P") -> 23 | AJ46: =COUNTIF(E46:AH46,"A") -> 1
...

Sheet ECE (Daffodils)
A1: Goverment high school (SJCHS)
A2: Monthly Attendence Month of September-2024
A3: S.No | B3: Student Name | C3: Father Name | D3: Class | E3: =TEXT(E4,"ddd") -> Sun | F3: =TEXT(F4,"ddd") -> Mon | G3: =TEXT(G4,"ddd") -> Tue | H3: =TEXT(H4,"ddd") -> Wed | I3: =TEXT(I4,"ddd") -> Thu | J3: =TEXT(J4,"ddd") -> Fri | K3: =TEXT(K4,"ddd") -> Sat | L3: =TEXT(L4,"ddd") -> Sun | ... AH3: =TEXT(AH4,"ddd") -> Mon | AI3: Present | AJ3: Absent | AK3: Year 2024
E4: 45536 | F4: 45537 | G4: 45538 | H4: 45539 | I4: 45540 | J4: 45541 | K4: 45542 | L4: 45543 | M4: 45544 | N4: 45545 | O4: 45546 | P4: 45547 | Q4: 45548 | R4: 45549 | S4: 45550 | T4: 45551 | U4: 45552 | V4: 45553 | W4: 45554 | X4: 45555 | Y4: 45556 | Z4: 45557 | AA4: 45558 | AB4: 45559 | AC4: 45560 | AD4: 45561 | AE4: 45562 | AF4: 45563 | AG4: 45564 | AH4: 45565 | AK4: Total days | AL4: =SUM(AL5:AL7) -> 30
A5: 1 | B5: Alishba Batool | C5: Irfan Ali | D5: ECE | E5: SUNDAY - SUNDAY - SUNDAY - SUNDAY - SUNDAY - SUNDAY | F5: P | G5: P | H5: P | I5: P | J5: P | K5: P | L5: SUNDAY - SUNDAY - SUNDAY - SUNDAY - SUNDAY - SUNDAY | M5: P | N5: P | O5: P | P5: P | Q5: P | R5: P | S5: SUNDAY - SUNDAY - SUNDAY - SUNDAY - SUNDAY - SUNDAY | T5: A | U5: 12 RABI UL AWWAL - 12 RABI UL AWWAL - 12 RABI UL AWWAL | V5: P | W5: P | X5: P | Y5: P | Z5: SUNDAY - SUNDAY - SUNDAY - SUNDAY - SUNDAY - SUNDAY | AA5: P | AB5: P | AC5: P | AD5: P | AE5: P | AF5: P | AG5: SUNDAY - SUNDAY - SUNDAY - SUNDAY - SUNDAY - SUNDAY | AH5: P | AI5: =COUNTIF(E5:AH5,"P") -> 23 | AJ5: =COUNTIF(E5:AH5,"A") -> 1 | AK5: Working days | AL5: 24
A6: 2 | B6: Amna | C6: Imtiaz Hussain | D6: ECE | F6: P | G6: P | H6: P | I6: P | J6: P | K6: P | M6: P | N6: P | O6: P | P6: P | Q6: P | R6: P | T6: A | V6: A | W6: P | X6: P | Y6: P | AA6: P | AB6: P | AC6: P | AD6: P | AE6: P | AF6: P | AH6: P | AI6: =COUNTIF(E6:AH6,"P") -> 22 | AJ6: =COUNTIF(E6:AH6,"A") -> 2 | AK6: Sunday | AL6: 5
A7: 3 | B7: Aniza Memon | C7: M. Qasim | D7: ECE | F7: P | G7: P | H7: P | I7: P | J7: P | K7: P | M7: P | N7: P | O7: P | P7: P | Q7: P | R7: P | T7: A | V7: P | W7: P | X7: A | Y7: P | AA7: P | AB7: P | AC7: P | AD7: P | AE7: P | AF7: P | AH7: P | AI7: =COUNTIF(E7:AH7,"P") -> 22 | AJ7: =COUNTIF(E7:AH7,"A") -> 2 | AK7: 12 Rabi Ul Awwal | AL7: 1
A8: 4 | B8: Areeba | C8: Altaf Hussain | D8: ECE | F8: P | G8: P | H8: P | I8: P | J8: P | K8: A | M8: P | N8: P | O8: P | P8: P | Q8: P | R8: P | T8: P | V8: P | W8: A | X8: P | Y8: P | AA8: P | AB8: P | AC8: P | AD8: P | AE8: P | AF8: P | AH8: P | AI8: =COUNTIF(E8:AH8,"P") -> 22 | AJ8: =COUNTIF(E8:AH8,"A") -> 2
A9: 5 | B9: Batool | C9: Amjad Ali | D9: ECE | F9: P | G9: P | H9: P | I9: P | J9: A | K9: P | M9: P | N9: P | O9: P | P9: P | Q9: P | R9: P | T9: P | V9: P | W9: P | X9: P | Y9: P | AA9: P | AB9: P | AC9: A | AD9: P | AE9: P | AF9: P | AH9: P | AI9: =COUNTIF(E9:AH9,"P") -> 22 | AJ9: =COUNTIF(E9:AH9,"A") -> 2 | AK9: Present Days Detail
A10: 6 | B10: Dua | C10: Khalid Hussain | D10: ECE | F10: P | G10: P | H10: P | I10: P | J10: P | K10: P | M10: P | N10: P | O10: P | P10: P | Q10: P | R10: P | T10: P | V10: P | W10: P | X10: P | Y10: P | AA10: P | AB10: P | AC10: P | AD10: P | AE10: P | AF10: P | AH10: P | AI10: =COUNTIF(E10:AH10,"P") -> 24 | AJ10: =COUNTIF(E10:AH10,"A") -> 0 | AK10: Detail | AL10: Boys | AM10: Girls | AN10: Total
A11: 7 | B11: Faiza | C11: Liaqat Ali | D11: ECE | F11: P | G11: P | H11: P | I11: P | J11: P | K11: P | M11: P | N11: P | O11: P | P11: P | Q11: P | R11: P | T11: A | V11: P | W11: P | X11: P | Y11: P | AA11: P | AB11: P | AC11: P | AD11: A | AE11: P | AF11: A | AH11: P | AI11: =COUNTIF(E11:AH11,"P") -> 21 | AJ11: =COUNTIF(E11:AH11,"A") -> 3 | AK11: Due Present days | AL11: =32*AL5 -> 768 | AM11: =24*AL5 -> 576 | AN11: =SUM(AL11:AM11) -> 1344
A12: 8 | B12: Fatima | C12: Aziz-ur-Rehman | D12: ECE | F12: P | G12: P | H12: P | I12: P | J12: P | K12: P | M12: P | N12: P | O12: P | P12: P | Q12: P | R12: P | T12: P | V12: P | W12: P | X12: A | Y12: A | AA12: P | AB12: P | AC12: P | AD12: P | AE12: P | AF12: P | AH12: P | AI12: =COUNTIF(E12:AH12,"P") -> 22 | AJ12: =COUNTIF(E12:AH12,"A") -> 2 | AK12: Actual present days | AL12: =SUM(AI29:AI60) -> 678 | AM12: =SUM(AI5:AI28) -> 518 | AN12: =AL12+AM12 -> 1196
A13: 9 | B13: Hafsa | C13: Hafeezullah | D13: ECE | F13: P | G13: P | H13: P | I13: P | J13: P | K13: P | M13: P | N13: P | O13: P | P13: P | Q13: P | T13: A | V13: P | W13: A | X13: A | Y13: A | AA13: P | AB13: P | AC13: P | AD13: P | AE13: A | AF13: A | AH13: A | AI13: =COUNTIF(E13:AH13,"P") -> 16 | AJ13: =COUNTIF(E13:AH13,"A") -> 7 | AK13: % | AL13: =AL12/AL11 -> 0.8828125 | AM13: =AM12/AM11 -> 0.89930556 | AN13: =AN12/AN11 -> 0.88988095
A14: 10 | B14: Insha Arzoo | C14: Meeral | D14: ECE | F14: P | G14: P | H14: P | I14: P | J14: P | K14: P | M14: P | N14: P | O14: P | P14: P | Q14: P | R14: P | T14: A | V14: P | W14: P | X14: P | Y14: P | AA14: P | AB14: P | AC14: P | AD14: P | AE14: A | AF14: A | AH14: A | AI14: =COUNTIF(E14:AH14,"P") -> 20 | AJ14: =COUNTIF(E14:AH14,"A") -> 4
A15: 11 | B15: Kauser Fatima | C15: Amir Jamil | D15: ECE | F15: P | G15: P | H15: P | I15: P | J15: P | K15: P | M15: P | N15: P | O15: P | P15: P | Q15: P | R15: L | T15: L | V15: P | W15: L | X15: L | Y15: L | AA15: L | AB15: P | AC15: P | AD15: P | AE15: P | AF15: P | AH15: P | AI15: =COUNTIF(E15:AH15,"P") -> 18 | AJ15: =COUNTIF(E15:AH15,"A") -> 0
A16: 12 | B16: Mehrunisa | C16: Aijaz Ali | D16: ECE | F16: P | G16: P | H16: P | I16: A | J16: A | K16: A | M16: P | N16: P | O16: P | P16: P | Q16: P | R16: P | T16: A | V16: P | W16: P | X16: P | Y16: P | AA16: P | AB16: P | AC16: P | AD16: P | AE16: P | AF16: P | AH16: P | AI16: =COUNTIF(E16:AH16,"P") -> 20 | AJ16: =COUNTIF(E16:AH16,"A") -> 4
A17: 13 | B17: Mirha | C17: M. Luqman | D17: ECE | F17: P | G17: P | H17: P | I17: P | J17: P | K17: P | M17: P | N17: P | O17: P | P17: P | Q17: P | R17: P | T17: A | V17: A | W17: P | X17: P | Y17: P | AA17: P | AB17: P | AC17: P | AD17: P | AE17: P | AF17: P | AH17: P | AI17: =COUNTIF(E17:AH17,"P") -> 22 | AJ17: =COUNTIF(E17:AH17,"A") -> 2 | AK17: Absent Days Details
A18: 14 | B18: Misbah Bhutto | C18: M. Azeem | D18: ECE | F18: P | G18: P | H18: P | I18: P | J18: P | K18: P | M18: P | N18: P | O18: P | P18: P | Q18: A | R18: P | T18: P | V18: P | W18: A | X18: P | Y18: P | AA18: P | AB18: P | AC18: P | AD18: P | AE18: P | AF18: P | AH18: A | AI18: =COUNTIF(E18:AH18,"P") -> 21 | AJ18: =COUNTIF(E18:AH18,"A") -> 3 | AK18: Detail | AL18: Boys | AM18: Girls | AN18: Total
A19: 15 | B19: Rimsha | C19: Meer Ameer-ud-Din | D19: ECE | F19: P | G19: P | H19: P | I19: P | J19: P | K19: P | M19: P | N19: P | O19: P | P19: P | Q19: P | R19: P | T19: P | V19: P | W19: P | X19: P | Y19: P | AA19: P | AB19: P | AC19: P | AD19: P | AE19: P | AF19: A | AH19: A | AI19: =COUNTIF(E19:AH19,"P") -> 22 | AJ19: =COUNTIF(E19:AH19,"A") -> 2 | AK19: Due Present days | AL19: =32*AL5 -> 768 | AM19: =24*AL5 -> 576 | AN19: =AL19+AM19 -> 1344
A20: 16 | B20: Sidra | C20: Khalid Hussain | D20: ECE | F20: P | G20: P | H20: P | I20: P | J20: P | K20: P | M20: P | N20: P | O20: P | P20: P | Q20: P | R20: P | T20: A | V20: P | W20: P | X20: P | Y20: P | AA20: P | AB20: P | AC20: P | AD20: P | AE20: P | AF20: P | AH20: P | AI20: =COUNTIF(E20:AH20,"P") -> 23 | AJ20: =COUNTIF(E20:AH20,"A") -> 1 | AK20: Absent days | AL20: =AL19-AL12 -> 90 | AM20: =AM19-AM12 -> 58 | AN20: =AL20+AM20 -> 148
A21: 17 | B21: Sidra Batool | C21: M. Khan | D21: ECE | F21: P | G21: P | H21: P | I21: P | J21: P | K21: P | M21: P | N21: P | O21: P | P21: P | Q21: P | R21: P | T21: P | V21: P | W21: P | X21: P | Y21: P | AA21: P | AB21: P | AC21: P | AD21: P | AE21: P | AF21: P | AH21: P | AI21: =COUNTIF(E21:AH21,"P") -> 24 | AJ21: =COUNTIF(E21:AH21,"A") -> 0 | AK21: % | AL21: =AL20/AL19 -> 0.1171875 | AM21: =AM20/AM19 -> 0.10069444 | AN21: =AN20/AN19 -> 0.11011905
A22: 18 | B22: Taniya Bibi | C22: Wazir Ali | D22: ECE | F22: P | G22: A | H22: P | I22: P | J22: P | K22: P | M22: P | N22: P | O22: P | P22: P | Q22: P | R22: A | T22: P | V22: P | W22: P | X22: P | Y22: P | AA22: P | AB22: P | AC22: P | AD22: P | AE22: A | AF22: P | AH22: P | AI22: =COUNTIF(E22:AH22,"P") -> 21 | AJ22: =COUNTIF(E22:AH22,"A") -> 3
A23: 19 | B23: Tanzeela | C23: Hizbullah | D23: ECE | F23: P | G23: P | H23: P | I23: P | J23: P | K23: P | M23: P | N23: P | O23: P | P23: P | Q23: P | R23: P | T23: P | V23: P | W23: P | X23: P | Y23: P | AA23: P | AB23: P | AC23: P | AD23: P | AE23: P | AF23: P | AH23: P | AI23: =COUNTIF(E23:AH23,"P") -> 24 | AJ23: =COUNTIF(E23:AH23,"A") -> 0
A24: 20 | B24: Tayaba Fatima | C24: Waseem Ahmed | D24: ECE | F24: P | G24: P | H24: P | I24: P | J24: P | K24: P | M24: P | N24: P | O24: P | P24: P | Q24: P | R24: P | T24: P | V24: P | W24: P | X24: P | Y24: P | AA24: P | AB24: P | AC24: P | AD24: P | AE24: P | AF24: P | AH24: P | AI24: =COUNTIF(E24:AH24,"P") -> 24 | AJ24: =COUNTIF(E24:AH24,"A") -> 0
A25: 21 | B25: Tooba Noor | C25: M. Shareef | D25: ECE | F25: P | G25: P | H25: P | I25: P | J25: P | K25: P | M25: P | N25: P | O25: P | P25: P | Q25: P | R25: P | T25: P | V25: P | W25: P | X25: P | Y25: P | AA25: P | AB25: P | AC25: P | AD25: P | AE25: P | AF25: P | AH25: P | AI25: =COUNTIF(E25:AH25,"P") -> 24 | AJ25: =COUNTIF(E25:AH25,"A") -> 0
A26: 22 | B26: Umm-e-Kulsoom | C26: Shah Ali | D26: ECE | F26: P | G26: P | H26: P | I26: P | J26: P | K26: P | M26: P | N26: P | O26: P | P26: P | Q26: P | R26: P | T26: A | V26: P | W26: P | X26: P | Y26: P | AA26: P | AB26: P | AC26: P | AD26: P | AE26: P | AF26: P | AH26: P | AI26: =COUNTIF(E26:AH26,"P") -> 23 | AJ26: =COUNTIF(E26:AH26,"A") -> 1
A27: 23 | B27: Zunaira | C27: Amjad Ali | D27: ECE | F27: P | G27: P | H27: P | I27: P | J27: A | K27: P | M27: P | N27: P | O27: P | P27: P | Q27: P | R27: P | T27: P | V27: P | W27: P | X27: P | Y27: P | AA27: P | AB27: P | AC27: A | AD27: P | AE27: P | AF27: P | AH27: P | AI27: =COUNTIF(E27:AH27,"P") -> 22 | AJ27: =COUNTIF(E27:AH27,"A") -> 2
A28: 24 | B28: Sahib Khatoon | C28: A. Qayoom | D28: ECE | F28: P | G28: P | H28: P | I28: P | J28: P | K28: A | M28: P | N28: P | O28: P | P28: P | Q28: P | R28: A | T28: A | V28: A | W28: P | X28: A | Y28: P | AA28: P | AB28: P | AC28: P | AD28: A | AE28: A | AF28: P | AH28: A | AI28: =COUNTIF(E28:AH28,"P") -> 16 | AJ28: =COUNTIF(E28:AH28,"A") -> 8
A29: 1 | B29: Abrar | C29: Jan Muhammad | D29: ECE | F29: P | G29: P | H29: P | I29: P | J29: P | K29: P | M29: P | N29: P | O29: P | P29: P | Q29: P | R29: P | T29: A | V29: P | W29: P | X29: P | Y29: P | AA29: P | AB29: P | AC29: P | AD29: P | AE29: P | AF29: P | AH29: P | AI29: =COUNTIF(E29:AH29,"P") -> 23 | AJ29: =COUNTIF(E29:AH29,"A") -> 1
A30: 2 | B30: Azan Shafeeque | C30: M. Shafeeque | D30: ECE | F30: P | G30: P | H30: P | I30: P | J30: P | K30: P | M30: P | N30: P | O30: P | P30: P | Q30: P | R30: P | T30: A | V30: P | W30: P | X30: P | Y30: P | AA30: P | AB30: P | AC30: P | AD30: P | AE30: P | AF30: P | AH30: P | AI30: =COUNTIF(E30:AH30,"P") -> 23 | AJ30: =COUNTIF(E30:AH30,"A") -> 1
A31: 3 | B31: Azan Fayaz | C31: Fayaz Hussain | D31: ECE | F31: P | G31: P | H31: P | I31: P | J31: P | K31: P | M31: P | N31: P | O31: P | P31: P | Q31: A | R31: P | T31: P | V31: P | W31: P | X31: P | Y31: P | AA31: P | AB31: P | AC31: P | AD31: P | AE31: P | AF31: P | AH31: P | AI31: =COUNTIF(E31:AH31,"P") -> 23 | AJ31: =COUNTIF(E31:AH31,"A") -> 1
A32: 4 | B32: Adil Ahmed | C32: Faiz Muhammad | D32: ECE | F32: P | G32: P | H32: P | I32: P | J32: P | K32: A | M32: P | N32: P | O32: P | P32: P | Q32: A | R32: P | T32: A | V32: P | W32: A | X32: P | Y32: P | AA32: P | AB32: P | AC32: P | AD32: P | AE32: A | AF32: P | AH32: P | AI32: =COUNTIF(E32:AH32,"P") -> 19 | AJ32: =COUNTIF(E32:AH32,"A") -> 5
A33: 5 | B33: Ab. Qudoos | C33: Sikandar | D33: ECE | F33: P | G33: P | H33: P | I33: P | J33: A | K33: P | M33: P | N33: P | O33: P | P33: P | Q33: P | R33: P | T33: P | V33: P | W33: P | X33: P | Y33: P | AA33: P | AB33: P | AC33: P | AD33: P | AE33: P | AF33: P | AH33: P | AI33: =COUNTIF(E33:AH33,"P") -> 23 | AJ33: =COUNTIF(E33:AH33,"A") -> 1
... A55: 27 | B55: Ammadullah | C55: Shabir Ahmed | D55: ECE | F55: P | G55: P | H55: A | I55: P | J55: P | K55: P | M55: P | N55: P | O55: P | P55: P | Q55: A | R55: A | T55: P | V55: P | W55: P | X55: P | Y55: A | AA55: P | AB55: P | AC55: P | AD55: P | AE55: P | AF55: A | AH55: P | AI55: =COUNTIF(E55:AH55,"P") -> 19 | AJ55: =COUNTIF(E55:AH55,"A") -> 5
A56: 28 | B56: M Fahad | D56: ECE | F56: P | G56: P | H56: P | I56: P | J56: P | K56: P | M56: P | N56: P | O56: P | P56: P | Q56: P | R56: P | T56: P | V56: P | W56: P | X56: P | Y56: A | AA56: P | AB56: P | AC56: P | AD56: A | AE56: P | AF56: P | AH56: P | AI56: =COUNTIF(E56:AH56,"P") -> 22 | AJ56: =COUNTIF(E56:AH56,"A") -> 2
A57: 29 | B57: Ab. Hadi | D57: ECE | F57: P | G57: P | H57: P | I57: A | J57: P | K57: P | M57: P | N57: A | O57: A | P57: P | Q57: P | R57: P | T57: P | V57: P | W57: P | X57: P | Y57: P | AA57: P | AB57: P | AC57: P | AD57: P | AE57: P | AF57: P | AH57: P | AI57: =COUNTIF(E57:AH57,"P") -> 21 | AJ57: =COUNTIF(E57:AH57,"A") -> 3
A58: 30 | B58: Bilal | C58: M. Fahad | D58: ECE | F58: - | G58: - | H58: - | I58: - | J58: - | K58: - | M58: - | N58: - | O58: - | P58: - | Q58: P | R58: P | T58: A | V58: P | W58: P | X58: P | Y58: P | AA58: P | AB58: P | AC58: P | AD58: P | AE58: P | AF58: P | AH58: P | AI58: =COUNTIF(E58:AH58,"P") -> 13 | AJ58: =COUNTIF(E58:AH58,"A") -> 1
A59: 31 | B59: Parsa Batool | D59: ECE | F59: P | G59: P | H59: P | I59: P | J59: P | K59: P | M59: P | N59: P | O59: P | P59: P | Q59: P | R59: P | T59: P | V59: P | W59: P | X59: P | Y59: A | AA59: P | AB59: P | AC59: P | AD59: P | AE59: P | AF59: A | AH59: P | AI59: =COUNTIF(E59:AH59,"P") -> 22 | AJ59: =COUNTIF(E59:AH59,"A") -> 2
A60: 32 | B60: Ab. Bari | D60: ECE | F60: - | G60: - | H60: - | I60: - | J60: - | K60: - | M60: - | N60: - | O60: - | P60: - | Q60: - | R60: - | T60: - | V60: P | W60: P | X60: P | Y60: P | AA60: P | AB60: P | AC60: P | AD60: P | AE60: P | AF60: P | AH60: P | AI60: =COUNTIF(E60:AH60,"P") -> 11 | AJ60: =COUNTIF(E60:AH60,"A") -> 0

Sheet Class-I
A1: Goverment high school (SJCHS)
A2: Monthly Attendence Month of September-2024
A3: S.No | B3: Student Name | C3: Father Name | D3: Class | E3: =TEXT(E4,"ddd") -> Sun | F3: =TEXT(F4,"ddd") -> Mon | G3: =TEXT(G4,"ddd") -> Tue | H3: =TEXT(H4,"ddd") -> Wed | I3: =TEXT(I4,"ddd") -> Thu | J3: =TEXT(J4,"ddd") -> Fri | K3: =TEXT(K4,"ddd") -> Sat | L3: =TEXT(L4,"ddd") -> Sun | ... AH3: =TEXT(AH4,"ddd") -> Mon | AI3: Present | AJ3: Absent | AK3: Year 2024
E4: 45536 | F4: 45537 | G4: 45538 | H4: 45539 | I4: 45540 | J4: 45541 | K4: 45542 | L4: 45543 | M4: 45544 | N4: 45545 | O4: 45546 | P4: 45547 | Q4: 45548 | R4: 45549 | S4: 45550 | T4: 45551 | U4: 45552 | V4: 45553 | W4: 45554 | X4: 45555 | Y4: 45556 | Z4: 45557 | AA4: 45558 | AB4: 45559 | AC4: 45560 | AD4: 45561 | AE4: 45562 | AF4: 45563 | AG4: 45564 | AH4: 45565 | AK4: Total days | AL4: =SUM(AL5:AL7) -> 30
A5: 1 | B5: Anum | C5: M. Arif | D5: One | E5: SUNDAY - SUNDAY - SUNDAY - SUNDAY - SUNDAY - SUNDAY | F5: P | G5: P | H5: P | I5: P | J5: P | K5: P | L5: SUNDAY - SUNDAY - SUNDAY - SUNDAY - SUNDAY - SUNDAY | M5: P | N5: P | O5: P | P5: P | Q5: P | R5: P | S5: SUNDAY - SUNDAY - SUNDAY - SUNDAY - SUNDAY - SUNDAY | T5: P | U5: 12 RABI UL AWWAL - 12 RABI UL AWWAL - 12 RABI UL AWWAL | V5: P | W5: P | X5: P | Y5: P | Z5: SUNDAY - SUNDAY - SUNDAY - SUNDAY - SUNDAY - SUNDAY | AA5: P | AB5: P | AC5: P | AD5: P | AE5: P | AF5: P | AG5: SUNDAY - SUNDAY - SUNDAY - SUNDAY - SUNDAY - SUNDAY | AH5: P | AI5: =COUNTIF(E5:AH5,"P") -> 24 | AJ5: =COUNTIF(E5:AH5,"A") -> 0 | AK5: Working days | AL5: 24
A6: 2 | B6: Ayat | C6: Meer Mohammad | D6: One | F6: P | G6: A | H6: P | I6: A | J6: A | K6: A | M6: P | N6: A | O6: P | P6: A | Q6: P | R6: A | T6: P | V6: P | W6: P | X6: P | Y6: P | AA6: P | AB6: P | AC6: P | AD6: A | AE6: P | AF6: P | AH6: P | AI6: =COUNTIF(E6:AH6,"P") -> 16 | AJ6: =COUNTIF(E6:AH6,"A") -> 8 | AK6: Sunday | AL6: 5
A7: 3 | B7: Amna | C7: Saeed Ahmed | D7: One | F7: P | G7: P | H7: P | I7: P | J7: P | K7: P | M7: P | N7: P | O7: P | P7: P | Q7: P | R7: P | T7: P | V7: P | W7: P | X7: P | Y7: P | AA7: P | AB7: P | AC7: P | AD7: A | AE7: P | AF7: P | AH7: P | AI7: =COUNTIF(E7:AH7,"P") -> 23 | AJ7: =COUNTIF(E7:AH7,"A") -> 1 | AK7: 12 Rabi Ul Awwal | AL7: 1
A8: 4 | B8: Adeeba | C8: Qurban Ali | D8: One | F8: P | G8: P | H8: P | I8: P | J8: P | K8: P | M8: P | N8: P | O8: P | P8: P | Q8: P | R8: P | T8: P | V8: A | W8: P | X8: P | Y8: P | AA8: P | AB8: P | AC8: P | AD8: P | AE8: P | AF8: P | AH8: P | AI8: =COUNTIF(E8:AH8,"P") -> 23 | AJ8: =COUNTIF(E8:AH8,"A") -> 1
A9: 5 | B9: Emaan Noor | C9: Noor Mohammad | D9: One | F9: P | G9: P | H9: P | I9: P | J9: P | K9: P | M9: P | N9: P | O9: P | P9: P | Q9: P | R9: P | T9: A | V9: P | W9: P | X9: P | Y9: P | AA9: P | AB9: P | AC9: P | AD9: P | AE9: P | AF9: P | AH9: P | AI9: =COUNTIF(E9:AH9,"P") -> 23 | AJ9: =COUNTIF(E9:AH9,"A") -> 1 | AK9: Present Days Detail
A10: 6 | B10: Horain | C10: Saeed Ahmed | D10: One | F10: P | G10: P | H10: P | I10: P | J10: A | K10: A | M10: P | N10: P | O10: P | P10: P | Q10: P | R10: P | T10: P | V10: P | W10: A | X10: P | Y10: P | AA10: P | AB10: P | AC10: P | AD10: P | AE10: P | AF10: A | AH10: A | AI10: =COUNTIF(E10:AH10,"P") -> 19 | AJ10: =COUNTIF(E10:AH10,"A") -> 5 | AK10: Detail | AL10: Boys | AM10: Girls | AN10: Total
A11: 7 | B11: Hannah | C11: Luqman Ali | D11: One | F11: P | G11: P | H11: P | I11: P | J11: P | K11: P | M11: P | N11: P | O11: P | P11: P | Q11: P | R11: P | T11: A | V11: A | W11: P | X11: P | Y11: P | AA11: P | AB11: P | AC11: P | AD11: P | AE11: P | AF11: P | AH11: P | AI11: =COUNTIF(E11:AH11,"P") -> 22 | AJ11: =COUNTIF(E11:AH11,"A") -> 2 | AK11: Due Present days | AL11: =32*AL5 -> 768 | AM11: =24*AL5 -> 576 | AN11: =SUM(AL11:AM11) -> 1344
A12: 8 | B12: Horiya | C12: Siddique | D12: One | F12: P | G12: P | H12: P | I12: P | J12: P | K12: P | M12: P | N12: P | O12: P | P12: P | Q12: P | R12: P | T12: A | V12: A | W12: P | X12: P | Y12: P | AA12: P | AB12: P | AC12: P | AD12: P | AE12: A | AF12: P | AH12: P | AI12: =COUNTIF(E12:AH12,"P") -> 21 | AJ12: =COUNTIF(E12:AH12,"A") -> 3 | AK12: Actual present days | AL12: =SUM(AI29:AI60) -> 683 | AM12: =SUM(AI5:AI28) -> 476 | AN12: =AL12+AM12 -> 1159
A13: 9 | B13: Hareem Fatima | C13: Deedar Ali | D13: One | F13: P | G13: P | H13: P | I13: P | J13: P | K13: P | M13: P | N13: P | O13: P | P13: P | Q13: P | R13: P | T13: P | V13: P | W13: P | X13: P | Y13: A | AA13: P | AB13: P | AC13: P | AD13: P | AE13: P | AF13: P | AH13: P | AI13: =COUNTIF(E13:AH13,"P") -> 23 | AJ13: =COUNTIF(E13:AH13,"A") -> 1 | AK13: % | AL13: =AL12/AL11 -> 0.88932292 | AM13: =AM12/AM11 -> 0.82638889 | AN13: =AN12/AN11 -> 0.86235119
A14: 10 | B14: Maham Noor | C14: Zaheer Abbas | D14: One | F14: P | G14: P | H14: P | I14: P | J14: L | K14: L | M14: A | N14: A | O14: A | P14: P | Q14: P | R14: P | T14: P | V14: P | W14: P | X14: P | Y14: P | AA14: P | AB14: P | AC14: P | AD14: P | AE14: P | AF14: P | AH14: P | AI14: =COUNTIF(E14:AH14,"P") -> 19 | AJ14: =COUNTIF(E14:AH14,"A") -> 3
A15: 11 | B15: Maria | C15: Mehboob Ali | D15: One | F15: P | G15: P | H15: P | I15: P | J15: P | K15: P | M15: P | N15: P | O15: P | P15: P | Q15: P | R15: P | T15: P | V15: P | W15: P | X15: A | Y15: P | AA15: A | AB15: P | AC15: P | AD15: P | AE15: P | AF15: P | AH15: P | AI15: =COUNTIF(E15:AH15,"P") -> 22 | AJ15: =COUNTIF(E15:AH15,"A") -> 2
A16: 12 | B16: Mehreen | C16: M. Maroof | D16: One | F16: P | G16: P | H16: P | I16: P | J16: P | K16: P | M16: P | N16: P | O16: P | P16: P | Q16: P | R16: P | T16: P | V16: P | W16: P | X16: P | Y16: P | AA16: P | AB16: P | AC16: A | AD16: P | AE16: A | AF16: A | AH16: P | AI16: =COUNTIF(E16:AH16,"P") -> 21 | AJ16: =COUNTIF(E16:AH16,"A") -> 3
A17: 13 | B17: Mahira | C17: Arbab Ali | D17: One | F17: P | G17: P | H17: A | I17: A | J17: A | K17: A | M17: P | N17: P | O17: P | P17: P | Q17: P | R17: P | T17: P | V17: P | W17: A | X17: A | Y17: A | AA17: P | AB17: P | AC17: A | AD17: P | AE17: P | AF17: A | AH17: P | AI17: =COUNTIF(E17:AH17,"P") -> 15 | AJ17: =COUNTIF(E17:AH17,"A") -> 9 | AK17: Absent Days Details
A18: 14 | B18: Meerab | C18: Yasir Ahmed | D18: One | F18: P | G18: P | H18: P | I18: P | J18: A | K18: P | M18: P | N18: P | O18: A | P18: A | Q18: P | R18: P | T18: P | V18: P | W18: P | X18: P | Y18: P | AA18: P | AB18: P | AC18: P | AD18: P | AE18: P | AF18: A | AH18: A | AI18: =COUNTIF(E18:AH18,"P") -> 19 | AJ18: =COUNTIF(E18:AH18,"A") -> 5 | AK18: Detail | AL18: Boys | AM18: Girls | AN18: Total
A19: 15 | B19: Qudsia Zehra | C19: Awaheed Ali | D19: One | F19: P | G19: P | H19: P | I19: P | J19: A | K19: P | M19: P | N19: P | O19: P | P19: P | Q19: P | R19: A | T19: P | V19: A | W19: P | X19: P | Y19: P | AA19: P | AB19: P | AC19: P | AD19: P | AE19: P | AF19: P | AH19: P | AI19: =COUNTIF(E19:AH19,"P") -> 21 | AJ19: =COUNTIF(E19:AH19,"A") -> 3 | AK19: Due Present days | AL19: =32*AL5 -> 768 | AM19: =24*AL5 -> 576 | AN19: =AL19+AM19 -> 1344
A20: 16 | B20: Paras | C20: Sadam | D20: One | F20: P | G20: P | H20: P | I20: P | J20: P | K20: A | M20: P | N20: P | O20: A | P20: P | Q20: P | R20: A | T20: A | V20: A | W20: A | X20: P | Y20: P | AA20: P | AB20: P | AC20: P | AD20: P | AE20: P | AF20: A | AH20: P | AI20: =COUNTIF(E20:AH20,"P") -> 17 | AJ20: =COUNTIF(E20:AH20,"A") -> 7 | AK20: Absent days | AL20: =AL19-AL12 -> 85 | AM20: =AM19-AM12 -> 100 | AN20: =AL20+AM20 -> 185
A21: 17 | B21: Thamna Batool | C21: Shehzad | D21: One | F21: P | G21: P | H21: P | I21: A | J21: A | K21: P | M21: A | N21: A | O21: A | P21: A | Q21: A | R21: A | T21: A | V21: P | W21: P | X21: P | Y21: P | AA21: P | AB21: P | AC21: P | AD21: P | AE21: P | AF21: P | AH21: P | AI21: =COUNTIF(E21:AH21,"P") -> 15 | AJ21: =COUNTIF(E21:AH21,"A") -> 9 | AK21: % | AL21: =AL20/AL19 -> 0.11067708 | AM21: =AM20/AM19 -> 0.17361111 | AN21: =AN20/AN19 -> 0.13764881
A22: 18 | B22: Tamana Fatima | C22: Shehzad | D22: One | F22: P | G22: P | H22: P | I22: A | J22: A | K22: P | M22: A | N22: A | O22: A | P22: A | Q22: A | R22: A | T22: A | V22: P | W22: P | X22: P | Y22: P | AA22: P | AB22: P | AC22: P | AD22: P | AE22: P | AF22: P | AH22: P | AI22: =COUNTIF(E22:AH22,"P") -> 15 | AJ22: =COUNTIF(E22:AH22,"A") -> 9
A23: 19 | B23: Zaiba Bakhtawar | C23: Hameed | D23: One | F23: P | G23: A | H23: P | I23: P | J23: P | K23: P | M23: P | N23: P | O23: P | P23: P | Q23: P | R23: P | T23: A | V23: P | W23: P | X23: P | Y23: P | AA23: P | AB23: P | AC23: P | AD23: P | AE23: P | AF23: P | AH23: P | AI23: =COUNTIF(E23:AH23,"P") -> 22 | AJ23: =COUNTIF(E23:AH23,"A") -> 2
A24: 20 | B24: Zainab | C24: A. Aziz | D24: One | F24: P | G24: P | H24: P | I24: P | J24: P | K24: P | M24: P | N24: P | O24: P | P24: P | Q24: P | R24: P | T24: P | V24: P | W24: P | X24: P | Y24: P | AA24: P | AB24: P | AC24: A | AD24: P | AE24: P | AF24: P | AH24: P | AI24: =COUNTIF(E24:AH24,"P") -> 23 | AJ24: =COUNTIF(E24:AH24,"A") -> 1
A25: 21 | B25: Zainab | C25: Zulfiqar | D25: One | F25: P | G25: P | H25: P | I25: A | J25: A | K25: P | M25: P | N25: P | O25: P | P25: P | Q25: P | R25: P | T25: P | V25: P | W25: P | X25: P | Y25: P | AA25: P | AB25: P | AC25: P | AD25: A | AE25: P | AF25: P | AH25: P | AI25: =COUNTIF(E25:AH25,"P") -> 21 | AJ25: =COUNTIF(E25:AH25,"A") -> 3
A26: 22 | B26: Waniya | C26: Asad Ali | D26: One | F26: A | G26: P | H26: P | I26: A | J26: A | K26: A | M26: P | N26: P | O26: P | P26: P | Q26: P | R26: P | T26: P | V26: A | W26: P | X26: A | Y26: P | AA26: A | AB26: P | AC26: P | AD26: P | AE26: A | AF26: A | AH26: A | AI26: =COUNTIF(E26:AH26,"P") -> 14 | AJ26: =COUNTIF(E26:AH26,"A") -> 10
A27: 23 | B27: Haram | C27: Moien Khan | D27: One | F27: P | G27: P | H27: P | I27: P | J27: P | K27: A | M27: A | N27: P | O27: P | P27: A | Q27: P | R27: P | T27: P | V27: P | W27: P | X27: P | Y27: P | AA27: P | AB27: P | AC27: P | AD27: P | AE27: P | AF27: P | AH27: A | AI27: =COUNTIF(E27:AH27,"P") -> 20 | AJ27: =COUNTIF(E27:AH27,"A") -> 4
A28: 24 | B28: Ayesha | C28: A. Latif | D28: One | F28: - | G28: - | H28: - | I28: - | J28: - | K28: - | M28: P | N28: P | O28: P | P28: P | Q28: P | R28: P | T28: P | V28: P | W28: P | X28: P | Y28: P | AA28: P | AB28: P | AC28: P | AD28: P | AE28: P | AF28: P | AH28: P | AI28: =COUNTIF(E28:AH28,"P") -> 18 | AJ28: =COUNTIF(E28:AH28,"A") -> 0
A29: 1 | B29: Arsalan | C29: Zulfiqar | D29: One | F29: P | G29: P | H29: P | I29: P | J29: A | K29: A | M29: A | N29: A | O29: A | P29: A | Q29: A | R29: A | T29: A | V29: A | W29: A | X29: A | Y29: A | AA29: P | AB29: P | AC29: P | AD29: P | AE29: A | AF29: A | AH29: P | AI29: =COUNTIF(E29:AH29,"P") -> 9 | AJ29: =COUNTIF(E29:AH29,"A") -> 15
A30: 2 | B30: Arsalan | C30: Faheem | D30: One | F30: P | G30: P | H30: P | I30: P | J30: A | K30: A | M30: P | N30: P | O30: P | P30: A | Q30: P | R30: A | T30: P | V30: P | W30: P | X30: P | Y30: A | AA30: P | AB30: P | AC30: A | AD30: A | AE30: P | AF30: A | AH30: P | AI30: =COUNTIF(E30:AH30,"P") -> 16 | AJ30: =COUNTIF(E30:AH30,"A") -> 8
A31: 3 | B31: A. Nawaz | C31: M. Nawaz | D31: One | F31: P | G31: P | H31: P | I31: P | J31: P | K31: P | M31: P | N31: P | O31: P | P31: P | Q31: P | R31: P | T31: A | V31: P | W31: P | X31: P | Y31: P | AA31: P | AB31: P | AC31: P | AD31: P | AE31: P | AF31: P | AH31: P | AI31: =COUNTIF(E31:AH31,"P") -> 23 | AJ31: =COUNTIF(E31:AH31,"A") -> 1
A32: 4 | B32: A. Malik | C32: Sohail | D32: One | F32: A | G32: P | H32: P | I32: P | J32: A | K32: A | M32: P | N32: P | O32: P | P32: P | Q32: A | R32: P | T32: A | V32: P | W32: P | X32: P | Y32: A | AA32: P | AB32: P | AC32: P | AD32: P | AE32: P | AF32: A | AH32: P | AI32: =COUNTIF(E32:AH32,"P") -> 17 | AJ32: =COUNTIF(E32:AH32,"A") -> 7
A33: 5 | B33: Abdullah | C33: Imtiaz | D33: One | F33: P | G33: P | H33: P | I33: P | J33: P | K33: P | M33: P | N33: P | O33: P | P33: P | Q33: P | R33: P | T33: A | V33: P | W33: P | X33: P | Y33: P | AA33: P | AB33: P | AC33: P | AD33: P | AE33: P | AF33: P | AH33: P | AI33: =COUNTIF(E33:AH33,"P") -> 23 | AJ33: =COUNTIF(E33:AH33,"A") -> 1
... A60: 32 | B60: Zain Ali | C60: Altaf | D60: One | F60: P | G60: P | H60: P | I60: P | J60: A | K60: P | M60: P | N60: P | O60: P | P60: P | Q60: P | R60: A | T60: P | V60: P | W60: A | X60: P | Y60: P | AA60: P | AB60: P | AC60: P | AD60: P | AE60: P | AF60: P | AH60: P | AI60: =COUNTIF(E60:AH60,"P") -> 21 | AJ60: =COUNTIF(E60:AH60,"A") -> 3

Sheet Class-II
A1: Goverment High School (SJCHS)
A2: Monthly Attendence Month of September-2024
A3: S.No | B3: Student Name | C3: Father Name | D3: Class | E3: =TEXT(E4,"ddd") -> Sun | F3: =TEXT(F4,"ddd") -> Mon | G3: =TEXT(G4,"ddd") -> Tue | H3: =TEXT(H4,"ddd") -> Wed | I3: =TEXT(I4,"ddd") -> Thu | J3: =TEXT(J4,"ddd") -> Fri | K3: =TEXT(K4,"ddd") -> Sat | L3: =TEXT(L4,"ddd") -> Sun | ... AH3: =TEXT(AH4,"ddd") -> Mon | AI3: Present | AJ3: Absent | AK3: Year 2024
E4: 45536 | F4: 45537 | G4: 45538 | H4: 45539 | I4: 45540 | J4: 45541 | K4: 45542 | L4: 45543 | M4: 45544 | N4: 45545 | O4: 45546 | P4: 45547 | Q4: 45548 | R4: 45549 | S4: 45550 | T4: 45551 | U4: 45552 | V4: 45553 | W4: 45554 | X4: 45555 | Y4: 45556 | Z4: 45557 | AA4: 45558 | AB4: 45559 | AC4: 45560 | AD4: 45561 | AE4: 45562 | AF4: 45563 | AG4: 45564 | AH4: 45565 | AK4: Total days | AL4: =SUM(AL5:AL7) -> 30
A5: 1 | B5: Abiha Zehra | C5: Ab. Mateen | D5: Two | E5: SUNDAY - SUNDAY - SUNDAY - SUNDAY - SUNDAY - SUNDAY | F5: P | G5: P | H5: P | I5: P | J5: A | K5: P | L5: SUNDAY - SUNDAY - SUNDAY - SUNDAY - SUNDAY - SUNDAY | M5: P | N5: P | O5: P | P5: P | Q5: P | R5: P | S5: SUNDAY - SUNDAY - SUNDAY - SUNDAY - SUNDAY - SUNDAY | T5: A | U5: 12 RABI UL AWWAL - 12 RABI UL AWWAL | V5: P | W5: P | X5: A | Y5: A | Z5: SUNDAY - SUNDAY - SUNDAY - SUNDAY - SUNDAY - SUNDAY | AA5: P | AB5: P | AC5: A | AD5: P | AE5: P | AF5: A | AG5: SUNDAY - SUNDAY - SUNDAY - SUNDAY - SUNDAY - SUNDAY | AH5: P | AI5: =COUNTIF(E5:AH5,"P") -> 18 | AJ5: =COUNTIF(E5:AH5,"A") -> 6 | AK5: Working days | AL5: 24
A6: 2 | B6: Aleena Zia | C6: Khuda Baksh | D6: Two | F6: P | G6: P | H6: P | I6: P | J6: A | K6: P | M6: P | N6: A | O6: P | P6: P | Q6: P | R6: P | T6: P | V6: P | W6: P | X6: P | Y6: P | AA6: P | AB6: P | AC6: P | AD6: P | AE6: A | AF6: P | AH6: L | AI6: =COUNTIF(E6:AH6,"P") -> 20 | AJ6: =COUNTIF(E6:AH6,"A") -> 3 | AK6: Sunday | AL6: 5
A7: 3 | B7: Anumta Jamali | C7: Zaheer Abbas | D7: Two | F7: P | G7: P | H7: P | I7: P | J7: A | K7: P | M7: P | N7: P | O7: P | P7: P | Q7: P | R7: P | T7: A | V7: P | W7: P | X7: P | Y7: P | AA7: P | AB7: P | AC7: P | AD7: P | AE7: P | AF7: P | AH7: P | AI7: =COUNTIF(E7:AH7,"P") -> 22 | AJ7: =COUNTIF(E7:AH7,"A") -> 2 | AK7: 12 Rabi Ul Awwal | AL7: 1
A8: 4 | B8: Anusha | C8: Mukhtiyar Ali | D8: Two | F8: A | G8: P | H8: P | I8: P | J8: A | K8: P | M8: A | N8: P | O8: P | P8: P | Q8: P | R8: P | T8: A | V8: P | W8: P | X8: P | Y8: P | AA8: P | AB8: P | AC8: P | AD8: P | AE8: P | AF8: P | AH8: P | AI8: =COUNTIF(E8:AH8,"P") -> 20 | AJ8: =COUNTIF(E8:AH8,"A") -> 4
A9: 5 | B9: Ayat | C9: Faiq Ali | D9: Two | F9: P | G9: P | H9: P | I9: P | J9: A | K9: P | M9: P | N9: A | O9: P | P9: A | Q9: P | R9: P | T9: P | V9: P | W9: P | X9: P | Y9: A | AA9: P | AB9: P | AC9: P | AD9: P | AE9: P | AF9: A | AH9: P | AI9: =COUNTIF(E9:AH9,"P") -> 19 | AJ9: =COUNTIF(E9:AH9,"A") -> 5 | AK9: Present Days Detail
A10: 6 | B10: Ayesha | C10: Ali Muhammad | D10: Two | F10: P | G10: P | H10: P | I10: P | J10: P | K10: P | M10: P | N10: P | O10: P | P10: P | Q10: P | R10: P | T10: P | V10: P | W10: P | X10: P | Y10: P | AA10: A | AB10: P | AC10: A | AD10: P | AE10: P | AF10: P | AH10: P | AI10: =COUNTIF(E10:AH10,"P") -> 22 | AJ10: =COUNTIF(E10:AH10,"A") -> 2 | AK10: Detail | AL10: Boys | AM10: Girls | AN10: Total
A11: 7 | B11: Dua | C11: Akbar Ali | D11: Two | F11: P | G11: P | H11: P | I11: P | J11: P | K11: P | M11: P | N11: P | O11: P | P11: P | Q11: P | R11: A | T11: P | V11: P | W11: P | X11: P | Y11: P | AA11: P | AB11: P | AC11: P | AD11: P | AE11: P | AF11: P | AH11: P | AI11: =COUNTIF(E11:AH11,"P") -> 23 | AJ11: =COUNTIF(E11:AH11,"A") -> 1 | AK11: Due Present days | AL11: =25*AL5 -> 600 | AM11: =26*AL5 -> 624 | AN11: =SUM(AL11:AM11) -> 1224
A12: 8 | B12: Fiza | C12: Akbar Ali | D12: Two | F12: P | G12: P | H12: P | I12: P | J12: P | K12: P | M12: P | N12: P | O12: P | P12: P | Q12: A | R12: P | T12: P | V12: P | W12: P | X12: P | Y12: P | AA12: P | AB12: P | AC12: P | AD12: P | AE12: P | AF12: P | AH12: P | AI12: =COUNTIF(E12:AH12,"P") -> 23 | AJ12: =COUNTIF(E12:AH12,"A") -> 1 | AK12: Actual present days | AL12: =SUM(AI30:AI55) -> 515 | AM12: =SUM(AI5:AI29) -> 508 | AN12: =AL12+AM12 -> 1023
A13: 9 | B13: Jannat Fatima | C13: Zulfiqar | D13: Two | F13: P | G13: P | H13: P | I13: P | J13: P | K13: P | M13: P | N13: A | O13: A | P13: P | Q13: A | R13: A | T13: P | V13: P | W13: P | X13: P | Y13: P | AA13: P | AB13: P | AC13: P | AD13: A | AE13: P | AF13: P | AH13: P | AI13: =COUNTIF(E13:AH13,"P") -> 19 | AJ13: =COUNTIF(E13:AH13,"A") -> 5 | AK13: % | AL13: =AL12/AL11 -> 0.85833333 | AM13: =AM12/AM11 -> 0.81410256 | AN13: =AN12/AN11 -> 0.83578431
A14: 10 | B14: Kashaf | C14: Abdul Rehman | D14: Two | F14: P | G14: P | H14: P | I14: P | J14: A | K14: P | M14: P | N14: P | O14: P | P14: P | Q14: P | R14: P | T14: A | V14: P | W14: P | X14: P | Y14: P | AA14: P | AB14: P | AC14: P | AD14: P | AE14: A | AF14: P | AH14: P | AI14: =COUNTIF(E14:AH14,"P") -> 21 | AJ14: =COUNTIF(E14:AH14,"A") -> 3
A15: 11 | B15: Masooma | C15: M. Raheem | D15: Two | F15: A | G15: P | H15: P | I15: A | J15: P | K15: P | M15: P | N15: P | O15: P | P15: P | Q15: P | R15: P | T15: P | V15: P | W15: P | X15: P | Y15: P | AA15: P | AB15: P | AC15: P | AD15: P | AE15: A | AF15: P | AH15: P | AI15: =COUNTIF(E15:AH15,"P") -> 21 | AJ15: =COUNTIF(E15:AH15,"A") -> 3
A16: 12 | B16: Muneeza | C16: Mir Amirudin | D16: Two | F16: P | G16: P | H16: P | I16: P | J16: P | K16: P | M16: P | N16: P | O16: P | P16: P | Q16: P | R16: P | T16: P | V16: P | W16: P | X16: P | Y16: P | AA16: P | AB16: P | AC16: P | AD16: P | AE16: P | AF16: A | AH16: L | AI16: =COUNTIF(E16:AH16,"P") -> 22 | AJ16: =COUNTIF(E16:AH16,"A") -> 1
A17: 13 | B17: Nayyara | C17: Khalid Hussain | D17: Two | F17: P | G17: P | H17: P | I17: P | J17: A | K17: P | M17: A | N17: P | O17: P | P17: P | Q17: P | R17: P | T17: P | V17: P | W17: P | X17: P | Y17: P | AA17: P | AB17: P | AC17: P | AD17: A | AE17: P | AF17: P | AH17: P | AI17: =COUNTIF(E17:AH17,"P") -> 21 | AJ17: =COUNTIF(E17:AH17,"A") -> 3 | AK17: Absent Days Details
A18: 14 | B18: Rashida | C18: Sajjad Ahmed | D18: Two | F18: P | G18: P | H18: P | I18: P | J18: P | K18: P | M18: P | N18: P | O18: P | P18: P | Q18: P | R18: P | T18: P | V18: P | W18: P | X18: P | Y18: P | AA18: P | AB18: P | AC18: P | AD18: P | AE18: P | AF18: P | AH18: P | AI18: =COUNTIF(E18:AH18,"P") -> 24 | AJ18: =COUNTIF(E18:AH18,"A") -> 0 | AK18: Detail | AL18: Boys | AM18: Girls | AN18: Total
A19: 15 | B19: Rubab Zahra | C19: Abdul Aziz | D19: Two | F19: P | G19: P | H19: P | I19: P | J19: P | K19: P | M19: P | N19: P | O19: P | P19: P | Q19: P | R19: P | T19: A | V19: P | W19: P | X19: P | Y19: P | AA19: P | AB19: P | AC19: P | AD19: P | AE19: P | AF19: P | AH19: P | AI19: =COUNTIF(E19:AH19,"P") -> 23 | AJ19: =COUNTIF(E19:AH19,"A") -> 1 | AK19: Due Present days | AL19: =25*AL5 -> 600 | AM19: =26*AL5 -> 624 | AN19: =AL19+AM19 -> 1224
A20: 16 | B20: Saba Jamali | C20: Sajid Ali | D20: Two | F20: P | G20: P | H20: P | I20: P | J20: P | K20: P | M20: P | N20: P | O20: P | P20: P | Q20: P | R20: P | T20: P | V20: P | W20: P | X20: P | Y20: P | AA20: P | AB20: P | AC20: P | AD20: P | AE20: P | AF20: P | AH20: P | AI20: =COUNTIF(E20:AH20,"P") -> 24 | AJ20: =COUNTIF(E20:AH20,"A") -> 0 | AK20: Absent days | AL20: =AL19-AL12 -> 85 | AM20: =AM19-AM12 -> 116 | AN20: =AL20+AM20 -> 201
A21: 17 | B21: Tahreem Fatima | C21: Khalid Hussain | D21: Two | F21: P | G21: P | H21: P | I21: P | J21: P | K21: P | M21: P | N21: P | O21: P | P21: P | Q21: P | R21: P | T21: P | V21: P | W21: P | X21: P | Y21: P | AA21: P | AB21: P | AC21: P | AD21: P | AE21: P | AF21: P | AH21: P | AI21: =COUNTIF(E21:AH21,"P") -> 24 | AJ21: =COUNTIF(E21:AH21,"A") -> 0 | AK21: % | AL21: =AL20/AL19 -> 0.14166667 | AM21: =AM20/AM19 -> 0.18589744 | AN21: =AN20/AN19 -> 0.16421569
A22: 18 | B22: Sehar Fatima | C22: Altaf Hussain | D22: Two | F22: P | G22: P | H22: P | I22: P | J22: P | K22: P | M22: P | N22: P | O22: P | P22: P | Q22: P | R22: P | T22: P | V22: P | W22: P | X22: P | Y22: P | AA22: P | AB22: P | AC22: P | AD22: P | AE22: P | AF22: P | AH22: P | AI22: =COUNTIF(E22:AH22,"P") -> 24 | AJ22: =COUNTIF(E22:AH22,"A") -> 0
A23: 19 | B23: Taskeen | C23: Amjad Ali | D23: Two | F23: P | G23: P | H23: P | I23: P | J23: A | K23: P | M23: P | N23: P | O23: P | P23: P | Q23: P | R23: P | T23: P | V23: P | W23: P | X23: P | Y23: A | AA23: P | AB23: A | AC23: A | AD23: P | AE23: P | AF23: P | AH23: P | AI23: =COUNTIF(E23:AH23,"P") -> 20 | AJ23: =COUNTIF(E23:AH23,"A") -> 4
A24: 20 | B24: Zainab | C24: Sikandar | D24: Two | F24: P | G24: P | H24: P | I24: P | J24: A | K24: P | M24: P | N24: P | O24: P | P24: P | Q24: P | R24: P | T24: P | V24: P | W24: P | X24: P | Y24: P | AA24: P | AB24: P | AC24: P | AD24: P | AE24: P | AF24: P | AH24: P | AI24: =COUNTIF(E24:AH24,"P") -> 23 | AJ24: =COUNTIF(E24:AH24,"A") -> 1
A25: 21 | B25: Kashish | C25: M. Noman | D25: Two | F25: P | G25: P | H25: P | I25: P | J25: P | K25: P | M25: P | N25: P | O25: P | P25: P | Q25: P | R25: P | T25: P | V25: P | W25: P | X25: P | Y25: A | AA25: P | AB25: P | AC25: P | AD25: P | AE25: P | AF25: P | AH25: P | AI25: =COUNTIF(E25:AH25,"P") -> 23 | AJ25: =COUNTIF(E25:AH25,"A") -> 1
A26: 22 | B26: Saba | C26: Asif | D26: Two | F26: P | G26: P | H26: A | I26: P | J26: P | K26: A | M26: P | N26: P | O26: P | P26: P | Q26: P | R26: P | T26: P | V26: P | W26: P | X26: P | Y26: P | AA26: P | AB26: P | AC26: P | AD26: P | AE26: P | AF26: P | AH26: P | AI26: =COUNTIF(E26:AH26,"P") -> 22 | AJ26: =COUNTIF(E26:AH26,"A") -> 2
A27: 23 | B27: Afsana | C27: Ab. Hafeez | D27: Two | F27: - | G27: - | H27: - | I27: - | J27: - | K27: - | M27: - | N27: - | O27: - | P27: - | Q27: - | R27: P | T27: P | V27: P | W27: A | X27: A | Y27: P | AA27: P | AB27: P | AC27: P | AD27: P | AE27: P | AF27: P | AH27: P | AI27: =COUNTIF(E27:AH27,"P") -> 11 | AJ27: =COUNTIF(E27:AH27,"A") -> 2
A28: 24 | B28: Ayesha | C28: Ab. Hafeez | D28: Two | F28: - | G28: - | H28: - | I28: - | J28: - | K28: - | M28: - | N28: - | O28: - | P28: - | Q28: - | R28: P | T28: P | V28: P | W28: A | X28: A | Y28: P | AA28: P | AB28: P | AC28: P | AD28: P | AE28: P | AF28: P | AH28: P | AI28: =COUNTIF(E28:AH28,"P") -> 11 | AJ28: =COUNTIF(E28:AH28,"A") -> 2
A29: 25 | B29: Sehrish | D29: Two | F29: - | G29: - | H29: - | I29: - | J29: - | K29: - | M29: - | N29: - | O29: - | P29: - | Q29: - | R29: - | T29: - | V29: - | W29: - | X29: - | Y29: P | AA29: P | AB29: P | AC29: P | AD29: P | AE29: P | AF29: P | AH29: P | AI29: =COUNTIF(E29:AH29,"P") -> 8 | AJ29: =COUNTIF(E29:AH29,"A") -> 0
A30: 1 | B30: Abdul Musawir | C30: M. Ismail | D30: Two | F30: P | G30: P | H30: P | I30: P | J30: P | K30: P | M30: P | N30: P | O30: P | P30: P | Q30: P | R30: P | T30: P | V30: P | W30: P | X30: P | Y30: P | AA30: P | AB30: P | AC30: P | AD30: P | AE30: P | AF30: P | AH30: A | AI30: =COUNTIF(E30:AH30,"P") -> 23 | AJ30: =COUNTIF(E30:AH30,"A") -> 1
A31: 2 | B31: Abdul Rehman | C31: Sajid Ali | D31: Two | F31: P | G31: P | H31: P | I31: P | J31: A | K31: P | M31: P | N31: P | O31: P | P31: P | Q31: P | R31: P | T31: P | V31: P | W31: P | X31: P | Y31: P | AA31: P | AB31: P | AC31: P | AD31: P | AE31: P | AF31: P | AH31: P | AI31: =COUNTIF(E31:AH31,"P") -> 23 | AJ31: =COUNTIF(E31:AH31,"A") -> 1
A32: 3 | B32: Abdul Wahab | C32: Abdul Hafeez | D32: Two | F32: P | G32: P | H32: P | I32: P | J32: A | K32: A | M32: A | N32: P | O32: P | P32: P | Q32: P | R32: A | T32: A | V32: P | W32: P | X32: P | Y32: A | AA32: P | AB32: P | AC32: A | AD32: P | AE32: P | AF32: P | AH32: P | AI32: =COUNTIF(E32:AH32,"P") -> 17 | AJ32: =COUNTIF(E32:AH32,"A") -> 7
A33: 4 | B33: Abdullah | C33: Riazuddin | D33: Two | F33: P | G33: P | H33: P | I33: P | J33: P | K33: P | M33: P | N33: P | O33: P | P33: P | Q33: P | R33: P | T33: P | V33: P | W33: P | X33: P | Y33: P | AA33: P | AB33: P | AC33: L | AD33: L | AE33: L | AF33: L | AH33: P | AI33: =COUNTIF(E33:AH33,"P") -> 20 | AJ33: =COUNTIF(E33:AH33,"A") -> 0
A34: 5 | B34: Ali Shanawar | C34: Mukhtiyar | D34: Two | F34: A | G34: P | H34: P | I34: P | J34: A | K34: P | M34: A | N34: A | O34: P | P34: P | Q34: P | R34: P | T34: A | V34: P | W34: P | X34: P | Y34: P | AA34: P | AB34: P | AC34: P | AD34: P | AE34: P | AF34: P | AH34: P | AI34: =COUNTIF(E34:AH34,"P") -> 19 | AJ34: =COUNTIF(E34:AH34,"A") -> 5
A35: 6 | B35: Faizan | C35: Lutfullah | D35: Two | F35: P | G35: P | H35: P | I35: P | J35: A | K35: P | M35: P | N35: P | O35: P | P35: P | Q35: P | R35: P | T35: P | V35: P | W35: P | X35: P | Y35: P | AA35: P | AB35: P | AC35: P | AD35: A | AE35: L | AF35: L | AH35: P | AI35: =COUNTIF(E35:AH35,"P") -> 20 | AJ35: =COUNTIF(E35:AH35,"A") -> 2
A36: 7 | B36: Fayaz | C36: Samano Khan | D36: Two | F36: P | G36: P | H36: P | I36: P | J36: A | K36: P | M36: A | N36: A | O36: A | P36: A | Q36: A | R36: A | T36: P | V36: P | W36: P | X36: P | Y36: P | AA36: P | AB36: P | AC36: P | AD36: A | AE36: P | AF36: P | AH36: P | AI36: =COUNTIF(E36:AH36,"P") -> 16 | AJ36: =COUNTIF(E36:AH36,"A") -> 8
A37: 8 | B37: Ghulam Abbas | C37: Kamran Ali | D37: Two | F37: P | G37: A | H37: P | I37: P | J37: A | K37: P | M37: P | N37: P | O37: P | P37: P | Q37: A | R37: P | T37: A | V37: P | W37: P | X37: P | Y37: P | AA37: P | AB37: A | AC37: P | AD37: P | AE37: P | AF37: P | AH37: P | AI37: =COUNTIF(E37:AH37,"P") -> 19 | AJ37: =COUNTIF(E37:AH37,"A") -> 5
A38: 9 | B38: Ghulam Mehdi | C38: Rizwan | D38: Two | F38: P | G38: P | H38: P | I38: P | J38: P | K38: P | M38: P | N38: P | O38: P | P38: P | Q38: P | R38: P | T38: P | V38: P | W38: P | X38: P | Y38: A | AA38: P | AB38: P | AC38: P | AD38: P | AE38: P | AF38: P | AH38: P | AI38: =COUNTIF(E38:AH38,"P") -> 23 | AJ38: =COUNTIF(E38:AH38,"A") -> 1
