Workbook

Sheet Compile Sheet-November-2024
A4: Class | B4: Total Enrolment & Attendance November-24
B5: Boys | C5: Girls | D5: Total | E5: total working Days | F5: Total working days-Boys | G5: Total working days-Girls | H5: Total working days-All | I5: P-Days Boys | J5: P-Days Girls | K5: P-Days All | L5: Percentage-Girls | M5: Percentage-Boys | N5: Percentage-Boys | O5: Total average
A6: ECE (ROSE) | B6: 27 | C6: 27 | D6: =SUM(B6:C6) -> 54 | E6: 24 | F6: =B6*E6 -> 648 | G6: =C6*E6 -> 648 | H6: =SUM(F6:G6) -> 1296 | I6: =Kg!AL14 -> #REF! | J6: =Kg!AM14 -> #REF! | K6: =SUM(I6:J6) -> #REF! | L6: =J6/G6 -> #REF! | M6: =I6/F6 -> #REF! | N6: =K6/H6 -> #REF! | O6: =AVERAGE(L6:M6) -> #REF!
A7: ECE (Daffodils) | B7: 31 | C7: 25 | D7: =SUM(B7:C7) -> 56 | E7: 24 | F7: =B7*E7 -> 744 | G7: =C7*E7 -> 600 | H7: =SUM(F7:G7) -> 1344 | I7: =#REF! -> #REF! | J7: =#REF! -> #REF! | K7: =SUM(I7:J7) -> #REF! | L7: =J7/G7 -> #REF! | M7: =I7/F7 -> #REF! | N7: =K7/H7 -> #REF! | O7: =AVERAGE(L7:M7) -> #REF!
A8: One | B8: 32 | C8: 24 | D8: =SUM(B8:C8) -> 56 | E8: 24 | F8: =B8*E8 -> 768 | G8: =C8*E8 -> 576 | H8: =SUM(F8:G8) -> 1344 | I8: ='Class-I'!AL14 -> 572 | J8: ='Class-I'!AM14 -> 516 | K8: =SUM(I8:J8) -> 1088 | L8: =J8/G8 -> 0.89583333 | M8: =I8/F8 -> 0.74479167 | N8: =K8/H8 -> 0.80952381 | O8: =AVERAGE(L8:M8) -> 0.8203125
A9: Two | B9: 26 | C9: 26 | D9: =SUM(B9:C9) -> 52 | E9: 24 | F9: =B9*E9 -> 624 | G9: =C9*E9 -> 624 | H9: =SUM(F9:G9) -> 1248 | I9: ='Class-II'!AL14 -> 464 | J9: ='Class-II'!AM14 -> 555 | K9: =SUM(I9:J9) -> 1019 | L9: =J9/G9 -> 0.88942308 | M9: =I9/F9 -> 0.74358974 | N9: =K9/H9 -> 0.81650641 | O9: =AVERAGE(L9:M9) -> 0.81650641
A10: Three | B10: 28 | C10: 24 | D10: =SUM(B10:C10) -> 52 | E10: 24 | F10: =B10*E10 -> 672 | G10: =C10*E10 -> 576 | H10: =SUM(F10:G10) -> 1248 | I10: ='Class-III'!AL14 -> #REF! | J10: ='Class-III'!AM14 -> 400 | K10: =SUM(I10:J10) -> #REF! | L10: =J10/G10 -> 0.69444444 | M10: =I10/F10 -> #REF! | N10: =K10/H10 -> #REF! | O10: =AVERAGE(L10:M10) -> #REF!
A11: Four | B11: 21 | C11: 32 | D11: =SUM(B11:C11) -> 53 | E11: 24 | F11: =B11*E11 -> 504 | G11: =C11*E11 -> 768 | H11: =SUM(F11:G11) -> 1272 | I11: ='Class-IV'!AL14 -> 375 | J11: ='Class-IV'!AM14 -> #REF! | K11: =SUM(I11:J11) -> #REF! | L11: =J11/G11 -> #REF! | M11: =I11/F11 -> 0.74404762 | N11: =K11/H11 -> #REF! | O11: =AVERAGE(L11:M11) -> #REF!
A12: Five | B12: 23 | C12: 23 | D12: =SUM(B12:C12) -> 46 | E12: 24 | F12: =B12*E12 -> 552 | G12: =C12*E12 -> 552 | H12: =SUM(F12:G12) -> 1104 | I12: ='Class-V'!AL14 -> 471 | J12: ='Class-V'!AM14 -> 22 | K12: =SUM(I12:J12) -> 493 | L12: =J12/G12 -> 0.039855072 | M12: =I12/F12 -> 0.85326087 | N12: =K12/H12 -> 0.44655797 | O12: =AVERAGE(L12:M12) -> 0.44655797
A13: Six | B13: 17 | C13: 28 | D13: =SUM(B13:C13) -> 45 | E13: 24 | F13: =B13*E13 -> 408 | G13: =C13*E13 -> 672 | H13: =SUM(F13:G13) -> 1080 | I13: =#REF! -> #REF! | J13: =#REF! -> #REF! | K13: =SUM(I13:J13) -> #REF! | L13: =J13/G13 -> #REF! | M13: =I13/F13 -> #REF! | N13: =K13/H13 -> #REF! | O13: =AVERAGE(L13:M13) -> #REF!
A14: Seven | B14: 29 | C14: 19 | D14: =SUM(B14:C14) -> 48 | E14: 24 | F14: =B14*E14 -> 696 | G14: =C14*E14 -> 456 | H14: =SUM(F14:G14) -> 1152 | I14: =#REF! -> #REF! | J14: =#REF! -> #REF! | K14: =SUM(I14:J14) -> #REF! | L14: =J14/G14 -> #REF! | M14: =I14/F14 -> #REF! | N14: =K14/H14 -> #REF! | O14: =AVERAGE(L14:M14) -> #REF!
A15: Eight | B15: 19 | C15: 23 | D15: =SUM(B15:C15) -> 42 | E15: 24 | F15: =B15*E15 -> 456 | G15: =C15*E15 -> 552 | H15: =SUM(F15:G15) -> 1008 | I15: =#REF! -> #REF! | J15: =#REF! -> #REF! | K15: =SUM(I15:J15) -> #REF! | L15: =J15/G15 -> #REF! | M15: =I15/F15 -> #REF! | N15: =K15/H15 -> #REF! | O15: =AVERAGE(L15:M15) -> #REF!
A16: Ninth | B16: 16 | C16: 19 | D16: =SUM(B16:C16) -> 35 | E16: 24 | F16: =B16*E16 -> 384 | G16: =C16*E16 -> 456 | H16: =SUM(F16:G16) -> 840 | I16: =#REF! -> #REF! | J16: =#REF! -> #REF! | K16: =SUM(I16:J16) -> #REF! | L16: =J16/G16 -> #REF! | M16: =I16/F16 -> #REF! | N16: =K16/H16 -> #REF! | O16: =AVERAGE(L16:M16) -> #REF!
A17: Total | B17: =SUM(B6:B16) -> 269 | C17: =SUM(C6:C16) -> 270 | D17: =SUM(D6:D16) -> 539 | E17: =SUM(E6:E16) -> 264 | F17: =SUM(F6:F16) -> 6456 | G17: =SUM(G6:G16) -> 6480 | H17: =SUM(H6:H16) -> 12936 | I17: =SUM(I6:I16) -> #REF! | ... K17: =SUM(K6:K16) -> #REF! | L17: =J17/G17 -> #REF! | M17: =I17/F17 -> #REF! | N17: =AVERAGE(N6:N16) -> #REF! | O17: =AVERAGE(O6:O16) -> #REF!
A18: % | B18: 1 | C18: 1 | D18: 1 | E18: 1 | F18: 1 | G18: 1 | H18: 1 | I18: =I17/F17 -> #REF! | J18: =J17/G17 -> #REF! | K18: =K17/H17 -> #REF! | L18: 0.54 | M18: 0.56 | N18: 0.55 | O18: =AVERAGE(L17:M17) -> #REF!

Sheet ECE 
A1: Goverment high school (SJCHS)
A2: Monthly Attendence Month of November-2024
A3: S.No | B3: Student Name | C3: Father Name | D3: Class | E3: =TEXT(E4,"ddd") -> Fri | F3: =TEXT(F4,"ddd") -> Sat | G3: =TEXT(G4,"ddd") -> Sun | H3: =TEXT(H4,"ddd") -> Mon | I3: =TEXT(I4,"ddd") -> Tue | J3: =TEXT(J4,"ddd") -> Wed | K3: =TEXT(K4,"ddd") -> Thu | L3: =TEXT(L4,"ddd") -> Fri | ... AH3: =TEXT(AH4,"ddd") -> Sat | AI3: Present | AJ3: Absent | AK3: Year 2024
E4: 45597 | F4: 45598 | G4: 45599 | H4: 45600 | I4: 45601 | J4: 45602 | K4: 45603 | L4: 45604 | M4: 45605 | N4: 45606 | O4: 45607 | P4: 45608 | Q4: 45609 | R4: 45610 | S4: 45611 | T4: 45612 | U4: 45613 | V4: 45614 | W4: 45615 | X4: 45616 | Y4: 45617 | Z4: 45618 | AA4: 45619 | AB4: 45620 | AC4: 45621 | AD4: 45622 | AE4: 45623 | AF4: 45624 | AG4: 45625 | AH4: 45626 | AK4: Total days | AL4: =SUM(AL5:AL8) -> 30
A5: 1 | B5: Zahid Ali | C5: Abdullah Panwar | D5: ECE | E5: P | F5: P | G5: SUNDAY - SUNDAY - SUNDAY - SUNDAY - SUNDAY- SUNDAY | H5: P | I5: P | J5: P | K5: L | L5: P | M5: IQBAL DAY - IQBAL DAY - IQBAL DAY - IQBAL DAY - IQBAL DAY | N5: SUNDAY - SUNDAY - SUNDAY - SUNDAY - SUNDAY- SUNDAY | O5: A | P5: P | Q5: P | R5: P | S5: PTM - PTM - PTM - PTM - PTM --TM - PTM - PTM - PTM - PTM | T5: P | U5: SUNDAY - SUNDAY - SUNDAY - SUNDAY - SUNDAY- SUNDAY | V5: A | W5: P | X5: P | Y5: A | Z5: A | AA5: P | AB5: SUNDAY - SUNDAY - SUNDAY - SUNDAY - SUNDAY- SUNDAY | AC5: L | AD5: L | AE5: L | AF5: L | AG5: L | AH5: L | AI5: =COUNTIF(E5:AH5,"P") -> 13 | AJ5: =COUNTIF(E5:AH5,"A") -> 4 | AK5: Working days | AL5: 24
A6: 2 | B6: Hammad Ullah | C6: Muhammad Saleh | D6: ECE | E6: P | F6: P | H6: P | I6: P | J6: P | K6: P | L6: A | O6: P | P6: P | Q6: A | R6: L | T6: L | V6: L | W6: P | X6: P | Y6: P | Z6: P | AA6: P | AC6: P | AD6: P | AE6: P | AF6: P | AG6: P | AH6: P | AI6: =COUNTIF(E6:AH6,"P") -> 19 | AJ6: =COUNTIF(E6:AH6,"A") -> 2 | AK6: Sunday | AL6: 4
A7: 3 | B7: Aamir | C7: Sher Chand | D7: ECE | E7: P | F7: A | H7: P | I7: P | J7: P | K7: P | L7: P | O7: P | P7: P | Q7: P | R7: P | T7: A | V7: P | W7: P | X7: P | Y7: P | Z7: P | AA7: A | AC7: P | AD7: P | AE7: P | AF7: P | AG7: P | AH7: A | AI7: =COUNTIF(E7:AH7,"P") -> 20 | AJ7: =COUNTIF(E7:AH7,"A") -> 4 | AK7: Iqbal Day | AL7: 1
A8: 4 | B8: Muhammad Hassan | C8: Sartaj | D8: ECE | E8: P | F8: A | H8: P | I8: P | J8: P | K8: P | L8: P | O8: P | P8: P | Q8: P | R8: P | T8: P | V8: P | W8: P | X8: P | Y8: P | Z8: P | AA8: A | AC8: P | AD8: P | AE8: A | AF8: P | AG8: P | AH8: A | AI8: =COUNTIF(E8:AH8,"P") -> 20 | AJ8: =COUNTIF(E8:AH8,"A") -> 4 | AK8: PTM | AL8: 1
A9: 5 | B9: Dileep Kumar | C9: Narayon | D9: ECE | E9: P | F9: P | H9: P | I9: A | J9: L | K9: L | L9: L | O9: L | P9: L | Q9: L | R9: L | T9: L | V9: A | W9: A | X9: A | Y9: P | Z9: P | AA9: A | AC9: L | AD9: P | AE9: A | AF9: P | AG9: P | AH9: P | AI9: =COUNTIF(E9:AH9,"P") -> 9 | AJ9: =COUNTIF(E9:AH9,"A") -> 6
A10: 6 | B10: Dileep Kumar | C10: Ranja Ram | D10: ECE | E10: A | F10: P | H10: P | I10: P | J10: P | K10: P | L10: P | O10: A | P10: P | Q10: P | R10: P | T10: P | V10: P | W10: P | X10: P | Y10: P | Z10: P | AA10: P | AC10: P | AD10: P | AE10: A | AF10: P | AG10: P | AH10: P | AI10: =COUNTIF(E10:AH10,"P") -> 21 | AJ10: =COUNTIF(E10:AH10,"A") -> 3
A11: 7 | B11: Ghulam Mustafa | C11: Nali Methal | D11: ECE | E11: P | F11: A | H11: P | I11: P | J11: P | K11: P | L11: A | O11: P | P11: P | Q11: P | R11: A | T11: A | V11: P | W11: P | X11: P | Y11: P | Z11: P | AA11: A | AC11: P | AD11: P | AE11: P | AF11: P | AG11: P | AH11: P | AI11: =COUNTIF(E11:AH11,"P") -> 19 | AJ11: =COUNTIF(E11:AH11,"A") -> 5 | AK11: Present Days Detail
A12: 8 | B12: Zameer Ali | C12: Muhammad Ashraf | D12: ECE | E12: P | F12: A | H12: P | I12: P | J12: P | K12: P | L12: P | O12: P | P12: A | Q12: P | R12: A | T12: P | V12: P | W12: P | X12: P | Y12: P | Z12: P | AA12: P | AC12: P | AD12: A | AE12: P | AF12: P | AG12: P | AH12: P | AI12: =COUNTIF(E12:AH12,"P") -> 20 | AJ12: =COUNTIF(E12:AH12,"A") -> 4 | AK12: Detail | AL12: Boys | AM12: Girls | AN12: Total
A13: 9 | B13: Tahir Khan | C13: Shahid Khan | D13: ECE | E13: P | F13: A | H13: P | I13: P | J13: P | K13: P | L13: P | O13: P | P13: P | Q13: P | R13: A | T13: P | V13: P | W13: P | X13: P | Y13: P | Z13: P | AA13: P | AC13: P | AD13: P | AE13: P | AF13: P | AG13: P | AH13: P | AI13: =COUNTIF(E13:AH13,"P") -> 22 | AJ13: =COUNTIF(E13:AH13,"A") -> 2 | AK13: Due Present days | AL13: =27*$AL$5 -> 648 | AM13: =27*$AL$5 -> 648 | AN13: =SUM(AL13:AM13) -> 1296
A14: 10 | B14: Abdullah | C14: Tariq | D14: ECE | E14: A | F14: A | H14: A | I14: A | J14: A | K14: A | L14: A | O14: A | P14: A | Q14: A | R14: A | T14: P | V14: P | W14: P | X14: P | Y14: P | Z14: P | AA14: P | AC14: P | AD14: P | AE14: P | AF14: P | AG14: P | AH14: P | AI14: =COUNTIF(E14:AH14,"P") -> 13 | AJ14: =COUNTIF(E14:AH14,"A") -> 11 | AK14: Actual present days | AL14: =SUM(AI6,AI9,AI11,AI13,AI16,AI21,AI22,AI23,AI24,AI25,AI26,AI27,AI32,AI34,AI36,AI40,#REF!,#REF!,#REF!,#REF!,#REF!,#REF!,#REF!,#REF!,#REF!,#REF!,#REF!) -> #REF! | AM14: =SUM(AI5,AI7,AI8,AI10,AI12,AI14,AI15,AI17,AI18,AI19,AI20,AI28,AI29,AI30,AI31,AI33,AI35,AI37,AI38,AI39,#REF!,#REF!,#REF!,#REF!,#REF!,#REF!,#REF!) -> #REF! | AN14: =AL14+AM14 -> #REF!
A15: 11 | B15: Muhammad Ali | C15: Naqeeb Zaman | D15: ECE | E15: P | F15: P | H15: A | I15: P | J15: P | K15: P | L15: P | O15: A | P15: P | Q15: A | R15: P | T15: P | V15: P | W15: P | X15: P | Y15: P | Z15: P | AA15: P | AC15: P | AD15: P | AE15: P | AF15: A | AG15: P | AH15: A | AI15: =COUNTIF(E15:AH15,"P") -> 19 | AJ15: =COUNTIF(E15:AH15,"A") -> 5 | AK15: % | AL15: =AL14/AL13 -> #REF! | AM15: =AM14/AM13 -> #REF! | AN15: =AN14/AN13 -> #REF!
A16: 12 | B16: Muhammad Hashim | C16: Ajmal Khan | D16: ECE | E16: P | F16: P | H16: P | I16: P | J16: P | K16: P | L16: P | O16: P | P16: P | Q16: P | R16: P | T16: P | V16: P | W16: P | X16: P | Y16: P | Z16: P | AA16: P | AC16: P | AD16: P | AE16: P | AF16: P | AG16: P | AH16: P | AI16: =COUNTIF(E16:AH16,"P") -> 24 | AJ16: =COUNTIF(E16:AH16,"A") -> 0
A17: 13 | B17: Abbas | C17: Ibrahim | D17: ECE | E17: P | F17: P | H17: P | I17: P | J17: P | K17: P | L17: P | O17: P | P17: P | Q17: A | R17: A | T17: P | V17: P | W17: A | X17: A | Y17: P | Z17: P | AA17: A | AC17: P | AD17: P | AE17: P | AF17: P | AG17: P | AH17: P | AI17: =COUNTIF(E17:AH17,"P") -> 19 | AJ17: =COUNTIF(E17:AH17,"A") -> 5
A18: 14 | B18: Jabbar Ali | C18: Muhammad Hussain | D18: ECE | E18: A | F18: A | H18: A | I18: P | J18: P | K18: A | L18: P | O18: P | P18: A | Q18: P | R18: A | T18: A | V18: A | W18: A | X18: A | Y18: A | Z18: A | AA18: A | AC18: P | AD18: P | AE18: P | AF18: P | AG18: A | AH18: P | AI18: =COUNTIF(E18:AH18,"P") -> 10 | AJ18: =COUNTIF(E18:AH18,"A") -> 14
A19: 15 | B19: Muhammad Gul Hassan | C19: Gul Sher | D19: ECE | E19: P | F19: P | H19: P | I19: P | J19: P | K19: P | L19: A | O19: P | P19: P | Q19: P | R19: P | T19: P | V19: A | W19: A | X19: A | Y19: P | Z19: A | AA19: A | AC19: A | AD19: A | AE19: P | AF19: P | AG19: P | AH19: A | AI19: =COUNTIF(E19:AH19,"P") -> 15 | AJ19: =COUNTIF(E19:AH19,"A") -> 9 | AK19: Absent Days Details
A20: 16 | B20: Salman | C20: Saif Ur Rehman | D20: ECE | E20: P | F20: P | H20: P | I20: P | J20: P | K20: P | L20: P | O20: A | P20: P | Q20: P | R20: P | T20: P | V20: P | W20: P | X20: A | Y20: P | Z20: P | AA20: P | AC20: P | AD20: P | AE20: P | AF20: P | AG20: P | AH20: P | AI20: =COUNTIF(E20:AH20,"P") -> 22 | AJ20: =COUNTIF(E20:AH20,"A") -> 2 | AK20: Detail | AL20: Boys | AM20: Girls | AN20: Total
A21: 17 | B21: Majid | C21: Abdul Majeed | D21: ECE | E21: P | F21: P | H21: P | I21: P | J21: P | K21: P | L21: P | O21: P | P21: P | Q21: P | R21: A | T21: P | V21: P | W21: P | X21: P | Y21: P | Z21: P | AA21: A | AC21: P | AD21: P | AE21: P | AF21: P | AG21: P | AH21: P | AI21: =COUNTIF(E21:AH21,"P") -> 22 | AJ21: =COUNTIF(E21:AH21,"A") -> 2 | AK21: Due Present days | AL21: =27*$AL$5 -> 648 | AM21: =27*$AL$5 -> 648 | AN21: =AL21+AM21 -> 1296
A22: 18 | B22: Mureed Ali | C22: Salman | D22: ECE | E22: P | F22: P | H22: P | I22: P | J22: P | K22: P | L22: P | O22: P | P22: P | Q22: P | R22: A | T22: P | V22: P | W22: P | X22: P | Y22: P | Z22: P | AA22: P | AC22: P | AD22: P | AE22: P | AF22: P | AG22: P | AH22: P | AI22: =COUNTIF(E22:AH22,"P") -> 23 | AJ22: =COUNTIF(E22:AH22,"A") -> 1 | AK22: Absent days | AL22: =AL21-AL14 -> #REF! | AM22: =AM21-AM14 -> #REF! | AN22: =AL22+AM22 -> #REF!
A23: 19 | B23: Sadaf Bibi | C23: Aashiq Ali | D23: ECE | E23: P | F23: P | H23: P | I23: P | J23: P | K23: P | L23: P | O23: P | P23: P | Q23: P | R23: P | T23: P | V23: P | W23: P | X23: P | Y23: P | Z23: P | AA23: P | AC23: A | AD23: P | AE23: P | AF23: P | AG23: P | AH23: P | AI23: =COUNTIF(E23:AH23,"P") -> 23 | AJ23: =COUNTIF(E23:AH23,"A") -> 1 | AK23: % | AL23: =AL22/AL21 -> #REF! | AM23: =AM22/AM21 -> #REF! | AN23: =AN22/AN21 -> #REF!
A24: 20 | B24: Andeesha | C24: Rabeela | D24: ECE | E24: P | F24: P | H24: P | I24: P | J24: P | K24: P | L24: P | O24: P | P24: P | Q24: P | R24: A | T24: P | V24: P | W24: P | X24: P | Y24: A | Z24: P | AA24: P | AC24: P | AD24: P | AE24: P | AF24: P | AG24: P | AH24: P | AI24: =COUNTIF(E24:AH24,"P") -> 22 | AJ24: =COUNTIF(E24:AH24,"A") -> 2
A25: 21 | B25: Rukhsar | C25: Missri | D25: ECE | E25: P | F25: P | H25: P | I25: P | J25: P | K25: P | L25: A | O25: P | P25: P | Q25: P | R25: A | T25: P | V25: P | W25: P | X25: P | Y25: P | Z25: P | AA25: P | AC25: P | AD25: P | AE25: P | AF25: A | AG25: P | AH25: P | AI25: =COUNTIF(E25:AH25,"P") -> 21 | AJ25: =COUNTIF(E25:AH25,"A") -> 3
A26: 22 | B26: Shiwani | C26: Ashoke | D26: ECE | E26: P | F26: P | H26: P | I26: P | J26: P | K26: P | L26: P | O26: P | P26: P | Q26: P | R26: A | T26: P | V26: P | W26: P | X26: P | Y26: A | Z26: P | AA26: P | AC26: P | AD26: P | AE26: P | AF26: P | AG26: P | AH26: P | AI26: =COUNTIF(E26:AH26,"P") -> 22 | AJ26: =COUNTIF(E26:AH26,"A") -> 2
A27: 23 | B27: Saneera Bibi | C27: Muslim | D27: ECE | E27: A | F27: P | H27: P | I27: P | J27: L | K27: L | L27: L | O27: P | P27: A | Q27: P | R27: P | T27: P | V27: P | W27: P | X27: A | Y27: A | Z27: P | AA27: P | AC27: P | AD27: P | AE27: P | AF27: A | AG27: P | AH27: A | AI27: =COUNTIF(E27:AH27,"P") -> 15 | AJ27: =COUNTIF(E27:AH27,"A") -> 6
A28: 24 | B28: Benazeer | C28: Wazeer | D28: ECE | E28: P | F28: P | H28: A | I28: P | J28: P | K28: P | L28: P | O28: P | P28: P | Q28: P | R28: P | T28: P | V28: A | W28: A | X28: A | Y28: A | Z28: A | AA28: A | AC28: P | AD28: P | AE28: P | AF28: P | AG28: P | AH28: A | AI28: =COUNTIF(E28:AH28,"P") -> 16 | AJ28: =COUNTIF(E28:AH28,"A") -> 8
A29: 25 | B29: Seri Devi | C29: Wazeer | D29: ECE | E29: P | F29: P | H29: P | I29: P | J29: P | K29: P | L29: P | O29: P | P29: P | Q29: P | R29: P | T29: P | V29: P | W29: P | X29: P | Y29: P | Z29: P | AA29: P | AC29: A | AD29: P | AE29: P | AF29: P | AG29: P | AH29: P | AI29: =COUNTIF(E29:AH29,"P") -> 23 | AJ29: =COUNTIF(E29:AH29,"A") -> 1
A30: 26 | B30: Rukhsar | C30: Shahid | D30: ECE | E30: P | F30: A | H30: A | I30: P | J30: P | K30: P | L30: P | O30: P | P30: A | Q30: P | R30: P | T30: P | V30: P | W30: P | X30: P | Y30: P | Z30: P | AA30: P | AC30: P | AD30: P | AE30: P | AF30: P | AG30: P | AH30: P | AI30: =COUNTIF(E30:AH30,"P") -> 21 | AJ30: =COUNTIF(E30:AH30,"A") -> 3
A31: 27 | B31: Bushra | C31: Ayaz | D31: ECE | E31: P | F31: P | H31: P | I31: P | J31: P | K31: L | L31: L | O31: A | P31: P | Q31: P | R31: P | T31: A | V31: A | W31: A | X31: P | Y31: P | Z31: P | AA31: P | AC31: P | AD31: P | AE31: P | AF31: P | AG31: P | AH31: P | AI31: =COUNTIF(E31:AH31,"P") -> 18 | AJ31: =COUNTIF(E31:AH31,"A") -> 4
A32: 28 | B32: Shazma | C32: Muhammad Zahid | D32: ECE | E32: P | F32: P | H32: A | I32: A | J32: A | K32: A | L32: P | O32: P | P32: P | Q32: P | R32: A | T32: P | V32: P | W32: P | X32: P | Y32: P | Z32: P | AA32: A | AC32: P | AD32: P | AE32: P | AF32: A | AG32: P | AH32: A | AI32: =COUNTIF(E32:AH32,"P") -> 16 | AJ32: =COUNTIF(E32:AH32,"A") -> 8
A33: 29 | B33: Shazma | C33: Izzat Khan | D33: ECE | E33: P | F33: P | H33: P | I33: P | J33: P | K33: P | L33: P | O33: P | P33: P | Q33: P | R33: P | T33: P | V33: P | W33: P | X33: P | Y33: P | Z33: P | AA33: L | AC33: L | AD33: A | AE33: P | AF33: L | AG33: L | AH33: L | AI33: =COUNTIF(E33:AH33,"P") -> 18 | AJ33: =COUNTIF(E33:AH33,"A") -> 1
A34: 30 | B34: Sanjana | C34: Nadeem Chand | D34: ECE | E34: P | F34: P | H34: P | I34: P | J34: P | K34: P | L34: P | O34: P | P34: P | Q34: P | R34: P | T34: P | V34: P | W34: P | X34: P | Y34: P | Z34: P | AA34: P | AC34: P | AD34: P | AE34: P | AF34: L | AG34: P | AH34: P | AI34: =COUNTIF(E34:AH34,"P") -> 23 | AJ34: =COUNTIF(E34:AH34,"A") -> 0
A35: 31 | B35: Bindu | C35: Addu | D35: ECE | E35: P | F35: P | H35: P | I35: P | J35: P | K35: P | L35: P | O35: P | P35: P | Q35: P | R35: A | T35: P | V35: P | W35: A | X35: P | Y35: P | Z35: P | AA35: P | AC35: P | AD35: P | AE35: P | AF35: P | AG35: P | AH35: A | AI35: =COUNTIF(E35:AH35,"P") -> 21 | AJ35: =COUNTIF(E35:AH35,"A") -> 3
... A40: 36 | B40: Sawera | C40: Amir Shah | D40: ECE | E40: P | F40: P | H40: P | I40: P | J40: P | K40: P | L40: P | O40: P | P40: P | Q40: P | R40: P | T40: P | V40: P | W40: P | X40: P | Y40: P | Z40: P | AA40: P | AC40: P | AD40: P | AE40: P | AF40: A | AG40: P | AH40: A | AI40: =COUNTIF(E40:AH40,"P") -> 22 | AJ40: =COUNTIF(E40:AH40,"A") -> 2

Sheet Kg
A1: Goverment high school (SJCHS)
A2: Monthly Attendence Month of November-2024
A3: S.No | B3: Student Name | C3: Father Name | D3: Class | E3: =TEXT(E4,"ddd") -> Fri | F3: =TEXT(F4,"ddd") -> Sat | G3: =TEXT(G4,"ddd") -> Sun | H3: =TEXT(H4,"ddd") -> Mon | I3: =TEXT(I4,"ddd") -> Tue | J3: =TEXT(J4,"ddd") -> Wed | K3: =TEXT(K4,"ddd") -> Thu | L3: =TEXT(L4,"ddd") -> Fri | ... AH3: =TEXT(AH4,"ddd") -> Sat | AI3: Present | AJ3: Absent | AK3: Year 2024
E4: 45597 | F4: 45598 | G4: 45599 | H4: 45600 | I4: 45601 | J4: 45602 | K4: 45603 | L4: 45604 | M4: 45605 | N4: 45606 | O4: 45607 | P4: 45608 | Q4: 45609 | R4: 45610 | S4: 45611 | T4: 45612 | U4: 45613 | V4: 45614 | W4: 45615 | X4: 45616 | Y4: 45617 | Z4: 45618 | AA4: 45619 | AB4: 45620 | AC4: 45621 | AD4: 45622 | AE4: 45623 | AF4: 45624 | AG4: 45625 | AH4: 45626 | AK4: Total days | AL4: =SUM(AL5:AL8) -> 30
A5: 1 | B5: Hasnain | C5: Khalil Ahmed | D5: Kg | E5: P | F5: P | G5: SUNDAY - SUNDAY - SUNDAY - SUNDAY - SUNDAY- SUNDAY | H5: P | I5: P | J5: P | K5: P | L5: P | M5: IQBAL DAY - IQBAL DAY - IQBAL DAY - IQBAL DAY - IQBAL DAY | N5: SUNDAY - SUNDAY - SUNDAY - SUNDAY - SUNDAY- SUNDAY | O5: A | P5: P | Q5: P | R5: P | S5: P | T5: P | U5: SUNDAY - SUNDAY - SUNDAY - SUNDAY - SUNDAY- SUNDAY | V5: A | W5: P | X5: P | Y5: A | Z5: A | AA5: P | AB5: SUNDAY - SUNDAY - SUNDAY - SUNDAY - SUNDAY- SUNDAY | AC5: L | AD5: P | AE5: P | AF5: P | AG5: P | AH5: L | AI5: =COUNTIF(E5:AH5,"P") -> 19 | AJ5: =COUNTIF(E5:AH5,"A") -> 4 | AK5: Working days | AL5: 24
A6: 2 | B6: Fawad Khan | C6: Baroz Khan | D6: Kg | E6: P | F6: P | H6: P | I6: P | J6: P | K6: P | L6: A | O6: P | P6: P | Q6: A | R6: P | S6: P | T6: P | V6: L | W6: P | X6: P | Y6: P | Z6: P | AA6: P | AC6: P | AD6: P | AE6: P | AF6: P | AG6: P | AH6: P | AI6: =COUNTIF(E6:AH6,"P") -> 22 | AJ6: =COUNTIF(E6:AH6,"A") -> 2 | AK6: Sunday | AL6: 4
A7: 3 | B7: Faheem | C7: Sajid Mehmood | D7: Kg | E7: P | F7: A | H7: P | I7: P | J7: P | K7: P | L7: P | O7: P | P7: P | Q7: P | R7: P | S7: P | T7: A | V7: P | W7: P | X7: P | Y7: P | Z7: P | AA7: A | AC7: P | AD7: P | AE7: P | AF7: P | AG7: P | AH7: A | AI7: =COUNTIF(E7:AH7,"P") -> 21 | AJ7: =COUNTIF(E7:AH7,"A") -> 4 | AK7: Iqbal Day | AL7: 1
A8: 4 | B8: Abu Bakar Sidique | C8: Muhammad Muslim | D8: Kg | E8: P | F8: A | H8: P | I8: P | J8: P | K8: P | L8: P | O8: P | P8: P | Q8: P | R8: P | S8: P | T8: P | V8: P | W8: P | X8: P | Y8: P | Z8: P | AA8: A | AC8: P | AD8: P | AE8: A | AF8: P | AG8: P | AH8: A | AI8: =COUNTIF(E8:AH8,"P") -> 21 | AJ8: =COUNTIF(E8:AH8,"A") -> 4 | AK8: PTM | AL8: 1
A9: 5 | B9: Muhammad Hasnain | C9: Hazar Khan | D9: Kg | E9: P | F9: P | H9: P | I9: A | J9: L | K9: L | L9: L | O9: L | P9: P | Q9: P | R9: P | S9: P | T9: L | V9: A | W9: A | X9: A | Y9: P | Z9: P | AA9: A | AC9: L | AD9: P | AE9: A | AF9: P | AG9: P | AH9: P | AI9: =COUNTIF(E9:AH9,"P") -> 13 | AJ9: =COUNTIF(E9:AH9,"A") -> 6
A10: 6 | B10: Muhammad Sultan | C10: Rahib | D10: Kg | E10: A | F10: P | H10: P | I10: P | J10: P | K10: P | L10: P | O10: A | P10: P | Q10: P | R10: P | S10: P | T10: P | V10: P | W10: P | X10: P | Y10: P | Z10: P | AA10: P | AC10: P | AD10: P | AE10: A | AF10: P | AG10: P | AH10: P | AI10: =COUNTIF(E10:AH10,"P") -> 22 | AJ10: =COUNTIF(E10:AH10,"A") -> 3
A11: 7 | B11: Muhammad Muavia | C11: Basheer Afzal | D11: Kg | E11: P | F11: A | H11: P | I11: P | J11: P | K11: P | L11: A | O11: P | P11: P | Q11: P | R11: A | S11: P | T11: A | V11: P | W11: P | X11: P | Y11: P | Z11: P | AA11: A | AC11: P | AD11: P | AE11: P | AF11: P | AG11: P | AH11: P | AI11: =COUNTIF(E11:AH11,"P") -> 20 | AJ11: =COUNTIF(E11:AH11,"A") -> 5 | AK11: Present Days Detail
A12: 8 | B12: Asad Ullah | C12: Mir Muhammad | D12: Kg | E12: P | F12: A | H12: P | I12: P | J12: A | K12: P | L12: P | O12: P | P12: A | Q12: P | R12: P | S12: P | T12: P | V12: P | W12: P | X12: P | Y12: P | Z12: P | AA12: P | AC12: P | AD12: A | AE12: P | AF12: P | AG12: P | AH12: P | AI12: =COUNTIF(E12:AH12,"P") -> 21 | AJ12: =COUNTIF(E12:AH12,"A") -> 4 | AK12: Detail | AL12: Boys | AM12: Girls | AN12: Total
A13: 9 | B13: Naqeem Ullah | C13: Mir Muhammad | D13: Kg | E13: P | F13: A | H13: P | I13: P | J13: P | K13: P | L13: P | O13: P | P13: P | Q13: P | R13: P | S13: P | T13: P | V13: P | W13: P | X13: P | Y13: P | Z13: P | AA13: P | AC13: P | AD13: P | AE13: P | AF13: P | AG13: P | AH13: P | AI13: =COUNTIF(E13:AH13,"P") -> 24 | AJ13: =COUNTIF(E13:AH13,"A") -> 1 | AK13: Due Present days | AL13: =27*$AL$5 -> 648 | AM13: =27*$AL$5 -> 648 | AN13: =SUM(AL13:AM13) -> 1296
A14: 10 | B14: Muhammad Faizan | C14: Jameel Ahmed | D14: Kg | E14: A | F14: A | H14: P | I14: P | J14: P | K14: P | L14: P | O14: P | P14: P | Q14: P | R14: A | S14: P | T14: P | V14: P | W14: P | X14: P | Y14: P | Z14: P | AA14: P | AC14: P | AD14: P | AE14: P | AF14: P | AG14: P | AH14: P | AI14: =COUNTIF(E14:AH14,"P") -> 22 | AJ14: =COUNTIF(E14:AH14,"A") -> 3 | AK14: Actual present days | AL14: =SUM(AI6,AI9,AI11,AI13,AI16,AI21,AI22,AI23,AI24,AI25,AI26,AI27,AI32,AI34,AI36,AI40,#REF!,#REF!,#REF!,#REF!,#REF!,#REF!,#REF!,#REF!,#REF!,#REF!,#REF!) -> #REF! | AM14: =SUM(AI5,AI7,AI8,AI10,AI12,AI14,AI15,AI17,AI18,AI19,AI20,AI28,AI29,AI30,AI31,AI33,AI35,AI37,AI38,AI39,#REF!,#REF!,#REF!,#REF!,#REF!,#REF!,#REF!) -> #REF! | AN14: =AL14+AM14 -> #REF!
A15: 11 | B15: Muhammad Sufyan | C15: Nadeem Ahmed | D15: Kg | E15: P | F15: P | H15: A | I15: P | J15: P | K15: P | L15: P | O15: A | P15: P | Q15: A | R15: P | S15: P | T15: P | V15: P | W15: P | X15: P | Y15: P | Z15: P | AA15: P | AC15: P | AD15: P | AE15: P | AF15: A | AG15: P | AH15: A | AI15: =COUNTIF(E15:AH15,"P") -> 20 | AJ15: =COUNTIF(E15:AH15,"A") -> 5 | AK15: % | AL15: =AL14/AL13 -> #REF! | AM15: =AM14/AM13 -> #REF! | AN15: =AN14/AN13 -> #REF!
A16: 12 | B16: Muhammad Yaseen | C16: Ghos Bukhsh | D16: Kg | E16: P | F16: P | H16: P | I16: P | J16: P | K16: P | L16: P | O16: P | P16: P | Q16: P | R16: P | S16: P | T16: P | V16: P | W16: P | X16: P | Y16: P | Z16: P | AA16: P | AC16: P | AD16: P | AE16: P | AF16: P | AG16: P | AH16: P | AI16: =COUNTIF(E16:AH16,"P") -> 25 | AJ16: =COUNTIF(E16:AH16,"A") -> 0
A17: 13 | B17: Rahul | C17: Ramesh | D17: Kg | E17: P | F17: P | H17: P | I17: P | J17: P | K17: P | L17: P | O17: P | P17: P | Q17: A | R17: A | S17: P | T17: P | V17: P | W17: A | X17: A | Y17: P | Z17: P | AA17: A | AC17: P | AD17: P | AE17: P | AF17: P | AG17: P | AH17: P | AI17: =COUNTIF(E17:AH17,"P") -> 20 | AJ17: =COUNTIF(E17:AH17,"A") -> 5
A18: 14 | B18: Rehan | C18: Nawaz Ali | D18: Kg | E18: P | F18: P | H18: A | I18: P | J18: P | K18: A | L18: P | O18: P | P18: A | Q18: P | R18: A | S18: P | T18: A | V18: P | W18: P | X18: P | Y18: P | Z18: P | AA18: P | AC18: P | AD18: P | AE18: P | AF18: P | AG18: A | AH18: P | AI18: =COUNTIF(E18:AH18,"P") -> 19 | AJ18: =COUNTIF(E18:AH18,"A") -> 6
A19: 15 | B19: Anesh Kumar | C19: Manthar | D19: Kg | E19: P | F19: P | H19: P | I19: P | J19: P | K19: P | L19: A | O19: P | P19: P | Q19: P | R19: P | S19: P | T19: P | V19: A | W19: A | X19: A | Y19: P | Z19: A | AA19: A | AC19: A | AD19: A | AE19: P | AF19: P | AG19: P | AH19: A | AI19: =COUNTIF(E19:AH19,"P") -> 16 | AJ19: =COUNTIF(E19:AH19,"A") -> 9 | AK19: Absent Days Details
A20: 16 | B20: Muhammad Arsalan Khan | C20: Ajmal Khan | D20: Kg | E20: P | F20: P | H20: P | I20: P | J20: P | K20: P | L20: P | O20: A | P20: P | Q20: P | R20: P | S20: P | T20: P | V20: P | W20: P | X20: A | Y20: P | Z20: P | AA20: P | AC20: P | AD20: P | AE20: P | AF20: P | AG20: P | AH20: P | AI20: =COUNTIF(E20:AH20,"P") -> 23 | AJ20: =COUNTIF(E20:AH20,"A") -> 2 | AK20: Detail | AL20: Boys | AM20: Girls | AN20: Total
A21: 17 | B21: Muhammad Sufyan | C21: Muhammad Rehman | D21: Kg | E21: P | F21: P | H21: P | I21: P | J21: P | K21: P | L21: P | O21: P | P21: P | Q21: P | R21: A | S21: P | T21: P | V21: P | W21: P | X21: P | Y21: P | Z21: P | AA21: A | AC21: P | AD21: P | AE21: P | AF21: P | AG21: P | AH21: P | AI21: =COUNTIF(E21:AH21,"P") -> 23 | AJ21: =COUNTIF(E21:AH21,"A") -> 2 | AK21: Due Present days | AL21: =27*$AL$5 -> 648 | AM21: =27*$AL$5 -> 648 | AN21: =AL21+AM21 -> 1296
A22: 18 | B22: Tanveer | C22: Adu | D22: Kg | E22: P | F22: P | H22: P | I22: P | J22: P | K22: P | L22: P | O22: P | P22: P | Q22: P | R22: A | S22: P | T22: P | V22: P | W22: P | X22: P | Y22: P | Z22: P | AA22: P | AC22: P | AD22: P | AE22: P | AF22: P | AG22: P | AH22: P | AI22: =COUNTIF(E22:AH22,"P") -> 24 | AJ22: =COUNTIF(E22:AH22,"A") -> 1 | AK22: Absent days | AL22: =AL21-AL14 -> #REF! | AM22: =AM21-AM14 -> #REF! | AN22: =AL22+AM22 -> #REF!
A23: 19 | B23: Kashif | C23: Siraj Khan | D23: Kg | E23: P | F23: P | H23: P | I23: P | J23: P | K23: P | L23: P | O23: P | P23: P | Q23: P | R23: P | S23: P | T23: P | V23: P | W23: P | X23: P | Y23: P | Z23: P | AA23: P | AC23: A | AD23: P | AE23: P | AF23: P | AG23: P | AH23: P | AI23: =COUNTIF(E23:AH23,"P") -> 24 | AJ23: =COUNTIF(E23:AH23,"A") -> 1 | AK23: % | AL23: =AL22/AL21 -> #REF! | AM23: =AM22/AM21 -> #REF! | AN23: =AN22/AN21 -> #REF!
A24: 20 | B24: Hussain | C24: Sartaj | D24: Kg | E24: P | F24: P | H24: P | I24: P | J24: P | K24: P | L24: P | O24: P | P24: P | Q24: P | R24: A | S24: P | T24: P | V24: P | W24: P | X24: P | Y24: A | Z24: P | AA24: P | AC24: P | AD24: P | AE24: P | AF24: P | AG24: P | AH24: P | AI24: =COUNTIF(E24:AH24,"P") -> 23 | AJ24: =COUNTIF(E24:AH24,"A") -> 2
A25: 21 | B25: Muhammad Ullah | C25: Nemat | D25: Kg | E25: P | F25: P | H25: P | I25: P | J25: P | K25: P | L25: A | O25: P | P25: P | Q25: P | R25: A | S25: P | T25: P | V25: P | W25: P | X25: P | Y25: P | Z25: P | AA25: P | AC25: P | AD25: P | AE25: P | AF25: A | AG25: P | AH25: P | AI25: =COUNTIF(E25:AH25,"P") -> 22 | AJ25: =COUNTIF(E25:AH25,"A") -> 3
A26: 22 | B26: Ali Abbas | C26: Altaf Hussain | D26: Kg | E26: P | F26: P | H26: P | I26: P | J26: P | K26: P | L26: P | O26: P | P26: P | Q26: P | R26: A | S26: P | T26: P | V26: P | W26: P | X26: P | Y26: A | Z26: P | AA26: P | AC26: P | AD26: P | AE26: P | AF26: P | AG26: P | AH26: P | AI26: =COUNTIF(E26:AH26,"P") -> 23 | AJ26: =COUNTIF(E26:AH26,"A") -> 2
A27: 23 | B27: Abdul Rehman | C27: Ayaz | D27: Kg | E27: A | F27: P | H27: P | I27: P | J27: P | K27: P | L27: P | O27: P | P27: A | Q27: P | R27: P | S27: P | T27: P | V27: P | W27: P | X27: A | Y27: A | Z27: P | AA27: P | AC27: P | AD27: P | AE27: P | AF27: A | AG27: P | AH27: A | AI27: =COUNTIF(E27:AH27,"P") -> 19 | AJ27: =COUNTIF(E27:AH27,"A") -> 6
A28: 24 | B28: Sohra | C28: Sher Chand | D28: Kg | E28: P | F28: P | H28: A | I28: P | J28: P | K28: P | L28: P | O28: P | P28: P | Q28: P | R28: P | S28: P | T28: P | V28: A | W28: A | X28: A | Y28: A | Z28: A | AA28: A | AC28: P | AD28: P | AE28: P | AF28: P | AG28: P | AH28: A | AI28: =COUNTIF(E28:AH28,"P") -> 17 | AJ28: =COUNTIF(E28:AH28,"A") -> 8
A29: 25 | B29: Sagar | C29: Rukesh | D29: Kg | E29: P | F29: P | H29: P | I29: P | J29: P | K29: P | L29: P | O29: P | P29: P | Q29: P | R29: P | S29: P | T29: P | V29: P | W29: P | X29: P | Y29: P | Z29: P | AA29: P | AC29: A | AD29: P | AE29: P | AF29: P | AG29: P | AH29: P | AI29: =COUNTIF(E29:AH29,"P") -> 24 | AJ29: =COUNTIF(E29:AH29,"A") -> 1
A30: 26 | B30: Meena | C30: Mahashiv | D30: Kg | E30: P | F30: A | H30: A | I30: P | J30: P | K30: P | L30: P | O30: P | P30: A | Q30: P | R30: P | S30: P | T30: P | V30: P | W30: P | X30: P | Y30: P | Z30: P | AA30: P | AC30: P | AD30: P | AE30: P | AF30: P | AG30: P | AH30: P | AI30: =COUNTIF(E30:AH30,"P") -> 22 | AJ30: =COUNTIF(E30:AH30,"A") -> 3
A31: 27 | B31: Kiran | C31: Nadeem Chand | D31: Kg | E31: P | F31: P | H31: P | I31: P | J31: P | K31: L | L31: L | O31: A | P31: P | Q31: P | R31: P | S31: P | T31: A | V31: A | W31: A | X31: P | Y31: P | Z31: P | AA31: P | AC31: P | AD31: P | AE31: P | AF31: P | AG31: P | AH31: P | AI31: =COUNTIF(E31:AH31,"P") -> 19 | AJ31: =COUNTIF(E31:AH31,"A") -> 4
A32: 28 | B32: Zahra Batool | C32: Hazar Khan | D32: Kg | E32: P | F32: P | H32: A | I32: A | J32: A | K32: A | L32: P | O32: P | P32: P | Q32: P | R32: A | S32: P | T32: P | V32: P | W32: P | X32: P | Y32: P | Z32: P | AA32: A | AC32: P | AD32: P | AE32: P | AF32: A | AG32: P | AH32: A | AI32: =COUNTIF(E32:AH32,"P") -> 17 | AJ32: =COUNTIF(E32:AH32,"A") -> 8
A33: 29 | B33: Sadia Bibi | C33: Muslim | D33: Kg | E33: P | F33: P | H33: P | I33: P | J33: P | K33: P | L33: P | O33: P | P33: P | Q33: P | R33: P | S33: P | T33: P | V33: P | W33: P | X33: P | Y33: P | Z33: P | AA33: L | AC33: L | AD33: A | AE33: P | AF33: L | AG33: L | AH33: L | AI33: =COUNTIF(E33:AH33,"P") -> 19 | AJ33: =COUNTIF(E33:AH33,"A") -> 1
A34: 30 | B34: Areesha | C34: Abdullah Panwar | D34: Kg | E34: P | F34: P | H34: P | I34: P | J34: P | K34: P | L34: P | O34: P | P34: P | Q34: P | R34: P | S34: P | T34: P | V34: P | W34: P | X34: P | Y34: P | Z34: P | AA34: P | AC34: P | AD34: P | AE34: P | AF34: L | AG34: P | AH34: P | AI34: =COUNTIF(E34:AH34,"P") -> 24 | AJ34: =COUNTIF(E34:AH34,"A") -> 0
A35: 31 | B35: Misra | C35: Gul Hassan | D35: Kg | E35: P | F35: P | H35: P | I35: P | J35: P | K35: P | L35: P | O35: P | P35: P | Q35: P | R35: A | S35: P | T35: P | V35: P | W35: A | X35: P | Y35: P | Z35: P | AA35: P | AC35: P | AD35: P | AE35: P | AF35: P | AG35: P | AH35: A | AI35: =COUNTIF(E35:AH35,"P") -> 22 | AJ35: =COUNTIF(E35:AH35,"A") -> 3
... A45: 41 | B45: Sanam Batool | C45: Khalid Hussain Khaskheli | D45: Kg | E45: P | F45: P | H45: P | I45: P | J45: P | K45: P | L45: P | O45: P | P45: P | Q45: P | R45: P | S45: P | T45: P | V45: P | W45: P | X45: P | Y45: P | Z45: P | AA45: P | AC45: P | AD45: P | AE45: P | AF45: A | AG45: P | AH45: A | AI45: =COUNTIF(E45:AH45,"P") -> 23 | AJ45: =COUNTIF(E45:AH45,"A") -> 2

Sheet Class-I
A1: Goverment high school (SJCHS)
A2: Monthly Attendence Month of November-2024
A3: S.No | B3: Student Name | C3: Father Name | D3: Class | E3: =TEXT(E4,"ddd") -> Fri | F3: =TEXT(F4,"ddd") -> Sat | G3: =TEXT(G4,"ddd") -> Sun | H3: =TEXT(H4,"ddd") -> Mon | I3: =TEXT(I4,"ddd") -> Tue | J3: =TEXT(J4,"ddd") -> Wed | K3: =TEXT(K4,"ddd") -> Thu | L3: =TEXT(L4,"ddd") -> Fri | ... AH3: =TEXT(AH4,"ddd") -> Sat | AI3: Present | AJ3: Absent | AK3: Year 2024
E4: 45597 | F4: 45598 | G4: 45599 | H4: 45600 | I4: 45601 | J4: 45602 | K4: 45603 | L4: 45604 | M4: 45605 | N4: 45606 | O4: 45607 | P4: 45608 | Q4: 45609 | R4: 45610 | S4: 45611 | T4: 45612 | U4: 45613 | V4: 45614 | W4: 45615 | X4: 45616 | Y4: 45617 | Z4: 45618 | AA4: 45619 | AB4: 45620 | AC4: 45621 | AD4: 45622 | AE4: 45623 | AF4: 45624 | AG4: 45625 | AH4: 45626 | AK4: Total days | AL4: =SUM(AL5:AL8) -> 30
A5: 1 | B5: Sajjad | C5: Nazeer Ali | D5: One | E5: P | F5: P | G5: SUNDAY - SUNDAY - SUNDAY - SUNDAY - SUNDAY - SUNDAY - SUNDAY - SUNDAY - SUNDAY | H5: P | I5: P | J5: P | K5: P | L5: P | M5: IQBAL DAY - IQBAL DAY - IQBAL DAY - IQBAL DAY - IQBAL DAY | N5: SUNDAY - SUNDAY - SUNDAY - SUNDAY - SUNDAY - SUNDAY - SUNDAY - SUNDAY - SUNDAY | O5: P | P5: P | Q5: P | R5: P | S5: P | T5: P | U5: SUNDAY - SUNDAY - SUNDAY - SUNDAY - SUNDAY - SUNDAY - SUNDAY - SUNDAY - SUNDAY | V5: P | W5: P | X5: P | Y5: P | Z5: P | AA5: P | AB5: SUNDAY - SUNDAY - SUNDAY - SUNDAY - SUNDAY - SUNDAY - SUNDAY - SUNDAY - SUNDAY | AC5: P | AD5: P | AE5: P | AF5: P | AG5: P | AH5: P | AI5: =COUNTIF(E5:AH5,"P") -> 25 | AJ5: =COUNTIF(E5:AH5,"A") -> 0 | AK5: Working days | AL5: 24
A6: 2 | B6: Hassan Raza | C6: Muhammad Saleem | D6: One | E6: P | F6: A | H6: P | I6: P | J6: P | K6: P | L6: P | O6: P | P6: P | Q6: P | R6: P | S6: A | T6: P | V6: P | W6: A | X6: P | Y6: A | Z6: P | AA6: A | AC6: A | AD6: A | AE6: A | AF6: A | AG6: A | AH6: A | AI6: =COUNTIF(E6:AH6,"P") -> 14 | AJ6: =COUNTIF(E6:AH6,"A") -> 11 | AK6: Sunday | AL6: 4
A7: 3 | B7: Waseem | C7: Sajid Mehmood | D7: One | E7: P | F7: P | H7: P | I7: P | J7: A | K7: P | L7: P | O7: P | P7: P | Q7: P | R7: P | S7: P | T7: P | V7: P | W7: P | X7: P | Y7: P | Z7: P | AA7: P | AC7: P | AD7: P | AE7: P | AF7: P | AG7: P | AH7: P | AI7: =COUNTIF(E7:AH7,"P") -> 24 | AJ7: =COUNTIF(E7:AH7,"A") -> 1 | AK7: Iqbal Day | AL7: 1
A8: 4 | B8: Wassan | C8: Narayan | D8: One | E8: P | F8: P | H8: P | I8: P | J8: P | K8: P | L8: P | O8: P | P8: P | Q8: P | R8: P | S8: P | T8: P | V8: P | W8: P | X8: P | Y8: P | Z8: P | AA8: P | AC8: P | AD8: P | AE8: P | AF8: P | AG8: P | AH8: P | AI8: =COUNTIF(E8:AH8,"P") -> 25 | AJ8: =COUNTIF(E8:AH8,"A") -> 0 | AK8: PTM | AL8: 1
A9: 5 | B9: Dana | C9: Magla | D9: One | E9: P | F9: A | H9: P | I9: P | J9: P | K9: P | L9: P | O9: P | P9: P | Q9: P | R9: P | S9: P | T9: P | V9: P | W9: A | X9: P | Y9: P | Z9: P | AA9: A | AC9: P | AD9: P | AE9: P | AF9: P | AG9: P | AH9: P | AI9: =COUNTIF(E9:AH9,"P") -> 22 | AJ9: =COUNTIF(E9:AH9,"A") -> 3
A10: 6 | B10: Ashoke | C10: Magla | D10: One | E10: P | F10: P | H10: A | I10: P | J10: P | K10: P | L10: P | O10: P | P10: P | Q10: P | R10: P | S10: A | T10: P | V10: P | W10: P | X10: P | Y10: A | Z10: P | AA10: A | AC10: P | AD10: P | AE10: P | AF10: P | AG10: A | AH10: P | AI10: =COUNTIF(E10:AH10,"P") -> 20 | AJ10: =COUNTIF(E10:AH10,"A") -> 5
A11: 7 | B11: Awais | C11: Muhammad Saleh | D11: One | E11: P | F11: A | H11: P | I11: P | J11: P | K11: P | L11: P | O11: P | P11: P | Q11: P | R11: P | S11: P | T11: P | V11: P | W11: P | X11: P | Y11: P | Z11: P | AA11: P | AC11: P | AD11: P | AE11: P | AF11: P | AG11: P | AH11: P | AI11: =COUNTIF(E11:AH11,"P") -> 24 | AJ11: =COUNTIF(E11:AH11,"A") -> 1 | AK11: Present Days Detail
A12: 8 | B12: Hasnain | C12: Khalil Ahmed | D12: One | E12: P | F12: P | H12: P | I12: P | J12: A | K12: P | L12: P | O12: P | P12: P | Q12: P | R12: P | S12: P | T12: P | V12: P | W12: A | X12: A | Y12: A | Z12: P | AA12: A | AC12: P | AD12: P | AE12: P | AF12: P | AG12: P | AH12: P | AI12: =COUNTIF(E12:AH12,"P") -> 20 | AJ12: =COUNTIF(E12:AH12,"A") -> 5 | AK12: Detail | AL12: Boys | AM12: Girls | AN12: Total
A13: 9 | B13: Muhammad Umair | C13: Nadeem Ahmed | D13: One | E13: P | F13: P | H13: P | I13: P | J13: P | K13: A | L13: P | O13: A | P13: P | Q13: A | R13: P | S13: P | T13: P | V13: A | W13: P | X13: P | Y13: P | Z13: P | AA13: A | AC13: A | AD13: P | AE13: P | AF13: P | AG13: P | AH13: P | AI13: =COUNTIF(E13:AH13,"P") -> 19 | AJ13: =COUNTIF(E13:AH13,"A") -> 6 | AK13: Due Present days | AL13: =32*$AL$5 -> 768 | AM13: =24*$AL$5 -> 576 | AN13: =SUM(AL13:AM13) -> 1344
A14: 10 | B14: Habib Ullah | C14: Muhammad Yaqoob | D14: One | E14: A | F14: P | H14: A | I14: P | J14: A | K14: P | L14: P | O14: P | P14: P | Q14: P | R14: P | S14: P | T14: P | V14: P | W14: P | X14: P | Y14: P | Z14: P | AA14: P | AC14: P | AD14: P | AE14: P | AF14: P | AG14: P | AH14: P | AI14: =COUNTIF(E14:AH14,"P") -> 22 | AJ14: =COUNTIF(E14:AH14,"A") -> 3 | AK14: Actual present days | AL14: =SUM(AI29:AI54) -> 572 | AM14: =SUM(AI5:AI28) -> 516 | AN14: =AL14+AM14 -> 1088
A15: 11 | B15: Borya | C15: Magla | D15: One | E15: P | F15: P | H15: P | I15: P | J15: P | K15: P | L15: P | O15: P | P15: P | Q15: P | R15: P | S15: P | T15: P | V15: P | W15: P | X15: P | Y15: P | Z15: A | AA15: P | AC15: P | AD15: P | AE15: P | AF15: P | AG15: P | AH15: P | AI15: =COUNTIF(E15:AH15,"P") -> 24 | AJ15: =COUNTIF(E15:AH15,"A") -> 1 | AK15: % | AL15: =AL14/AL13 -> 0.74479167 | AM15: =AM14/AM13 -> 0.89583333 | AN15: =AN14/AN13 -> 0.80952381
A16: 12 | B16: Ankit | C16: Ashoke | D16: One | E16: P | F16: P | H16: P | I16: P | J16: P | K16: P | L16: A | O16: P | P16: P | Q16: P | R16: P | S16: A | T16: P | V16: P | W16: A | X16: P | Y16: P | Z16: P | AA16: P | AC16: P | AD16: P | AE16: P | AF16: P | AG16: P | AH16: P | AI16: =COUNTIF(E16:AH16,"P") -> 22 | AJ16: =COUNTIF(E16:AH16,"A") -> 3
A17: 13 | B17: Sanjeet | C17: Addu | D17: One | E17: P | F17: A | H17: A | I17: P | J17: P | K17: A | L17: P | O17: P | P17: P | Q17: P | R17: P | S17: P | T17: P | V17: A | W17: P | X17: P | Y17: P | Z17: A | AA17: P | AC17: A | AD17: A | AE17: P | AF17: P | AG17: P | AH17: P | AI17: =COUNTIF(E17:AH17,"P") -> 18 | AJ17: =COUNTIF(E17:AH17,"A") -> 7
A18: 14 | B18: Muhammad Irfan | C18: Basheer Afzal | D18: One | E18: P | F18: P | H18: P | I18: P | J18: P | K18: P | L18: P | O18: P | P18: P | Q18: P | R18: P | S18: A | T18: P | V18: P | W18: P | X18: A | Y18: P | Z18: P | AA18: A | AC18: A | AD18: P | AE18: A | AF18: P | AG18: A | AH18: P | AI18: =COUNTIF(E18:AH18,"P") -> 19 | AJ18: =COUNTIF(E18:AH18,"A") -> 6
A19: 15 | B19: Moosa | C19: Akhtar Khan | D19: One | E19: P | F19: P | H19: P | I19: P | J19: P | K19: A | L19: A | O19: P | P19: P | Q19: P | R19: P | S19: A | T19: P | V19: P | W19: P | X19: P | Y19: A | Z19: P | AA19: P | AC19: A | AD19: P | AE19: P | AF19: P | AG19: A | AH19: A | AI19: =COUNTIF(E19:AH19,"P") -> 18 | AJ19: =COUNTIF(E19:AH19,"A") -> 7 | AK19: Absent Days Details
A20: 16 | B20: Adil Azad | C20: Altaf Hussain | D20: One | E20: P | F20: A | H20: P | I20: P | J20: P | K20: P | L20: P | O20: P | P20: P | Q20: P | R20: P | S20: P | T20: P | V20: P | W20: P | X20: P | Y20: P | Z20: A | AA20: P | AC20: P | AD20: P | AE20: P | AF20: P | AG20: P | AH20: P | AI20: =COUNTIF(E20:AH20,"P") -> 23 | AJ20: =COUNTIF(E20:AH20,"A") -> 2 | AK20: Detail | AL20: Boys | AM20: Girls | AN20: Total
A21: 17 | B21: Shiraz | C21: Siraj Khan | D21: One | E21: P | F21: P | H21: P | I21: P | J21: A | K21: P | L21: P | O21: P | P21: P | Q21: P | R21: P | S21: A | T21: P | V21: P | W21: P | X21: P | Y21: P | Z21: P | AA21: P | AC21: P | AD21: P | AE21: P | AF21: P | AG21: P | AH21: P | AI21: =COUNTIF(E21:AH21,"P") -> 23 | AJ21: =COUNTIF(E21:AH21,"A") -> 2 | AK21: Due Present days | AL21: =32*$AL$5 -> 768 | AM21: =24*$AL$5 -> 576 | AN21: =AL21+AM21 -> 1344
A22: 18 | B22: Muhammad Saeed | C22: Naik Badshah | D22: One | E22: P | F22: P | H22: P | I22: P | J22: P | K22: P | L22: P | O22: P | P22: P | Q22: P | R22: P | S22: A | T22: P | V22: P | W22: P | X22: P | Y22: P | Z22: P | AA22: P | AC22: P | AD22: P | AE22: P | AF22: P | AG22: P | AH22: P | AI22: =COUNTIF(E22:AH22,"P") -> 24 | AJ22: =COUNTIF(E22:AH22,"A") -> 1 | AK22: Absent days | AL22: =AL21-AL14 -> 196 | AM22: =AM21-AM14 -> 60 | AN22: =AL22+AM22 -> 256
A23: 19 | B23: Ghulam Hussain | C23: Waqar Ahmed | D23: One | E23: A | F23: P | H23: P | I23: P | J23: P | K23: P | L23: A | O23: P | P23: A | Q23: P | R23: P | S23: P | T23: P | V23: P | W23: P | X23: P | Y23: P | Z23: P | AA23: P | AC23: P | AD23: P | AE23: P | AF23: P | AG23: P | AH23: P | AI23: =COUNTIF(E23:AH23,"P") -> 22 | AJ23: =COUNTIF(E23:AH23,"A") -> 3 | AK23: % | AL23: =AL22/AL21 -> 0.25520833 | AM23: =AM22/AM21 -> 0.10416667 | AN23: =AN22/AN21 -> 0.19047619
A24: 20 | B24: Gul Hassan | C24: Waqar Ahmed | D24: One | E24: P | F24: P | H24: P | I24: P | J24: P | K24: P | L24: P | O24: P | P24: P | Q24: P | R24: P | S24: P | T24: P | V24: P | W24: P | X24: P | Y24: P | Z24: P | AA24: P | AC24: P | AD24: P | AE24: P | AF24: P | AG24: P | AH24: P | AI24: =COUNTIF(E24:AH24,"P") -> 25 | AJ24: =COUNTIF(E24:AH24,"A") -> 0
A25: 21 | B25: Sheroz Jan | C25: Jan Muhammad | D25: One | E25: P | F25: P | H25: P | I25: P | J25: P | K25: A | L25: P | O25: P | P25: P | Q25: P | R25: A | S25: P | T25: P | V25: P | W25: P | X25: P | Y25: P | Z25: P | AA25: P | AC25: P | AD25: P | AE25: P | AF25: P | AG25: P | AH25: P | AI25: =COUNTIF(E25:AH25,"P") -> 23 | AJ25: =COUNTIF(E25:AH25,"A") -> 2
A26: 22 | B26: Muhammad Hussain | C26: Muhammad Hayat | D26: One | E26: P | F26: P | H26: P | I26: P | J26: P | K26: P | L26: P | O26: P | P26: P | Q26: P | R26: P | S26: P | T26: P | V26: P | W26: P | X26: P | Y26: P | Z26: P | AA26: P | AC26: P | AD26: P | AE26: P | AF26: P | AG26: A | AH26: A | AI26: =COUNTIF(E26:AH26,"P") -> 23 | AJ26: =COUNTIF(E26:AH26,"A") -> 2
A27: 23 | B27: Muhammad Irfan | C27: Muhammad Hayat | D27: One | E27: P | F27: P | H27: P | I27: P | J27: A | K27: P | L27: P | O27: P | P27: P | Q27: A | R27: A | S27: A | T27: P | V27: P | W27: P | X27: P | Y27: P | Z27: A | AA27: P | AC27: L | AD27: L | AE27: P | AF27: P | AG27: P | AH27: P | AI27: =COUNTIF(E27:AH27,"P") -> 18 | AJ27: =COUNTIF(E27:AH27,"A") -> 5
A28: 24 | B28: Mairaj | C28: Manzoor Ahmed | D28: One | E28: A | F28: P | H28: P | I28: P | J28: P | K28: P | L28: A | O28: A | P28: P | Q28: P | R28: P | S28: A | T28: A | V28: P | W28: P | X28: P | Y28: A | Z28: P | AA28: P | AC28: P | AD28: P | AE28: P | AF28: P | AG28: P | AH28: P | AI28: =COUNTIF(E28:AH28,"P") -> 19 | AJ28: =COUNTIF(E28:AH28,"A") -> 6
A29: 25 | B29: Rehan | C29: Mamtaz Ali | D29: One | E29: P | F29: A | H29: P | I29: P | J29: P | K29: P | L29: P | O29: P | P29: P | Q29: P | R29: P | S29: P | T29: A | V29: P | W29: P | X29: P | Y29: P | Z29: P | AA29: P | AC29: P | AD29: P | AE29: P | AF29: P | AG29: P | AH29: P | AI29: =COUNTIF(E29:AH29,"P") -> 23 | AJ29: =COUNTIF(E29:AH29,"A") -> 2
A30: 26 | B30: Iman | C30: Anees | D30: One | E30: P | F30: A | H30: P | I30: P | J30: P | K30: P | L30: P | O30: P | P30: P | Q30: P | R30: P | S30: P | T30: A | V30: P | W30: P | X30: A | Y30: P | Z30: P | AA30: A | AC30: A | AD30: A | AE30: P | AF30: P | AG30: P | AH30: A | AI30: =COUNTIF(E30:AH30,"P") -> 18 | AJ30: =COUNTIF(E30:AH30,"A") -> 7
A31: 27 | B31: Muskan | C31: Gul Hassan | D31: One | E31: P | F31: P | H31: P | I31: P | J31: P | K31: P | L31: P | O31: P | P31: P | Q31: P | R31: P | S31: P | T31: P | V31: P | W31: P | X31: A | Y31: P | Z31: P | AA31: P | AC31: P | AD31: P | AE31: P | AF31: P | AG31: P | AH31: P | AI31: =COUNTIF(E31:AH31,"P") -> 24 | AJ31: =COUNTIF(E31:AH31,"A") -> 1
A32: 28 | B32: Waseema | C32: Allah Bachayo | D32: One | E32: P | F32: A | H32: A | I32: P | J32: P | K32: A | L32: P | O32: P | P32: P | Q32: A | R32: P | S32: P | T32: A | V32: P | W32: P | X32: P | Y32: A | Z32: P | AA32: A | AC32: P | AD32: P | AE32: P | AF32: P | AG32: P | AH32: P | AI32: =COUNTIF(E32:AH32,"P") -> 18 | AJ32: =COUNTIF(E32:AH32,"A") -> 7
A33: 29 | B33: Pirya Farooq Sarjo | C33: Muhammad Shoaib | D33: One | E33: A | F33: P | H33: P | I33: P | J33: P | K33: P | L33: P | O33: P | P33: P | Q33: A | R33: A | S33: A | T33: A | V33: A | W33: A | X33: L | Y33: P | Z33: A | AA33: A | AC33: P | AD33: P | AE33: P | AF33: P | AG33: P | AH33: P | AI33: =COUNTIF(E33:AH33,"P") -> 15 | AJ33: =COUNTIF(E33:AH33,"A") -> 9
A34: 30 | B34: Zainab Bibi | C34: Baroz Khan | D34: One | E34: P | F34: P | H34: P | I34: P | J34: P | K34: P | L34: P | O34: P | P34: P | Q34: P | R34: P | S34: P | T34: P | V34: P | W34: P | X34: P | Y34: P | Z34: P | AA34: P | AC34: P | AD34: P | AE34: P | AF34: P | AG34: P | AH34: P | AI34: =COUNTIF(E34:AH34,"P") -> 25 | AJ34: =COUNTIF(E34:AH34,"A") -> 0
A35: 31 | B35: Muskan | C35: Saeed Ur Rehman | D35: One | E35: A | F35: P | H35: P | I35: P | J35: P | K35: A | L35: A | O35: P | P35: P | Q35: P | R35: P | S35: P | T35: P | V35: P | W35: P | X35: P | Y35: P | Z35: A | AA35: P | AC35: P | AD35: P | AE35: P | AF35: P | AG35: P | AH35: P | AI35: =COUNTIF(E35:AH35,"P") -> 21 | AJ35: =COUNTIF(E35:AH35,"A") -> 4
... A54: 26 | B54: Sumaiya | C54: Muhammad Rafeeque | D54: One | E54: A | F54: P | H54: P | I54: P | J54: A | K54: P | L54: P | O54: P | P54: P | Q54: P | R54: P | S54: P | T54: A | V54: P | W54: P | X54: A | Y54: P | Z54: P | AA54: P | AC54: P | AD54: P | AE54: P | AF54: A | AG54: P | AH54: P | AI54: =COUNTIF(E54:AH54,"P") -> 20 | AJ54: =COUNTIF(E54:AH54,"A") -> 5

Sheet Class-II
A1: Goverment High School (SJCHS)
A2: Monthly Attendence Month of November-2024
A3: S.No | B3: Student Name | C3: Father Name | D3: Class | E3: =TEXT(E4,"ddd") -> Fri | F3: =TEXT(F4,"ddd") -> Sat | G3: =TEXT(G4,"ddd") -> Sun | H3: =TEXT(H4,"ddd") -> Mon | I3: =TEXT(I4,"ddd") -> Tue | J3: =TEXT(J4,"ddd") -> Wed | K3: =TEXT(K4,"ddd") -> Thu | L3: =TEXT(L4,"ddd") -> Fri | ... AH3: =TEXT(AH4,"ddd") -> Sat | AI3: Present | AJ3: Absent | AK3: Year 2024
E4: 45597 | F4: 45598 | G4: 45599 | H4: 45600 | I4: 45601 | J4: 45602 | K4: 45603 | L4: 45604 | M4: 45605 | N4: 45606 | O4: 45607 | P4: 45608 | Q4: 45609 | R4: 45610 | S4: 45611 | T4: 45612 | U4: 45613 | V4: 45614 | W4: 45615 | X4: 45616 | Y4: 45617 | Z4: 45618 | AA4: 45619 | AB4: 45620 | AC4: 45621 | AD4: 45622 | AE4: 45623 | AF4: 45624 | AG4: 45625 | AH4: 45626 | AK4: Total days | AL4: =SUM(AL5:AL8) -> 30
A5: 1 | B5: Ghawa Ram | C5: Khalil ahmed | D5: Two | E5: P | F5: P | G5: SUNDAY - SUNDAY - SUNDAY - SUNDAY - SUNDAY - SUNDAY | H5: P | I5: P | J5: P | K5: P | L5: P | M5: IQBAL DAY - IQBAL DAY - IQBAL DAY - IQBAL DAY - IQBAL DAY | N5: SUNDAY - SUNDAY - SUNDAY - SUNDAY - SUNDAY - SUNDAY | O5: P | P5: P | Q5: P | R5: A | S5: P | T5: P | U5: SUNDAY - SUNDAY - SUNDAY - SUNDAY - SUNDAY - SUNDAY | V5: P | W5: P | X5: A | Y5: P | Z5: A | AA5: P | AB5: SUNDAY - SUNDAY - SUNDAY - SUNDAY - SUNDAY - SUNDAY | AC5: P | AD5: A | AE5: P | AF5: P | AG5: P | AH5: A | AI5: =COUNTIF(E5:AH5,"P") -> 20 | AJ5: =COUNTIF(E5:AH5,"A") -> 5 | AK5: Working days | AL5: 25
A6: 2 | B6: Arman | C6: Zubair Ahmed | D6: Two | E6: P | F6: P | H6: P | I6: P | J6: P | K6: P | L6: P | O6: P | P6: P | Q6: P | R6: P | S6: P | T6: P | V6: P | W6: P | X6: P | Y6: P | Z6: A | AA6: P | AC6: P | AD6: P | AE6: P | AF6: P | AG6: P | AH6: P | AI6: =COUNTIF(E6:AH6,"P") -> 24 | AJ6: =COUNTIF(E6:AH6,"A") -> 1 | AK6: Sunday | AL6: 4
A7: 3 | B7: Naveed Hussain | C7: Hazar Khan | D7: Two | E7: P | F7: P | H7: P | I7: P | J7: P | K7: P | L7: P | O7: P | P7: P | Q7: P | R7: P | S7: P | T7: P | V7: P | W7: P | X7: P | Y7: P | Z7: P | AA7: P | AC7: P | AD7: P | AE7: P | AF7: P | AG7: P | AH7: P | AI7: =COUNTIF(E7:AH7,"P") -> 25 | AJ7: =COUNTIF(E7:AH7,"A") -> 0 | AK7: Iqbal Day | AL7: 1
A8: 4 | B8: Kaleem Ullah | C8: Muhammad Yaqoob | D8: Two | E8: P | F8: P | H8: P | I8: P | J8: P | K8: P | L8: P | O8: P | P8: P | Q8: P | R8: P | S8: P | T8: P | V8: L | W8: P | X8: P | Y8: P | Z8: P | AA8: P | AC8: P | AD8: P | AE8: P | AF8: A | AG8: A | AH8: A | AI8: =COUNTIF(E8:AH8,"P") -> 21 | AJ8: =COUNTIF(E8:AH8,"A") -> 3
A9: 5 | B9: Amjad | C9: Sher Alam | D9: Two | E9: P | F9: P | H9: P | I9: P | J9: P | K9: P | L9: P | O9: P | P9: P | Q9: P | R9: P | S9: A | T9: P | V9: P | W9: P | X9: P | Y9: P | Z9: P | AA9: A | AC9: P | AD9: P | AE9: A | AF9: P | AG9: P | AH9: P | AI9: =COUNTIF(E9:AH9,"P") -> 22 | AJ9: =COUNTIF(E9:AH9,"A") -> 3
A10: 6 | B10: Ghulam Umar Abdul Rehman | C10: Ghulam Rabbani | D10: Two | E10: P | F10: P | H10: A | I10: P | J10: P | K10: P | L10: P | O10: A | P10: P | Q10: P | R10: P | S10: P | T10: P | V10: P | W10: P | X10: P | Y10: P | Z10: A | AA10: P | AC10: P | AD10: P | AE10: P | AF10: A | AG10: P | AH10: P | AI10: =COUNTIF(E10:AH10,"P") -> 21 | AJ10: =COUNTIF(E10:AH10,"A") -> 4
A11: 7 | B11: Mudassir Shah | C11: Amir Shah | D11: Two | E11: P | F11: P | H11: A | I11: P | J11: P | K11: P | L11: A | O11: P | P11: P | Q11: P | R11: P | S11: P | T11: P | V11: P | W11: P | X11: P | Y11: P | Z11: P | AA11: P | AC11: A | AD11: P | AE11: P | AF11: P | AG11: P | AH11: A | AI11: =COUNTIF(E11:AH11,"P") -> 21 | AJ11: =COUNTIF(E11:AH11,"A") -> 4 | AK11: Present Days Detail
A12: 8 | B12: Talha | C12: Haneef Ullah | D12: Two | E12: P | F12: A | H12: P | I12: P | J12: P | K12: P | L12: P | O12: P | P12: P | Q12: P | R12: P | S12: P | T12: P | V12: P | W12: P | X12: P | Y12: P | Z12: P | AA12: P | AC12: P | AD12: P | AE12: P | AF12: P | AG12: P | AH12: P | AI12: =COUNTIF(E12:AH12,"P") -> 24 | AJ12: =COUNTIF(E12:AH12,"A") -> 1 | AK12: Detail | AL12: Boys | AM12: Girls | AN12: Total
A13: 9 | B13: Muhammad Noman | C13: Jameel Ahmed | D13: Two | E13: P | F13: P | H13: P | I13: P | J13: P | K13: P | L13: P | O13: P | P13: P | Q13: P | R13: P | S13: P | T13: P | V13: P | W13: P | X13: P | Y13: P | Z13: P | AA13: P | AC13: P | AD13: P | AE13: P | AF13: P | AG13: P | AH13: P | AI13: =COUNTIF(E13:AH13,"P") -> 25 | AJ13: =COUNTIF(E13:AH13,"A") -> 0 | AK13: Due Present days | AL13: =26*$AL$5 -> 650 | AM13: =26*$AL$5 -> 650 | AN13: =SUM(AL13:AM13) -> 1300
A14: 10 | B14: Naresh | C14: Rabeela | D14: Two | E14: P | F14: P | H14: P | I14: P | J14: P | K14: P | L14: P | O14: A | P14: P | Q14: P | R14: P | S14: P | T14: P | V14: P | W14: P | X14: P | Y14: P | Z14: P | AA14: P | AC14: P | AD14: P | AE14: P | AF14: P | AG14: P | AH14: P | AI14: =COUNTIF(E14:AH14,"P") -> 24 | AJ14: =COUNTIF(E14:AH14,"A") -> 1 | AK14: Actual present days | AL14: =SUM(AI31:AI51) -> 464 | AM14: =SUM(AI5:AI30) -> 555 | AN14: =AL14+AM14 -> 1019
A15: 11 | B15: Veer Wazir | C15: Wazir Mil | D15: Two | E15: P | F15: A | H15: P | I15: P | J15: P | K15: P | L15: P | O15: P | P15: A | Q15: A | R15: P | S15: P | T15: A | V15: P | W15: P | X15: P | Y15: P | Z15: P | AA15: P | AC15: P | AD15: P | AE15: A | AF15: P | AG15: P | AH15: A | AI15: =COUNTIF(E15:AH15,"P") -> 19 | AJ15: =COUNTIF(E15:AH15,"A") -> 6 | AK15: % | AL15: =AL14/AL13 -> 0.71384615 | AM15: =AM14/AM13 -> 0.85384615 | AN15: =AN14/AN13 -> 0.78384615
A16: 12 | B16: Wishaal | C16: Nadeem Chand | D16: Two | E16: P | F16: P | H16: P | I16: P | J16: P | K16: P | L16: P | O16: P | P16: P | Q16: P | R16: P | S16: A | T16: P | V16: A | W16: P | X16: P | Y16: A | Z16: P | AA16: P | AC16: P | AD16: P | AE16: P | AF16: P | AG16: P | AH16: P | AI16: =COUNTIF(E16:AH16,"P") -> 22 | AJ16: =COUNTIF(E16:AH16,"A") -> 3
A17: 13 | B17: Shah Jahan | C17: Liaqat Ali Brohi | D17: Two | E17: P | F17: P | H17: P | I17: P | J17: P | K17: P | L17: P | O17: P | P17: P | Q17: P | R17: P | S17: P | T17: P | V17: P | W17: P | X17: P | Y17: P | Z17: P | AA17: P | AC17: P | AD17: P | AE17: P | AF17: P | AG17: P | AH17: P | AI17: =COUNTIF(E17:AH17,"P") -> 25 | AJ17: =COUNTIF(E17:AH17,"A") -> 0
A18: 14 | B18: Siraj | C18: Allah Bachayo | D18: Two | E18: P | F18: P | H18: P | I18: P | J18: P | K18: P | L18: P | O18: P | P18: P | Q18: P | R18: P | S18: P | T18: P | V18: P | W18: P | X18: P | Y18: P | Z18: P | AA18: P | AC18: P | AD18: P | AE18: P | AF18: P | AG18: P | AH18: P | AI18: =COUNTIF(E18:AH18,"P") -> 25 | AJ18: =COUNTIF(E18:AH18,"A") -> 0
A19: 15 | B19: Muzammil | C19: Muhammad Ashraf | D19: Two | E19: A | F19: P | H19: P | I19: P | J19: P | K19: P | L19: P | O19: P | P19: P | Q19: P | R19: A | S19: P | T19: P | V19: P | W19: P | X19: P | Y19: P | Z19: P | AA19: P | AC19: P | AD19: P | AE19: P | AF19: P | AG19: P | AH19: P | AI19: =COUNTIF(E19:AH19,"P") -> 23 | AJ19: =COUNTIF(E19:AH19,"A") -> 2 | AK19: Absent Days Details
A20: 16 | B20: Murtaza | C20: Najb Uddin | D20: Two | E20: P | F20: P | H20: A | I20: P | J20: A | K20: P | L20: P | O20: P | P20: P | Q20: P | R20: P | S20: P | T20: P | V20: P | W20: P | X20: P | Y20: P | Z20: P | AA20: P | AC20: P | AD20: A | AE20: P | AF20: P | AG20: P | AH20: P | AI20: =COUNTIF(E20:AH20,"P") -> 22 | AJ20: =COUNTIF(E20:AH20,"A") -> 3 | AK20: Detail | AL20: Boys | AM20: Girls | AN20: Total
A21: 17 | B21: Haseeb Ullah | C21: Wahid Bukhsh | D21: Two | E21: P | F21: P | H21: P | I21: P | J21: A | K21: P | L21: A | O21: A | P21: A | Q21: P | R21: P | S21: P | T21: P | V21: A | W21: A | X21: A | Y21: A | Z21: A | AA21: A | AC21: P | AD21: P | AE21: P | AF21: A | AG21: P | AH21: A | AI21: =COUNTIF(E21:AH21,"P") -> 13 | AJ21: =COUNTIF(E21:AH21,"A") -> 12 | AK21: Due Present days | AL21: =32*$AL$5 -> 800 | AM21: =24*$AL$5 -> 600 | AN21: =AL21+AM21 -> 1400
A22: 18 | B22: Zubair | C22: Gul Muhammad | D22: Two | E22: P | F22: P | H22: P | I22: P | J22: P | K22: P | L22: P | O22: P | P22: P | Q22: P | R22: P | S22: P | T22: P | V22: P | W22: P | X22: P | Y22: P | Z22: P | AA22: P | AC22: P | AD22: P | AE22: P | AF22: P | AG22: P | AH22: P | AI22: =COUNTIF(E22:AH22,"P") -> 25 | AJ22: =COUNTIF(E22:AH22,"A") -> 0 | AK22: Absent days | AL22: =AL21-AL14 -> 336 | AM22: =AM21-AM14 -> 45 | AN22: =AL22+AM22 -> 381
A23: 19 | B23: Sajjad Ali | C23: Inayat Ali | D23: Two | E23: P | F23: P | H23: P | I23: P | J23: P | K23: P | L23: P | O23: P | P23: P | Q23: P | R23: P | S23: P | T23: P | V23: P | W23: P | X23: P | Y23: P | Z23: P | AA23: P | AC23: P | AD23: P | AE23: P | AF23: P | AG23: P | AH23: P | AI23: =COUNTIF(E23:AH23,"P") -> 25 | AJ23: =COUNTIF(E23:AH23,"A") -> 0 | AK23: % | AL23: =AL22/AL21 -> 0.42 | AM23: =AM22/AM21 -> 0.075 | AN23: =AN22/AN21 -> 0.27214286
A24: 20 | B24: Nadir Khan | C24: Akhtar Khan | D24: Two | E24: P | F24: P | H24: P | I24: P | J24: P | K24: P | L24: P | O24: P | P24: P | Q24: P | R24: A | S24: L | T24: L | V24: L | W24: P | X24: P | Y24: P | Z24: P | AA24: P | AC24: P | AD24: P | AE24: P | AF24: P | AG24: P | AH24: P | AI24: =COUNTIF(E24:AH24,"P") -> 21 | AJ24: =COUNTIF(E24:AH24,"A") -> 1
A25: 21 | B25: Muhammad Khan | C25: Muhammad Rafiq | D25: Two | E25: P | F25: P | H25: P | I25: P | J25: P | K25: P | L25: P | O25: P | P25: P | Q25: P | R25: P | S25: P | T25: P | V25: P | W25: P | X25: P | Y25: P | Z25: P | AA25: P | AC25: P | AD25: P | AE25: P | AF25: P | AG25: P | AH25: A | AI25: =COUNTIF(E25:AH25,"P") -> 24 | AJ25: =COUNTIF(E25:AH25,"A") -> 1
A26: 22 | B26: Abdul Hafeez | C26: Muhammad Rafiq | D26: Two | E26: P | F26: A | H26: L | I26: L | J26: L | K26: L | L26: L | O26: L | P26: L | Q26: L | R26: L | S26: L | T26: P | V26: P | W26: P | X26: P | Y26: P | Z26: P | AA26: P | AC26: P | AD26: P | AE26: P | AF26: P | AG26: P | AH26: P | AI26: =COUNTIF(E26:AH26,"P") -> 14 | AJ26: =COUNTIF(E26:AH26,"A") -> 1
A27: 23 | B27: Muhammad Bilal | C27: Shabeer | D27: Two | E27: P | F27: P | H27: P | I27: P | J27: P | K27: P | L27: P | O27: P | P27: P | Q27: P | R27: P | S27: P | T27: P | V27: P | W27: P | X27: P | Y27: P | Z27: P | AA27: P | AC27: P | AD27: P | AE27: P | AF27: P | AG27: P | AH27: P | AI27: =COUNTIF(E27:AH27,"P") -> 25 | AJ27: =COUNTIF(E27:AH27,"A") -> 0
A28: 24 | B28: Gulzar Ali | C28: Mushtaq | D28: Two | E28: P | F28: A | H28: A | I28: A | J28: A | K28: A | L28: A | O28: A | P28: A | Q28: A | R28: A | S28: A | T28: A | V28: A | W28: A | X28: A | Y28: A | Z28: A | AA28: A | AC28: A | AD28: A | AE28: A | AF28: A | AG28: A | AH28: A | AI28: =COUNTIF(E28:AH28,"P") -> 1 | AJ28: =COUNTIF(E28:AH28,"A") -> 24
A29: 25 | B29: Adnan Khan | C29: Noor Ali Shah | D29: Two | E29: P | F29: P | H29: P | I29: P | J29: P | K29: P | L29: P | O29: A | P29: A | Q29: A | R29: A | S29: P | T29: P | V29: P | W29: P | X29: P | Y29: P | Z29: P | AA29: P | AC29: P | AD29: P | AE29: P | AF29: P | AG29: P | AH29: P | AI29: =COUNTIF(E29:AH29,"P") -> 21 | AJ29: =COUNTIF(E29:AH29,"A") -> 4
A30: 26 | B30: Afzal Khan | C30: Ajmal Khan | D30: Two | E30: A | F30: A | H30: P | I30: P | J30: P | K30: P | L30: P | O30: P | P30: P | Q30: P | R30: P | S30: P | T30: P | V30: P | W30: P | X30: P | Y30: P | Z30: P | AA30: P | AC30: P | AD30: P | AE30: P | AF30: P | AG30: P | AH30: P | AI30: =COUNTIF(E30:AH30,"P") -> 23 | AJ30: =COUNTIF(E30:AH30,"A") -> 2
A31: 1 | B31: Ghaffar | C31: Abdullah Panwar | D31: Two | E31: P | F31: P | H31: P | I31: P | J31: P | K31: P | L31: P | O31: P | P31: P | Q31: P | R31: P | S31: P | T31: P | V31: P | W31: P | X31: L | Y31: P | Z31: P | AA31: P | AC31: P | AD31: P | AE31: P | AF31: P | AG31: P | AH31: P | AI31: =COUNTIF(E31:AH31,"P") -> 24 | AJ31: =COUNTIF(E31:AH31,"A") -> 0
A32: 2 | B32: Rehan | C32: Shah Hussain | D32: Two | E32: P | F32: P | H32: P | I32: P | J32: P | K32: P | L32: P | O32: P | P32: P | Q32: P | R32: P | S32: P | T32: P | V32: P | W32: P | X32: P | Y32: P | Z32: P | AA32: P | AC32: P | AD32: P | AE32: P | AF32: P | AG32: P | AH32: P | AI32: =COUNTIF(E32:AH32,"P") -> 25 | AJ32: =COUNTIF(E32:AH32,"A") -> 0
A33: 3 | B33: Muhammad Zubair | C33: Gul Sher | D33: Two | E33: P | F33: P | H33: P | I33: P | J33: P | K33: P | L33: P | O33: P | P33: P | Q33: P | R33: P | S33: P | T33: A | V33: P | W33: P | X33: P | Y33: A | Z33: P | AA33: P | AC33: P | AD33: P | AE33: P | AF33: P | AG33: P | AH33: A | AI33: =COUNTIF(E33:AH33,"P") -> 22 | AJ33: =COUNTIF(E33:AH33,"A") -> 3
A34: 4 | B34: Iqra Bibi | C34: Naqeeb Zaman | D34: Two | E34: P | F34: P | H34: P | I34: P | J34: P | K34: P | L34: P | O34: P | P34: P | Q34: P | R34: P | S34: P | T34: A | V34: P | W34: P | X34: P | Y34: P | Z34: P | AA34: P | AC34: P | AD34: P | AE34: P | AF34: P | AG34: P | AH34: P | AI34: =COUNTIF(E34:AH34,"P") -> 24 | AJ34: =COUNTIF(E34:AH34,"A") -> 1
A35: 5 | B35: Sajida | C35: Abdul Majeed Tanori | D35: Two | E35: P | F35: P | H35: L | I35: L | J35: L | K35: L | L35: L | O35: L | P35: L | Q35: L | R35: L | S35: L | T35: L | V35: L | W35: L | X35: L | Y35: A | Z35: A | AA35: A | AC35: A | AD35: A | AE35: A | AF35: A | AG35: A | AH35: A | AI35: =COUNTIF(E35:AH35,"P") -> 2 | AJ35: =COUNTIF(E35:AH35,"A") -> 9
... A51: 21 | B51: Kulsoom Ali | C51: Ali Hassan | D51: Two | E51: P | F51: P | H51: P | I51: P | J51: P | K51: P | L51: P | O51: P | P51: P | Q51: P | R51: P | S51: A | T51: P | V51: P | W51: P | X51: P | Y51: P | Z51: P | AA51: P | AC51: P | AD51: P | AE51: P | AF51: P | AG51: P | AH51: P | AI51: =COUNTIF(E51:AH51,"P") -> 24 | AJ51: =COUNTIF(E51:AH51,"A") -> 1

Sheet Class-III
A1: Goverment high school (SJCHS)
A2: Monthly Attendence Month of November-2024
A3: S.No | B3: Student Name | C3: Father Name | D3: Class | E3: =TEXT(E4,"ddd") -> Fri | F3: =TEXT(F4,"ddd") -> Sat | G3: =TEXT(G4,"ddd") -> Sun | H3: =TEXT(H4,"ddd") -> Mon | I3: =TEXT(I4,"ddd") -> Tue | J3: =TEXT(J4,"ddd") -> Wed | K3: =TEXT(K4,"ddd") -> Thu | L3: =TEXT(L4,"ddd") -> Fri | ... AH3: =TEXT(AH4,"ddd") -> Sat | AI3: Present | AJ3: Absent | AK3: Year 2024
E4: 45597 | F4: 45598 | G4: 45599 | H4: 45600 | I4: 45601 | J4: 45602 | K4: 45603 | L4: 45604 | M4: 45605 | N4: 45606 | O4: 45607 | P4: 45608 | Q4: 45609 | R4: 45610 | S4: 45611 | T4: 45612 | U4: 45613 | V4: 45614 | W4: 45615 | X4: 45616 | Y4: 45617 | Z4: 45618 | AA4: 45619 | AB4: 45620 | AC4: 45621 | AD4: 45622 | AE4: 45623 | AF4: 45624 | AG4: 45625 | AH4: 45626 | AK4: Total days | AL4: =SUM(AL5:AL8) -> 30
