Workbook

Sheet Compile Sheet-November-2024
A4: Class | B4: Total Enrolment & Attendance November-24
B5: Boys | C5: Girls | D5: Total | E5: total working Days | F5: Total working days-Boys | G5: Total working days-Girls | H5: Total working days-All | I5: P-Days Boys | J5: P-Days Girls | K5: P-Days All | L5: Percentage-Girls | M5: Percentage-Boys | N5: Total Percentage | O5: Total average
A6: ECE (ROSE) | B6: 30 | C6: 23 | D6: =SUM(B6:C6) -> 53 | E6: 12 | F6: =B6*E6 -> 360 | G6: =C6*E6 -> 276 | H6: =SUM(F6:G6) -> 636 | I6: ='ECE (ROSE)'!$AN$14 -> 355 | J6: ='ECE (ROSE)'!AO14 -> 268 | K6: =SUM(I6:J6) -> 623 | L6: =J6/G6 -> 0.97101449 | M6: =I6/F6 -> 0.98611111 | N6: =K6/H6 -> 0.97955975 | O6: =AVERAGE(L6:M6) -> 0.9785628
A7: ECE (Daffodils) | B7: 32 | C7: 24 | D7: =SUM(B7:C7) -> 56 | E7: 12 | F7: =B7*E7 -> 384 | G7: =C7*E7 -> 288 | H7: =SUM(F7:G7) -> 672 | I7: ='ECE (Daffodills)'!$AN$14 -> 378 | J7: ='ECE (Daffodills)'!$AO$14 -> 286 | K7: =SUM(I7:J7) -> 664 | L7: =J7/G7 -> 0.99305556 | M7: =I7/F7 -> 0.984375 | N7: =K7/H7 -> 0.98809524 | O7: =AVERAGE(L7:M7) -> 0.98871528
A8: One | B8: 32 | C8: 23 | D8: =SUM(B8:C8) -> 55 | E8: 11 | F8: =B8*E8 -> 352 | G8: =C8*E8 -> 253 | H8: =SUM(F8:G8) -> 605 | I8: ='Class-I'!$AN$14 -> 334 | J8: ='Class-I'!$AO$14 -> 235 | K8: =SUM(I8:J8) -> 569 | L8: =J8/G8 -> 0.92885375 | M8: =I8/F8 -> 0.94886364 | N8: =K8/H8 -> 0.94049587 | O8: =AVERAGE(L8:M8) -> 0.9388587
A9: Two | B9: 24 | C9: 23 | D9: =SUM(B9:C9) -> 47 | E9: 11 | F9: =B9*E9 -> 264 | G9: =C9*E9 -> 253 | H9: =SUM(F9:G9) -> 517 | I9: ='Class-II'!$AN$14 -> 263 | J9: ='Class-II'!$AO$14 -> 252 | K9: =SUM(I9:J9) -> 515 | L9: =J9/G9 -> 0.99604743 | M9: =I9/F9 -> 0.99621212 | N9: =K9/H9 -> 0.99613153 | O9: =AVERAGE(L9:M9) -> 0.99612978
A10: Three | B10: 26 | C10: 23 | D10: =SUM(B10:C10) -> 49 | E10: 11 | F10: =B10*E10 -> 286 | G10: =C10*E10 -> 253 | H10: =SUM(F10:G10) -> 539 | I10: ='Class-III'!$AN$14 -> 275 | J10: ='Class-III'!AO14 -> 247 | K10: =SUM(I10:J10) -> 522 | L10: =J10/G10 -> 0.97628458 | M10: =I10/F10 -> 0.96153846 | N10: =K10/H10 -> 0.96846011 | O10: =AVERAGE(L10:M10) -> 0.96891152
A11: Four | B11: 20 | C11: 32 | D11: =SUM(B11:C11) -> 52 | E11: 10 | F11: =B11*E11 -> 200 | G11: =C11*E11 -> 320 | H11: =SUM(F11:G11) -> 520 | I11: ='Class-IV'!AN14 -> 178 | J11: ='Class-IV'!AO14 -> 305 | K11: =SUM(I11:J11) -> 483 | L11: =J11/G11 -> 0.953125 | M11: =I11/F11 -> 0.89 | N11: =K11/H11 -> 0.92884615 | O11: =AVERAGE(L11:M11) -> 0.9215625
A12: Five | B12: 23 | C12: 23 | D12: =SUM(B12:C12) -> 46 | E12: 10 | F12: =B12*E12 -> 230 | G12: =C12*E12 -> 230 | H12: =SUM(F12:G12) -> 460 | I12: ='Class-V'!AN14 -> 229 | J12: ='Class-V'!AO14 -> 225 | K12: =SUM(I12:J12) -> 454 | L12: =J12/G12 -> 0.97826087 | M12: =I12/F12 -> 0.99565217 | N12: =K12/H12 -> 0.98695652 | O12: =AVERAGE(L12:M12) -> 0.98695652
A13: Six | B13: 16 | C13: 25 | D13: =SUM(B13:C13) -> 41 | E13: 11 | F13: =B13*E13 -> 176 | G13: =C13*E13 -> 275 | H13: =SUM(F13:G13) -> 451 | I13: ='Class-VI'!AN13 -> 175 | J13: ='Class-VI'!AO13 -> 272 | K13: =SUM(I13:J13) -> 447 | L13: =J13/G13 -> 0.98909091 | M13: =I13/F13 -> 0.99431818 | N13: =K13/H13 -> 0.99113082 | O13: =AVERAGE(L13:M13) -> 0.99170455
A14: Seven | B14: 27 | C14: 18 | D14: =SUM(B14:C14) -> 45 | E14: 12 | F14: =B14*E14 -> 324 | G14: =C14*E14 -> 216 | H14: =SUM(F14:G14) -> 540 | I14: ='Class-VII'!AM14 -> 306 | J14: ='Class-VII'!AN14 -> 212 | K14: =SUM(I14:J14) -> 518 | L14: =J14/G14 -> 0.98148148 | M14: =I14/F14 -> 0.94444444 | N14: =K14/H14 -> 0.95925926 | O14: =AVERAGE(L14:M14) -> 0.96296296
A15: Eight | B15: 19 | C15: 22 | D15: =SUM(B15:C15) -> 41 | E15: 10 | F15: =B15*E15 -> 190 | G15: =C15*E15 -> 220 | H15: =SUM(F15:G15) -> 410 | I15: ='Class-VIII'!AN14 -> 176 | J15: ='Class-VIII'!AO14 -> 214 | K15: =SUM(I15:J15) -> 390 | L15: =J15/G15 -> 0.97272727 | M15: =I15/F15 -> 0.92631579 | N15: =K15/H15 -> 0.95121951 | O15: =AVERAGE(L15:M15) -> 0.94952153
A16: Ninth | B16: 16 | C16: 19 | D16: =SUM(B16:C16) -> 35 | E16: 10 | F16: =B16*E16 -> 160 | G16: =C16*E16 -> 190 | H16: =SUM(F16:G16) -> 350 | I16: ='Class-IX'!AN14 -> 140 | J16: ='Class-IX'!AO14 -> 175 | K16: =SUM(I16:J16) -> 315 | L16: =J16/G16 -> 0.92105263 | M16: =I16/F16 -> 0.875 | N16: =K16/H16 -> 0.9 | O16: =AVERAGE(L16:M16) -> 0.89802632
A17: Total | B17: =SUM(B6:B16) -> 265 | C17: =SUM(C6:C16) -> 255 | D17: =SUM(D6:D16) -> 520 | E17: =SUM(E6:E16) -> 120 | F17: =SUM(F6:F16) -> 2926 | G17: =SUM(G6:G16) -> 2774 | H17: =SUM(H6:H16) -> 5700 | I17: =SUM(I6:I16) -> 2809 | ... K17: =SUM(K6:K16) -> 5500 | L17: =J17/G17 -> 0.97007931 | M17: =I17/F17 -> 0.96001367 | N17: =AVERAGE(N6:N16) -> 0.96274134 | O17: =AVERAGE(O6:O16) -> 0.96199204
A18: % | B18: 1 | C18: 1 | D18: 1 | E18: 1 | F18: 1 | G18: 1 | H18: 1 | I18: =I17/F17 -> 0.96001367 | J18: =J17/G17 -> 0.97007931 | K18: =K17/H17 -> 0.96491228 | L18: 0.54 | M18: 0.56 | N18: 0.55 | O18: =AVERAGE(L17:M17) -> 0.96504649

Sheet ECE (ROSE)
A1: Goverment high school (SJCHS)
A2: Monthly Attendence Month of March-2025
A3: S.No | B3: GR | C3: Student Name | D3: Father Name | E3: Class | F3: =TEXT(F4,"ddd") -> Sat | G3: =TEXT(G4,"ddd") -> Sun | H3: =TEXT(H4,"ddd") -> Mon | I3: =TEXT(I4,"ddd") -> Tue | J3: =TEXT(J4,"ddd") -> Wed | K3: =TEXT(K4,"ddd") -> Thu | L3: =TEXT(L4,"ddd") -> Fri | M3: =TEXT(M4,"ddd") -> Sat | ... AJ3: =TEXT(AJ4,"ddd") -> Mon | AK3: Present | AL3: Absent | AM3: Year 2024
F4: 45717 | G4: 45718 | H4: 45719 | I4: 45720 | J4: 45721 | K4: 45722 | L4: 45723 | M4: 45724 | N4: 45725 | O4: 45726 | P4: 45727 | Q4: 45728 | R4: 45729 | S4: 45730 | T4: 45731 | U4: 45732 | V4: 45733 | W4: 45734 | X4: 45735 | Y4: 45736 | Z4: 45737 | AA4: 45738 | AB4: 45739 | AC4: 45740 | AD4: 45741 | AE4: 45742 | AF4: 45743 | AG4: 45744 | AH4: 45745 | AI4: 45746 | AJ4: 45747 | AM4: Total days | AN4: =SUM(AN5:AN8) -> 31
A5: 1 | B5: 112 | C5: Eman | D5: Shahnawaz Khan | E5: ECE | F5: P | G5: SUNDAY - SUNDAY - SUNDAY - SUNDAY - SUNDAY - SUNDAY | H5: P | I5: p | J5: P | K5: P | L5: P | M5: P | N5: SUNDAY - SUNDAY - SUNDAY - SUNDAY - SUNDAY - SUNDAY | O5: P | P5: P | Q5: A | R5: P | S5: p | T5: Examination | AK5: =COUNTIF(F5:AJ5,"P") -> 11 | AL5: =COUNTIF(F5:AJ5,"A") -> 1 | AM5: Working days | AN5: 12
A6: 2 | B6: 135 | C6: Masooma | D6: Faiq Ali | E6: ECE | F6: P | H6: P | I6: p | J6: P | K6: P | L6: P | M6: P | O6: P | P6: P | Q6: P | R6: P | S6: p | AK6: =COUNTIF(F6:AJ6,"P") -> 12 | AL6: =COUNTIF(F6:AJ6,"A") -> 0 | AM6: Sunday | AN6: 2
A7: 3 | B7: 137 | C7: Hafsa Batool | D7: Gul Mohammad Chandio | E7: ECE | F7: P | H7: P | I7: p | J7: P | K7: P | L7: P | M7: P | O7: P | P7: P | Q7: P | R7: P | S7: p | AK7: =COUNTIF(F7:AJ7,"P") -> 12 | AL7: =COUNTIF(F7:AJ7,"A") -> 0 | AM7: Examination | AN7: 17
A8: 4 | B8: 173 | C8: Hoor Fatima | D8: Shahid Ali | E8: ECE | F8: P | H8: P | I8: p | J8: P | K8: P | L8: P | M8: P | O8: P | P8: P | Q8: P | R8: P | S8: p | AK8: =COUNTIF(F8:AJ8,"P") -> 12 | AL8: =COUNTIF(F8:AJ8,"A") -> 0
A9: 5 | B9: 143 | C9: Kinza | D9: Aijaz Ali | E9: ECE | F9: P | H9: P | I9: p | J9: P | K9: P | L9: P | M9: P | O9: P | P9: P | Q9: P | R9: P | S9: p | AK9: =COUNTIF(F9:AJ9,"P") -> 12 | AL9: =COUNTIF(F9:AJ9,"A") -> 0
A10: 6 | B10: 146 | C10: Fatima Ansari | D10: Ayaz Ali Ansari | E10: ECE | F10: P | H10: P | I10: p | J10: P | K10: P | L10: P | M10: P | O10: P | P10: P | Q10: P | R10: P | S10: p | AK10: =COUNTIF(F10:AJ10,"P") -> 12 | AL10: =COUNTIF(F10:AJ10,"A") -> 0
A11: 7 | B11: 148 | C11: Zil-e-Huma | D11: Abdul Qayoom | E11: ECE | F11: P | H11: P | I11: p | J11: P | K11: P | L11: P | M11: P | O11: P | P11: P | Q11: P | R11: P | S11: p | AK11: =COUNTIF(F11:AJ11,"P") -> 12 | AL11: =COUNTIF(F11:AJ11,"A") -> 0 | AM11: Present Days Detail
A12: 8 | B12: 150 | C12: Ayat Fatima | D12: Imran Hussain | E12: ECE | F12: P | H12: P | I12: p | J12: P | K12: P | L12: P | M12: P | O12: P | P12: P | Q12: P | R12: P | S12: p | AK12: =COUNTIF(F12:AJ12,"P") -> 12 | AL12: =COUNTIF(F12:AJ12,"A") -> 0 | AM12: Detail | AN12: Boys | AO12: Girls | AP12: Total
A13: 9 | B13: 151 | C13: Aqsa | D13: Ahsan Ali | E13: ECE | F13: P | H13: P | I13: p | J13: P | K13: P | L13: P | M13: P | O13: P | P13: P | Q13: P | R13: P | S13: p | AK13: =COUNTIF(F13:AJ13,"P") -> 12 | AL13: =COUNTIF(F13:AJ13,"A") -> 0 | AM13: Due Present days | AN13: =30*$AN$5 -> 360 | AO13: =23*$AN$5 -> 276 | AP13: =SUM(AN13:AO13) -> 636
A14: 10 | B14: 160 | C14: Safa | D14: Dil Murad | E14: ECE | F14: P | H14: P | I14: p | J14: P | K14: P | L14: P | M14: P | O14: P | P14: P | Q14: P | R14: P | S14: p | AK14: =COUNTIF(F14:AJ14,"P") -> 12 | AL14: =COUNTIF(F14:AJ14,"A") -> 0 | AM14: Actual present days | AN14: =SUM(AK28:AK57) -> 355 | AO14: =SUM(AK5:AK27) -> 268 | AP14: =AN14+AO14 -> 623
A15: 11 | B15: 161 | C15: Hifza | D15: Zakir Ali | E15: ECE | F15: A | H15: P | I15: p | J15: P | K15: P | L15: P | M15: P | O15: P | P15: P | Q15: P | R15: P | S15: A | AK15: =COUNTIF(F15:AJ15,"P") -> 10 | AL15: =COUNTIF(F15:AJ15,"A") -> 2 | AM15: % | AN15: =AN14/AN13 -> 0.98611111 | AO15: =AO14/AO13 -> 0.97101449 | AP15: =AP14/AP13 -> 0.97955975
A16: 12 | B16: 162 | C16: Zameeran | D16: Babar Ali | E16: ECE | F16: P | H16: P | I16: p | J16: P | K16: P | L16: P | M16: P | O16: P | P16: P | Q16: P | R16: P | S16: P | AK16: =COUNTIF(F16:AJ16,"P") -> 12 | AL16: =COUNTIF(F16:AJ16,"A") -> 0
A17: 13 | B17: 163 | C17: Parwisha | D17: Sarfaraz Ahmed | E17: ECE | F17: P | H17: P | I17: p | J17: P | K17: P | L17: P | M17: P | O17: P | P17: P | Q17: P | R17: P | S17: P | AK17: =COUNTIF(F17:AJ17,"P") -> 12 | AL17: =COUNTIF(F17:AJ17,"A") -> 0
A18: 14 | B18: 166 | C18: Aiza | D18: Irshad-Ul-Haq | E18: ECE | F18: P | H18: P | I18: p | J18: P | K18: P | L18: P | M18: P | O18: P | P18: P | Q18: P | R18: P | S18: P | AK18: =COUNTIF(F18:AJ18,"P") -> 12 | AL18: =COUNTIF(F18:AJ18,"A") -> 0
A19: 15 | B19: 168 | C19: Shazia | D19: Rashid Ali | E19: ECE | F19: P | H19: P | I19: p | J19: P | K19: P | L19: P | M19: P | O19: P | P19: P | Q19: P | R19: P | S19: P | AK19: =COUNTIF(F19:AJ19,"P") -> 12 | AL19: =COUNTIF(F19:AJ19,"A") -> 0 | AM19: Absent Days Details
A20: 16 | B20: 170 | C20: Ume Farwa | D20: Meer Ameer-u-Din | E20: ECE | F20: P | H20: P | I20: p | J20: P | K20: P | L20: P | M20: P | O20: P | P20: P | Q20: P | R20: P | S20: P | AK20: =COUNTIF(F20:AJ20,"P") -> 12 | AL20: =COUNTIF(F20:AJ20,"A") -> 0 | AM20: Detail | AN20: Boys | AO20: Girls | AP20: Total
A21: 17 | B21: 171 | C21: Ume Rubab | D21: Mohsin Ali | E21: ECE | F21: P | H21: P | I21: p | J21: P | K21: P | L21: P | M21: P | O21: L | P21: L | Q21: L | R21: L | S21: P | AK21: =COUNTIF(F21:AJ21,"P") -> 8 | AL21: =COUNTIF(F21:AJ21,"A") -> 0 | AM21: Due Present days | AN21: =30*$AN$5 -> 360 | AO21: =23*$AN$5 -> 276 | AP21: =AN21+AO21 -> 636
A22: 18 | B22: 172 | C22: Khatija | D22: M. Afzal | E22: ECE | F22: P | H22: P | I22: p | J22: P | K22: P | L22: P | M22: P | O22: P | P22: P | Q22: P | R22: P | S22: P | AK22: =COUNTIF(F22:AJ22,"P") -> 12 | AL22: =COUNTIF(F22:AJ22,"A") -> 0 | AM22: Absent days | AN22: =AN21-AN14 -> 5 | AO22: =AO21-AO14 -> 8 | AP22: =AN22+AO22 -> 13
A23: 19 | B23: 180 | C23: Fiza | D23: Ahmed | E23: ECE | F23: P | H23: P | I23: p | J23: P | K23: P | L23: P | M23: P | O23: P | P23: P | Q23: P | R23: P | S23: P | AK23: =COUNTIF(F23:AJ23,"P") -> 12 | AL23: =COUNTIF(F23:AJ23,"A") -> 0 | AM23: % | AN23: =AN22/AN21 -> 0.013888889 | AO23: =AO22/AO21 -> 0.028985507 | AP23: =AP22/AP21 -> 0.020440252
A24: 20 | B24: 181 | C24: Eshaal | D24: M. Fahad | E24: ECE | F24: P | H24: P | I24: p | J24: P | K24: P | L24: P | M24: P | O24: P | P24: P | Q24: P | R24: P | S24: P | AK24: =COUNTIF(F24:AJ24,"P") -> 12 | AL24: =COUNTIF(F24:AJ24,"A") -> 0
A25: 21 | B25: 195 | C25: Rija Batool | D25: Ghulam Mehdi | E25: ECE | F25: P | H25: P | I25: p | J25: P | K25: P | L25: P | M25: P | O25: P | P25: P | Q25: P | R25: P | S25: A | AK25: =COUNTIF(F25:AJ25,"P") -> 11 | AL25: =COUNTIF(F25:AJ25,"A") -> 1
A26: 22 | B26: 183 | C26: Mustirah | D26: Faisal | E26: ECE | F26: P | H26: P | I26: p | J26: P | K26: P | L26: P | M26: P | O26: P | P26: P | Q26: P | R26: P | S26: P | AK26: =COUNTIF(F26:AJ26,"P") -> 12 | AL26: =COUNTIF(F26:AJ26,"A") -> 0
A27: 23 | B27: 170 | C27: Hoorain Noor | D27: Muhammad Akram | E27: ECE | F27: P | H27: P | I27: p | J27: P | K27: P | L27: P | M27: P | O27: P | P27: P | Q27: P | R27: P | S27: P | AK27: =COUNTIF(F27:AJ27,"P") -> 12 | AL27: =COUNTIF(F27:AJ27,"A") -> 0
A28: 1 | B28: 189 | C28: Zakria | D28: Iqramudin | E28: ECE | F28: P | H28: P | I28: p | J28: P | K28: P | L28: P | M28: P | O28: P | P28: P | Q28: P | R28: P | S28: P | AK28: =COUNTIF(F28:AJ28,"P") -> 12 | AL28: =COUNTIF(F28:AJ28,"A") -> 0
A29: 2 | B29: 99 | C29: Rehan Ali | D29: Abdul Rehman | E29: ECE | F29: P | H29: P | I29: p | J29: P | K29: P | L29: P | M29: P | O29: P | P29: P | Q29: P | R29: P | S29: P | AK29: =COUNTIF(F29:AJ29,"P") -> 12 | AL29: =COUNTIF(F29:AJ29,"A") -> 0
A30: 3 | B30: 98 | C30: Dilkash | D30: Faraz Hussain | E30: ECE | F30: P | H30: P | I30: p | J30: P | K30: P | L30: P | M30: P | O30: P | P30: P | Q30: P | R30: P | S30: P | AK30: =COUNTIF(F30:AJ30,"P") -> 12 | AL30: =COUNTIF(F30:AJ30,"A") -> 0 | AN30: 1+AN30
A31: 4 | B31: 136 | C31: Ali | D31: Saddam Hussain | E31: ECE | F31: P | H31: P | I31: p | J31: P | K31: P | L31: A | M31: P | O31: P | P31: P | Q31: P | R31: P | S31: P | AK31: =COUNTIF(F31:AJ31,"P") -> 11 | AL31: =COUNTIF(F31:AJ31,"A") -> 1
A32: 5 | B32: 139 | C32: Mohammad Aliyan | D32: Shabir Ahmed Bhutto | E32: ECE | F32: P | H32: P | I32: p | J32: P | K32: P | L32: P | M32: P | O32: P | P32: P | Q32: P | R32: P | S32: P | AK32: =COUNTIF(F32:AJ32,"P") -> 12 | AL32: =COUNTIF(F32:AJ32,"A") -> 0
A33: 6 | B33: 142 | C33: Muhammad Sahil | D33: Irshad Ali | E33: ECE | F33: P | H33: P | I33: p | J33: P | K33: P | L33: P | M33: P | O33: P | P33: P | Q33: P | R33: P | S33: P | AK33: =COUNTIF(F33:AJ33,"P") -> 12 | AL33: =COUNTIF(F33:AJ33,"A") -> 0
A34: 7 | B34: 144 | C34: Zaryab Sultan | D34: Muhammad Zaman | E34: ECE | F34: P | H34: P | I34: p | J34: P | K34: P | L34: P | M34: P | O34: P | P34: P | Q34: P | R34: P | S34: P | AK34: =COUNTIF(F34:AJ34,"P") -> 12 | AL34: =COUNTIF(F34:AJ34,"A") -> 0
A35: 8 | B35: 145 | C35: M. Ibrahim | D35: Fayaz Ali Ansari | E35: ECE | F35: P | H35: P | I35: p | J35: P | K35: P | L35: P | M35: P | O35: P | P35: P | Q35: P | R35: P | S35: P | AK35: =COUNTIF(F35:AJ35,"P") -> 12 | AL35: =COUNTIF(F35:AJ35,"A") -> 0
A36: 9 | B36: 152 | C36: Muhammad Fawad | D36: Waseem Ahmed Channa | E36: ECE | F36: P | H36: P | I36: p | J36: P | K36: P | L36: P | M36: P | O36: P | P36: P | Q36: P | R36: P | S36: P | AK36: =COUNTIF(F36:AJ36,"P") -> 12 | AL36: =COUNTIF(F36:AJ36,"A") -> 0
A37: 10 | B37: 153 | C37: Muhammad Haris | D37: M. Shareef Niyazi | E37: ECE | F37: P | H37: P | I37: p | J37: P | K37: P | L37: P | M37: P | O37: P | P37: P | Q37: P | R37: P | S37: P | AK37: =COUNTIF(F37:AJ37,"P") -> 12 | AL37: =COUNTIF(F37:AJ37,"A") -> 0
A38: 11 | B38: 154 | C38: Muhammad Ayan | D38: Abdul Ghaffar | E38: ECE | F38: P | H38: P | I38: p | J38: P | K38: P | L38: P | M38: P | O38: P | P38: P | Q38: P | R38: P | S38: P | AK38: =COUNTIF(F38:AJ38,"P") -> 12 | AL38: =COUNTIF(F38:AJ38,"A") -> 0
A39: 12 | B39: 155 | C39: Danish | D39: Ayaz Ali | E39: ECE | F39: P | H39: P | I39: p | J39: P | K39: P | L39: P | M39: P | O39: P | P39: P | Q39: P | R39: P | S39: P | AK39: =COUNTIF(F39:AJ39,"P") -> 12 | AL39: =COUNTIF(F39:AJ39,"A") -> 0
A40: 13 | B40: 156 | C40: Mujahid Ali | D40: Sajjad Ali | E40: ECE | F40: P | H40: A | I40: A | J40: P | K40: P | L40: P | M40: P | O40: P | P40: P | Q40: P | R40: P | S40: P | AK40: =COUNTIF(F40:AJ40,"P") -> 10 | AL40: =COUNTIF(F40:AJ40,"A") -> 2
...

Sheet ECE (Daffodills)
A1: Goverment high school (SJCHS)
A2: Monthly Attendence Month of March-2025
A3: S.No | B3: GR | C3: Student Name | D3: Father Name | E3: Class | F3: =TEXT(F4,"ddd") -> Sat | G3: =TEXT(G4,"ddd") -> Sun | H3: =TEXT(H4,"ddd") -> Mon | I3: =TEXT(I4,"ddd") -> Tue | J3: =TEXT(J4,"ddd") -> Wed | K3: =TEXT(K4,"ddd") -> Thu | L3: =TEXT(L4,"ddd") -> Fri | M3: =TEXT(M4,"ddd") -> Sat | ... AJ3: =TEXT(AJ4,"ddd") -> Mon | AK3: Present | AL3: Absent | AM3: Year 2024
F4: 45717 | G4: 45718 | H4: 45719 | I4: 45720 | J4: 45721 | K4: 45722 | L4: 45723 | M4: 45724 | N4: 45725 | O4: 45726 | P4: 45727 | Q4: 45728 | R4: 45729 | S4: 45730 | T4: 45731 | U4: 45732 | V4: 45733 | W4: 45734 | X4: 45735 | Y4: 45736 | Z4: 45737 | AA4: 45738 | AB4: 45739 | AC4: 45740 | AD4: 45741 | AE4: 45742 | AF4: 45743 | AG4: 45744 | AH4: 45745 | AI4: 45746 | AJ4: 45747 | AM4: Total days | AN4: =SUM(AN5:AN8) -> 31
A5: 1 | B5: 106 | C5: Alishba Batool | D5: Irfan Ali | E5: ECE | F5: P | G5: SUNDAY - SUNDAY - SUNDAY - SUNDAY - SUNDAY - SUNDAY | H5: P | I5: P | J5: P | K5: P | L5: P | M5: P | N5: SUNDAY - SUNDAY - SUNDAY - SUNDAY - SUNDAY - SUNDAY | O5: P | P5: P | Q5: P | R5: P | S5: P | T5: Examination | AK5: =COUNTIF(F5:AJ5,"P") -> 12 | AL5: =COUNTIF(F5:AJ5,"A") -> 0 | AM5: Working days | AN5: 12
A6: 2 | B6: 75 | C6: Amna | D6: Imtiaz Hussain | E6: ECE | F6: P | H6: P | I6: P | J6: P | K6: P | L6: P | M6: P | O6: P | P6: P | Q6: P | R6: P | S6: P | AK6: =COUNTIF(F6:AJ6,"P") -> 12 | AL6: =COUNTIF(F6:AJ6,"A") -> 0 | AM6: Sunday | AN6: 2
A7: 3 | B7: 109 | C7: Aniza Memon | D7: M. Qasim | E7: ECE | F7: P | H7: P | I7: P | J7: P | K7: P | L7: P | M7: P | O7: P | P7: P | Q7: P | R7: P | S7: P | AK7: =COUNTIF(F7:AJ7,"P") -> 12 | AL7: =COUNTIF(F7:AJ7,"A") -> 0 | AM7: Examination | AN7: 17
A8: 4 | B8: 49 | C8: Areeba | D8: Altaf Hussain | E8: ECE | F8: P | H8: P | I8: P | J8: P | K8: P | L8: P | M8: P | O8: P | P8: P | Q8: P | R8: P | S8: P | AK8: =COUNTIF(F8:AJ8,"P") -> 12 | AL8: =COUNTIF(F8:AJ8,"A") -> 0
A9: 5 | B9: 104 | C9: Batool | D9: Amjad Ali | E9: ECE | F9: P | H9: P | I9: P | J9: P | K9: P | L9: P | M9: P | O9: P | P9: P | Q9: P | R9: P | S9: P | AK9: =COUNTIF(F9:AJ9,"P") -> 12 | AL9: =COUNTIF(F9:AJ9,"A") -> 0
A10: 6 | B10: 88 | C10: Dua | D10: Khalid Hussain | E10: ECE | F10: P | H10: P | I10: P | J10: P | K10: P | L10: P | M10: P | O10: P | P10: P | Q10: P | R10: P | S10: P | AK10: =COUNTIF(F10:AJ10,"P") -> 12 | AL10: =COUNTIF(F10:AJ10,"A") -> 0
A11: 7 | B11: 59 | C11: Faiza | D11: Liaqat Ali | E11: ECE | F11: P | H11: P | I11: P | J11: P | K11: P | L11: P | M11: P | O11: P | P11: P | Q11: P | R11: P | S11: P | AK11: =COUNTIF(F11:AJ11,"P") -> 12 | AL11: =COUNTIF(F11:AJ11,"A") -> 0 | AM11: Present Days Detail
A12: 8 | B12: 83 | C12: Fatima | D12: Aziz-ur-Rehman | E12: ECE | F12: P | H12: P | I12: P | J12: P | K12: P | L12: P | M12: P | O12: P | P12: P | Q12: P | R12: P | S12: P | AK12: =COUNTIF(F12:AJ12,"P") -> 12 | AL12: =COUNTIF(F12:AJ12,"A") -> 0 | AM12: Detail | AN12: Boys | AO12: Girls | AP12: Total
A13: 9 | B13: 89 | C13: Hafsa | D13: Hafeezullah | E13: ECE | F13: P | H13: P | I13: P | J13: P | K13: P | L13: P | M13: P | O13: P | P13: P | Q13: P | R13: P | S13: P | AK13: =COUNTIF(F13:AJ13,"P") -> 12 | AL13: =COUNTIF(F13:AJ13,"A") -> 0 | AM13: Due Present days | AN13: =32*$AN$5 -> 384 | AO13: =24*$AN$5 -> 288 | AP13: =SUM(AN13:AO13) -> 672
A14: 10 | B14: 86 | C14: Insha Arzoo | D14: Meeral | E14: ECE | F14: P | H14: P | I14: P | J14: P | K14: P | L14: P | M14: P | O14: P | P14: P | Q14: P | R14: P | S14: P | AK14: =COUNTIF(F14:AJ14,"P") -> 12 | AL14: =COUNTIF(F14:AJ14,"A") -> 0 | AM14: Actual present days | AN14: =SUM(AK29:AK60) -> 378 | AO14: =SUM(AK5:AK28) -> 286 | AP14: =AN14+AO14 -> 664
A15: 11 | B15: 105 | C15: Kauser Fatima | D15: Amir Jamil | E15: ECE | F15: P | H15: P | I15: P | J15: P | K15: P | L15: P | M15: P | O15: P | P15: P | Q15: P | R15: P | S15: P | AK15: =COUNTIF(F15:AJ15,"P") -> 12 | AL15: =COUNTIF(F15:AJ15,"A") -> 0 | AM15: % | AN15: =AN14/AN13 -> 0.984375 | AO15: =AO14/AO13 -> 0.99305556 | AP15: =AP14/AP13 -> 0.98809524
A16: 12 | B16: 84 | C16: Mirha | D16: M. Luqman | E16: ECE | F16: P | H16: P | I16: P | J16: P | K16: P | L16: P | M16: P | O16: P | P16: P | Q16: P | R16: P | S16: P | AK16: =COUNTIF(F16:AJ16,"P") -> 12 | AL16: =COUNTIF(F16:AJ16,"A") -> 0
A17: 13 | B17: 85 | C17: Misbah Bhutto | D17: M. Azeem | E17: ECE | F17: P | H17: P | I17: P | J17: P | K17: P | L17: P | M17: P | O17: P | P17: P | Q17: P | R17: P | S17: P | AK17: =COUNTIF(F17:AJ17,"P") -> 12 | AL17: =COUNTIF(F17:AJ17,"A") -> 0
A18: 14 | B18: 102 | C18: Rimsha | D18: Meer Ameer-ud-Din | E18: ECE | F18: P | H18: P | I18: P | J18: P | K18: P | L18: P | M18: P | O18: P | P18: P | Q18: P | R18: P | S18: P | AK18: =COUNTIF(F18:AJ18,"P") -> 12 | AL18: =COUNTIF(F18:AJ18,"A") -> 0
A19: 15 | B19: 87 | C19: Sidra Batool | D19: Muhammad Khan | E19: ECE | F19: P | H19: P | I19: P | J19: P | K19: P | L19: P | M19: P | O19: P | P19: P | Q19: A | R19: A | S19: A | AK19: =COUNTIF(F19:AJ19,"P") -> 9 | AL19: =COUNTIF(F19:AJ19,"A") -> 3 | AM19: Absent Days Details
A20: 16 | B20: 71 | C20: Sidra | D20: Khalid Hussain | E20: ECE | F20: P | H20: P | I20: P | J20: P | K20: P | L20: P | M20: P | O20: P | P20: P | Q20: P | R20: P | S20: P | AK20: =COUNTIF(F20:AJ20,"P") -> 12 | AL20: =COUNTIF(F20:AJ20,"A") -> 0 | AM20: Detail | AN20: Boys | AO20: Girls | AP20: Total
A21: 17 | B21: 81 | C21: Taniya Bibi | D21: Wazir Ali | E21: ECE | F21: A | H21: P | I21: P | J21: P | K21: P | L21: P | M21: P | O21: P | P21: P | Q21: P | R21: P | S21: P | AK21: =COUNTIF(F21:AJ21,"P") -> 11 | AL21: =COUNTIF(F21:AJ21,"A") -> 1 | AM21: Due Present days | AN21: =32*$AN$5 -> 384 | AO21: =24*$AN$5 -> 288 | AP21: =AN21+AO21 -> 672
A22: 18 | B22: 82 | C22: Tanzeela | D22: Hizbullah | E22: ECE | F22: P | H22: P | I22: P | J22: P | K22: P | L22: P | M22: P | O22: P | P22: P | Q22: P | R22: P | S22: P | AK22: =COUNTIF(F22:AJ22,"P") -> 12 | AL22: =COUNTIF(F22:AJ22,"A") -> 0 | AM22: Absent days | AN22: =AN21-AN14 -> 6 | AO22: =AO21-AO14 -> 2 | AP22: =AN22+AO22 -> 8
A23: 19 | B23: 68 | C23: Tayaba Fatima | D23: Waseem Ahmed | E23: ECE | F23: P | H23: P | I23: P | J23: P | K23: P | L23: P | M23: P | O23: P | P23: P | Q23: P | R23: P | S23: P | AK23: =COUNTIF(F23:AJ23,"P") -> 12 | AL23: =COUNTIF(F23:AJ23,"A") -> 0 | AM23: % | AN23: =AN22/AN21 -> 0.015625 | AO23: =AO22/AO21 -> 0.0069444444 | AP23: =AP22/AP21 -> 0.011904762
A24: 20 | B24: 69 | C24: Tooba Noor | D24: M. Shareef | E24: ECE | F24: P | H24: P | I24: P | J24: P | K24: P | L24: P | M24: P | O24: P | P24: P | Q24: P | R24: P | S24: P | AK24: =COUNTIF(F24:AJ24,"P") -> 12 | AL24: =COUNTIF(F24:AJ24,"A") -> 0
A25: 21 | B25: 70 | C25: Umm-e-Kulsoom | D25: Shah Ali | E25: ECE | F25: P | H25: P | I25: P | J25: P | K25: P | L25: P | M25: P | O25: P | P25: P | Q25: P | R25: P | S25: P | AK25: 14 | AL25: =COUNTIF(F25:AJ25,"A") -> 0
A26: 22 | B26: 103 | C26: Zunaira | D26: Amjad Ali | E26: ECE | F26: P | H26: P | I26: P | J26: P | K26: P | L26: P | M26: P | O26: P | P26: P | Q26: P | R26: P | S26: P | AK26: =COUNTIF(F26:AJ26,"P") -> 12 | AL26: =COUNTIF(F26:AJ26,"A") -> 0
A27: 23 | B27: 149 | C27: Sahib Khatoon | D27: A. Qayoom | E27: ECE | F27: P | H27: P | I27: P | J27: P | K27: P | L27: P | M27: P | O27: P | P27: P | Q27: P | R27: P | S27: P | AK27: =COUNTIF(F27:AJ27,"P") -> 12 | AL27: =COUNTIF(F27:AJ27,"A") -> 0
A28: 24 | B28: 169 | C28: Parsa Batool | D28: Imran Ali | E28: ECE | F28: P | H28: P | I28: P | J28: P | K28: P | L28: P | M28: P | O28: P | P28: P | Q28: P | R28: P | S28: P | AK28: =COUNTIF(F28:AJ28,"P") -> 12 | AL28: =COUNTIF(F28:AJ28,"A") -> 0
A29: 1 | B29: 61 | C29: Abrar | D29: Jan Muhammad | E29: ECE | F29: P | H29: P | I29: P | J29: P | K29: P | L29: P | M29: P | O29: P | P29: P | Q29: P | R29: P | S29: P | AK29: =COUNTIF(F29:AJ29,"P") -> 12 | AL29: =COUNTIF(F29:AJ29,"A") -> 0
A30: 2 | B30: 79 | C30: Azan Shafeeque | D30: M. Shafeeque | E30: ECE | F30: P | H30: P | I30: P | J30: P | K30: P | L30: P | M30: P | O30: P | P30: P | Q30: P | R30: P | S30: P | AK30: =COUNTIF(F30:AJ30,"P") -> 12 | AL30: =COUNTIF(F30:AJ30,"A") -> 0
A31: 3 | B31: 16 | C31: Azan Fayaz | D31: Fayaz Hussain | E31: ECE | F31: P | H31: P | I31: P | J31: P | K31: P | L31: P | M31: P | O31: P | P31: P | Q31: P | R31: P | S31: P | AK31: =COUNTIF(F31:AJ31,"P") -> 12 | AL31: =COUNTIF(F31:AJ31,"A") -> 0
A32: 4 | B32: 78 | C32: Adil Ahmed | D32: Faiz Muhammad | E32: ECE | F32: P | H32: A | I32: P | J32: P | K32: P | L32: P | M32: P | O32: P | P32: P | Q32: P | R32: P | S32: P | AK32: =COUNTIF(F32:AJ32,"P") -> 11 | AL32: =COUNTIF(F32:AJ32,"A") -> 1
A33: 5 | B33: 76 | C33: Ab. Qudoos | D33: Sikandar | E33: ECE | F33: P | H33: P | I33: P | J33: P | K33: P | L33: P | M33: P | O33: P | P33: P | Q33: P | R33: P | S33: P | AK33: =COUNTIF(F33:AJ33,"P") -> 12 | AL33: =COUNTIF(F33:AJ33,"A") -> 0
A34: 6 | B34: 95 | C34: Ab. Rehman | D34: M. Aslam | E34: ECE | F34: P | H34: P | I34: P | J34: P | K34: P | L34: P | M34: P | O34: P | P34: P | Q34: P | R34: P | S34: P | AK34: =COUNTIF(F34:AJ34,"P") -> 12 | AL34: =COUNTIF(F34:AJ34,"A") -> 0
A35: 7 | B35: 108 | C35: Arham | D35: Qasim Memon | E35: ECE | F35: P | H35: P | I35: P | J35: P | K35: P | L35: P | M35: P | O35: P | P35: P | Q35: P | R35: P | S35: P | AK35: =COUNTIF(F35:AJ35,"P") -> 12 | AL35: =COUNTIF(F35:AJ35,"A") -> 0
A36: 8 | B36: 131 | C36: Amar Farooque | D36: M. Farooque | E36: ECE | F36: P | H36: P | I36: P | J36: P | K36: P | L36: P | M36: P | O36: P | P36: P | Q36: P | R36: P | S36: P | AK36: =COUNTIF(F36:AJ36,"P") -> 12 | AL36: =COUNTIF(F36:AJ36,"A") -> 0
A37: 9 | B37: 101 | C37: Ashfaque | D37: M. Zubair | E37: ECE | F37: P | H37: P | I37: P | J37: P | K37: P | L37: P | M37: P | O37: P | P37: P | Q37: P | R37: P | S37: P | AK37: =COUNTIF(F37:AJ37,"P") -> 12 | AL37: =COUNTIF(F37:AJ37,"A") -> 0
... A60: 32 | B60: 97 | C60: Faheem | D60: M.Ibrahim | E60: ECE | F60: P | H60: A | I60: P | J60: P | K60: P | L60: P | M60: P | O60: P | P60: P | Q60: P | R60: P | S60: P | AK60: =COUNTIF(F60:AJ60,"P") -> 11 | AL60: =COUNTIF(F60:AJ60,"A") -> 1

Sheet Class-I
A1: Goverment high school (SJCHS)
A2: Monthly Attendence Month of March-2025
A3: S.No | B3: GR | C3: Student Name | D3: Father Name | E3: Class | F3: =TEXT(F4,"ddd") -> Sat | G3: =TEXT(G4,"ddd") -> Sun | H3: =TEXT(H4,"ddd") -> Mon | I3: =TEXT(I4,"ddd") -> Tue | J3: =TEXT(J4,"ddd") -> Wed | K3: =TEXT(K4,"ddd") -> Thu | L3: =TEXT(L4,"ddd") -> Fri | M3: =TEXT(M4,"ddd") -> Sat | ... AJ3: =TEXT(AJ4,"ddd") -> Mon | AK3: Present | AL3: Absent | AM3: Year 2024
F4: 45717 | G4: 45718 | H4: 45719 | I4: 45720 | J4: 45721 | K4: 45722 | L4: 45723 | M4: 45724 | N4: 45725 | O4: 45726 | P4: 45727 | Q4: 45728 | R4: 45729 | S4: 45730 | T4: 45731 | U4: 45732 | V4: 45733 | W4: 45734 | X4: 45735 | Y4: 45736 | Z4: 45737 | AA4: 45738 | AB4: 45739 | AC4: 45740 | AD4: 45741 | AE4: 45742 | AF4: 45743 | AG4: 45744 | AH4: 45745 | AI4: 45746 | AJ4: 45747 | AM4: Total days | AN4: =SUM(AN5:AN8) -> 31
A5: 1 | B5: 815 | C5: Anum | D5: M. Arif | E5: One | F5: P | G5: SUNDAY - SUNDAY - SUNDAY - SUNDAY - SUNDAY - SUNDAY - SUNDAY - SUNDAY - SUNDAY | H5: P | I5: P | J5: p | K5: P | L5: P | M5: P | N5: SUNDAY - SUNDAY - SUNDAY - SUNDAY - SUNDAY - SUNDAY - SUNDAY - SUNDAY - SUNDAY | O5: p | P5: P | Q5: P | R5: P | S5: Examination | AK5: =COUNTIF(F5:AJ5,"P") -> 11 | AL5: =COUNTIF(F5:AJ5,"A") -> 0 | AM5: Working days | AN5: 11
A6: 2 | B6: 819 | C6: Amna | D6: Saeed Ahmed | E6: One | F6: P | H6: P | I6: P | J6: P | K6: P | L6: P | M6: P | O6: p | P6: P | Q6: P | R6: P | AK6: =COUNTIF(F6:AJ6,"P") -> 11 | AL6: =COUNTIF(F6:AJ6,"A") -> 0 | AM6: Sunday | AN6: 2
A7: 3 | B7: 812 | C7: Adeeba | D7: Qurban Ali | E7: One | F7: P | H7: P | I7: P | J7: P | K7: P | L7: P | M7: P | O7: p | P7: P | Q7: P | R7: P | AK7: =COUNTIF(F7:AJ7,"P") -> 11 | AL7: =COUNTIF(F7:AJ7,"A") -> 0 | AM7: Examination | AN7: 18
A8: 4 | B8: 801 | C8: Emaan Noor | D8: Noor Mohammad | E8: One | F8: P | H8: P | I8: P | J8: P | K8: P | L8: P | M8: P | O8: p | P8: P | Q8: P | R8: P | AK8: =COUNTIF(F8:AJ8,"P") -> 11 | AL8: =COUNTIF(F8:AJ8,"A") -> 0
A9: 5 | B9: 828 | C9: Horain | D9: Saeed Ahmed | E9: One | F9: P | H9: P | I9: P | J9: P | K9: P | L9: P | M9: P | O9: p | P9: P | Q9: P | R9: P | AK9: =COUNTIF(F9:AJ9,"P") -> 11 | AL9: =COUNTIF(F9:AJ9,"A") -> 0
A10: 6 | B10: 829 | C10: Hannah | D10: Luqman Ali | E10: One | F10: P | H10: P | I10: P | J10: P | K10: P | L10: P | M10: P | O10: p | P10: P | Q10: P | R10: P | AK10: =COUNTIF(F10:AJ10,"P") -> 11 | AL10: =COUNTIF(F10:AJ10,"A") -> 0
A11: 7 | B11: 814 | C11: Horiya | D11: Siddique | E11: One | F11: P | H11: P | I11: P | J11: P | K11: P | L11: P | M11: P | O11: p | P11: P | Q11: P | R11: P | AK11: =COUNTIF(F11:AJ11,"P") -> 11 | AL11: =COUNTIF(F11:AJ11,"A") -> 0 | AM11: Present Days Detail
A12: 8 | B12: 817 | C12: Hareem Fatima | D12: Deedar Ali | E12: One | F12: P | H12: P | I12: P | J12: P | K12: P | L12: P | M12: P | O12: p | P12: P | Q12: P | R12: P | AK12: =COUNTIF(F12:AJ12,"P") -> 11 | AL12: =COUNTIF(F12:AJ12,"A") -> 0 | AM12: Detail | AN12: Boys | AO12: Girls | AP12: Total
A13: 9 | B13: 807 | C13: Maham Noor | D13: Zaheer Abbas | E13: One | F13: P | H13: P | I13: P | J13: P | K13: P | L13: P | M13: P | O13: p | P13: P | Q13: P | R13: P | AK13: =COUNTIF(F13:AJ13,"P") -> 11 | AL13: =COUNTIF(F13:AJ13,"A") -> 0 | AM13: Due Present days | AN13: =32*$AN$5 -> 352 | AO13: =23*$AN$5 -> 253 | AP13: =SUM(AN13:AO13) -> 605
A14: 10 | B14: 827 | C14: Maria | D14: Mehboob Ali | E14: One | F14: P | H14: P | I14: P | J14: P | K14: P | L14: P | M14: P | O14: p | P14: P | Q14: P | R14: A | AK14: =COUNTIF(F14:AJ14,"P") -> 10 | AL14: =COUNTIF(F14:AJ14,"A") -> 1 | AM14: Actual present days | AN14: =SUM(AK28:AK59) -> 334 | AO14: =SUM(AK5:AK27) -> 235 | AP14: =AN14+AO14 -> 569
A15: 11 | B15: 802 | C15: Mehreen | D15: M. Maroof | E15: One | F15: P | H15: P | I15: P | J15: P | K15: P | L15: P | M15: P | O15: p | P15: P | Q15: P | R15: P | AK15: =COUNTIF(F15:AJ15,"P") -> 11 | AL15: =COUNTIF(F15:AJ15,"A") -> 0 | AM15: % | AN15: =AN14/AN13 -> 0.94886364 | AO15: =AO14/AO13 -> 0.92885375 | AP15: =AP14/AP13 -> 0.94049587
A16: 12 | C16: Mahira | D16: Arbab Ali | E16: One | F16: A | H16: A | I16: A | J16: A | K16: A | L16: P | M16: P | O16: p | P16: P | Q16: P | R16: P | AK16: =COUNTIF(F16:AJ16,"P") -> 6 | AL16: =COUNTIF(F16:AJ16,"A") -> 5
A17: 13 | B17: 836 | C17: Meerab | D17: Yasir Ahmed | E17: One | F17: P | H17: P | I17: P | J17: P | K17: P | L17: P | M17: P | O17: p | P17: P | Q17: P | R17: P | AK17: =COUNTIF(F17:AJ17,"P") -> 11 | AL17: =COUNTIF(F17:AJ17,"A") -> 0
A18: 14 | B18: 835 | C18: Qudsia Zehra | D18: Awaheed Ali | E18: One | F18: P | H18: P | I18: P | J18: P | K18: P | L18: P | M18: P | O18: p | P18: P | Q18: P | R18: P | AK18: =COUNTIF(F18:AJ18,"P") -> 11 | AL18: =COUNTIF(F18:AJ18,"A") -> 0
A19: 15 | C19: Paras | D19: Sadam | E19: One | F19: P | H19: P | I19: P | J19: P | K19: P | L19: P | M19: P | O19: p | P19: P | Q19: P | R19: A | AK19: =COUNTIF(F19:AJ19,"P") -> 10 | AL19: =COUNTIF(F19:AJ19,"A") -> 1 | AM19: Absent Days Details
A20: 16 | B20: 892 | C20: Thamna Batool | D20: Shehzad | E20: One | F20: P | H20: P | I20: P | J20: P | K20: P | L20: P | M20: P | O20: p | P20: P | Q20: P | R20: P | AK20: =COUNTIF(F20:AJ20,"P") -> 11 | AL20: =COUNTIF(F20:AJ20,"A") -> 0 | AM20: Detail | AN20: Boys | AO20: Girls | AP20: Total
A21: 17 | B21: 838 | C21: Tamana Fatima | D21: Shehzad | E21: One | F21: P | H21: P | I21: P | J21: P | K21: P | L21: P | M21: P | O21: p | P21: P | Q21: P | R21: P | AK21: =COUNTIF(F21:AJ21,"P") -> 11 | AL21: =COUNTIF(F21:AJ21,"A") -> 0 | AM21: Due Present days | AN21: =32*$AN$5 -> 352 | AO21: =24*$AN$5 -> 264 | AP21: =AN21+AO21 -> 616
A22: 18 | B22: 808 | C22: Haram | D22: Moien Khan | E22: One | F22: P | H22: P | I22: P | J22: P | K22: P | L22: P | M22: P | O22: p | P22: P | Q22: P | R22: A | AK22: =COUNTIF(F22:AJ22,"P") -> 10 | AL22: =COUNTIF(F22:AJ22,"A") -> 1 | AM22: Absent days | AN22: =AN21-AN14 -> 18 | AO22: =AO21-AO14 -> 29 | AP22: =AN22+AO22 -> 47
A23: 19 | B23: 800 | C23: Ayesha | D23: A. Latif | E23: One | F23: P | H23: P | I23: P | J23: P | K23: P | L23: P | M23: P | O23: p | P23: P | Q23: P | R23: P | AK23: =COUNTIF(F23:AJ23,"P") -> 11 | AL23: =COUNTIF(F23:AJ23,"A") -> 0 | AM23: % | AN23: =AN22/AN21 -> 0.051136364 | AO23: =AO22/AO21 -> 0.10984848 | AP23: =AP22/AP21 -> 0.076298701
A24: 20 | B24: 823 | C24: Zaiba Bakhtawar | D24: Hameed | E24: One | F24: P | H24: P | I24: P | J24: P | K24: P | L24: P | M24: P | O24: p | P24: P | Q24: P | R24: P | AK24: =COUNTIF(F24:AJ24,"P") -> 11 | AL24: =COUNTIF(F24:AJ24,"A") -> 0
A25: 21 | B25: 793 | C25: Zainab | D25: A. Aziz | E25: One | F25: P | H25: P | I25: P | J25: P | K25: P | L25: P | M25: P | O25: p | P25: P | Q25: P | R25: P | AK25: =COUNTIF(F25:AJ25,"P") -> 11 | AL25: =COUNTIF(F25:AJ25,"A") -> 0
A26: 22 | B26: 811 | C26: Zainab | D26: Zulfiqar | E26: One | F26: P | H26: P | I26: P | J26: P | K26: P | L26: P | M26: P | O26: p | P26: P | Q26: P | R26: P | AK26: =COUNTIF(F26:AJ26,"P") -> 11 | AL26: =COUNTIF(F26:AJ26,"A") -> 0
A27: 23 | B27: 822 | C27: Ayat | D27: Mir Muhammad | E27: One | F27: P | H27: A | I27: A | J27: A | K27: A | L27: A | M27: A | O27: A | P27: A | Q27: A | R27: A | AK27: =COUNTIF(F27:AJ27,"P") -> 1 | AL27: =COUNTIF(F27:AJ27,"A") -> 10
A28: 1 | B28: 824 | C28: Arsalan | D28: Zulfiqar | E28: One | F28: P | H28: P | I28: P | J28: P | K28: P | L28: P | M28: P | O28: P | P28: P | Q28: P | R28: P | AK28: =COUNTIF(F28:AJ28,"P") -> 11 | AL28: =COUNTIF(F28:AJ28,"A") -> 0
A29: 2 | B29: 791 | C29: Arsalan | D29: Faheem | E29: One | F29: P | H29: P | I29: P | J29: P | K29: P | L29: P | M29: P | O29: P | P29: P | Q29: P | R29: P | AK29: =COUNTIF(F29:AJ29,"P") -> 11 | AL29: =COUNTIF(F29:AJ29,"A") -> 0
A30: 3 | B30: 809 | C30: Ahmed Nawaz | D30: Ali Nawaz | E30: One | F30: P | H30: P | I30: P | J30: P | K30: P | L30: P | M30: P | O30: P | P30: P | Q30: P | R30: P | AK30: =COUNTIF(F30:AJ30,"P") -> 11 | AL30: =COUNTIF(F30:AJ30,"A") -> 0
A31: 4 | B31: 837 | C31: A. Malik | D31: Sohail | E31: One | F31: P | H31: P | I31: P | J31: P | K31: P | L31: P | M31: P | O31: P | P31: P | Q31: P | R31: P | AK31: =COUNTIF(F31:AJ31,"P") -> 11 | AL31: =COUNTIF(F31:AJ31,"A") -> 0
A32: 5 | B32: 798 | C32: Abdullah | D32: Imtiaz | E32: One | F32: P | H32: P | I32: P | J32: P | K32: P | L32: P | M32: P | O32: P | P32: P | Q32: P | R32: P | AK32: =COUNTIF(F32:AJ32,"P") -> 11 | AL32: =COUNTIF(F32:AJ32,"A") -> 0
A33: 6 | B33: 816 | C33: Aqeel | D33: A. Ghaffar | E33: One | F33: P | H33: P | I33: P | J33: P | K33: P | L33: P | M33: P | O33: P | P33: P | Q33: P | R33: P | AK33: =COUNTIF(F33:AJ33,"P") -> 11 | AL33: =COUNTIF(F33:AJ33,"A") -> 0
A34: 7 | B34: 797 | C34: A. Wasay | D34: Aslam | E34: One | F34: P | H34: P | I34: P | J34: P | K34: P | L34: P | M34: A | O34: A | P34: A | Q34: A | R34: A | AK34: =COUNTIF(F34:AJ34,"P") -> 6 | AL34: =COUNTIF(F34:AJ34,"A") -> 5
A35: 8 | C35: A. Qadir | D35: A. Hammad | E35: One | F35: P | H35: P | I35: P | J35: P | K35: P | L35: P | M35: P | O35: P | P35: A | Q35: A | R35: P | AK35: =COUNTIF(F35:AJ35,"P") -> 9 | AL35: =COUNTIF(F35:AJ35,"A") -> 2
A36: 9 | B36: 795 | C36: Asghar Ali | D36: Akbar Ali | E36: One | F36: P | H36: P | I36: P | J36: P | K36: P | L36: P | M36: P | O36: P | P36: P | Q36: P | R36: P | AK36: =COUNTIF(F36:AJ36,"P") -> 11 | AL36: =COUNTIF(F36:AJ36,"A") -> 0
A37: 10 | B37: 796 | C37: A. Nafay | D37: Irshad ul Haq | E37: One | F37: P | H37: P | I37: P | J37: P | K37: P | L37: P | M37: P | O37: P | P37: P | Q37: P | R37: P | AK37: =COUNTIF(F37:AJ37,"P") -> 11 | AL37: =COUNTIF(F37:AJ37,"A") -> 0
A38: 11 | B38: 821 | C38: Hasaan | D38: Manzoor | E38: One | F38: P | H38: P | I38: P | J38: P | K38: P | L38: P | M38: P | O38: P | P38: P | Q38: P | R38: P | AK38: =COUNTIF(F38:AJ38,"P") -> 11 | AL38: =COUNTIF(F38:AJ38,"A") -> 0
A39: 12 | B39: 776 | C39: Hammad | D39: Rehmatullah | E39: One | F39: P | H39: P | I39: P | J39: P | K39: P | L39: P | M39: P | O39: P | P39: P | Q39: P | R39: P | AK39: =COUNTIF(F39:AJ39,"P") -> 11 | AL39: =COUNTIF(F39:AJ39,"A") -> 0
A40: 13 | B40: 820 | C40: Hammad | D40: Shahid | E40: One | F40: P | H40: P | I40: P | J40: P | K40: P | L40: P | M40: P | O40: P | P40: P | Q40: P | R40: P | AK40: =COUNTIF(F40:AJ40,"P") -> 11 | AL40: =COUNTIF(F40:AJ40,"A") -> 0
...

Sheet Class-II
A1: Goverment High School (SJCHS)
A2: Monthly Attendence Month of March-2025
A3: S.No | B3: GR | C3: Student Name | D3: Father Name | E3: Class | F3: =TEXT(F4,"ddd") -> Sat | G3: =TEXT(G4,"ddd") -> Sun | H3: =TEXT(H4,"ddd") -> Mon | I3: =TEXT(I4,"ddd") -> Tue | J3: =TEXT(J4,"ddd") -> Wed | K3: =TEXT(K4,"ddd") -> Thu | L3: =TEXT(L4,"ddd") -> Fri | M3: =TEXT(M4,"ddd") -> Sat | ... AJ3: =TEXT(AJ4,"ddd") -> Mon | AK3: Present | AL3: Absent | AM3: Year 2024
F4: 45717 | G4: 45718 | H4: 45719 | I4: 45720 | J4: 45721 | K4: 45722 | L4: 45723 | M4: 45724 | N4: 45725 | O4: 45726 | P4: 45727 | Q4: 45728 | R4: 45729 | S4: 45730 | T4: 45731 | U4: 45732 | V4: 45733 | W4: 45734 | X4: 45735 | Y4: 45736 | Z4: 45737 | AA4: 45738 | AB4: 45739 | AC4: 45740 | AD4: 45741 | AE4: 45742 | AF4: 45743 | AG4: 45744 | AH4: 45745 | AI4: 45746 | AJ4: 45747 | AM4: Total days | AN4: =SUM(AN5:AN8) -> 31
A5: 1 | B5: 772 | C5: Abiha Zehra | D5: Ab. Mateen | E5: Two | F5: P | G5: SUNDAY - SUNDAY - SUNDAY - SUNDAY - SUNDAY - SUNDAY | H5: P | I5: P | J5: P | K5: P | L5: P | M5: P | N5: SUNDAY - SUNDAY - SUNDAY - SUNDAY - SUNDAY - SUNDAY | O5: p | P5: P | Q5: P | R5: P | S5: Examination | AK5: =COUNTIF(F5:AJ5,"P") -> 11 | AL5: =COUNTIF(F5:AJ5,"A") -> 0 | AM5: Working days | AN5: 11
A6: 2 | B6: 673 | C6: Aleena Zia | D6: Khuda Baksh | E6: Two | F6: P | H6: P | I6: P | J6: P | K6: P | L6: P | M6: P | O6: p | P6: P | Q6: P | R6: P | AK6: =COUNTIF(F6:AJ6,"P") -> 11 | AL6: =COUNTIF(F6:AJ6,"A") -> 0 | AM6: Sunday | AN6: 2
A7: 3 | B7: 6523 | C7: Anumta Jamali | D7: Zaheer Abbas | E7: Two | F7: P | H7: P | I7: P | J7: P | K7: P | L7: P | M7: P | O7: p | P7: P | Q7: A | R7: P | AK7: =COUNTIF(F7:AJ7,"P") -> 10 | AL7: =COUNTIF(F7:AJ7,"A") -> 1 | AM7: Examination | AN7: 18
A8: 4 | B8: 665 | C8: Ayat | D8: Faiq Ali | E8: Two | F8: P | H8: P | I8: P | J8: P | K8: P | L8: P | M8: P | O8: p | P8: P | Q8: P | R8: P | AK8: =COUNTIF(F8:AJ8,"P") -> 11 | AL8: =COUNTIF(F8:AJ8,"A") -> 0
A9: 5 | B9: 656 | C9: Ayesha | D9: Ali Muhammad | E9: Two | F9: P | H9: P | I9: P | J9: P | K9: P | L9: P | M9: P | O9: p | P9: P | Q9: P | R9: P | AK9: =COUNTIF(F9:AJ9,"P") -> 11 | AL9: =COUNTIF(F9:AJ9,"A") -> 0
A10: 6 | B10: 910 | C10: Ayesha | D10: Zulfiqar | E10: Two | F10: P | H10: P | I10: P | J10: P | K10: P | L10: P | M10: P | O10: p | P10: P | Q10: P | R10: P | AK10: =COUNTIF(F10:AJ10,"P") -> 11 | AL10: =COUNTIF(F10:AJ10,"A") -> 0
A11: 7 | B11: 679 | C11: Dua | D11: Akbar Ali | E11: Two | F11: P | H11: P | I11: P | J11: P | K11: P | L11: P | M11: P | O11: p | P11: P | Q11: P | R11: P | AK11: =COUNTIF(F11:AJ11,"P") -> 11 | AL11: =COUNTIF(F11:AJ11,"A") -> 0 | AM11: Present Days Detail
A12: 8 | B12: 675 | C12: Fiza | D12: Akbar Ali | E12: Two | F12: P | H12: P | I12: P | J12: P | K12: P | L12: P | M12: P | O12: p | P12: P | Q12: P | R12: P | AK12: =COUNTIF(F12:AJ12,"P") -> 11 | AL12: =COUNTIF(F12:AJ12,"A") -> 0 | AM12: Detail | AN12: Boys | AO12: Girls | AP12: Total
A13: 9 | B13: 774 | C13: Jannat Fatima | D13: Zulfiqar | E13: Two | F13: P | H13: P | I13: P | J13: P | K13: P | L13: P | M13: P | O13: p | P13: P | Q13: P | R13: P | AK13: =COUNTIF(F13:AJ13,"P") -> 11 | AL13: =COUNTIF(F13:AJ13,"A") -> 0 | AM13: Due Present days | AN13: =24*$AN$5 -> 264 | AO13: =23*$AN$5 -> 253 | AP13: =SUM(AN13:AO13) -> 517
A14: 10 | B14: 655 | C14: Kashaf | D14: Abdul Rehman | E14: Two | F14: P | H14: P | I14: P | J14: P | K14: P | L14: P | M14: P | O14: p | P14: P | Q14: P | R14: P | AK14: =COUNTIF(F14:AJ14,"P") -> 11 | AL14: =COUNTIF(F14:AJ14,"A") -> 0 | AM14: Actual present days | AN14: =SUM(AK28:AK51) -> 263 | AO14: =SUM(AK5:AK27) -> 252 | AP14: =AN14+AO14 -> 515
A15: 11 | B15: 653 | C15: Kashish | D15: M. Noman | E15: Two | F15: P | H15: P | I15: P | J15: P | K15: P | L15: P | M15: P | O15: p | P15: P | Q15: P | R15: P | AK15: =COUNTIF(F15:AJ15,"P") -> 11 | AL15: =COUNTIF(F15:AJ15,"A") -> 0 | AM15: % | AN15: =AN14/AN13 -> 0.99621212 | AO15: =AO14/AO13 -> 0.99604743 | AP15: =AP14/AP13 -> 0.99613153
A16: 12 | B16: 657 | C16: Masooma | D16: M. Raheem | E16: Two | F16: P | H16: P | I16: P | J16: P | K16: P | L16: P | M16: P | O16: p | P16: P | Q16: P | R16: P | AK16: =COUNTIF(F16:AJ16,"P") -> 11 | AL16: =COUNTIF(F16:AJ16,"A") -> 0
A17: 13 | B17: 672 | C17: Muneeza | D17: Mir Amirudin | E17: Two | F17: P | H17: P | I17: P | J17: P | K17: P | L17: P | M17: P | O17: p | P17: P | Q17: P | R17: P | AK17: =COUNTIF(F17:AJ17,"P") -> 11 | AL17: =COUNTIF(F17:AJ17,"A") -> 0
A18: 14 | B18: 702 | C18: Nayyara | D18: Khalid Hussain | E18: Two | F18: P | H18: P | I18: P | J18: P | K18: P | L18: P | M18: P | O18: p | P18: P | Q18: P | R18: P | AK18: =COUNTIF(F18:AJ18,"P") -> 11 | AL18: =COUNTIF(F18:AJ18,"A") -> 0
A19: 15 | B19: 659 | C19: Rashida | D19: Sajjad Ahmed | E19: Two | F19: P | H19: P | I19: P | J19: P | K19: P | L19: P | M19: P | O19: p | P19: P | Q19: P | R19: P | AK19: =COUNTIF(F19:AJ19,"P") -> 11 | AL19: =COUNTIF(F19:AJ19,"A") -> 0 | AM19: Absent Days Details
A20: 16 | B20: 661 | C20: Rubab Zahra | D20: Abdul Aziz | E20: Two | F20: P | H20: P | I20: P | J20: P | K20: P | L20: P | M20: P | O20: p | P20: P | Q20: P | R20: P | AK20: =COUNTIF(F20:AJ20,"P") -> 11 | AL20: =COUNTIF(F20:AJ20,"A") -> 0 | AM20: Detail | AN20: Boys | AO20: Girls | AP20: Total
A21: 17 | B21: 522 | C21: Soha Jamali | D21: Sajid Ali | E21: Two | F21: P | H21: P | I21: P | J21: P | K21: P | L21: P | M21: P | O21: p | P21: P | Q21: P | R21: P | AK21: =COUNTIF(F21:AJ21,"P") -> 11 | AL21: =COUNTIF(F21:AJ21,"A") -> 0 | AM21: Due Present days | AN21: =26*$AN$5 -> 286 | AO21: =26*$AN$5 -> 286 | AP21: =AN21+AO21 -> 572
A22: 18 | B22: 654 | C22: Sehar Fatima | D22: Altaf Hussain | E22: Two | F22: P | H22: P | I22: P | J22: P | K22: P | L22: P | M22: P | O22: p | P22: P | Q22: P | R22: P | AK22: =COUNTIF(F22:AJ22,"P") -> 11 | AL22: =COUNTIF(F22:AJ22,"A") -> 0 | AM22: Absent days | AN22: =AN21-AN14 -> 23 | AO22: =AO21-AO14 -> 34 | AP22: =AN22+AO22 -> 57
A23: 19 | B23: 660 | C23: Saba | D23: Asif | E23: Two | F23: P | H23: P | I23: P | J23: P | K23: P | L23: P | M23: P | O23: p | P23: P | Q23: P | R23: P | AK23: =COUNTIF(F23:AJ23,"P") -> 11 | AL23: =COUNTIF(F23:AJ23,"A") -> 0 | AM23: % | AN23: =AN22/AN21 -> 0.08041958 | AO23: =AO22/AO21 -> 0.11888112 | AP23: =AP22/AP21 -> 0.09965035
A24: 20 | B24: 841 | C24: Sehrish | D24: Fida Hussain | E24: Two | F24: P | H24: P | I24: P | J24: P | K24: P | L24: P | M24: P | O24: p | P24: P | Q24: P | R24: P | AK24: =COUNTIF(F24:AJ24,"P") -> 11 | AL24: =COUNTIF(F24:AJ24,"A") -> 0
A25: 21 | B25: 676 | C25: Tahreem Fatima | D25: Khalid Hussain | E25: Two | F25: P | H25: P | I25: P | J25: P | K25: P | L25: P | M25: P | O25: p | P25: P | Q25: P | R25: P | AK25: =COUNTIF(F25:AJ25,"P") -> 11 | AL25: =COUNTIF(F25:AJ25,"A") -> 0
A26: 22 | B26: 658 | C26: Taskeen | D26: Amjad Ali | E26: Two | F26: P | H26: P | I26: P | J26: P | K26: P | L26: P | M26: P | O26: p | P26: P | Q26: P | R26: P | AK26: =COUNTIF(F26:AJ26,"P") -> 11 | AL26: =COUNTIF(F26:AJ26,"A") -> 0
A27: 23 | B27: 785 | C27: Zainab | D27: Sikandar | E27: Two | F27: P | H27: P | I27: P | J27: P | K27: P | L27: P | M27: P | O27: p | P27: P | Q27: P | R27: P | AK27: =COUNTIF(F27:AJ27,"P") -> 11 | AL27: =COUNTIF(F27:AJ27,"A") -> 0
A28: 1 | B28: 784 | C28: Abdul Musawir | D28: M. Ismail | E28: Two | F28: P | H28: P | I28: P | J28: P | K28: P | L28: P | M28: P | O28: p | P28: P | Q28: P | R28: P | AK28: =COUNTIF(F28:AJ28,"P") -> 11 | AL28: =COUNTIF(F28:AJ28,"A") -> 0
A29: 2 | B29: 700 | C29: Abdul Rehman | D29: Sajid Ali | E29: Two | F29: P | H29: P | I29: P | J29: P | K29: P | L29: P | M29: P | O29: p | P29: P | Q29: P | R29: P | AK29: =COUNTIF(F29:AJ29,"P") -> 11 | AL29: =COUNTIF(F29:AJ29,"A") -> 0
A30: 3 | B30: 680 | C30: Abdul Wahab | D30: Abdul Hafeez | E30: Two | F30: P | H30: P | I30: P | J30: P | K30: P | L30: P | M30: P | O30: p | P30: P | Q30: P | R30: P | AK30: =COUNTIF(F30:AJ30,"P") -> 11 | AL30: =COUNTIF(F30:AJ30,"A") -> 0
A31: 4 | B31: 650 | C31: Abdullah | D31: Riazuddin | E31: Two | F31: P | H31: P | I31: P | J31: P | K31: P | L31: P | M31: P | O31: p | P31: P | Q31: P | R31: P | AK31: =COUNTIF(F31:AJ31,"P") -> 11 | AL31: =COUNTIF(F31:AJ31,"A") -> 0
A32: 5 | B32: 911 | C32: Burair Abbas | D32: Azhar Abbas | E32: Two | F32: P | H32: P | I32: P | J32: P | K32: P | L32: P | M32: P | O32: p | P32: P | Q32: P | R32: P | AK32: =COUNTIF(F32:AJ32,"P") -> 11 | AL32: =COUNTIF(F32:AJ32,"A") -> 0
A33: 6 | B33: 683 | C33: Faizan | D33: Lutfullah | E33: Two | F33: P | H33: P | I33: P | J33: P | K33: P | L33: P | M33: P | O33: p | P33: P | Q33: P | R33: P | AK33: =COUNTIF(F33:AJ33,"P") -> 11 | AL33: =COUNTIF(F33:AJ33,"A") -> 0
A34: 7 | B34: 662 | C34: Fayaz | D34: Samano Khan | E34: Two | F34: P | H34: P | I34: P | J34: P | K34: P | L34: P | M34: P | O34: p | P34: P | Q34: P | R34: P | AK34: =COUNTIF(F34:AJ34,"P") -> 11 | AL34: =COUNTIF(F34:AJ34,"A") -> 0
A35: 8 | B35: 681 | C35: Ghulam Abbas | D35: Kamran Ali | E35: Two | F35: P | H35: P | I35: P | J35: P | K35: P | L35: P | M35: P | O35: p | P35: P | Q35: P | R35: P | AK35: =COUNTIF(F35:AJ35,"P") -> 11 | AL35: =COUNTIF(F35:AJ35,"A") -> 0
... A51: 24 | B51: 783 | C51: Zain | D51: Zahid Ali | E51: Two | F51: P | H51: P | I51: P | J51: P | K51: P | L51: P | M51: P | O51: p | P51: P | Q51: P | R51: P | AK51: =COUNTIF(F51:AJ51,"P") -> 11 | AL51: =COUNTIF(F51:AJ51,"A") -> 0

Sheet Class-III
A1: Goverment high school (SJCHS)
A2: Monthly Attendence Month of March-2025
A3: S.No | B3: GR | C3: Student Name | D3: Father Name | E3: Class | F3: =TEXT(F4,"ddd") -> Sat | G3: =TEXT(G4,"ddd") -> Sun | H3: =TEXT(H4,"ddd") -> Mon | I3: =TEXT(I4,"ddd") -> Tue | J3: =TEXT(J4,"ddd") -> Wed | K3: =TEXT(K4,"ddd") -> Thu | L3: =TEXT(L4,"ddd") -> Fri | M3: =TEXT(M4,"ddd") -> Sat | ... AJ3: =TEXT(AJ4,"ddd") -> Mon | AK3: Present | AL3: Absent | AM3: Year 2024
F4: 45717 | G4: 45718 | H4: 45719 | I4: 45720 | J4: 45721 | K4: 45722 | L4: 45723 | M4: 45724 | N4: 45725 | O4: 45726 | P4: 45727 | Q4: 45728 | R4: 45729 | S4: 45730 | T4: 45731 | U4: 45732 | V4: 45733 | W4: 45734 | X4: 45735 | Y4: 45736 | Z4: 45737 | AA4: 45738 | AB4: 45739 | AC4: 45740 | AD4: 45741 | AE4: 45742 | AF4: 45743 | AG4: 45744 | AH4: 45745 | AI4: 45746 | AJ4: 45747 | AM4: Total days | AN4: =SUM(AN5:AN8) -> 31
A5: 1 | B5: 646 | C5: Abbas Ali | D5: Deedar Ali | E5: Three | F5: P | G5: SUNDAY - SUNDAY - SUNDAY - SUNDAY - SUNDAY - SUNDAY | H5: P | I5: P | J5: P | K5: P | L5: p | M5: P | N5: SUNDAY - SUNDAY - SUNDAY - SUNDAY - SUNDAY - SUNDAY | O5: P | P5: P | Q5: P | R5: P | S5: Examination | AK5: =COUNTIF(F5:AJ5,"P") -> 11 | AL5: =COUNTIF(F5:AJ5,"A") -> 0 | AM5: Working days | AN5: 11
A6: 2 | B6: 690 | C6: Abdul Rafay | D6: Noor Ul Haq | E6: Three | F6: P | H6: P | I6: P | J6: P | K6: P | L6: p | M6: P | O6: P | P6: P | Q6: P | R6: P | AK6: =COUNTIF(F6:AJ6,"P") -> 11 | AL6: =COUNTIF(F6:AJ6,"A") -> 0 | AM6: Sunday | AN6: 2
A7: 3 | B7: 684 | C7: Abdul Rahim | D7: Abdul Hafeez | E7: Three | F7: P | H7: P | I7: P | J7: P | K7: P | L7: p | M7: P | O7: P | P7: P | Q7: P | R7: P | AK7: =COUNTIF(F7:AJ7,"P") -> 11 | AL7: =COUNTIF(F7:AJ7,"A") -> 0 | AM7: Examination | AN7: 18
A8: 4 | B8: 551 | C8: Abdullah | D8: Munawar Ali | E8: Three | F8: P | H8: P | I8: P | J8: P | K8: P | L8: p | M8: P | O8: P | P8: P | Q8: P | R8: P | AK8: =COUNTIF(F8:AJ8,"P") -> 11 | AL8: =COUNTIF(F8:AJ8,"A") -> 0
A9: 5 | B9: 490 | C9: Abdul Qudoos | D9: Waheed Ahmed | E9: Three | F9: P | H9: P | I9: P | J9: P | K9: P | L9: P | M9: P | O9: P | P9: P | Q9: P | R9: P | AK9: =COUNTIF(F9:AJ9,"P") -> 11 | AL9: =COUNTIF(F9:AJ9,"A") -> 0
A10: 6 | B10: 647 | C10: Ali Haider | D10: Akber Ali | E10: Three | F10: P | H10: P | I10: P | J10: P | K10: P | L10: P | M10: P | O10: P | P10: P | Q10: P | R10: P | AK10: =COUNTIF(F10:AJ10,"P") -> 11 | AL10: =COUNTIF(F10:AJ10,"A") -> 0
A11: 7 | B11: 908 | C11: Atteeque ur Rehman | D11: Raffique Ahmed | E11: Three | F11: P | H11: P | I11: P | J11: P | K11: P | L11: P | M11: P | O11: P | P11: P | Q11: P | R11: P | AK11: =COUNTIF(F11:AJ11,"P") -> 11 | AL11: =COUNTIF(F11:AJ11,"A") -> 0 | AM11: Present Days Detail
A12: 8 | B12: 585 | C12: Aqib Ali | D12: Abdul Ghaffar | E12: Three | F12: P | H12: P | I12: P | J12: P | K12: P | L12: P | M12: P | O12: P | P12: P | Q12: P | R12: P | AK12: =COUNTIF(F12:AJ12,"P") -> 11 | AL12: =COUNTIF(F12:AJ12,"A") -> 0 | AM12: Detail | AN12: Boys | AO12: Girls | AP12: Total
A13: 9 | B13: 555 | C13: Ayaz Ali | D13: Arbab Ali | E13: Three | F13: P | H13: P | I13: P | J13: P | K13: P | L13: P | M13: P | O13: P | P13: P | Q13: P | R13: P | AK13: =COUNTIF(F13:AJ13,"P") -> 11 | AL13: =COUNTIF(F13:AJ13,"A") -> 0 | AM13: Due Present days | AN13: =26*$AN$5 -> 286 | AO13: =23*$AN$5 -> 253 | AP13: =SUM(AN13:AO13) -> 539
A14: 10 | B14: 691 | C14: Azan | D14: Nisar Ahmed | E14: Three | F14: P | H14: P | I14: P | J14: P | K14: P | L14: P | M14: P | O14: P | P14: P | Q14: P | R14: P | AK14: =COUNTIF(F14:AJ14,"P") -> 11 | AL14: =COUNTIF(F14:AJ14,"A") -> 0 | AM14: Actual present days | AN14: =SUM(AK5:AK30) -> 275 | AO14: =SUM(AK31:AK53) -> 247 | AP14: =AN14+AO14 -> 522
A15: 11 | B15: 13 | C15: Muhammad Essa | D15: Sajid Ali | E15: Three | F15: P | H15: P | I15: P | J15: P | K15: P | L15: P | M15: P | O15: P | P15: P | Q15: P | R15: P | AK15: =COUNTIF(F15:AJ15,"P") -> 11 | AL15: =COUNTIF(F15:AJ15,"A") -> 0 | AM15: % | AN15: =AN14/AN13 -> 0.96153846 | AO15: =AO14/AO13 -> 0.97628458 | AP15: =AP14/AP13 -> 0.96846011
A16: 12 | B16: 528 | C16: Faizan Ahmed | D16: Riaz Ahmed | E16: Three | F16: P | H16: P | I16: P | J16: P | K16: P | L16: P | M16: P | O16: P | P16: A | Q16: P | R16: A | AK16: =COUNTIF(F16:AJ16,"P") -> 9 | AL16: =COUNTIF(F16:AJ16,"A") -> 2
A17: 13 | B17: 689 | C17: Haider Ali | D17: Imran Ali | E17: Three | F17: P | H17: P | I17: P | J17: P | K17: P | L17: P | M17: P | O17: P | P17: P | Q17: P | R17: P | AK17: =COUNTIF(F17:AJ17,"P") -> 11 | AL17: =COUNTIF(F17:AJ17,"A") -> 0
A18: 14 | B18: 648 | C18: Meer Alam | D18: Dil Murad | E18: Three | F18: P | H18: P | I18: P | J18: P | K18: P | L18: P | M18: P | O18: P | P18: P | Q18: P | R18: P | AK18: =COUNTIF(F18:AJ18,"P") -> 11 | AL18: =COUNTIF(F18:AJ18,"A") -> 0
A19: 15 | B19: 578 | C19: M. Ahsan | D19: M. Arif | E19: Three | F19: P | H19: P | I19: P | J19: P | K19: P | L19: P | M19: P | O19: P | P19: P | Q19: P | R19: P | AK19: =COUNTIF(F19:AJ19,"P") -> 11 | AL19: =COUNTIF(F19:AJ19,"A") -> 0 | AM19: Absent Days Details
A20: 16 | B20: 573 | C20: M. Qasim | D20: Mohsin Ali | E20: Three | F20: P | H20: P | I20: P | J20: P | K20: A | L20: L | M20: L | O20: L | P20: L | Q20: L | R20: L | AK20: =COUNTIF(F20:AJ20,"P") -> 4 | AL20: =COUNTIF(F20:AJ20,"A") -> 1 | AM20: Detail | AN20: Boys | AO20: Girls | AP20: Total
A21: 17 | B21: 479 | C21: M. Shayan | D21: Zulfiqar Ali | E21: Three | F21: P | H21: P | I21: P | J21: P | K21: P | L21: P | M21: P | O21: P | P21: P | Q21: P | R21: A | AK21: =COUNTIF(F21:AJ21,"P") -> 10 | AL21: =COUNTIF(F21:AJ21,"A") -> 1 | AM21: Due Present days | AN21: =28*$AN$5 -> 308 | AO21: =24*$AN$5 -> 264 | AP21: =AN21+AO21 -> 572
A22: 18 | B22: 575 | C22: M. Zawiyar | D22: Zulfiqar Ali Mangi | E22: Three | F22: P | H22: P | I22: P | J22: P | K22: P | L22: P | M22: P | O22: P | P22: P | Q22: P | R22: P | AK22: =COUNTIF(F22:AJ22,"P") -> 11 | AL22: =COUNTIF(F22:AJ22,"A") -> 0 | AM22: Absent days | AN22: =AN21-AN14 -> 33 | AO22: =AO21-AO14 -> 17 | AP22: =AN22+AO22 -> 50
A23: 19 | B23: 586 | C23: Muneer Ahmed | D23: Ghous Bux | E23: Three | F23: P | H23: P | I23: P | J23: P | K23: P | L23: P | M23: P | O23: P | P23: P | Q23: P | R23: P | AK23: =COUNTIF(F23:AJ23,"P") -> 11 | AL23: =COUNTIF(F23:AJ23,"A") -> 0 | AM23: % | AN23: =AN22/AN21 -> 0.10714286 | AO23: =AO22/AO21 -> 0.064393939 | AP23: =AP22/AP21 -> 0.087412587
A24: 20 | B24: 580 | C24: Saif Ali | D24: Riaz uddin Qureshi | E24: Three | F24: P | H24: P | I24: P | J24: P | K24: P | L24: P | M24: P | O24: P | P24: P | Q24: P | R24: P | AK24: =COUNTIF(F24:AJ24,"P") -> 11 | AL24: =COUNTIF(F24:AJ24,"A") -> 0
A25: 21 | B25: 583 | C25: Shah Fahad | D25: M. Ibrahim | E25: Three | F25: P | H25: P | I25: P | J25: P | K25: P | L25: P | M25: P | O25: P | P25: P | Q25: P | R25: P | AK25: =COUNTIF(F25:AJ25,"P") -> 11 | AL25: =COUNTIF(F25:AJ25,"A") -> 0
A26: 22 | B26: 480 | C26: Shehbaz Ali | D26: Zaheer Abbas | E26: Three | F26: P | H26: P | I26: P | J26: P | K26: P | L26: P | M26: P | O26: P | P26: P | Q26: P | R26: P | AK26: =COUNTIF(F26:AJ26,"P") -> 11 | AL26: =COUNTIF(F26:AJ26,"A") -> 0
A27: 23 | B27: 576 | C27: Zain Ali | D27: Zaheer Abbas | E27: Three | F27: P | H27: P | I27: P | J27: P | K27: P | L27: P | M27: P | O27: P | P27: P | Q27: P | R27: P | AK27: =COUNTIF(F27:AJ27,"P") -> 11 | AL27: =COUNTIF(F27:AJ27,"A") -> 0
A28: 24 | B28: 685 | C28: Zain Zulfiqar | D28: Zulfiqar Qureshi | E28: Three | F28: P | H28: P | I28: P | J28: P | K28: P | L28: P | M28: P | O28: P | P28: P | Q28: P | R28: P | AK28: =COUNTIF(F28:AJ28,"P") -> 11 | AL28: =COUNTIF(F28:AJ28,"A") -> 0
A29: 25 | B29: 688 | C29: Zeeshan | D29: Muneer Ahmed | E29: Three | F29: P | H29: P | I29: A | J29: P | K29: P | L29: P | M29: P | O29: P | P29: P | Q29: P | R29: P | AK29: =COUNTIF(F29:AJ29,"P") -> 10 | AL29: =COUNTIF(F29:AJ29,"A") -> 1
A30: 26 | B30: 546 | C30: Zeeshan | D30: M. Hussain | E30: Three | F30: P | H30: P | I30: P | J30: P | K30: P | L30: P | M30: P | O30: P | P30: P | Q30: P | R30: P | AK30: =COUNTIF(F30:AJ30,"P") -> 11 | AL30: =COUNTIF(F30:AJ30,"A") -> 0
A31: 1 | B31: 544 | C31: Anjuman | D31: Ab. Ghaffar | E31: Three | F31: P | H31: P | I31: P | J31: P | K31: P | L31: P | M31: P | O31: P | P31: P | Q31: P | R31: P | AK31: =COUNTIF(F31:AJ31,"P") -> 11 | AL31: =COUNTIF(F31:AJ31,"A") -> 0
A32: 2 | B32: 780 | C32: Ayeza | D32: M. Ameen Solangi | E32: Three | F32: P | H32: P | I32: P | J32: P | K32: P | L32: P | M32: P | O32: P | P32: P | Q32: P | R32: P | AK32: =COUNTIF(F32:AJ32,"P") -> 11 | AL32: =COUNTIF(F32:AJ32,"A") -> 0
A33: 3 | B33: 844 | C33: Bushra | D33: Farhan | E33: Three | F33: P | H33: P | I33: P | J33: P | K33: P | L33: P | M33: P | O33: P | P33: P | Q33: P | R33: P | AK33: =COUNTIF(F33:AJ33,"P") -> 11 | AL33: =COUNTIF(F33:AJ33,"A") -> 0
A34: 4 | B34: 569 | C34: Dua Batool | D34: Muneer Ahmed Tahiri | E34: Three | F34: P | H34: P | I34: P | J34: P | K34: P | L34: P | M34: P | O34: P | P34: P | Q34: P | R34: P | AK34: =COUNTIF(F34:AJ34,"P") -> 11 | AL34: =COUNTIF(F34:AJ34,"A") -> 0
A35: 5 | B35: 582 | C35: Fiza | D35: Hamid Ali Siyal | E35: Three | F35: P | H35: P | I35: P | J35: P | K35: P | L35: P | M35: P | O35: P | P35: P | Q35: P | R35: P | AK35: =COUNTIF(F35:AJ35,"P") -> 11 | AL35: =COUNTIF(F35:AJ35,"A") -> 0
... A53: 23 | B53: 572 | C53: Zainab Batool | D53: Mohsin Ali | E53: Three | F53: P | H53: P | I53: P | J53: P | K53: P | L53: L | M53: L | O53: L | P53: L | Q53: L | R53: L | AK53: =COUNTIF(F53:AJ53,"P") -> 5 | AL53: =COUNTIF(F53:AJ53,"A") -> 0

Sheet Class-IV
A1: Goverment high school (SJCHS)
A2: Monthly Attendence Month of March-2025
A3: S.No | C3: Student Name | D3: Father Name | E3: Class | F3: =TEXT(F4,"ddd") -> Sat | G3: =TEXT(G4,"ddd") -> Sun | H3: =TEXT(H4,"ddd") -> Mon | I3: =TEXT(I4,"ddd") -> Tue | J3: =TEXT(J4,"ddd") -> Wed | K3: =TEXT(K4,"ddd") -> Thu | L3: =TEXT(L4,"ddd") -> Fri | M3: =TEXT(M4,"ddd") -> Sat | ... AF3: =TEXT(AF4,"ddd") -> Thu | AG3: Tue | AH3: =TEXT(AH4,"ddd") -> Sat | AI3: =TEXT(AI4,"ddd") -> Sun | AJ3: =TEXT(AJ4,"ddd") -> Mon | AK3: Present | AL3: Absent | AM3: Year 2024
B4: GR | F4: 45717 | G4: 45718 | H4: 45719 | I4: 45720 | J4: 45721 | K4: 45722 | L4: 45723 | M4: 45724 | N4: 45725 | O4: 45726 | P4: 45727 | Q4: 45728 | R4: 45729 | S4: 45730 | T4: 45731 | U4: 45732 | V4: 45733 | W4: 45734 | X4: 45735 | Y4: 45736 | Z4: 45737 | AA4: 45738 | AB4: 45739 | AC4: 45740 | AD4: 45741 | AE4: 45742 | AF4: 45743 | AG4: 45744 | AH4: 45745 | AI4: 45746 | AJ4: 45747 | AM4: Total days | AN4: =SUM(AN5:AN8) -> 31
A5: 1 | B5: 527 | C5: Aqeel Ahmed | D5: Najeebullah | E5: Four | F5: P | G5: SUNDAY - SUNDAY - SUNDAY - SUNDAY - SUNDAY - SUNDAY | H5: P | I5: P | J5: P | K5: P | L5: P | M5: p | N5: SUNDAY - SUNDAY - SUNDAY - SUNDAY - SUNDAY - SUNDAY | O5: P | P5: P | Q5: P | R5: Examination | AK5: =COUNTIF(F5:AJ5,"P") -> 10 | AL5: =COUNTIF(F5:AJ5,"A") -> 0 | AM5: Working days | AN5: 10
A6: 2 | B6: 472 | C6: Alijan | D6: M. Shafique | E6: Four | F6: P | H6: P | I6: P | J6: P | K6: P | L6: P | M6: p | O6: P | P6: P | Q6: P | AK6: =COUNTIF(F6:AJ6,"P") -> 10 | AL6: =COUNTIF(F6:AJ6,"A") -> 0 | AM6: Sunday | AN6: 2
A7: 3 | B7: 549 | C7: Dost M. | D7: M. Usman | E7: Four | F7: P | H7: P | I7: P | J7: P | K7: P | L7: P | M7: p | O7: P | P7: P | Q7: P | AK7: =COUNTIF(F7:AJ7,"P") -> 10 | AL7: =COUNTIF(F7:AJ7,"A") -> 0 | AM7: Examination | AN7: 19
A8: 4 | B8: 405 | C8: Fahad | D8: Riaz | E8: Four | F8: A | H8: A | I8: A | J8: A | K8: A | L8: A | M8: A | O8: A | P8: A | Q8: A | AK8: =COUNTIF(F8:AJ8,"P") -> 0 | AL8: =COUNTIF(F8:AJ8,"A") -> 10
A9: 5 | B9: 593 | C9: Imdad Ali | D9: Hamid Ali | E9: Four | F9: P | H9: P | I9: P | J9: P | K9: P | L9: P | M9: p | O9: P | P9: P | Q9: A | AK9: =COUNTIF(F9:AJ9,"P") -> 9 | AL9: =COUNTIF(F9:AJ9,"A") -> 1
A10: 6 | B10: 548 | C10: M. Suleman | D10: Usman | E10: Four | F10: P | H10: P | I10: P | J10: P | K10: P | L10: P | M10: p | O10: P | P10: P | Q10: P | AK10: =COUNTIF(F10:AJ10,"P") -> 10 | AL10: =COUNTIF(F10:AJ10,"A") -> 0
A11: 7 | B11: 447 | C11: M. Faisal | D11: Abdull Sattar | E11: Four | F11: P | H11: P | I11: P | J11: P | K11: P | L11: P | M11: p | O11: P | P11: P | Q11: P | AK11: =COUNTIF(F11:AJ11,"P") -> 10 | AL11: =COUNTIF(F11:AJ11,"A") -> 0 | AM11: Present Days Detail
A12: 8 | B12: 501 | C12: Muzammil | D12: Deedar Ali | E12: Four | F12: P | H12: P | I12: P | J12: P | K12: P | L12: P | M12: p | O12: P | P12: P | Q12: P | AK12: =COUNTIF(F12:AJ12,"P") -> 10 | AL12: =COUNTIF(F12:AJ12,"A") -> 0 | AM12: Detail | AN12: Boys | AO12: Girls | AP12: Total
A13: 9 | B13: 497 | C13: Tanveer Ahmed | D13: Wazeer Ahmed | E13: Four | F13: P | H13: A | I13: P | J13: P | K13: P | L13: P | M13: p | O13: P | P13: P | Q13: P | AK13: =COUNTIF(F13:AJ13,"P") -> 9 | AL13: =COUNTIF(F13:AJ13,"A") -> 1 | AM13: Due Present days | AN13: =20*$AN$5 -> 200 | AO13: =32*$AN$5 -> 320 | AP13: =SUM(AN13:AO13) -> 520
A14: 10 | B14: 550 | C14: Zain | D14: Zaheer Ahmed | E14: Four | F14: P | H14: P | I14: P | J14: P | K14: P | L14: P | M14: p | O14: P | P14: P | Q14: P | AK14: =COUNTIF(F14:AJ14,"P") -> 10 | AL14: =COUNTIF(F14:AJ14,"A") -> 0 | AM14: Actual present days | AN14: =SUM(AK5:AK24) -> 178 | AO14: =SUM(AK25:AK56) -> 305 | AP14: =AN14+AO14 -> 483
A15: 11 | B15: 433 | C15: Zulfiqar | D15: Nazeer Ali | E15: Four | F15: P | H15: P | I15: P | J15: P | K15: P | L15: P | M15: p | O15: P | P15: P | Q15: P | AK15: =COUNTIF(F15:AJ15,"P") -> 10 | AL15: =COUNTIF(F15:AJ15,"A") -> 0 | AM15: % | AN15: =AN14/AN13 -> 0.89 | AO15: =AO14/AO13 -> 0.953125 | AP15: =AP14/AP13 -> 0.92884615
A16: 12 | B16: 495 | C16: Tasawur Ali | D16: Ahsan Ali | E16: Four | F16: P | H16: P | I16: P | J16: P | K16: P | L16: P | M16: p | O16: P | P16: P | Q16: P | AK16: =COUNTIF(F16:AJ16,"P") -> 10 | AL16: =COUNTIF(F16:AJ16,"A") -> 0
A17: 13 | B17: 595 | C17: Zain-ul-Abdin | D17: Dill Murad | E17: Four | F17: P | H17: P | I17: P | J17: P | K17: P | L17: P | M17: p | O17: P | P17: P | Q17: P | AK17: =COUNTIF(F17:AJ17,"P") -> 10 | AL17: =COUNTIF(F17:AJ17,"A") -> 0
A18: 14 | B18: 497 | C18: Sameer Ali | D18: Gulbahar Ali | E18: Four | F18: P | H18: P | I18: P | J18: P | K18: P | L18: P | M18: p | O18: P | P18: P | Q18: P | AK18: =COUNTIF(F18:AJ18,"P") -> 10 | AL18: =COUNTIF(F18:AJ18,"A") -> 0
A19: 15 | B19: 883 | C19: M. Anees | D19: M. Ramzan | E19: Four | F19: P | H19: P | I19: P | J19: P | K19: P | L19: P | M19: p | O19: P | P19: P | Q19: P | AK19: =COUNTIF(F19:AJ19,"P") -> 10 | AL19: =COUNTIF(F19:AJ19,"A") -> 0 | AM19: Absent Days Details
